Workbook

Sheet 20Trips
A1: trip_id | B1: duration | C1: dep_terminal | D1: arr_terminal | E1: dep_time | F1: arr_time | G1: cost_to_cs | H1: dep_min | I1: arr_min
A2: DEPOT | B2: 0 | C2: - | D2: - | E2: - | F2: - | G2: 20 | H2: - | I2: -
A3: AB1 | B3: 135 | C3: Terminal A | D3: Terminal B | E3: 0.38888889 | F3: 0.48263889 | G3: =VLOOKUP(D3,$AB$33:$AD$36,3,FALSE) -> 30 | H3: =ROUND(E3*1440,0) -> 560 | I3: =ROUND(F3*1440,0) -> 695 | S3: 1
A4: AB2 | B4: 135 | C4: Terminal A | D4: Terminal B | E4: 0.51388889 | F4: 0.60763889 | G4: =VLOOKUP(D4,$AB$33:$AD$36,3,FALSE) -> 30 | H4: =ROUND(E4*1440,0) -> 740 | I4: =ROUND(F4*1440,0) -> 875 | N4: ='20Trips'!$B$24+VLOOKUP(VLOOKUP(#REF!,'20Trips'!$A$2:$I$22,4,FALSE),'20Trips'!$AB$32:$AH$36,4,FALSE) -> #REF! | S4: =S3+1 -> 2
A5: AB3 | B5: 135 | C5: Terminal A | D5: Terminal B | E5: 0.57638889 | F5: 0.67013889 | G5: =VLOOKUP(D5,$AB$33:$AD$36,3,FALSE) -> 30 | H5: =ROUND(E5*1440,0) -> 830 | I5: =ROUND(F5*1440,0) -> 965 | S5: =S4+1 -> 3
A6: AB4 | B6: 135 | C6: Terminal A | D6: Terminal B | E6: 0.63888889 | F6: 0.73263889 | G6: =VLOOKUP(D6,$AB$33:$AD$36,3,FALSE) -> 30 | H6: =ROUND(E6*1440,0) -> 920 | I6: =ROUND(F6*1440,0) -> 1055 | S6: =S5+1 -> 4
A7: AB5 | B7: 135 | C7: Terminal A | D7: Terminal B | E7: 0.68055556 | F7: 0.77430556 | G7: =VLOOKUP(D7,$AB$33:$AD$36,3,FALSE) -> 30 | H7: =ROUND(E7*1440,0) -> 980 | I7: =ROUND(F7*1440,0) -> 1115 | S7: =S6+1 -> 5
A8: AC1 | B8: 140 | C8: Terminal A | D8: Terminal C | E8: 0.38541667 | F8: 0.48263889 | G8: =VLOOKUP(D8,$AB$33:$AD$36,3,FALSE) -> 30 | H8: =ROUND(E8*1440,0) -> 555 | I8: =ROUND(F8*1440,0) -> 695 | S8: =S7+1 -> 6
A9: AC2 | B9: 140 | C9: Terminal A | D9: Terminal C | E9: 0.46875 | F9: 0.56597222 | G9: =VLOOKUP(D9,$AB$33:$AD$36,3,FALSE) -> 30 | H9: =ROUND(E9*1440,0) -> 675 | I9: =ROUND(F9*1440,0) -> 815 | S9: =S8+1 -> 7
A10: AC3 | B10: 140 | C10: Terminal A | D10: Terminal C | E10: 0.55208333 | F10: 0.64930556 | G10: =VLOOKUP(D10,$AB$33:$AD$36,3,FALSE) -> 30 | H10: =ROUND(E10*1440,0) -> 795 | I10: =ROUND(F10*1440,0) -> 935 | S10: =S9+1 -> 8
A11: AC4 | B11: 140 | C11: Terminal A | D11: Terminal C | E11: 0.80208333 | F11: 0.89930556 | G11: =VLOOKUP(D11,$AB$33:$AD$36,3,FALSE) -> 30 | H11: =ROUND(E11*1440,0) -> 1155 | I11: =ROUND(F11*1440,0) -> 1295 | S11: =S10+1 -> 9
A12: AC5 | B12: 140 | C12: Terminal A | D12: Terminal C | E12: 0.84375 | F12: 0.94097222 | G12: =VLOOKUP(D12,$AB$33:$AD$36,3,FALSE) -> 30 | H12: =ROUND(E12*1440,0) -> 1215 | I12: =ROUND(F12*1440,0) -> 1355 | S12: =S11+1 -> 10
A13: BA1 | B13: 135 | C13: Terminal B | D13: Terminal A | E13: 0.375 | F13: 0.46875 | G13: =VLOOKUP(D13,$AB$33:$AD$36,3,FALSE) -> 30 | H13: =ROUND(E13*1440,0) -> 540 | I13: =ROUND(F13*1440,0) -> 675 | S13: =S12+1 -> 11
A14: BA2 | B14: 135 | C14: Terminal B | D14: Terminal A | E14: 0.4375 | F14: 0.53125 | G14: =VLOOKUP(D14,$AB$33:$AD$36,3,FALSE) -> 30 | H14: =ROUND(E14*1440,0) -> 630 | I14: =ROUND(F14*1440,0) -> 765 | S14: =S13+1 -> 12
A15: BA3 | B15: 135 | C15: Terminal B | D15: Terminal A | E15: 0.5 | F15: 0.59375 | G15: =VLOOKUP(D15,$AB$33:$AD$36,3,FALSE) -> 30 | H15: =ROUND(E15*1440,0) -> 720 | I15: =ROUND(F15*1440,0) -> 855 | S15: =S14+1 -> 13
A16: BA4 | B16: 135 | C16: Terminal B | D16: Terminal A | E16: 0.5625 | F16: 0.65625 | G16: =VLOOKUP(D16,$AB$33:$AD$36,3,FALSE) -> 30 | H16: =ROUND(E16*1440,0) -> 810 | I16: =ROUND(F16*1440,0) -> 945 | S16: =S15+1 -> 14
... A22: CA5 | B22: 140 | C22: Terminal C | D22: Terminal A | E22: 0.72222222 | F22: 0.81944444 | G22: =VLOOKUP(D22,$AB$33:$AD$36,3,FALSE) -> 30 | H22: =ROUND(E22*1440,0) -> 1040 | I22: =ROUND(F22*1440,0) -> 1180 | S22: =S21+1 -> 20
A23: CS1 | B23: 50 | C23: - | D23: - | E23: - | F23: - | G23: 0 | S23: =S22+1 -> 21
A24: CS1a | B24: 50 | C24: Terminal A | D24: Terminal A | E24: - | F24: - | G24: 0 | S24: =S23+1 -> 22
A25: CS2b | B25: 50 | C25: Terminal B | D25: Terminal B | E25: - | F25: - | G25: 0 | S25: =S24+1 -> 23
A26: CS3c | B26: 50 | C26: Terminal C | D26: Terminal C | E26: - | F26: - | G26: 0
A29: RESULTS
A30: ID | B30: Trips | F30: CPLEX | G30: Solution | AB30: TMAX | AC30: =MAX(F3:F22)*1440 -> 1355
A31: 0 | B31: DEPOT | G31: 0 | H31: 14 | I31: 29 | J31: 31 | K31: 13 | L31: 33 | M31: 18 | N31: 0
A32: =A31+1 -> 1 | B32: AB1 | G32: DEPOT | H32: =VLOOKUP(H31,$A$31:$B$62,2,FALSE) -> AD1 | I32: =VLOOKUP(I31,$A$31:$B$62,2,FALSE) -> DA1 | J32: =VLOOKUP(J31,$A$31:$B$62,2,FALSE) -> CS1 | K32: =VLOOKUP(K31,$A$31:$B$62,2,FALSE) -> AC5 | L32: =VLOOKUP(L31,$A$31:$B$64,2,FALSE) -> CS2b | M32: =VLOOKUP(M31,$A$31:$B$62,2,FALSE) -> BA4 | N32: =VLOOKUP(N31,$A$31:$B$62,2,FALSE) -> DEPOT | AB32: Terminal | AC32: Min_Layover | AD32: Duration to CS1 | AE32: Duration to CS1a | AF32: Duration to CS2b | AG32: Duration to CS3c | AH32: Duration to CS4d
A33: =A32+1 -> 2 | B33: AB2 | G33: 0 | H33: 28 | I33: 24 | J33: 31 | K33: 20 | L33: 22 | M33: 33 | N33: 19 | O33: 0 | AB33: Terminal A | AC33: 15 | AD33: 30 | AE33: 10 | AF33: 145 | AG33: 150 | AH33: 220
A34: =A33+1 -> 3 | B34: AB3 | G34: =VLOOKUP(G33,$A$31:$B$62,2,FALSE) -> DEPOT | H34: =VLOOKUP(H33,$A$31:$B$62,2,FALSE) -> CD1 | I34: =VLOOKUP(I33,$A$31:$B$62,2,FALSE) -> CA2 | J34: =VLOOKUP(J33,$A$31:$B$62,2,FALSE) -> CS1 | K34: =VLOOKUP(K33,$A$31:$B$62,2,FALSE) -> BA6 | L34: =VLOOKUP(L33,$A$31:$B$62,2,FALSE) -> BA8 | M34: =VLOOKUP(M33,$A$31:$B$64,2,FALSE) -> CS2b | N34: =VLOOKUP(N33,$A$31:$B$62,2,FALSE) -> BA5 | O34: =VLOOKUP(O33,$A$31:$B$62,2,FALSE) -> DEPOT | AB34: Terminal B | AC34: 15 | AD34: 30 | AE34: 145 | AF34: 10 | AG34: 155 | AH34: 160
A35: =A34+1 -> 4 | B35: AB4 | G35: 0 | H35: 10 | I35: 3 | J35: 32 | K35: 5 | L35: 32 | M35: 12 | N35: 0 | AB35: Terminal C | AC35: 15 | AD35: 30 | AE35: 150 | AF35: 155 | AG35: 10 | AH35: 280
A36: =A35+1 -> 5 | B36: AB5 | G36: =VLOOKUP(G35,$A$31:$B$62,2,FALSE) -> DEPOT | H36: =VLOOKUP(H35,$A$31:$B$62,2,FALSE) -> AC2 | I36: =VLOOKUP(I35,$A$31:$B$62,2,FALSE) -> AB3 | J36: =VLOOKUP(J35,$A$31:$B$64,2,FALSE) -> CS1a | K36: =VLOOKUP(K35,$A$31:$B$62,2,FALSE) -> AB5 | L36: =VLOOKUP(L35,$A$31:$B$64,2,FALSE) -> CS1a | M36: =VLOOKUP(M35,$A$31:$B$62,2,FALSE) -> AC4 | N36: =VLOOKUP(N35,$A$31:$B$62,2,FALSE) -> DEPOT | AB36: Terminal D | AC36: 15 | AD36: 30 | AE36: 220 | AF36: 160 | AG36: 280 | AH36: 10
A37: =A36+1 -> 6 | B37: AB6 | G37: 0 | H37: 23 | I37: 32 | J37: 2 | K37: 32 | L37: 4 | M37: 0 | AB37: CS | AC37: 100 | AD37: (MAX_DURATION == 500, time to recharge = 100 seconds)
A38: =A37+1 -> 7 | B38: AB7 | G38: =VLOOKUP(G37,$A$31:$B$62,2,FALSE) -> DEPOT | H38: =VLOOKUP(H37,$A$31:$B$62,2,FALSE) -> CA1 | I38: =VLOOKUP(I37,$A$31:$B$64,2,FALSE) -> CS1a | J38: =VLOOKUP(J37,$A$31:$B$62,2,FALSE) -> AB2 | K38: =VLOOKUP(K37,$A$31:$B$64,2,FALSE) -> CS1a | L38: =VLOOKUP(L37,$A$31:$B$62,2,FALSE) -> AB4 | M38: =VLOOKUP(M37,$A$31:$B$62,2,FALSE) -> DEPOT | AB38: MAX_DURATION | AC38: 350
A39: =A38+1 -> 8 | B39: AB8 | G39: 0 | H39: 16 | I39: 31 | J39: 26 | K39: 32 | L39: 7 | M39: 0
A40: =A39+1 -> 9 | B40: AC1 | G40: =VLOOKUP(G39,$A$31:$B$62,2,FALSE) -> DEPOT | H40: =VLOOKUP(H39,$A$31:$B$62,2,FALSE) -> BA2 | I40: =VLOOKUP(I39,$A$31:$B$62,2,FALSE) -> CS1 | J40: =VLOOKUP(J39,$A$31:$B$62,2,FALSE) -> CA4 | K40: =VLOOKUP(K39,$A$31:$B$64,2,FALSE) -> CS1a | L40: =VLOOKUP(L39,$A$31:$B$62,2,FALSE) -> AB7 | M40: =VLOOKUP(M39,$A$31:$B$62,2,FALSE) -> DEPOT
A41: =A40+1 -> 10 | B41: AC2 | G41: 0 | H41: 1 | I41: 31 | J41: 25 | K41: 32 | L41: 3 | M41: 0
A42: =A41+1 -> 11 | B42: AC3 | G42: =VLOOKUP(G41,$A$31:$B$62,2,FALSE) -> DEPOT | H42: =VLOOKUP(H41,$A$31:$B$62,2,FALSE) -> AB1 | I42: =VLOOKUP(I41,$A$31:$B$62,2,FALSE) -> CS1 | J42: =VLOOKUP(J41,$A$31:$B$62,2,FALSE) -> CA3 | K42: =VLOOKUP(K41,$A$31:$B$64,2,FALSE) -> CS1a | L42: =VLOOKUP(L41,$A$31:$B$62,2,FALSE) -> AB3 | M42: =VLOOKUP(M41,$A$31:$B$62,2,FALSE) -> DEPOT | AF42: =VLOOKUP($A5,'20Trips'!$A$3:$I$22,9,FALSE) -> 965
A43: =A42+1 -> 12 | B43: AC4 | G43: 0 | H43: 15 | I43: 30 | J43: 8 | K43: 33 | L43: 17 | M43: 31 | N43: 21 | O43: 0 | AF43: =VLOOKUP("BA6",'20Trips'!$A$3:$I$22,8,FALSE) -> #N/A
A44: =A43+1 -> 13 | B44: AC5 | G44: =VLOOKUP(G43,$A$31:$B$62,2,FALSE) -> DEPOT | H44: =VLOOKUP(H43,$A$31:$B$62,2,FALSE) -> BA1 | I44: =VLOOKUP(I43,$A$31:$B$62,2,FALSE) -> DC1 | J44: =VLOOKUP(J43,$A$31:$B$62,2,FALSE) -> AB8 | K44: =VLOOKUP(K43,$A$31:$B$64,2,FALSE) -> CS2b | L44: =VLOOKUP(L43,$A$31:$B$62,2,FALSE) -> BA3 | M44: =VLOOKUP(M43,$A$31:$B$62,2,FALSE) -> CS1 | N44: =VLOOKUP(N43,$A$31:$B$62,2,FALSE) -> BA7 | O44: =VLOOKUP(O43,$A$31:$B$62,2,FALSE) -> DEPOT
A45: =A44+1 -> 14 | B45: AD1 | G45: 0 | H45: 9 | I45: 32 | J45: 11 | K45: 31 | L45: 27 | M45: 0
A46: =A45+1 -> 15 | B46: BA1 | G46: =VLOOKUP(G45,$A$31:$B$62,2,FALSE) -> DEPOT | H46: =VLOOKUP(H45,$A$31:$B$62,2,FALSE) -> AC1 | I46: =VLOOKUP(I45,$A$31:$B$64,2,FALSE) -> CS1a | J46: =VLOOKUP(J45,$A$31:$B$62,2,FALSE) -> AC3 | K46: =VLOOKUP(K45,$A$31:$B$62,2,FALSE) -> CS1 | L46: =VLOOKUP(L45,$A$31:$B$62,2,FALSE) -> CA5 | M46: =VLOOKUP(M45,$A$31:$B$62,2,FALSE) -> DEPOT | AB46: Terminal | AC46: Min_Layover | AD46: Duration to CS1 | AE46: Duration to CS1a | AF46: Duration to CS2b | AG46: Duration to CS3c | AH46: Duration to CS4d
A47: =A46+1 -> 16 | B47: BA2 | AB47: Terminal A | AC47: 15 | AD47: 30 | AE47: 10 | AF47: 75 | AG47: 85 | AH47: 95
...

Sheet feasible_mat
B1: DEPOT | C1: AB1 | D1: AB2 | E1: AB3 | F1: AB4 | G1: AB5 | H1: AC1 | I1: AC2 | J1: AC3 | K1: AC4 | L1: AC5 | M1: BA1 | N1: BA2 | O1: BA3 | P1: BA4 | Q1: BA5 | R1: CA1 | S1: CA2 | T1: CA3 | U1: CA4 | V1: CA5
A2: DEPOT | B2: 0 | C2: 1 | D2: 1 | E2: 1 | F2: 1 | G2: 1 | H2: 1 | I2: 1 | J2: 1 | K2: 1 | L2: 1 | M2: 1 | N2: 1 | O2: 1 | P2: 1 | Q2: 1 | R2: 1 | S2: 1 | T2: 1 | U2: 1 | V2: 1
A3: AB1 | B3: 1 | C3: =IF(AND(VLOOKUP(C$1,'20Trips'!$A$3:$I$22,8,FALSE)-VLOOKUP($A3,'20Trips'!$A$3:$I$22,9,FALSE)>=VLOOKUP(VLOOKUP(C$1, '20Trips'!$A$3:$I$22,3,FALSE), '20Trips'!$AB$33:$AC$36, 2, FALSE)),1,0) -> 0 | D3: =IF(AND(VLOOKUP(D$1,'20Trips'!$A$3:$I$22,8,FALSE)-VLOOKUP($A3,'20Trips'!$A$3:$I$22,9,FALSE)>=VLOOKUP(VLOOKUP(D$1, '20Trips'!$A$3:$I$22,3,FALSE), '20Trips'!$AB$33:$AC$36, 2, FALSE)),1,0) -> 1 | E3: =IF(AND(VLOOKUP(E$1,'20Trips'!$A$3:$I$22,8,FALSE)-VLOOKUP($A3,'20Trips'!$A$3:$I$22,9,FALSE)>=VLOOKUP(VLOOKUP(E$1, '20Trips'!$A$3:$I$22,3,FALSE), '20Trips'!$AB$33:$AC$36, 2, FALSE)),1,0) -> 1 | F3: =IF(AND(VLOOKUP(F$1,'20Trips'!$A$3:$I$22,8,FALSE)-VLOOKUP($A3,'20Trips'!$A$3:$I$22,9,FALSE)>=VLOOKUP(VLOOKUP(F$1, '20Trips'!$A$3:$I$22,3,FALSE), '20Trips'!$AB$33:$AC$36, 2, FALSE)),1,0) -> 1 | G3: =IF(AND(VLOOKUP(G$1,'20Trips'!$A$3:$I$22,8,FALSE)-VLOOKUP($A3,'20Trips'!$A$3:$I$22,9,FALSE)>=VLOOKUP(VLOOKUP(G$1, '20Trips'!$A$3:$I$22,3,FALSE), '20Trips'!$AB$33:$AC$36, 2, FALSE)),1,0) -> 1 | H3: =IF(AND(VLOOKUP(H$1,'20Trips'!$A$3:$I$22,8,FALSE)-VLOOKUP($A3,'20Trips'!$A$3:$I$22,9,FALSE)>=VLOOKUP(VLOOKUP(H$1, '20Trips'!$A$3:$I$22,3,FALSE), '20Trips'!$AB$33:$AC$36, 2, FALSE)),1,0) -> 0 | I3: =IF(AND(VLOOKUP(I$1,'20Trips'!$A$3:$I$22,8,FALSE)-VLOOKUP($A3,'20Trips'!$A$3:$I$22,9,FALSE)>=VLOOKUP(VLOOKUP(I$1, '20Trips'!$A$3:$I$22,3,FALSE), '20Trips'!$AB$33:$AC$36, 2, FALSE)),1,0) -> 0 | J3: =IF(AND(VLOOKUP(J$1,'20Trips'!$A$3:$I$22,8,FALSE)-VLOOKUP($A3,'20Trips'!$A$3:$I$22,9,FALSE)>=VLOOKUP(VLOOKUP(J$1, '20Trips'!$A$3:$I$22,3,FALSE), '20Trips'!$AB$33:$AC$36, 2, FALSE)),1,0) -> 1 | ... V3: =IF(AND(VLOOKUP(V$1,'20Trips'!$A$3:$I$22,8,FALSE)-VLOOKUP($A3,'20Trips'!$A$3:$I$22,9,FALSE)>=VLOOKUP(VLOOKUP(V$1, '20Trips'!$A$3:$I$22,3,FALSE), '20Trips'!$AB$33:$AC$36, 2, FALSE)),1,0) -> 1
A4: AB2 | B4: 1 | C4: =IF(AND(VLOOKUP(C$1,'20Trips'!$A$3:$I$22,8,FALSE)-VLOOKUP($A4,'20Trips'!$A$3:$I$22,9,FALSE)>=VLOOKUP(VLOOKUP(C$1, '20Trips'!$A$3:$I$22,3,FALSE), '20Trips'!$AB$33:$AC$36, 2, FALSE)),1,0) -> 0 | D4: =IF(AND(VLOOKUP(D$1,'20Trips'!$A$3:$I$22,8,FALSE)-VLOOKUP($A4,'20Trips'!$A$3:$I$22,9,FALSE)>=VLOOKUP(VLOOKUP(D$1, '20Trips'!$A$3:$I$22,3,FALSE), '20Trips'!$AB$33:$AC$36, 2, FALSE)),1,0) -> 0 | E4: =IF(AND(VLOOKUP(E$1,'20Trips'!$A$3:$I$22,8,FALSE)-VLOOKUP($A4,'20Trips'!$A$3:$I$22,9,FALSE)>=VLOOKUP(VLOOKUP(E$1, '20Trips'!$A$3:$I$22,3,FALSE), '20Trips'!$AB$33:$AC$36, 2, FALSE)),1,0) -> 0 | F4: =IF(AND(VLOOKUP(F$1,'20Trips'!$A$3:$I$22,8,FALSE)-VLOOKUP($A4,'20Trips'!$A$3:$I$22,9,FALSE)>=VLOOKUP(VLOOKUP(F$1, '20Trips'!$A$3:$I$22,3,FALSE), '20Trips'!$AB$33:$AC$36, 2, FALSE)),1,0) -> 1 | G4: =IF(AND(VLOOKUP(G$1,'20Trips'!$A$3:$I$22,8,FALSE)-VLOOKUP($A4,'20Trips'!$A$3:$I$22,9,FALSE)>=VLOOKUP(VLOOKUP(G$1, '20Trips'!$A$3:$I$22,3,FALSE), '20Trips'!$AB$33:$AC$36, 2, FALSE)),1,0) -> 1 | H4: =IF(AND(VLOOKUP(H$1,'20Trips'!$A$3:$I$22,8,FALSE)-VLOOKUP($A4,'20Trips'!$A$3:$I$22,9,FALSE)>=VLOOKUP(VLOOKUP(H$1, '20Trips'!$A$3:$I$22,3,FALSE), '20Trips'!$AB$33:$AC$36, 2, FALSE)),1,0) -> 0 | I4: =IF(AND(VLOOKUP(I$1,'20Trips'!$A$3:$I$22,8,FALSE)-VLOOKUP($A4,'20Trips'!$A$3:$I$22,9,FALSE)>=VLOOKUP(VLOOKUP(I$1, '20Trips'!$A$3:$I$22,3,FALSE), '20Trips'!$AB$33:$AC$36, 2, FALSE)),1,0) -> 0 | J4: =IF(AND(VLOOKUP(J$1,'20Trips'!$A$3:$I$22,8,FALSE)-VLOOKUP($A4,'20Trips'!$A$3:$I$22,9,FALSE)>=VLOOKUP(VLOOKUP(J$1, '20Trips'!$A$3:$I$22,3,FALSE), '20Trips'!$AB$33:$AC$36, 2, FALSE)),1,0) -> 0 | ... V4: =IF(AND(VLOOKUP(V$1,'20Trips'!$A$3:$I$22,8,FALSE)-VLOOKUP($A4,'20Trips'!$A$3:$I$22,9,FALSE)>=VLOOKUP(VLOOKUP(V$1, '20Trips'!$A$3:$I$22,3,FALSE), '20Trips'!$AB$33:$AC$36, 2, FALSE)),1,0) -> 1
A5: AB3 | B5: 1 | C5: =IF(AND(VLOOKUP(C$1,'20Trips'!$A$3:$I$22,8,FALSE)-VLOOKUP($A5,'20Trips'!$A$3:$I$22,9,FALSE)>=VLOOKUP(VLOOKUP(C$1, '20Trips'!$A$3:$I$22,3,FALSE), '20Trips'!$AB$33:$AC$36, 2, FALSE)),1,0) -> 0 | D5: =IF(AND(VLOOKUP(D$1,'20Trips'!$A$3:$I$22,8,FALSE)-VLOOKUP($A5,'20Trips'!$A$3:$I$22,9,FALSE)>=VLOOKUP(VLOOKUP(D$1, '20Trips'!$A$3:$I$22,3,FALSE), '20Trips'!$AB$33:$AC$36, 2, FALSE)),1,0) -> 0 | E5: =IF(AND(VLOOKUP(E$1,'20Trips'!$A$3:$I$22,8,FALSE)-VLOOKUP($A5,'20Trips'!$A$3:$I$22,9,FALSE)>=VLOOKUP(VLOOKUP(E$1, '20Trips'!$A$3:$I$22,3,FALSE), '20Trips'!$AB$33:$AC$36, 2, FALSE)),1,0) -> 0 | F5: =IF(AND(VLOOKUP(F$1,'20Trips'!$A$3:$I$22,8,FALSE)-VLOOKUP($A5,'20Trips'!$A$3:$I$22,9,FALSE)>=VLOOKUP(VLOOKUP(F$1, '20Trips'!$A$3:$I$22,3,FALSE), '20Trips'!$AB$33:$AC$36, 2, FALSE)),1,0) -> 0 | G5: =IF(AND(VLOOKUP(G$1,'20Trips'!$A$3:$I$22,8,FALSE)-VLOOKUP($A5,'20Trips'!$A$3:$I$22,9,FALSE)>=VLOOKUP(VLOOKUP(G$1, '20Trips'!$A$3:$I$22,3,FALSE), '20Trips'!$AB$33:$AC$36, 2, FALSE)),1,0) -> 1 | H5: =IF(AND(VLOOKUP(H$1,'20Trips'!$A$3:$I$22,8,FALSE)-VLOOKUP($A5,'20Trips'!$A$3:$I$22,9,FALSE)>=VLOOKUP(VLOOKUP(H$1, '20Trips'!$A$3:$I$22,3,FALSE), '20Trips'!$AB$33:$AC$36, 2, FALSE)),1,0) -> 0 | I5: =IF(AND(VLOOKUP(I$1,'20Trips'!$A$3:$I$22,8,FALSE)-VLOOKUP($A5,'20Trips'!$A$3:$I$22,9,FALSE)>=VLOOKUP(VLOOKUP(I$1, '20Trips'!$A$3:$I$22,3,FALSE), '20Trips'!$AB$33:$AC$36, 2, FALSE)),1,0) -> 0 | J5: =IF(AND(VLOOKUP(J$1,'20Trips'!$A$3:$I$22,8,FALSE)-VLOOKUP($A5,'20Trips'!$A$3:$I$22,9,FALSE)>=VLOOKUP(VLOOKUP(J$1, '20Trips'!$A$3:$I$22,3,FALSE), '20Trips'!$AB$33:$AC$36, 2, FALSE)),1,0) -> 0 | ... V5: =IF(AND(VLOOKUP(V$1,'20Trips'!$A$3:$I$22,8,FALSE)-VLOOKUP($A5,'20Trips'!$A$3:$I$22,9,FALSE)>=VLOOKUP(VLOOKUP(V$1, '20Trips'!$A$3:$I$22,3,FALSE), '20Trips'!$AB$33:$AC$36, 2, FALSE)),1,0) -> 1
A6: AB4 | B6: 1 | C6: =IF(AND(VLOOKUP(C$1,'20Trips'!$A$3:$I$22,8,FALSE)-VLOOKUP($A6,'20Trips'!$A$3:$I$22,9,FALSE)>=VLOOKUP(VLOOKUP(C$1, '20Trips'!$A$3:$I$22,3,FALSE), '20Trips'!$AB$33:$AC$36, 2, FALSE)),1,0) -> 0 | D6: =IF(AND(VLOOKUP(D$1,'20Trips'!$A$3:$I$22,8,FALSE)-VLOOKUP($A6,'20Trips'!$A$3:$I$22,9,FALSE)>=VLOOKUP(VLOOKUP(D$1, '20Trips'!$A$3:$I$22,3,FALSE), '20Trips'!$AB$33:$AC$36, 2, FALSE)),1,0) -> 0 | E6: =IF(AND(VLOOKUP(E$1,'20Trips'!$A$3:$I$22,8,FALSE)-VLOOKUP($A6,'20Trips'!$A$3:$I$22,9,FALSE)>=VLOOKUP(VLOOKUP(E$1, '20Trips'!$A$3:$I$22,3,FALSE), '20Trips'!$AB$33:$AC$36, 2, FALSE)),1,0) -> 0 | F6: =IF(AND(VLOOKUP(F$1,'20Trips'!$A$3:$I$22,8,FALSE)-VLOOKUP($A6,'20Trips'!$A$3:$I$22,9,FALSE)>=VLOOKUP(VLOOKUP(F$1, '20Trips'!$A$3:$I$22,3,FALSE), '20Trips'!$AB$33:$AC$36, 2, FALSE)),1,0) -> 0 | G6: =IF(AND(VLOOKUP(G$1,'20Trips'!$A$3:$I$22,8,FALSE)-VLOOKUP($A6,'20Trips'!$A$3:$I$22,9,FALSE)>=VLOOKUP(VLOOKUP(G$1, '20Trips'!$A$3:$I$22,3,FALSE), '20Trips'!$AB$33:$AC$36, 2, FALSE)),1,0) -> 0 | H6: =IF(AND(VLOOKUP(H$1,'20Trips'!$A$3:$I$22,8,FALSE)-VLOOKUP($A6,'20Trips'!$A$3:$I$22,9,FALSE)>=VLOOKUP(VLOOKUP(H$1, '20Trips'!$A$3:$I$22,3,FALSE), '20Trips'!$AB$33:$AC$36, 2, FALSE)),1,0) -> 0 | I6: =IF(AND(VLOOKUP(I$1,'20Trips'!$A$3:$I$22,8,FALSE)-VLOOKUP($A6,'20Trips'!$A$3:$I$22,9,FALSE)>=VLOOKUP(VLOOKUP(I$1, '20Trips'!$A$3:$I$22,3,FALSE), '20Trips'!$AB$33:$AC$36, 2, FALSE)),1,0) -> 0 | J6: =IF(AND(VLOOKUP(J$1,'20Trips'!$A$3:$I$22,8,FALSE)-VLOOKUP($A6,'20Trips'!$A$3:$I$22,9,FALSE)>=VLOOKUP(VLOOKUP(J$1, '20Trips'!$A$3:$I$22,3,FALSE), '20Trips'!$AB$33:$AC$36, 2, FALSE)),1,0) -> 0 | ... V6: =IF(AND(VLOOKUP(V$1,'20Trips'!$A$3:$I$22,8,FALSE)-VLOOKUP($A6,'20Trips'!$A$3:$I$22,9,FALSE)>=VLOOKUP(VLOOKUP(V$1, '20Trips'!$A$3:$I$22,3,FALSE), '20Trips'!$AB$33:$AC$36, 2, FALSE)),1,0) -> 0
A7: AB5 | B7: 1 | C7: =IF(AND(VLOOKUP(C$1,'20Trips'!$A$3:$I$22,8,FALSE)-VLOOKUP($A7,'20Trips'!$A$3:$I$22,9,FALSE)>=VLOOKUP(VLOOKUP(C$1, '20Trips'!$A$3:$I$22,3,FALSE), '20Trips'!$AB$33:$AC$36, 2, FALSE)),1,0) -> 0 | D7: =IF(AND(VLOOKUP(D$1,'20Trips'!$A$3:$I$22,8,FALSE)-VLOOKUP($A7,'20Trips'!$A$3:$I$22,9,FALSE)>=VLOOKUP(VLOOKUP(D$1, '20Trips'!$A$3:$I$22,3,FALSE), '20Trips'!$AB$33:$AC$36, 2, FALSE)),1,0) -> 0 | E7: =IF(AND(VLOOKUP(E$1,'20Trips'!$A$3:$I$22,8,FALSE)-VLOOKUP($A7,'20Trips'!$A$3:$I$22,9,FALSE)>=VLOOKUP(VLOOKUP(E$1, '20Trips'!$A$3:$I$22,3,FALSE), '20Trips'!$AB$33:$AC$36, 2, FALSE)),1,0) -> 0 | F7: =IF(AND(VLOOKUP(F$1,'20Trips'!$A$3:$I$22,8,FALSE)-VLOOKUP($A7,'20Trips'!$A$3:$I$22,9,FALSE)>=VLOOKUP(VLOOKUP(F$1, '20Trips'!$A$3:$I$22,3,FALSE), '20Trips'!$AB$33:$AC$36, 2, FALSE)),1,0) -> 0 | G7: =IF(AND(VLOOKUP(G$1,'20Trips'!$A$3:$I$22,8,FALSE)-VLOOKUP($A7,'20Trips'!$A$3:$I$22,9,FALSE)>=VLOOKUP(VLOOKUP(G$1, '20Trips'!$A$3:$I$22,3,FALSE), '20Trips'!$AB$33:$AC$36, 2, FALSE)),1,0) -> 0 | H7: =IF(AND(VLOOKUP(H$1,'20Trips'!$A$3:$I$22,8,FALSE)-VLOOKUP($A7,'20Trips'!$A$3:$I$22,9,FALSE)>=VLOOKUP(VLOOKUP(H$1, '20Trips'!$A$3:$I$22,3,FALSE), '20Trips'!$AB$33:$AC$36, 2, FALSE)),1,0) -> 0 | I7: =IF(AND(VLOOKUP(I$1,'20Trips'!$A$3:$I$22,8,FALSE)-VLOOKUP($A7,'20Trips'!$A$3:$I$22,9,FALSE)>=VLOOKUP(VLOOKUP(I$1, '20Trips'!$A$3:$I$22,3,FALSE), '20Trips'!$AB$33:$AC$36, 2, FALSE)),1,0) -> 0 | J7: =IF(AND(VLOOKUP(J$1,'20Trips'!$A$3:$I$22,8,FALSE)-VLOOKUP($A7,'20Trips'!$A$3:$I$22,9,FALSE)>=VLOOKUP(VLOOKUP(J$1, '20Trips'!$A$3:$I$22,3,FALSE), '20Trips'!$AB$33:$AC$36, 2, FALSE)),1,0) -> 0 | ... V7: =IF(AND(VLOOKUP(V$1,'20Trips'!$A$3:$I$22,8,FALSE)-VLOOKUP($A7,'20Trips'!$A$3:$I$22,9,FALSE)>=VLOOKUP(VLOOKUP(V$1, '20Trips'!$A$3:$I$22,3,FALSE), '20Trips'!$AB$33:$AC$36, 2, FALSE)),1,0) -> 0
A8: AC1 | B8: 1 | C8: =IF(AND(VLOOKUP(C$1,'20Trips'!$A$3:$I$22,8,FALSE)-VLOOKUP($A8,'20Trips'!$A$3:$I$22,9,FALSE)>=VLOOKUP(VLOOKUP(C$1, '20Trips'!$A$3:$I$22,3,FALSE), '20Trips'!$AB$33:$AC$36, 2, FALSE)),1,0) -> 0 | D8: =IF(AND(VLOOKUP(D$1,'20Trips'!$A$3:$I$22,8,FALSE)-VLOOKUP($A8,'20Trips'!$A$3:$I$22,9,FALSE)>=VLOOKUP(VLOOKUP(D$1, '20Trips'!$A$3:$I$22,3,FALSE), '20Trips'!$AB$33:$AC$36, 2, FALSE)),1,0) -> 1 | E8: =IF(AND(VLOOKUP(E$1,'20Trips'!$A$3:$I$22,8,FALSE)-VLOOKUP($A8,'20Trips'!$A$3:$I$22,9,FALSE)>=VLOOKUP(VLOOKUP(E$1, '20Trips'!$A$3:$I$22,3,FALSE), '20Trips'!$AB$33:$AC$36, 2, FALSE)),1,0) -> 1 | F8: =IF(AND(VLOOKUP(F$1,'20Trips'!$A$3:$I$22,8,FALSE)-VLOOKUP($A8,'20Trips'!$A$3:$I$22,9,FALSE)>=VLOOKUP(VLOOKUP(F$1, '20Trips'!$A$3:$I$22,3,FALSE), '20Trips'!$AB$33:$AC$36, 2, FALSE)),1,0) -> 1 | G8: =IF(AND(VLOOKUP(G$1,'20Trips'!$A$3:$I$22,8,FALSE)-VLOOKUP($A8,'20Trips'!$A$3:$I$22,9,FALSE)>=VLOOKUP(VLOOKUP(G$1, '20Trips'!$A$3:$I$22,3,FALSE), '20Trips'!$AB$33:$AC$36, 2, FALSE)),1,0) -> 1 | H8: =IF(AND(VLOOKUP(H$1,'20Trips'!$A$3:$I$22,8,FALSE)-VLOOKUP($A8,'20Trips'!$A$3:$I$22,9,FALSE)>=VLOOKUP(VLOOKUP(H$1, '20Trips'!$A$3:$I$22,3,FALSE), '20Trips'!$AB$33:$AC$36, 2, FALSE)),1,0) -> 0 | I8: =IF(AND(VLOOKUP(I$1,'20Trips'!$A$3:$I$22,8,FALSE)-VLOOKUP($A8,'20Trips'!$A$3:$I$22,9,FALSE)>=VLOOKUP(VLOOKUP(I$1, '20Trips'!$A$3:$I$22,3,FALSE), '20Trips'!$AB$33:$AC$36, 2, FALSE)),1,0) -> 0 | J8: =IF(AND(VLOOKUP(J$1,'20Trips'!$A$3:$I$22,8,FALSE)-VLOOKUP($A8,'20Trips'!$A$3:$I$22,9,FALSE)>=VLOOKUP(VLOOKUP(J$1, '20Trips'!$A$3:$I$22,3,FALSE), '20Trips'!$AB$33:$AC$36, 2, FALSE)),1,0) -> 1 | ... V8: =IF(AND(VLOOKUP(V$1,'20Trips'!$A$3:$I$22,8,FALSE)-VLOOKUP($A8,'20Trips'!$A$3:$I$22,9,FALSE)>=VLOOKUP(VLOOKUP(V$1, '20Trips'!$A$3:$I$22,3,FALSE), '20Trips'!$AB$33:$AC$36, 2, FALSE)),1,0) -> 1
A9: AC2 | B9: 1 | C9: =IF(AND(VLOOKUP(C$1,'20Trips'!$A$3:$I$22,8,FALSE)-VLOOKUP($A9,'20Trips'!$A$3:$I$22,9,FALSE)>=VLOOKUP(VLOOKUP(C$1, '20Trips'!$A$3:$I$22,3,FALSE), '20Trips'!$AB$33:$AC$36, 2, FALSE)),1,0) -> 0 | D9: =IF(AND(VLOOKUP(D$1,'20Trips'!$A$3:$I$22,8,FALSE)-VLOOKUP($A9,'20Trips'!$A$3:$I$22,9,FALSE)>=VLOOKUP(VLOOKUP(D$1, '20Trips'!$A$3:$I$22,3,FALSE), '20Trips'!$AB$33:$AC$36, 2, FALSE)),1,0) -> 0 | E9: =IF(AND(VLOOKUP(E$1,'20Trips'!$A$3:$I$22,8,FALSE)-VLOOKUP($A9,'20Trips'!$A$3:$I$22,9,FALSE)>=VLOOKUP(VLOOKUP(E$1, '20Trips'!$A$3:$I$22,3,FALSE), '20Trips'!$AB$33:$AC$36, 2, FALSE)),1,0) -> 1 | F9: =IF(AND(VLOOKUP(F$1,'20Trips'!$A$3:$I$22,8,FALSE)-VLOOKUP($A9,'20Trips'!$A$3:$I$22,9,FALSE)>=VLOOKUP(VLOOKUP(F$1, '20Trips'!$A$3:$I$22,3,FALSE), '20Trips'!$AB$33:$AC$36, 2, FALSE)),1,0) -> 1 | G9: =IF(AND(VLOOKUP(G$1,'20Trips'!$A$3:$I$22,8,FALSE)-VLOOKUP($A9,'20Trips'!$A$3:$I$22,9,FALSE)>=VLOOKUP(VLOOKUP(G$1, '20Trips'!$A$3:$I$22,3,FALSE), '20Trips'!$AB$33:$AC$36, 2, FALSE)),1,0) -> 1 | H9: =IF(AND(VLOOKUP(H$1,'20Trips'!$A$3:$I$22,8,FALSE)-VLOOKUP($A9,'20Trips'!$A$3:$I$22,9,FALSE)>=VLOOKUP(VLOOKUP(H$1, '20Trips'!$A$3:$I$22,3,FALSE), '20Trips'!$AB$33:$AC$36, 2, FALSE)),1,0) -> 0 | I9: =IF(AND(VLOOKUP(I$1,'20Trips'!$A$3:$I$22,8,FALSE)-VLOOKUP($A9,'20Trips'!$A$3:$I$22,9,FALSE)>=VLOOKUP(VLOOKUP(I$1, '20Trips'!$A$3:$I$22,3,FALSE), '20Trips'!$AB$33:$AC$36, 2, FALSE)),1,0) -> 0 | J9: =IF(AND(VLOOKUP(J$1,'20Trips'!$A$3:$I$22,8,FALSE)-VLOOKUP($A9,'20Trips'!$A$3:$I$22,9,FALSE)>=VLOOKUP(VLOOKUP(J$1, '20Trips'!$A$3:$I$22,3,FALSE), '20Trips'!$AB$33:$AC$36, 2, FALSE)),1,0) -> 0 | ... V9: =IF(AND(VLOOKUP(V$1,'20Trips'!$A$3:$I$22,8,FALSE)-VLOOKUP($A9,'20Trips'!$A$3:$I$22,9,FALSE)>=VLOOKUP(VLOOKUP(V$1, '20Trips'!$A$3:$I$22,3,FALSE), '20Trips'!$AB$33:$AC$36, 2, FALSE)),1,0) -> 1
A10: AC3 | B10: 1 | C10: =IF(AND(VLOOKUP(C$1,'20Trips'!$A$3:$I$22,8,FALSE)-VLOOKUP($A10,'20Trips'!$A$3:$I$22,9,FALSE)>=VLOOKUP(VLOOKUP(C$1, '20Trips'!$A$3:$I$22,3,FALSE), '20Trips'!$AB$33:$AC$36, 2, FALSE)),1,0) -> 0 | D10: =IF(AND(VLOOKUP(D$1,'20Trips'!$A$3:$I$22,8,FALSE)-VLOOKUP($A10,'20Trips'!$A$3:$I$22,9,FALSE)>=VLOOKUP(VLOOKUP(D$1, '20Trips'!$A$3:$I$22,3,FALSE), '20Trips'!$AB$33:$AC$36, 2, FALSE)),1,0) -> 0 | E10: =IF(AND(VLOOKUP(E$1,'20Trips'!$A$3:$I$22,8,FALSE)-VLOOKUP($A10,'20Trips'!$A$3:$I$22,9,FALSE)>=VLOOKUP(VLOOKUP(E$1, '20Trips'!$A$3:$I$22,3,FALSE), '20Trips'!$AB$33:$AC$36, 2, FALSE)),1,0) -> 0 | F10: =IF(AND(VLOOKUP(F$1,'20Trips'!$A$3:$I$22,8,FALSE)-VLOOKUP($A10,'20Trips'!$A$3:$I$22,9,FALSE)>=VLOOKUP(VLOOKUP(F$1, '20Trips'!$A$3:$I$22,3,FALSE), '20Trips'!$AB$33:$AC$36, 2, FALSE)),1,0) -> 0 | G10: =IF(AND(VLOOKUP(G$1,'20Trips'!$A$3:$I$22,8,FALSE)-VLOOKUP($A10,'20Trips'!$A$3:$I$22,9,FALSE)>=VLOOKUP(VLOOKUP(G$1, '20Trips'!$A$3:$I$22,3,FALSE), '20Trips'!$AB$33:$AC$36, 2, FALSE)),1,0) -> 1 | H10: =IF(AND(VLOOKUP(H$1,'20Trips'!$A$3:$I$22,8,FALSE)-VLOOKUP($A10,'20Trips'!$A$3:$I$22,9,FALSE)>=VLOOKUP(VLOOKUP(H$1, '20Trips'!$A$3:$I$22,3,FALSE), '20Trips'!$AB$33:$AC$36, 2, FALSE)),1,0) -> 0 | I10: =IF(AND(VLOOKUP(I$1,'20Trips'!$A$3:$I$22,8,FALSE)-VLOOKUP($A10,'20Trips'!$A$3:$I$22,9,FALSE)>=VLOOKUP(VLOOKUP(I$1, '20Trips'!$A$3:$I$22,3,FALSE), '20Trips'!$AB$33:$AC$36, 2, FALSE)),1,0) -> 0 | J10: =IF(AND(VLOOKUP(J$1,'20Trips'!$A$3:$I$22,8,FALSE)-VLOOKUP($A10,'20Trips'!$A$3:$I$22,9,FALSE)>=VLOOKUP(VLOOKUP(J$1, '20Trips'!$A$3:$I$22,3,FALSE), '20Trips'!$AB$33:$AC$36, 2, FALSE)),1,0) -> 0 | ... V10: =IF(AND(VLOOKUP(V$1,'20Trips'!$A$3:$I$22,8,FALSE)-VLOOKUP($A10,'20Trips'!$A$3:$I$22,9,FALSE)>=VLOOKUP(VLOOKUP(V$1, '20Trips'!$A$3:$I$22,3,FALSE), '20Trips'!$AB$33:$AC$36, 2, FALSE)),1,0) -> 1
A11: AC4 | B11: 1 | C11: =IF(AND(VLOOKUP(C$1,'20Trips'!$A$3:$I$22,8,FALSE)-VLOOKUP($A11,'20Trips'!$A$3:$I$22,9,FALSE)>=VLOOKUP(VLOOKUP(C$1, '20Trips'!$A$3:$I$22,3,FALSE), '20Trips'!$AB$33:$AC$36, 2, FALSE)),1,0) -> 0 | D11: =IF(AND(VLOOKUP(D$1,'20Trips'!$A$3:$I$22,8,FALSE)-VLOOKUP($A11,'20Trips'!$A$3:$I$22,9,FALSE)>=VLOOKUP(VLOOKUP(D$1, '20Trips'!$A$3:$I$22,3,FALSE), '20Trips'!$AB$33:$AC$36, 2, FALSE)),1,0) -> 0 | E11: =IF(AND(VLOOKUP(E$1,'20Trips'!$A$3:$I$22,8,FALSE)-VLOOKUP($A11,'20Trips'!$A$3:$I$22,9,FALSE)>=VLOOKUP(VLOOKUP(E$1, '20Trips'!$A$3:$I$22,3,FALSE), '20Trips'!$AB$33:$AC$36, 2, FALSE)),1,0) -> 0 | F11: =IF(AND(VLOOKUP(F$1,'20Trips'!$A$3:$I$22,8,FALSE)-VLOOKUP($A11,'20Trips'!$A$3:$I$22,9,FALSE)>=VLOOKUP(VLOOKUP(F$1, '20Trips'!$A$3:$I$22,3,FALSE), '20Trips'!$AB$33:$AC$36, 2, FALSE)),1,0) -> 0 | G11: =IF(AND(VLOOKUP(G$1,'20Trips'!$A$3:$I$22,8,FALSE)-VLOOKUP($A11,'20Trips'!$A$3:$I$22,9,FALSE)>=VLOOKUP(VLOOKUP(G$1, '20Trips'!$A$3:$I$22,3,FALSE), '20Trips'!$AB$33:$AC$36, 2, FALSE)),1,0) -> 0 | H11: =IF(AND(VLOOKUP(H$1,'20Trips'!$A$3:$I$22,8,FALSE)-VLOOKUP($A11,'20Trips'!$A$3:$I$22,9,FALSE)>=VLOOKUP(VLOOKUP(H$1, '20Trips'!$A$3:$I$22,3,FALSE), '20Trips'!$AB$33:$AC$36, 2, FALSE)),1,0) -> 0 | I11: =IF(AND(VLOOKUP(I$1,'20Trips'!$A$3:$I$22,8,FALSE)-VLOOKUP($A11,'20Trips'!$A$3:$I$22,9,FALSE)>=VLOOKUP(VLOOKUP(I$1, '20Trips'!$A$3:$I$22,3,FALSE), '20Trips'!$AB$33:$AC$36, 2, FALSE)),1,0) -> 0 | J11: =IF(AND(VLOOKUP(J$1,'20Trips'!$A$3:$I$22,8,FALSE)-VLOOKUP($A11,'20Trips'!$A$3:$I$22,9,FALSE)>=VLOOKUP(VLOOKUP(J$1, '20Trips'!$A$3:$I$22,3,FALSE), '20Trips'!$AB$33:$AC$36, 2, FALSE)),1,0) -> 0 | ... V11: =IF(AND(VLOOKUP(V$1,'20Trips'!$A$3:$I$22,8,FALSE)-VLOOKUP($A11,'20Trips'!$A$3:$I$22,9,FALSE)>=VLOOKUP(VLOOKUP(V$1, '20Trips'!$A$3:$I$22,3,FALSE), '20Trips'!$AB$33:$AC$36, 2, FALSE)),1,0) -> 0
A12: AC5 | B12: 1 | C12: =IF(AND(VLOOKUP(C$1,'20Trips'!$A$3:$I$22,8,FALSE)-VLOOKUP($A12,'20Trips'!$A$3:$I$22,9,FALSE)>=VLOOKUP(VLOOKUP(C$1, '20Trips'!$A$3:$I$22,3,FALSE), '20Trips'!$AB$33:$AC$36, 2, FALSE)),1,0) -> 0 | D12: =IF(AND(VLOOKUP(D$1,'20Trips'!$A$3:$I$22,8,FALSE)-VLOOKUP($A12,'20Trips'!$A$3:$I$22,9,FALSE)>=VLOOKUP(VLOOKUP(D$1, '20Trips'!$A$3:$I$22,3,FALSE), '20Trips'!$AB$33:$AC$36, 2, FALSE)),1,0) -> 0 | E12: =IF(AND(VLOOKUP(E$1,'20Trips'!$A$3:$I$22,8,FALSE)-VLOOKUP($A12,'20Trips'!$A$3:$I$22,9,FALSE)>=VLOOKUP(VLOOKUP(E$1, '20Trips'!$A$3:$I$22,3,FALSE), '20Trips'!$AB$33:$AC$36, 2, FALSE)),1,0) -> 0 | F12: =IF(AND(VLOOKUP(F$1,'20Trips'!$A$3:$I$22,8,FALSE)-VLOOKUP($A12,'20Trips'!$A$3:$I$22,9,FALSE)>=VLOOKUP(VLOOKUP(F$1, '20Trips'!$A$3:$I$22,3,FALSE), '20Trips'!$AB$33:$AC$36, 2, FALSE)),1,0) -> 0 | G12: =IF(AND(VLOOKUP(G$1,'20Trips'!$A$3:$I$22,8,FALSE)-VLOOKUP($A12,'20Trips'!$A$3:$I$22,9,FALSE)>=VLOOKUP(VLOOKUP(G$1, '20Trips'!$A$3:$I$22,3,FALSE), '20Trips'!$AB$33:$AC$36, 2, FALSE)),1,0) -> 0 | H12: =IF(AND(VLOOKUP(H$1,'20Trips'!$A$3:$I$22,8,FALSE)-VLOOKUP($A12,'20Trips'!$A$3:$I$22,9,FALSE)>=VLOOKUP(VLOOKUP(H$1, '20Trips'!$A$3:$I$22,3,FALSE), '20Trips'!$AB$33:$AC$36, 2, FALSE)),1,0) -> 0 | I12: =IF(AND(VLOOKUP(I$1,'20Trips'!$A$3:$I$22,8,FALSE)-VLOOKUP($A12,'20Trips'!$A$3:$I$22,9,FALSE)>=VLOOKUP(VLOOKUP(I$1, '20Trips'!$A$3:$I$22,3,FALSE), '20Trips'!$AB$33:$AC$36, 2, FALSE)),1,0) -> 0 | J12: =IF(AND(VLOOKUP(J$1,'20Trips'!$A$3:$I$22,8,FALSE)-VLOOKUP($A12,'20Trips'!$A$3:$I$22,9,FALSE)>=VLOOKUP(VLOOKUP(J$1, '20Trips'!$A$3:$I$22,3,FALSE), '20Trips'!$AB$33:$AC$36, 2, FALSE)),1,0) -> 0 | ... V12: =IF(AND(VLOOKUP(V$1,'20Trips'!$A$3:$I$22,8,FALSE)-VLOOKUP($A12,'20Trips'!$A$3:$I$22,9,FALSE)>=VLOOKUP(VLOOKUP(V$1, '20Trips'!$A$3:$I$22,3,FALSE), '20Trips'!$AB$33:$AC$36, 2, FALSE)),1,0) -> 0
A13: BA1 | B13: 1 | C13: =IF(AND(VLOOKUP(C$1,'20Trips'!$A$3:$I$22,8,FALSE)-VLOOKUP($A13,'20Trips'!$A$3:$I$22,9,FALSE)>=VLOOKUP(VLOOKUP(C$1, '20Trips'!$A$3:$I$22,3,FALSE), '20Trips'!$AB$33:$AC$36, 2, FALSE)),1,0) -> 0 | D13: =IF(AND(VLOOKUP(D$1,'20Trips'!$A$3:$I$22,8,FALSE)-VLOOKUP($A13,'20Trips'!$A$3:$I$22,9,FALSE)>=VLOOKUP(VLOOKUP(D$1, '20Trips'!$A$3:$I$22,3,FALSE), '20Trips'!$AB$33:$AC$36, 2, FALSE)),1,0) -> 1 | E13: =IF(AND(VLOOKUP(E$1,'20Trips'!$A$3:$I$22,8,FALSE)-VLOOKUP($A13,'20Trips'!$A$3:$I$22,9,FALSE)>=VLOOKUP(VLOOKUP(E$1, '20Trips'!$A$3:$I$22,3,FALSE), '20Trips'!$AB$33:$AC$36, 2, FALSE)),1,0) -> 1 | F13: =IF(AND(VLOOKUP(F$1,'20Trips'!$A$3:$I$22,8,FALSE)-VLOOKUP($A13,'20Trips'!$A$3:$I$22,9,FALSE)>=VLOOKUP(VLOOKUP(F$1, '20Trips'!$A$3:$I$22,3,FALSE), '20Trips'!$AB$33:$AC$36, 2, FALSE)),1,0) -> 1 | G13: =IF(AND(VLOOKUP(G$1,'20Trips'!$A$3:$I$22,8,FALSE)-VLOOKUP($A13,'20Trips'!$A$3:$I$22,9,FALSE)>=VLOOKUP(VLOOKUP(G$1, '20Trips'!$A$3:$I$22,3,FALSE), '20Trips'!$AB$33:$AC$36, 2, FALSE)),1,0) -> 1 | H13: =IF(AND(VLOOKUP(H$1,'20Trips'!$A$3:$I$22,8,FALSE)-VLOOKUP($A13,'20Trips'!$A$3:$I$22,9,FALSE)>=VLOOKUP(VLOOKUP(H$1, '20Trips'!$A$3:$I$22,3,FALSE), '20Trips'!$AB$33:$AC$36, 2, FALSE)),1,0) -> 0 | I13: =IF(AND(VLOOKUP(I$1,'20Trips'!$A$3:$I$22,8,FALSE)-VLOOKUP($A13,'20Trips'!$A$3:$I$22,9,FALSE)>=VLOOKUP(VLOOKUP(I$1, '20Trips'!$A$3:$I$22,3,FALSE), '20Trips'!$AB$33:$AC$36, 2, FALSE)),1,0) -> 0 | J13: =IF(AND(VLOOKUP(J$1,'20Trips'!$A$3:$I$22,8,FALSE)-VLOOKUP($A13,'20Trips'!$A$3:$I$22,9,FALSE)>=VLOOKUP(VLOOKUP(J$1, '20Trips'!$A$3:$I$22,3,FALSE), '20Trips'!$AB$33:$AC$36, 2, FALSE)),1,0) -> 1 | ... V13: =IF(AND(VLOOKUP(V$1,'20Trips'!$A$3:$I$22,8,FALSE)-VLOOKUP($A13,'20Trips'!$A$3:$I$22,9,FALSE)>=VLOOKUP(VLOOKUP(V$1, '20Trips'!$A$3:$I$22,3,FALSE), '20Trips'!$AB$33:$AC$36, 2, FALSE)),1,0) -> 1
A14: BA2 | B14: 1 | C14: =IF(AND(VLOOKUP(C$1,'20Trips'!$A$3:$I$22,8,FALSE)-VLOOKUP($A14,'20Trips'!$A$3:$I$22,9,FALSE)>=VLOOKUP(VLOOKUP(C$1, '20Trips'!$A$3:$I$22,3,FALSE), '20Trips'!$AB$33:$AC$36, 2, FALSE)),1,0) -> 0 | D14: =IF(AND(VLOOKUP(D$1,'20Trips'!$A$3:$I$22,8,FALSE)-VLOOKUP($A14,'20Trips'!$A$3:$I$22,9,FALSE)>=VLOOKUP(VLOOKUP(D$1, '20Trips'!$A$3:$I$22,3,FALSE), '20Trips'!$AB$33:$AC$36, 2, FALSE)),1,0) -> 0 | E14: =IF(AND(VLOOKUP(E$1,'20Trips'!$A$3:$I$22,8,FALSE)-VLOOKUP($A14,'20Trips'!$A$3:$I$22,9,FALSE)>=VLOOKUP(VLOOKUP(E$1, '20Trips'!$A$3:$I$22,3,FALSE), '20Trips'!$AB$33:$AC$36, 2, FALSE)),1,0) -> 1 | F14: =IF(AND(VLOOKUP(F$1,'20Trips'!$A$3:$I$22,8,FALSE)-VLOOKUP($A14,'20Trips'!$A$3:$I$22,9,FALSE)>=VLOOKUP(VLOOKUP(F$1, '20Trips'!$A$3:$I$22,3,FALSE), '20Trips'!$AB$33:$AC$36, 2, FALSE)),1,0) -> 1 | G14: =IF(AND(VLOOKUP(G$1,'20Trips'!$A$3:$I$22,8,FALSE)-VLOOKUP($A14,'20Trips'!$A$3:$I$22,9,FALSE)>=VLOOKUP(VLOOKUP(G$1, '20Trips'!$A$3:$I$22,3,FALSE), '20Trips'!$AB$33:$AC$36, 2, FALSE)),1,0) -> 1 | H14: =IF(AND(VLOOKUP(H$1,'20Trips'!$A$3:$I$22,8,FALSE)-VLOOKUP($A14,'20Trips'!$A$3:$I$22,9,FALSE)>=VLOOKUP(VLOOKUP(H$1, '20Trips'!$A$3:$I$22,3,FALSE), '20Trips'!$AB$33:$AC$36, 2, FALSE)),1,0) -> 0 | I14: =IF(AND(VLOOKUP(I$1,'20Trips'!$A$3:$I$22,8,FALSE)-VLOOKUP($A14,'20Trips'!$A$3:$I$22,9,FALSE)>=VLOOKUP(VLOOKUP(I$1, '20Trips'!$A$3:$I$22,3,FALSE), '20Trips'!$AB$33:$AC$36, 2, FALSE)),1,0) -> 0 | J14: =IF(AND(VLOOKUP(J$1,'20Trips'!$A$3:$I$22,8,FALSE)-VLOOKUP($A14,'20Trips'!$A$3:$I$22,9,FALSE)>=VLOOKUP(VLOOKUP(J$1, '20Trips'!$A$3:$I$22,3,FALSE), '20Trips'!$AB$33:$AC$36, 2, FALSE)),1,0) -> 1 | ... V14: =IF(AND(VLOOKUP(V$1,'20Trips'!$A$3:$I$22,8,FALSE)-VLOOKUP($A14,'20Trips'!$A$3:$I$22,9,FALSE)>=VLOOKUP(VLOOKUP(V$1, '20Trips'!$A$3:$I$22,3,FALSE), '20Trips'!$AB$33:$AC$36, 2, FALSE)),1,0) -> 1
... A22: CA5 | B22: 1 | C22: =IF(AND(VLOOKUP(C$1,'20Trips'!$A$3:$I$22,8,FALSE)-VLOOKUP($A22,'20Trips'!$A$3:$I$22,9,FALSE)>=VLOOKUP(VLOOKUP(C$1, '20Trips'!$A$3:$I$22,3,FALSE), '20Trips'!$AB$33:$AC$36, 2, FALSE)),1,0) -> 0 | D22: =IF(AND(VLOOKUP(D$1,'20Trips'!$A$3:$I$22,8,FALSE)-VLOOKUP($A22,'20Trips'!$A$3:$I$22,9,FALSE)>=VLOOKUP(VLOOKUP(D$1, '20Trips'!$A$3:$I$22,3,FALSE), '20Trips'!$AB$33:$AC$36, 2, FALSE)),1,0) -> 0 | E22: =IF(AND(VLOOKUP(E$1,'20Trips'!$A$3:$I$22,8,FALSE)-VLOOKUP($A22,'20Trips'!$A$3:$I$22,9,FALSE)>=VLOOKUP(VLOOKUP(E$1, '20Trips'!$A$3:$I$22,3,FALSE), '20Trips'!$AB$33:$AC$36, 2, FALSE)),1,0) -> 0 | F22: =IF(AND(VLOOKUP(F$1,'20Trips'!$A$3:$I$22,8,FALSE)-VLOOKUP($A22,'20Trips'!$A$3:$I$22,9,FALSE)>=VLOOKUP(VLOOKUP(F$1, '20Trips'!$A$3:$I$22,3,FALSE), '20Trips'!$AB$33:$AC$36, 2, FALSE)),1,0) -> 0 | G22: =IF(AND(VLOOKUP(G$1,'20Trips'!$A$3:$I$22,8,FALSE)-VLOOKUP($A22,'20Trips'!$A$3:$I$22,9,FALSE)>=VLOOKUP(VLOOKUP(G$1, '20Trips'!$A$3:$I$22,3,FALSE), '20Trips'!$AB$33:$AC$36, 2, FALSE)),1,0) -> 0 | H22: =IF(AND(VLOOKUP(H$1,'20Trips'!$A$3:$I$22,8,FALSE)-VLOOKUP($A22,'20Trips'!$A$3:$I$22,9,FALSE)>=VLOOKUP(VLOOKUP(H$1, '20Trips'!$A$3:$I$22,3,FALSE), '20Trips'!$AB$33:$AC$36, 2, FALSE)),1,0) -> 0 | I22: =IF(AND(VLOOKUP(I$1,'20Trips'!$A$3:$I$22,8,FALSE)-VLOOKUP($A22,'20Trips'!$A$3:$I$22,9,FALSE)>=VLOOKUP(VLOOKUP(I$1, '20Trips'!$A$3:$I$22,3,FALSE), '20Trips'!$AB$33:$AC$36, 2, FALSE)),1,0) -> 0 | J22: =IF(AND(VLOOKUP(J$1,'20Trips'!$A$3:$I$22,8,FALSE)-VLOOKUP($A22,'20Trips'!$A$3:$I$22,9,FALSE)>=VLOOKUP(VLOOKUP(J$1, '20Trips'!$A$3:$I$22,3,FALSE), '20Trips'!$AB$33:$AC$36, 2, FALSE)),1,0) -> 0 | ... V22: =IF(AND(VLOOKUP(V$1,'20Trips'!$A$3:$I$22,8,FALSE)-VLOOKUP($A22,'20Trips'!$A$3:$I$22,9,FALSE)>=VLOOKUP(VLOOKUP(V$1, '20Trips'!$A$3:$I$22,3,FALSE), '20Trips'!$AB$33:$AC$36, 2, FALSE)),1,0) -> 0
D24: =AND(VLOOKUP(G$1,'20Trips'!$A$3:$G$22,5,FALSE)-VLOOKUP($A5,'20Trips'!$A$3:$G$22,6,FALSE)>=VLOOKUP(VLOOKUP(G$1, '20Trips'!$A$3:$G$22,3,FALSE), '20Trips'!$AB$33:$AC$36, 2, FALSE)/1440) -> FALSE | F24: =VLOOKUP(G$1,'20Trips'!$A$3:$I$22,8,FALSE)-VLOOKUP($A5,'20Trips'!$A$3:$I$22,9,FALSE)>=VLOOKUP(VLOOKUP(G$1,'20Trips'!$A$3:$G$22,3,FALSE),'20Trips'!$AB$33:$AC$36,2,FALSE) -> TRUE | I24: IF(AND(VLOOKUP(T$1,test!$A$3:$I$32,8,FALSE)-VLOOKUP($A16,test!$A$3:$I$32,9,FALSE)>=VLOOKUP(VLOOKUP(T$1, test!$A$3:$I$32,3,FALSE), test!$J$11:$K$14, 2, FALSE)),1,0)
D25: =VLOOKUP(G$1,'20Trips'!$A$3:$G$22,5,FALSE)-VLOOKUP($A5,'20Trips'!$A$3:$G$22,6,FALSE) -> 0.010416667 | F25: =VLOOKUP(G$1,'20Trips'!$A$3:$I$22,8,FALSE)-VLOOKUP($A5,'20Trips'!$A$3:$I$22,9,FALSE) -> 15 | I25: =VLOOKUP(P$1,'20Trips'!$A$3:$I$22,8,FALSE)-VLOOKUP(#REF!,'20Trips'!$A$3:$I$22,9,FALSE) -> #REF!
D26: =VLOOKUP(VLOOKUP(G$1, '20Trips'!$A$3:$G$22,3,FALSE), '20Trips'!$AB$33:$AC$36, 2, FALSE)/1440 -> 0.010416667 | F26: =VLOOKUP(VLOOKUP(G$1,'20Trips'!$A$3:$G$22,3,FALSE),'20Trips'!$AB$33:$AC$36,2,FALSE) -> 15

Sheet duration_mat
B1: DEPOT | C1: AB1 | D1: AB2 | E1: AB3 | F1: AB4 | G1: AB5 | H1: AC1 | I1: AC2 | J1: AC3 | K1: AC4 | L1: AC5 | M1: BA1 | N1: BA2 | O1: BA3 | P1: BA4 | Q1: BA5 | R1: CA1 | S1: CA2 | T1: CA3 | U1: CA4 | V1: CA5 | W1: CS1 | X1: CS1a | Y1: CS2b | Z1: CS3c | AA1: CS4d
A2: DEPOT | B2: 0 | C2: 0 | D2: 0 | E2: 0 | F2: 0 | G2: 0 | H2: 0 | I2: 0 | J2: 0 | K2: 0 | L2: 0 | M2: 0 | N2: 0 | O2: 0 | P2: 0 | Q2: 0 | R2: 0 | S2: 0 | T2: 0 | U2: 0 | V2: 0 | W2: 0 | X2: 0 | Y2: 0 | Z2: 0 | AA2: 0 | AB2: 0
A3: AB1 | B3: 0 | C3: =IF(AND(SUM(VLOOKUP($A3,'20Trips'!$A$3:$F$22,2,FALSE),VLOOKUP(C$1,'20Trips'!$A$3:$F$22,2,FALSE))<'20Trips'!$AC$38,$A3<>C$1,feasible_mat!C3=1),SUM(VLOOKUP($A3,'20Trips'!$A$3:$F$22,2,FALSE), VLOOKUP(C$1,'20Trips'!$A$3:$F$22,2,FALSE)),0) -> 0 | D3: =IF(AND(SUM(VLOOKUP($A3,'20Trips'!$A$3:$F$22,2,FALSE),VLOOKUP(D$1,'20Trips'!$A$3:$F$22,2,FALSE))<'20Trips'!$AC$38,$A3<>D$1,feasible_mat!D3=1),SUM(VLOOKUP($A3,'20Trips'!$A$3:$F$22,2,FALSE), VLOOKUP(D$1,'20Trips'!$A$3:$F$22,2,FALSE)),0) -> 270 | E3: =IF(AND(SUM(VLOOKUP($A3,'20Trips'!$A$3:$F$22,2,FALSE),VLOOKUP(E$1,'20Trips'!$A$3:$F$22,2,FALSE))<'20Trips'!$AC$38,$A3<>E$1,feasible_mat!E3=1),SUM(VLOOKUP($A3,'20Trips'!$A$3:$F$22,2,FALSE), VLOOKUP(E$1,'20Trips'!$A$3:$F$22,2,FALSE)),0) -> 270 | F3: =IF(AND(SUM(VLOOKUP($A3,'20Trips'!$A$3:$F$22,2,FALSE),VLOOKUP(F$1,'20Trips'!$A$3:$F$22,2,FALSE))<'20Trips'!$AC$38,$A3<>F$1,feasible_mat!F3=1),SUM(VLOOKUP($A3,'20Trips'!$A$3:$F$22,2,FALSE), VLOOKUP(F$1,'20Trips'!$A$3:$F$22,2,FALSE)),0) -> 270 | G3: =IF(AND(SUM(VLOOKUP($A3,'20Trips'!$A$3:$F$22,2,FALSE),VLOOKUP(G$1,'20Trips'!$A$3:$F$22,2,FALSE))<'20Trips'!$AC$38,$A3<>G$1,feasible_mat!G3=1),SUM(VLOOKUP($A3,'20Trips'!$A$3:$F$22,2,FALSE), VLOOKUP(G$1,'20Trips'!$A$3:$F$22,2,FALSE)),0) -> 270 | H3: =IF(AND(SUM(VLOOKUP($A3,'20Trips'!$A$3:$F$22,2,FALSE),VLOOKUP(H$1,'20Trips'!$A$3:$F$22,2,FALSE))<'20Trips'!$AC$38,$A3<>H$1,feasible_mat!H3=1),SUM(VLOOKUP($A3,'20Trips'!$A$3:$F$22,2,FALSE), VLOOKUP(H$1,'20Trips'!$A$3:$F$22,2,FALSE)),0) -> 0 | I3: =IF(AND(SUM(VLOOKUP($A3,'20Trips'!$A$3:$F$22,2,FALSE),VLOOKUP(I$1,'20Trips'!$A$3:$F$22,2,FALSE))<'20Trips'!$AC$38,$A3<>I$1,feasible_mat!I3=1),SUM(VLOOKUP($A3,'20Trips'!$A$3:$F$22,2,FALSE), VLOOKUP(I$1,'20Trips'!$A$3:$F$22,2,FALSE)),0) -> 0 | J3: =IF(AND(SUM(VLOOKUP($A3,'20Trips'!$A$3:$F$22,2,FALSE),VLOOKUP(J$1,'20Trips'!$A$3:$F$22,2,FALSE))<'20Trips'!$AC$38,$A3<>J$1,feasible_mat!J3=1),SUM(VLOOKUP($A3,'20Trips'!$A$3:$F$22,2,FALSE), VLOOKUP(J$1,'20Trips'!$A$3:$F$22,2,FALSE)),0) -> 275 | ... V3: =IF(AND(SUM(VLOOKUP($A3,'20Trips'!$A$3:$F$22,2,FALSE),VLOOKUP(V$1,'20Trips'!$A$3:$F$22,2,FALSE))<'20Trips'!$AC$38,$A3<>V$1,feasible_mat!V3=1),SUM(VLOOKUP($A3,'20Trips'!$A$3:$F$22,2,FALSE), VLOOKUP(V$1,'20Trips'!$A$3:$F$22,2,FALSE)),0) -> 275 | W3: 0 | X3: 0 | Y3: 0 | Z3: 0 | AA3: 0 | AB3: =AB2+1 -> 1
A4: AB2 | B4: 0 | C4: =IF(AND(SUM(VLOOKUP($A4,'20Trips'!$A$3:$F$22,2,FALSE),VLOOKUP(C$1,'20Trips'!$A$3:$F$22,2,FALSE))<'20Trips'!$AC$38,$A4<>C$1,feasible_mat!C4=1),SUM(VLOOKUP($A4,'20Trips'!$A$3:$F$22,2,FALSE), VLOOKUP(C$1,'20Trips'!$A$3:$F$22,2,FALSE)),0) -> 0 | D4: =IF(AND(SUM(VLOOKUP($A4,'20Trips'!$A$3:$F$22,2,FALSE),VLOOKUP(D$1,'20Trips'!$A$3:$F$22,2,FALSE))<'20Trips'!$AC$38,$A4<>D$1,feasible_mat!D4=1),SUM(VLOOKUP($A4,'20Trips'!$A$3:$F$22,2,FALSE), VLOOKUP(D$1,'20Trips'!$A$3:$F$22,2,FALSE)),0) -> 0 | E4: =IF(AND(SUM(VLOOKUP($A4,'20Trips'!$A$3:$F$22,2,FALSE),VLOOKUP(E$1,'20Trips'!$A$3:$F$22,2,FALSE))<'20Trips'!$AC$38,$A4<>E$1,feasible_mat!E4=1),SUM(VLOOKUP($A4,'20Trips'!$A$3:$F$22,2,FALSE), VLOOKUP(E$1,'20Trips'!$A$3:$F$22,2,FALSE)),0) -> 0 | F4: =IF(AND(SUM(VLOOKUP($A4,'20Trips'!$A$3:$F$22,2,FALSE),VLOOKUP(F$1,'20Trips'!$A$3:$F$22,2,FALSE))<'20Trips'!$AC$38,$A4<>F$1,feasible_mat!F4=1),SUM(VLOOKUP($A4,'20Trips'!$A$3:$F$22,2,FALSE), VLOOKUP(F$1,'20Trips'!$A$3:$F$22,2,FALSE)),0) -> 270 | G4: =IF(AND(SUM(VLOOKUP($A4,'20Trips'!$A$3:$F$22,2,FALSE),VLOOKUP(G$1,'20Trips'!$A$3:$F$22,2,FALSE))<'20Trips'!$AC$38,$A4<>G$1,feasible_mat!G4=1),SUM(VLOOKUP($A4,'20Trips'!$A$3:$F$22,2,FALSE), VLOOKUP(G$1,'20Trips'!$A$3:$F$22,2,FALSE)),0) -> 270 | H4: =IF(AND(SUM(VLOOKUP($A4,'20Trips'!$A$3:$F$22,2,FALSE),VLOOKUP(H$1,'20Trips'!$A$3:$F$22,2,FALSE))<'20Trips'!$AC$38,$A4<>H$1,feasible_mat!H4=1),SUM(VLOOKUP($A4,'20Trips'!$A$3:$F$22,2,FALSE), VLOOKUP(H$1,'20Trips'!$A$3:$F$22,2,FALSE)),0) -> 0 | I4: =IF(AND(SUM(VLOOKUP($A4,'20Trips'!$A$3:$F$22,2,FALSE),VLOOKUP(I$1,'20Trips'!$A$3:$F$22,2,FALSE))<'20Trips'!$AC$38,$A4<>I$1,feasible_mat!I4=1),SUM(VLOOKUP($A4,'20Trips'!$A$3:$F$22,2,FALSE), VLOOKUP(I$1,'20Trips'!$A$3:$F$22,2,FALSE)),0) -> 0 | J4: =IF(AND(SUM(VLOOKUP($A4,'20Trips'!$A$3:$F$22,2,FALSE),VLOOKUP(J$1,'20Trips'!$A$3:$F$22,2,FALSE))<'20Trips'!$AC$38,$A4<>J$1,feasible_mat!J4=1),SUM(VLOOKUP($A4,'20Trips'!$A$3:$F$22,2,FALSE), VLOOKUP(J$1,'20Trips'!$A$3:$F$22,2,FALSE)),0) -> 0 | ... V4: =IF(AND(SUM(VLOOKUP($A4,'20Trips'!$A$3:$F$22,2,FALSE),VLOOKUP(V$1,'20Trips'!$A$3:$F$22,2,FALSE))<'20Trips'!$AC$38,$A4<>V$1,feasible_mat!V4=1),SUM(VLOOKUP($A4,'20Trips'!$A$3:$F$22,2,FALSE), VLOOKUP(V$1,'20Trips'!$A$3:$F$22,2,FALSE)),0) -> 275 | W4: 0 | X4: 0 | Y4: 0 | Z4: 0 | AA4: 0 | AB4: =AB3+1 -> 2
A5: AB3 | B5: 0 | C5: =IF(AND(SUM(VLOOKUP($A5,'20Trips'!$A$3:$F$22,2,FALSE),VLOOKUP(C$1,'20Trips'!$A$3:$F$22,2,FALSE))<'20Trips'!$AC$38,$A5<>C$1,feasible_mat!C5=1),SUM(VLOOKUP($A5,'20Trips'!$A$3:$F$22,2,FALSE), VLOOKUP(C$1,'20Trips'!$A$3:$F$22,2,FALSE)),0) -> 0 | D5: =IF(AND(SUM(VLOOKUP($A5,'20Trips'!$A$3:$F$22,2,FALSE),VLOOKUP(D$1,'20Trips'!$A$3:$F$22,2,FALSE))<'20Trips'!$AC$38,$A5<>D$1,feasible_mat!D5=1),SUM(VLOOKUP($A5,'20Trips'!$A$3:$F$22,2,FALSE), VLOOKUP(D$1,'20Trips'!$A$3:$F$22,2,FALSE)),0) -> 0 | E5: =IF(AND(SUM(VLOOKUP($A5,'20Trips'!$A$3:$F$22,2,FALSE),VLOOKUP(E$1,'20Trips'!$A$3:$F$22,2,FALSE))<'20Trips'!$AC$38,$A5<>E$1,feasible_mat!E5=1),SUM(VLOOKUP($A5,'20Trips'!$A$3:$F$22,2,FALSE), VLOOKUP(E$1,'20Trips'!$A$3:$F$22,2,FALSE)),0) -> 0 | F5: =IF(AND(SUM(VLOOKUP($A5,'20Trips'!$A$3:$F$22,2,FALSE),VLOOKUP(F$1,'20Trips'!$A$3:$F$22,2,FALSE))<'20Trips'!$AC$38,$A5<>F$1,feasible_mat!F5=1),SUM(VLOOKUP($A5,'20Trips'!$A$3:$F$22,2,FALSE), VLOOKUP(F$1,'20Trips'!$A$3:$F$22,2,FALSE)),0) -> 0 | G5: =IF(AND(SUM(VLOOKUP($A5,'20Trips'!$A$3:$F$22,2,FALSE),VLOOKUP(G$1,'20Trips'!$A$3:$F$22,2,FALSE))<'20Trips'!$AC$38,$A5<>G$1,feasible_mat!G5=1),SUM(VLOOKUP($A5,'20Trips'!$A$3:$F$22,2,FALSE), VLOOKUP(G$1,'20Trips'!$A$3:$F$22,2,FALSE)),0) -> 270 | H5: =IF(AND(SUM(VLOOKUP($A5,'20Trips'!$A$3:$F$22,2,FALSE),VLOOKUP(H$1,'20Trips'!$A$3:$F$22,2,FALSE))<'20Trips'!$AC$38,$A5<>H$1,feasible_mat!H5=1),SUM(VLOOKUP($A5,'20Trips'!$A$3:$F$22,2,FALSE), VLOOKUP(H$1,'20Trips'!$A$3:$F$22,2,FALSE)),0) -> 0 | I5: =IF(AND(SUM(VLOOKUP($A5,'20Trips'!$A$3:$F$22,2,FALSE),VLOOKUP(I$1,'20Trips'!$A$3:$F$22,2,FALSE))<'20Trips'!$AC$38,$A5<>I$1,feasible_mat!I5=1),SUM(VLOOKUP($A5,'20Trips'!$A$3:$F$22,2,FALSE), VLOOKUP(I$1,'20Trips'!$A$3:$F$22,2,FALSE)),0) -> 0 | J5: =IF(AND(SUM(VLOOKUP($A5,'20Trips'!$A$3:$F$22,2,FALSE),VLOOKUP(J$1,'20Trips'!$A$3:$F$22,2,FALSE))<'20Trips'!$AC$38,$A5<>J$1,feasible_mat!J5=1),SUM(VLOOKUP($A5,'20Trips'!$A$3:$F$22,2,FALSE), VLOOKUP(J$1,'20Trips'!$A$3:$F$22,2,FALSE)),0) -> 0 | ... V5: =IF(AND(SUM(VLOOKUP($A5,'20Trips'!$A$3:$F$22,2,FALSE),VLOOKUP(V$1,'20Trips'!$A$3:$F$22,2,FALSE))<'20Trips'!$AC$38,$A5<>V$1,feasible_mat!V5=1),SUM(VLOOKUP($A5,'20Trips'!$A$3:$F$22,2,FALSE), VLOOKUP(V$1,'20Trips'!$A$3:$F$22,2,FALSE)),0) -> 275 | W5: 0 | X5: 0 | Y5: 0 | Z5: 0 | AA5: 0 | AB5: =AB4+1 -> 3
A6: AB4 | B6: 0 | C6: =IF(AND(SUM(VLOOKUP($A6,'20Trips'!$A$3:$F$22,2,FALSE),VLOOKUP(C$1,'20Trips'!$A$3:$F$22,2,FALSE))<'20Trips'!$AC$38,$A6<>C$1,feasible_mat!C6=1),SUM(VLOOKUP($A6,'20Trips'!$A$3:$F$22,2,FALSE), VLOOKUP(C$1,'20Trips'!$A$3:$F$22,2,FALSE)),0) -> 0 | D6: =IF(AND(SUM(VLOOKUP($A6,'20Trips'!$A$3:$F$22,2,FALSE),VLOOKUP(D$1,'20Trips'!$A$3:$F$22,2,FALSE))<'20Trips'!$AC$38,$A6<>D$1,feasible_mat!D6=1),SUM(VLOOKUP($A6,'20Trips'!$A$3:$F$22,2,FALSE), VLOOKUP(D$1,'20Trips'!$A$3:$F$22,2,FALSE)),0) -> 0 | E6: =IF(AND(SUM(VLOOKUP($A6,'20Trips'!$A$3:$F$22,2,FALSE),VLOOKUP(E$1,'20Trips'!$A$3:$F$22,2,FALSE))<'20Trips'!$AC$38,$A6<>E$1,feasible_mat!E6=1),SUM(VLOOKUP($A6,'20Trips'!$A$3:$F$22,2,FALSE), VLOOKUP(E$1,'20Trips'!$A$3:$F$22,2,FALSE)),0) -> 0 | F6: =IF(AND(SUM(VLOOKUP($A6,'20Trips'!$A$3:$F$22,2,FALSE),VLOOKUP(F$1,'20Trips'!$A$3:$F$22,2,FALSE))<'20Trips'!$AC$38,$A6<>F$1,feasible_mat!F6=1),SUM(VLOOKUP($A6,'20Trips'!$A$3:$F$22,2,FALSE), VLOOKUP(F$1,'20Trips'!$A$3:$F$22,2,FALSE)),0) -> 0 | G6: =IF(AND(SUM(VLOOKUP($A6,'20Trips'!$A$3:$F$22,2,FALSE),VLOOKUP(G$1,'20Trips'!$A$3:$F$22,2,FALSE))<'20Trips'!$AC$38,$A6<>G$1,feasible_mat!G6=1),SUM(VLOOKUP($A6,'20Trips'!$A$3:$F$22,2,FALSE), VLOOKUP(G$1,'20Trips'!$A$3:$F$22,2,FALSE)),0) -> 0 | H6: =IF(AND(SUM(VLOOKUP($A6,'20Trips'!$A$3:$F$22,2,FALSE),VLOOKUP(H$1,'20Trips'!$A$3:$F$22,2,FALSE))<'20Trips'!$AC$38,$A6<>H$1,feasible_mat!H6=1),SUM(VLOOKUP($A6,'20Trips'!$A$3:$F$22,2,FALSE), VLOOKUP(H$1,'20Trips'!$A$3:$F$22,2,FALSE)),0) -> 0 | I6: =IF(AND(SUM(VLOOKUP($A6,'20Trips'!$A$3:$F$22,2,FALSE),VLOOKUP(I$1,'20Trips'!$A$3:$F$22,2,FALSE))<'20Trips'!$AC$38,$A6<>I$1,feasible_mat!I6=1),SUM(VLOOKUP($A6,'20Trips'!$A$3:$F$22,2,FALSE), VLOOKUP(I$1,'20Trips'!$A$3:$F$22,2,FALSE)),0) -> 0 | J6: =IF(AND(SUM(VLOOKUP($A6,'20Trips'!$A$3:$F$22,2,FALSE),VLOOKUP(J$1,'20Trips'!$A$3:$F$22,2,FALSE))<'20Trips'!$AC$38,$A6<>J$1,feasible_mat!J6=1),SUM(VLOOKUP($A6,'20Trips'!$A$3:$F$22,2,FALSE), VLOOKUP(J$1,'20Trips'!$A$3:$F$22,2,FALSE)),0) -> 0 | ... V6: =IF(AND(SUM(VLOOKUP($A6,'20Trips'!$A$3:$F$22,2,FALSE),VLOOKUP(V$1,'20Trips'!$A$3:$F$22,2,FALSE))<'20Trips'!$AC$38,$A6<>V$1,feasible_mat!V6=1),SUM(VLOOKUP($A6,'20Trips'!$A$3:$F$22,2,FALSE), VLOOKUP(V$1,'20Trips'!$A$3:$F$22,2,FALSE)),0) -> 0 | W6: 0 | X6: 0 | Y6: 0 | Z6: 0 | AA6: 0 | AB6: =AB5+1 -> 4
A7: AB5 | B7: 0 | C7: =IF(AND(SUM(VLOOKUP($A7,'20Trips'!$A$3:$F$22,2,FALSE),VLOOKUP(C$1,'20Trips'!$A$3:$F$22,2,FALSE))<'20Trips'!$AC$38,$A7<>C$1,feasible_mat!C7=1),SUM(VLOOKUP($A7,'20Trips'!$A$3:$F$22,2,FALSE), VLOOKUP(C$1,'20Trips'!$A$3:$F$22,2,FALSE)),0) -> 0 | D7: =IF(AND(SUM(VLOOKUP($A7,'20Trips'!$A$3:$F$22,2,FALSE),VLOOKUP(D$1,'20Trips'!$A$3:$F$22,2,FALSE))<'20Trips'!$AC$38,$A7<>D$1,feasible_mat!D7=1),SUM(VLOOKUP($A7,'20Trips'!$A$3:$F$22,2,FALSE), VLOOKUP(D$1,'20Trips'!$A$3:$F$22,2,FALSE)),0) -> 0 | E7: =IF(AND(SUM(VLOOKUP($A7,'20Trips'!$A$3:$F$22,2,FALSE),VLOOKUP(E$1,'20Trips'!$A$3:$F$22,2,FALSE))<'20Trips'!$AC$38,$A7<>E$1,feasible_mat!E7=1),SUM(VLOOKUP($A7,'20Trips'!$A$3:$F$22,2,FALSE), VLOOKUP(E$1,'20Trips'!$A$3:$F$22,2,FALSE)),0) -> 0 | F7: =IF(AND(SUM(VLOOKUP($A7,'20Trips'!$A$3:$F$22,2,FALSE),VLOOKUP(F$1,'20Trips'!$A$3:$F$22,2,FALSE))<'20Trips'!$AC$38,$A7<>F$1,feasible_mat!F7=1),SUM(VLOOKUP($A7,'20Trips'!$A$3:$F$22,2,FALSE), VLOOKUP(F$1,'20Trips'!$A$3:$F$22,2,FALSE)),0) -> 0 | G7: =IF(AND(SUM(VLOOKUP($A7,'20Trips'!$A$3:$F$22,2,FALSE),VLOOKUP(G$1,'20Trips'!$A$3:$F$22,2,FALSE))<'20Trips'!$AC$38,$A7<>G$1,feasible_mat!G7=1),SUM(VLOOKUP($A7,'20Trips'!$A$3:$F$22,2,FALSE), VLOOKUP(G$1,'20Trips'!$A$3:$F$22,2,FALSE)),0) -> 0 | H7: =IF(AND(SUM(VLOOKUP($A7,'20Trips'!$A$3:$F$22,2,FALSE),VLOOKUP(H$1,'20Trips'!$A$3:$F$22,2,FALSE))<'20Trips'!$AC$38,$A7<>H$1,feasible_mat!H7=1),SUM(VLOOKUP($A7,'20Trips'!$A$3:$F$22,2,FALSE), VLOOKUP(H$1,'20Trips'!$A$3:$F$22,2,FALSE)),0) -> 0 | I7: =IF(AND(SUM(VLOOKUP($A7,'20Trips'!$A$3:$F$22,2,FALSE),VLOOKUP(I$1,'20Trips'!$A$3:$F$22,2,FALSE))<'20Trips'!$AC$38,$A7<>I$1,feasible_mat!I7=1),SUM(VLOOKUP($A7,'20Trips'!$A$3:$F$22,2,FALSE), VLOOKUP(I$1,'20Trips'!$A$3:$F$22,2,FALSE)),0) -> 0 | J7: =IF(AND(SUM(VLOOKUP($A7,'20Trips'!$A$3:$F$22,2,FALSE),VLOOKUP(J$1,'20Trips'!$A$3:$F$22,2,FALSE))<'20Trips'!$AC$38,$A7<>J$1,feasible_mat!J7=1),SUM(VLOOKUP($A7,'20Trips'!$A$3:$F$22,2,FALSE), VLOOKUP(J$1,'20Trips'!$A$3:$F$22,2,FALSE)),0) -> 0 | ... V7: =IF(AND(SUM(VLOOKUP($A7,'20Trips'!$A$3:$F$22,2,FALSE),VLOOKUP(V$1,'20Trips'!$A$3:$F$22,2,FALSE))<'20Trips'!$AC$38,$A7<>V$1,feasible_mat!V7=1),SUM(VLOOKUP($A7,'20Trips'!$A$3:$F$22,2,FALSE), VLOOKUP(V$1,'20Trips'!$A$3:$F$22,2,FALSE)),0) -> 0 | W7: 0 | X7: 0 | Y7: 0 | Z7: 0 | AA7: 0 | AB7: =AB6+1 -> 5
A8: AC1 | B8: 0 | C8: =IF(AND(SUM(VLOOKUP($A8,'20Trips'!$A$3:$F$22,2,FALSE),VLOOKUP(C$1,'20Trips'!$A$3:$F$22,2,FALSE))<'20Trips'!$AC$38,$A8<>C$1,feasible_mat!C8=1),SUM(VLOOKUP($A8,'20Trips'!$A$3:$F$22,2,FALSE), VLOOKUP(C$1,'20Trips'!$A$3:$F$22,2,FALSE)),0) -> 0 | D8: =IF(AND(SUM(VLOOKUP($A8,'20Trips'!$A$3:$F$22,2,FALSE),VLOOKUP(D$1,'20Trips'!$A$3:$F$22,2,FALSE))<'20Trips'!$AC$38,$A8<>D$1,feasible_mat!D8=1),SUM(VLOOKUP($A8,'20Trips'!$A$3:$F$22,2,FALSE), VLOOKUP(D$1,'20Trips'!$A$3:$F$22,2,FALSE)),0) -> 275 | E8: =IF(AND(SUM(VLOOKUP($A8,'20Trips'!$A$3:$F$22,2,FALSE),VLOOKUP(E$1,'20Trips'!$A$3:$F$22,2,FALSE))<'20Trips'!$AC$38,$A8<>E$1,feasible_mat!E8=1),SUM(VLOOKUP($A8,'20Trips'!$A$3:$F$22,2,FALSE), VLOOKUP(E$1,'20Trips'!$A$3:$F$22,2,FALSE)),0) -> 275 | F8: =IF(AND(SUM(VLOOKUP($A8,'20Trips'!$A$3:$F$22,2,FALSE),VLOOKUP(F$1,'20Trips'!$A$3:$F$22,2,FALSE))<'20Trips'!$AC$38,$A8<>F$1,feasible_mat!F8=1),SUM(VLOOKUP($A8,'20Trips'!$A$3:$F$22,2,FALSE), VLOOKUP(F$1,'20Trips'!$A$3:$F$22,2,FALSE)),0) -> 275 | G8: =IF(AND(SUM(VLOOKUP($A8,'20Trips'!$A$3:$F$22,2,FALSE),VLOOKUP(G$1,'20Trips'!$A$3:$F$22,2,FALSE))<'20Trips'!$AC$38,$A8<>G$1,feasible_mat!G8=1),SUM(VLOOKUP($A8,'20Trips'!$A$3:$F$22,2,FALSE), VLOOKUP(G$1,'20Trips'!$A$3:$F$22,2,FALSE)),0) -> 275 | H8: =IF(AND(SUM(VLOOKUP($A8,'20Trips'!$A$3:$F$22,2,FALSE),VLOOKUP(H$1,'20Trips'!$A$3:$F$22,2,FALSE))<'20Trips'!$AC$38,$A8<>H$1,feasible_mat!H8=1),SUM(VLOOKUP($A8,'20Trips'!$A$3:$F$22,2,FALSE), VLOOKUP(H$1,'20Trips'!$A$3:$F$22,2,FALSE)),0) -> 0 | I8: =IF(AND(SUM(VLOOKUP($A8,'20Trips'!$A$3:$F$22,2,FALSE),VLOOKUP(I$1,'20Trips'!$A$3:$F$22,2,FALSE))<'20Trips'!$AC$38,$A8<>I$1,feasible_mat!I8=1),SUM(VLOOKUP($A8,'20Trips'!$A$3:$F$22,2,FALSE), VLOOKUP(I$1,'20Trips'!$A$3:$F$22,2,FALSE)),0) -> 0 | J8: =IF(AND(SUM(VLOOKUP($A8,'20Trips'!$A$3:$F$22,2,FALSE),VLOOKUP(J$1,'20Trips'!$A$3:$F$22,2,FALSE))<'20Trips'!$AC$38,$A8<>J$1,feasible_mat!J8=1),SUM(VLOOKUP($A8,'20Trips'!$A$3:$F$22,2,FALSE), VLOOKUP(J$1,'20Trips'!$A$3:$F$22,2,FALSE)),0) -> 280 | ... V8: =IF(AND(SUM(VLOOKUP($A8,'20Trips'!$A$3:$F$22,2,FALSE),VLOOKUP(V$1,'20Trips'!$A$3:$F$22,2,FALSE))<'20Trips'!$AC$38,$A8<>V$1,feasible_mat!V8=1),SUM(VLOOKUP($A8,'20Trips'!$A$3:$F$22,2,FALSE), VLOOKUP(V$1,'20Trips'!$A$3:$F$22,2,FALSE)),0) -> 280 | W8: 0 | X8: 0 | Y8: 0 | Z8: 0 | AA8: 0 | AB8: =AB7+1 -> 6
A9: AC2 | B9: 0 | C9: =IF(AND(SUM(VLOOKUP($A9,'20Trips'!$A$3:$F$22,2,FALSE),VLOOKUP(C$1,'20Trips'!$A$3:$F$22,2,FALSE))<'20Trips'!$AC$38,$A9<>C$1,feasible_mat!C9=1),SUM(VLOOKUP($A9,'20Trips'!$A$3:$F$22,2,FALSE), VLOOKUP(C$1,'20Trips'!$A$3:$F$22,2,FALSE)),0) -> 0 | D9: =IF(AND(SUM(VLOOKUP($A9,'20Trips'!$A$3:$F$22,2,FALSE),VLOOKUP(D$1,'20Trips'!$A$3:$F$22,2,FALSE))<'20Trips'!$AC$38,$A9<>D$1,feasible_mat!D9=1),SUM(VLOOKUP($A9,'20Trips'!$A$3:$F$22,2,FALSE), VLOOKUP(D$1,'20Trips'!$A$3:$F$22,2,FALSE)),0) -> 0 | E9: =IF(AND(SUM(VLOOKUP($A9,'20Trips'!$A$3:$F$22,2,FALSE),VLOOKUP(E$1,'20Trips'!$A$3:$F$22,2,FALSE))<'20Trips'!$AC$38,$A9<>E$1,feasible_mat!E9=1),SUM(VLOOKUP($A9,'20Trips'!$A$3:$F$22,2,FALSE), VLOOKUP(E$1,'20Trips'!$A$3:$F$22,2,FALSE)),0) -> 275 | F9: =IF(AND(SUM(VLOOKUP($A9,'20Trips'!$A$3:$F$22,2,FALSE),VLOOKUP(F$1,'20Trips'!$A$3:$F$22,2,FALSE))<'20Trips'!$AC$38,$A9<>F$1,feasible_mat!F9=1),SUM(VLOOKUP($A9,'20Trips'!$A$3:$F$22,2,FALSE), VLOOKUP(F$1,'20Trips'!$A$3:$F$22,2,FALSE)),0) -> 275 | G9: =IF(AND(SUM(VLOOKUP($A9,'20Trips'!$A$3:$F$22,2,FALSE),VLOOKUP(G$1,'20Trips'!$A$3:$F$22,2,FALSE))<'20Trips'!$AC$38,$A9<>G$1,feasible_mat!G9=1),SUM(VLOOKUP($A9,'20Trips'!$A$3:$F$22,2,FALSE), VLOOKUP(G$1,'20Trips'!$A$3:$F$22,2,FALSE)),0) -> 275 | H9: =IF(AND(SUM(VLOOKUP($A9,'20Trips'!$A$3:$F$22,2,FALSE),VLOOKUP(H$1,'20Trips'!$A$3:$F$22,2,FALSE))<'20Trips'!$AC$38,$A9<>H$1,feasible_mat!H9=1),SUM(VLOOKUP($A9,'20Trips'!$A$3:$F$22,2,FALSE), VLOOKUP(H$1,'20Trips'!$A$3:$F$22,2,FALSE)),0) -> 0 | I9: =IF(AND(SUM(VLOOKUP($A9,'20Trips'!$A$3:$F$22,2,FALSE),VLOOKUP(I$1,'20Trips'!$A$3:$F$22,2,FALSE))<'20Trips'!$AC$38,$A9<>I$1,feasible_mat!I9=1),SUM(VLOOKUP($A9,'20Trips'!$A$3:$F$22,2,FALSE), VLOOKUP(I$1,'20Trips'!$A$3:$F$22,2,FALSE)),0) -> 0 | J9: =IF(AND(SUM(VLOOKUP($A9,'20Trips'!$A$3:$F$22,2,FALSE),VLOOKUP(J$1,'20Trips'!$A$3:$F$22,2,FALSE))<'20Trips'!$AC$38,$A9<>J$1,feasible_mat!J9=1),SUM(VLOOKUP($A9,'20Trips'!$A$3:$F$22,2,FALSE), VLOOKUP(J$1,'20Trips'!$A$3:$F$22,2,FALSE)),0) -> 0 | ... V9: =IF(AND(SUM(VLOOKUP($A9,'20Trips'!$A$3:$F$22,2,FALSE),VLOOKUP(V$1,'20Trips'!$A$3:$F$22,2,FALSE))<'20Trips'!$AC$38,$A9<>V$1,feasible_mat!V9=1),SUM(VLOOKUP($A9,'20Trips'!$A$3:$F$22,2,FALSE), VLOOKUP(V$1,'20Trips'!$A$3:$F$22,2,FALSE)),0) -> 280 | W9: 0 | X9: 0 | Y9: 0 | Z9: 0 | AA9: 0 | AB9: =AB8+1 -> 7
A10: AC3 | B10: 0 | C10: =IF(AND(SUM(VLOOKUP($A10,'20Trips'!$A$3:$F$22,2,FALSE),VLOOKUP(C$1,'20Trips'!$A$3:$F$22,2,FALSE))<'20Trips'!$AC$38,$A10<>C$1,feasible_mat!C10=1),SUM(VLOOKUP($A10,'20Trips'!$A$3:$F$22,2,FALSE), VLOOKUP(C$1,'20Trips'!$A$3:$F$22,2,FALSE)),0) -> 0 | D10: =IF(AND(SUM(VLOOKUP($A10,'20Trips'!$A$3:$F$22,2,FALSE),VLOOKUP(D$1,'20Trips'!$A$3:$F$22,2,FALSE))<'20Trips'!$AC$38,$A10<>D$1,feasible_mat!D10=1),SUM(VLOOKUP($A10,'20Trips'!$A$3:$F$22,2,FALSE), VLOOKUP(D$1,'20Trips'!$A$3:$F$22,2,FALSE)),0) -> 0 | E10: =IF(AND(SUM(VLOOKUP($A10,'20Trips'!$A$3:$F$22,2,FALSE),VLOOKUP(E$1,'20Trips'!$A$3:$F$22,2,FALSE))<'20Trips'!$AC$38,$A10<>E$1,feasible_mat!E10=1),SUM(VLOOKUP($A10,'20Trips'!$A$3:$F$22,2,FALSE), VLOOKUP(E$1,'20Trips'!$A$3:$F$22,2,FALSE)),0) -> 0 | F10: =IF(AND(SUM(VLOOKUP($A10,'20Trips'!$A$3:$F$22,2,FALSE),VLOOKUP(F$1,'20Trips'!$A$3:$F$22,2,FALSE))<'20Trips'!$AC$38,$A10<>F$1,feasible_mat!F10=1),SUM(VLOOKUP($A10,'20Trips'!$A$3:$F$22,2,FALSE), VLOOKUP(F$1,'20Trips'!$A$3:$F$22,2,FALSE)),0) -> 0 | G10: =IF(AND(SUM(VLOOKUP($A10,'20Trips'!$A$3:$F$22,2,FALSE),VLOOKUP(G$1,'20Trips'!$A$3:$F$22,2,FALSE))<'20Trips'!$AC$38,$A10<>G$1,feasible_mat!G10=1),SUM(VLOOKUP($A10,'20Trips'!$A$3:$F$22,2,FALSE), VLOOKUP(G$1,'20Trips'!$A$3:$F$22,2,FALSE)),0) -> 275 | H10: =IF(AND(SUM(VLOOKUP($A10,'20Trips'!$A$3:$F$22,2,FALSE),VLOOKUP(H$1,'20Trips'!$A$3:$F$22,2,FALSE))<'20Trips'!$AC$38,$A10<>H$1,feasible_mat!H10=1),SUM(VLOOKUP($A10,'20Trips'!$A$3:$F$22,2,FALSE), VLOOKUP(H$1,'20Trips'!$A$3:$F$22,2,FALSE)),0) -> 0 | I10: =IF(AND(SUM(VLOOKUP($A10,'20Trips'!$A$3:$F$22,2,FALSE),VLOOKUP(I$1,'20Trips'!$A$3:$F$22,2,FALSE))<'20Trips'!$AC$38,$A10<>I$1,feasible_mat!I10=1),SUM(VLOOKUP($A10,'20Trips'!$A$3:$F$22,2,FALSE), VLOOKUP(I$1,'20Trips'!$A$3:$F$22,2,FALSE)),0) -> 0 | J10: =IF(AND(SUM(VLOOKUP($A10,'20Trips'!$A$3:$F$22,2,FALSE),VLOOKUP(J$1,'20Trips'!$A$3:$F$22,2,FALSE))<'20Trips'!$AC$38,$A10<>J$1,feasible_mat!J10=1),SUM(VLOOKUP($A10,'20Trips'!$A$3:$F$22,2,FALSE), VLOOKUP(J$1,'20Trips'!$A$3:$F$22,2,FALSE)),0) -> 0 | ... V10: =IF(AND(SUM(VLOOKUP($A10,'20Trips'!$A$3:$F$22,2,FALSE),VLOOKUP(V$1,'20Trips'!$A$3:$F$22,2,FALSE))<'20Trips'!$AC$38,$A10<>V$1,feasible_mat!V10=1),SUM(VLOOKUP($A10,'20Trips'!$A$3:$F$22,2,FALSE), VLOOKUP(V$1,'20Trips'!$A$3:$F$22,2,FALSE)),0) -> 280 | W10: 0 | X10: 0 | Y10: 0 | Z10: 0 | AA10: 0 | AB10: =AB9+1 -> 8
A11: AC4 | B11: 0 | C11: =IF(AND(SUM(VLOOKUP($A11,'20Trips'!$A$3:$F$22,2,FALSE),VLOOKUP(C$1,'20Trips'!$A$3:$F$22,2,FALSE))<'20Trips'!$AC$38,$A11<>C$1,feasible_mat!C11=1),SUM(VLOOKUP($A11,'20Trips'!$A$3:$F$22,2,FALSE), VLOOKUP(C$1,'20Trips'!$A$3:$F$22,2,FALSE)),0) -> 0 | D11: =IF(AND(SUM(VLOOKUP($A11,'20Trips'!$A$3:$F$22,2,FALSE),VLOOKUP(D$1,'20Trips'!$A$3:$F$22,2,FALSE))<'20Trips'!$AC$38,$A11<>D$1,feasible_mat!D11=1),SUM(VLOOKUP($A11,'20Trips'!$A$3:$F$22,2,FALSE), VLOOKUP(D$1,'20Trips'!$A$3:$F$22,2,FALSE)),0) -> 0 | E11: =IF(AND(SUM(VLOOKUP($A11,'20Trips'!$A$3:$F$22,2,FALSE),VLOOKUP(E$1,'20Trips'!$A$3:$F$22,2,FALSE))<'20Trips'!$AC$38,$A11<>E$1,feasible_mat!E11=1),SUM(VLOOKUP($A11,'20Trips'!$A$3:$F$22,2,FALSE), VLOOKUP(E$1,'20Trips'!$A$3:$F$22,2,FALSE)),0) -> 0 | F11: =IF(AND(SUM(VLOOKUP($A11,'20Trips'!$A$3:$F$22,2,FALSE),VLOOKUP(F$1,'20Trips'!$A$3:$F$22,2,FALSE))<'20Trips'!$AC$38,$A11<>F$1,feasible_mat!F11=1),SUM(VLOOKUP($A11,'20Trips'!$A$3:$F$22,2,FALSE), VLOOKUP(F$1,'20Trips'!$A$3:$F$22,2,FALSE)),0) -> 0 | G11: =IF(AND(SUM(VLOOKUP($A11,'20Trips'!$A$3:$F$22,2,FALSE),VLOOKUP(G$1,'20Trips'!$A$3:$F$22,2,FALSE))<'20Trips'!$AC$38,$A11<>G$1,feasible_mat!G11=1),SUM(VLOOKUP($A11,'20Trips'!$A$3:$F$22,2,FALSE), VLOOKUP(G$1,'20Trips'!$A$3:$F$22,2,FALSE)),0) -> 0 | H11: =IF(AND(SUM(VLOOKUP($A11,'20Trips'!$A$3:$F$22,2,FALSE),VLOOKUP(H$1,'20Trips'!$A$3:$F$22,2,FALSE))<'20Trips'!$AC$38,$A11<>H$1,feasible_mat!H11=1),SUM(VLOOKUP($A11,'20Trips'!$A$3:$F$22,2,FALSE), VLOOKUP(H$1,'20Trips'!$A$3:$F$22,2,FALSE)),0) -> 0 | I11: =IF(AND(SUM(VLOOKUP($A11,'20Trips'!$A$3:$F$22,2,FALSE),VLOOKUP(I$1,'20Trips'!$A$3:$F$22,2,FALSE))<'20Trips'!$AC$38,$A11<>I$1,feasible_mat!I11=1),SUM(VLOOKUP($A11,'20Trips'!$A$3:$F$22,2,FALSE), VLOOKUP(I$1,'20Trips'!$A$3:$F$22,2,FALSE)),0) -> 0 | J11: =IF(AND(SUM(VLOOKUP($A11,'20Trips'!$A$3:$F$22,2,FALSE),VLOOKUP(J$1,'20Trips'!$A$3:$F$22,2,FALSE))<'20Trips'!$AC$38,$A11<>J$1,feasible_mat!J11=1),SUM(VLOOKUP($A11,'20Trips'!$A$3:$F$22,2,FALSE), VLOOKUP(J$1,'20Trips'!$A$3:$F$22,2,FALSE)),0) -> 0 | ... V11: =IF(AND(SUM(VLOOKUP($A11,'20Trips'!$A$3:$F$22,2,FALSE),VLOOKUP(V$1,'20Trips'!$A$3:$F$22,2,FALSE))<'20Trips'!$AC$38,$A11<>V$1,feasible_mat!V11=1),SUM(VLOOKUP($A11,'20Trips'!$A$3:$F$22,2,FALSE), VLOOKUP(V$1,'20Trips'!$A$3:$F$22,2,FALSE)),0) -> 0 | W11: 0 | X11: 0 | Y11: 0 | Z11: 0 | AA11: 0 | AB11: =AB10+1 -> 9
A12: AC5 | B12: 0 | C12: =IF(AND(SUM(VLOOKUP($A12,'20Trips'!$A$3:$F$22,2,FALSE),VLOOKUP(C$1,'20Trips'!$A$3:$F$22,2,FALSE))<'20Trips'!$AC$38,$A12<>C$1,feasible_mat!C12=1),SUM(VLOOKUP($A12,'20Trips'!$A$3:$F$22,2,FALSE), VLOOKUP(C$1,'20Trips'!$A$3:$F$22,2,FALSE)),0) -> 0 | D12: =IF(AND(SUM(VLOOKUP($A12,'20Trips'!$A$3:$F$22,2,FALSE),VLOOKUP(D$1,'20Trips'!$A$3:$F$22,2,FALSE))<'20Trips'!$AC$38,$A12<>D$1,feasible_mat!D12=1),SUM(VLOOKUP($A12,'20Trips'!$A$3:$F$22,2,FALSE), VLOOKUP(D$1,'20Trips'!$A$3:$F$22,2,FALSE)),0) -> 0 | E12: =IF(AND(SUM(VLOOKUP($A12,'20Trips'!$A$3:$F$22,2,FALSE),VLOOKUP(E$1,'20Trips'!$A$3:$F$22,2,FALSE))<'20Trips'!$AC$38,$A12<>E$1,feasible_mat!E12=1),SUM(VLOOKUP($A12,'20Trips'!$A$3:$F$22,2,FALSE), VLOOKUP(E$1,'20Trips'!$A$3:$F$22,2,FALSE)),0) -> 0 | F12: =IF(AND(SUM(VLOOKUP($A12,'20Trips'!$A$3:$F$22,2,FALSE),VLOOKUP(F$1,'20Trips'!$A$3:$F$22,2,FALSE))<'20Trips'!$AC$38,$A12<>F$1,feasible_mat!F12=1),SUM(VLOOKUP($A12,'20Trips'!$A$3:$F$22,2,FALSE), VLOOKUP(F$1,'20Trips'!$A$3:$F$22,2,FALSE)),0) -> 0 | G12: =IF(AND(SUM(VLOOKUP($A12,'20Trips'!$A$3:$F$22,2,FALSE),VLOOKUP(G$1,'20Trips'!$A$3:$F$22,2,FALSE))<'20Trips'!$AC$38,$A12<>G$1,feasible_mat!G12=1),SUM(VLOOKUP($A12,'20Trips'!$A$3:$F$22,2,FALSE), VLOOKUP(G$1,'20Trips'!$A$3:$F$22,2,FALSE)),0) -> 0 | H12: =IF(AND(SUM(VLOOKUP($A12,'20Trips'!$A$3:$F$22,2,FALSE),VLOOKUP(H$1,'20Trips'!$A$3:$F$22,2,FALSE))<'20Trips'!$AC$38,$A12<>H$1,feasible_mat!H12=1),SUM(VLOOKUP($A12,'20Trips'!$A$3:$F$22,2,FALSE), VLOOKUP(H$1,'20Trips'!$A$3:$F$22,2,FALSE)),0) -> 0 | I12: =IF(AND(SUM(VLOOKUP($A12,'20Trips'!$A$3:$F$22,2,FALSE),VLOOKUP(I$1,'20Trips'!$A$3:$F$22,2,FALSE))<'20Trips'!$AC$38,$A12<>I$1,feasible_mat!I12=1),SUM(VLOOKUP($A12,'20Trips'!$A$3:$F$22,2,FALSE), VLOOKUP(I$1,'20Trips'!$A$3:$F$22,2,FALSE)),0) -> 0 | J12: =IF(AND(SUM(VLOOKUP($A12,'20Trips'!$A$3:$F$22,2,FALSE),VLOOKUP(J$1,'20Trips'!$A$3:$F$22,2,FALSE))<'20Trips'!$AC$38,$A12<>J$1,feasible_mat!J12=1),SUM(VLOOKUP($A12,'20Trips'!$A$3:$F$22,2,FALSE), VLOOKUP(J$1,'20Trips'!$A$3:$F$22,2,FALSE)),0) -> 0 | ... V12: =IF(AND(SUM(VLOOKUP($A12,'20Trips'!$A$3:$F$22,2,FALSE),VLOOKUP(V$1,'20Trips'!$A$3:$F$22,2,FALSE))<'20Trips'!$AC$38,$A12<>V$1,feasible_mat!V12=1),SUM(VLOOKUP($A12,'20Trips'!$A$3:$F$22,2,FALSE), VLOOKUP(V$1,'20Trips'!$A$3:$F$22,2,FALSE)),0) -> 0 | W12: 0 | X12: 0 | Y12: 0 | Z12: 0 | AA12: 0 | AB12: =AB11+1 -> 10
