Workbook

Sheet test
A1: trip_id | B1: duration | C1: dep_terminal | D1: arr_terminal | E1: dep_time | F1: arr_time | G1: cost_to_cs | H1: dep_min | I1: arr_min
A2: DEPOT | B2: 0 | C2: - | D2: - | E2: - | F2: - | G2: 20 | H2: - | I2: -
A3: AB1 | B3: 135 | C3: Terminal A | D3: Terminal B | E3: 0.38888889 | F3: 0.48263889 | G3: =VLOOKUP(D3,$J$11:$L$14,3,FALSE) -> 30 | H3: =ROUND(E3*1440,0) -> 560 | I3: =ROUND(F3*1440,0) -> 695 | S3: 1
A4: AB2 | B4: 135 | C4: Terminal A | D4: Terminal B | E4: 0.51388889 | F4: 0.60763889 | G4: =VLOOKUP(D4,$J$11:$L$14,3,FALSE) -> 30 | H4: =ROUND(E4*1440,0) -> 740 | I4: =ROUND(F4*1440,0) -> 875 | N4: =test!$B$34+VLOOKUP(VLOOKUP(Recharged_Feasible_mat!$B34,test!$A$2:$I$32,4,FALSE),test!$J$10:$P$14,4,FALSE) -> 195 | S4: =S3+1 -> 2
A5: AB3 | B5: 135 | C5: Terminal A | D5: Terminal B | E5: 0.57638889 | F5: 0.67013889 | G5: =VLOOKUP(D5,$J$11:$L$14,3,FALSE) -> 30 | H5: =ROUND(E5*1440,0) -> 830 | I5: =ROUND(F5*1440,0) -> 965 | S5: =S4+1 -> 3
A6: AB4 | B6: 135 | C6: Terminal A | D6: Terminal B | E6: 0.63888889 | F6: 0.73263889 | G6: =VLOOKUP(D6,$J$11:$L$14,3,FALSE) -> 30 | H6: =ROUND(E6*1440,0) -> 920 | I6: =ROUND(F6*1440,0) -> 1055 | S6: =S5+1 -> 4
A7: AB5 | B7: 135 | C7: Terminal A | D7: Terminal B | E7: 0.68055556 | F7: 0.77430556 | G7: =VLOOKUP(D7,$J$11:$L$14,3,FALSE) -> 30 | H7: =ROUND(E7*1440,0) -> 980 | I7: =ROUND(F7*1440,0) -> 1115 | S7: =S6+1 -> 5
A8: AB6 | B8: 135 | C8: Terminal A | D8: Terminal B | E8: 0.72222222 | F8: 0.81597222 | G8: =VLOOKUP(D8,$J$11:$L$14,3,FALSE) -> 30 | H8: =ROUND(E8*1440,0) -> 1040 | I8: =ROUND(F8*1440,0) -> 1175 | J8: TMAX | K8: =MAX(F3:F32)*1440 -> 1355 | S8: =S7+1 -> 6
A9: AB7 | B9: 135 | C9: Terminal A | D9: Terminal B | E9: 0.76388889 | F9: 0.85763889 | G9: =VLOOKUP(D9,$J$11:$L$14,3,FALSE) -> 30 | H9: =ROUND(E9*1440,0) -> 1100 | I9: =ROUND(F9*1440,0) -> 1235 | S9: =S8+1 -> 7
A10: AB8 | B10: 135 | C10: Terminal A | D10: Terminal B | E10: 0.82638889 | F10: 0.92013889 | G10: =VLOOKUP(D10,$J$11:$L$14,3,FALSE) -> 30 | H10: =ROUND(E10*1440,0) -> 1190 | I10: =ROUND(F10*1440,0) -> 1325 | J10: Terminal | K10: Min_Layover | L10: Duration to CS1 | M10: Duration to CS1a | N10: Duration to CS2b | O10: Duration to CS3c | P10: Duration to CS4d | S10: =S9+1 -> 8
A11: AC1 | B11: 140 | C11: Terminal A | D11: Terminal C | E11: 0.38541667 | F11: 0.48263889 | G11: =VLOOKUP(D11,$J$11:$L$14,3,FALSE) -> 30 | H11: =ROUND(E11*1440,0) -> 555 | I11: =ROUND(F11*1440,0) -> 695 | J11: Terminal A | K11: 15 | L11: 30 | M11: 10 | N11: 145 | O11: 150 | P11: 220 | S11: =S10+1 -> 9
A12: AC2 | B12: 140 | C12: Terminal A | D12: Terminal C | E12: 0.46875 | F12: 0.56597222 | G12: =VLOOKUP(D12,$J$11:$L$14,3,FALSE) -> 30 | H12: =ROUND(E12*1440,0) -> 675 | I12: =ROUND(F12*1440,0) -> 815 | J12: Terminal B | K12: 15 | L12: 30 | M12: 145 | N12: 10 | O12: 155 | P12: 160 | S12: =S11+1 -> 10
A13: AC3 | B13: 140 | C13: Terminal A | D13: Terminal C | E13: 0.55208333 | F13: 0.64930556 | G13: =VLOOKUP(D13,$J$11:$L$14,3,FALSE) -> 30 | H13: =ROUND(E13*1440,0) -> 795 | I13: =ROUND(F13*1440,0) -> 935 | J13: Terminal C | K13: 15 | L13: 30 | M13: 150 | N13: 155 | O13: 10 | P13: 280 | S13: =S12+1 -> 11
A14: AC4 | B14: 140 | C14: Terminal A | D14: Terminal C | E14: 0.80208333 | F14: 0.89930556 | G14: =VLOOKUP(D14,$J$11:$L$14,3,FALSE) -> 30 | H14: =ROUND(E14*1440,0) -> 1155 | I14: =ROUND(F14*1440,0) -> 1295 | J14: Terminal D | K14: 15 | L14: 30 | M14: 220 | N14: 160 | O14: 280 | P14: 10 | S14: =S13+1 -> 12
A15: AC5 | B15: 140 | C15: Terminal A | D15: Terminal C | E15: 0.84375 | F15: 0.94097222 | G15: =VLOOKUP(D15,$J$11:$L$14,3,FALSE) -> 30 | H15: =ROUND(E15*1440,0) -> 1215 | I15: =ROUND(F15*1440,0) -> 1355 | J15: CS | K15: 100 | L15: (MAX_DURATION == 500, time to recharge = 100 seconds) | S15: =S14+1 -> 13
A16: AD1 | B16: 210 | C16: Terminal A | D16: Terminal D | E16: 0.38888889 | F16: 0.53472222 | G16: =VLOOKUP(D16,$J$11:$L$14,3,FALSE) -> 30 | H16: =ROUND(E16*1440,0) -> 560 | I16: =ROUND(F16*1440,0) -> 770 | J16: MAX_DURATION | K16: 350 | S16: =S15+1 -> 14
A17: BA1 | B17: 135 | C17: Terminal B | D17: Terminal A | E17: 0.375 | F17: 0.46875 | G17: =VLOOKUP(D17,$J$11:$L$14,3,FALSE) -> 30 | H17: =ROUND(E17*1440,0) -> 540 | I17: =ROUND(F17*1440,0) -> 675 | S17: =S16+1 -> 15
A18: BA2 | B18: 135 | C18: Terminal B | D18: Terminal A | E18: 0.4375 | F18: 0.53125 | G18: =VLOOKUP(D18,$J$11:$L$14,3,FALSE) -> 30 | H18: =ROUND(E18*1440,0) -> 630 | I18: =ROUND(F18*1440,0) -> 765 | S18: =S17+1 -> 16
A19: BA3 | B19: 135 | C19: Terminal B | D19: Terminal A | E19: 0.5 | F19: 0.59375 | G19: =VLOOKUP(D19,$J$11:$L$14,3,FALSE) -> 30 | H19: =ROUND(E19*1440,0) -> 720 | I19: =ROUND(F19*1440,0) -> 855 | S19: =S18+1 -> 17
A20: BA4 | B20: 135 | C20: Terminal B | D20: Terminal A | E20: 0.5625 | F20: 0.65625 | G20: =VLOOKUP(D20,$J$11:$L$14,3,FALSE) -> 30 | H20: =ROUND(E20*1440,0) -> 810 | I20: =ROUND(F20*1440,0) -> 945 | N20: =VLOOKUP($A5,test!$A$3:$I$32,9,FALSE) -> 965 | S20: =S19+1 -> 18
A21: BA5 | B21: 135 | C21: Terminal B | D21: Terminal A | E21: 0.625 | F21: 0.71875 | G21: =VLOOKUP(D21,$J$11:$L$14,3,FALSE) -> 30 | H21: =ROUND(E21*1440,0) -> 900 | I21: =ROUND(F21*1440,0) -> 1035 | N21: =VLOOKUP("BA6",test!$A$3:$I$32,8,FALSE) -> 990 | S21: =S20+1 -> 19
A22: BA6 | B22: 135 | C22: Terminal B | D22: Terminal A | E22: 0.6875 | F22: 0.78125 | G22: =VLOOKUP(D22,$J$11:$L$14,3,FALSE) -> 30 | H22: =ROUND(E22*1440,0) -> 990 | I22: =ROUND(F22*1440,0) -> 1125 | S22: =S21+1 -> 20
A23: BA7 | B23: 135 | C23: Terminal B | D23: Terminal A | E23: 0.75 | F23: 0.84375 | G23: =VLOOKUP(D23,$J$11:$L$14,3,FALSE) -> 30 | H23: =ROUND(E23*1440,0) -> 1080 | I23: =ROUND(F23*1440,0) -> 1215 | S23: =S22+1 -> 21
A24: BA8 | B24: 135 | C24: Terminal B | D24: Terminal A | E24: 0.79166667 | F24: 0.88541667 | G24: =VLOOKUP(D24,$J$11:$L$14,3,FALSE) -> 30 | H24: =ROUND(E24*1440,0) -> 1140 | I24: =ROUND(F24*1440,0) -> 1275 | J24: Terminal | K24: Min_Layover | L24: Duration to CS1 | M24: Duration to CS1a | N24: Duration to CS2b | O24: Duration to CS3c | P24: Duration to CS4d | S24: =S23+1 -> 22
A25: CA1 | B25: 140 | C25: Terminal C | D25: Terminal A | E25: 0.39583333 | F25: 0.49305556 | G25: =VLOOKUP(D25,$J$11:$L$14,3,FALSE) -> 30 | H25: =ROUND(E25*1440,0) -> 570 | I25: =ROUND(F25*1440,0) -> 710 | J25: Terminal A | K25: 15 | L25: 30 | M25: 10 | N25: 75 | O25: 85 | P25: 95 | S25: =S24+1 -> 23
A26: CA2 | B26: 140 | C26: Terminal C | D26: Terminal A | E26: 0.51388889 | F26: 0.61111111 | G26: =VLOOKUP(D26,$J$11:$L$14,3,FALSE) -> 30 | H26: =ROUND(E26*1440,0) -> 740 | I26: =ROUND(F26*1440,0) -> 880 | J26: Terminal B | K26: 15 | L26: 30 | M26: 75 | N26: 10 | O26: 60 | P26: 65 | S26: =S25+1 -> 24
A27: CA3 | B27: 140 | C27: Terminal C | D27: Terminal A | E27: 0.59722222 | F27: 0.69444444 | G27: =VLOOKUP(D27,$J$11:$L$14,3,FALSE) -> 30 | H27: =ROUND(E27*1440,0) -> 860 | I27: =ROUND(F27*1440,0) -> 1000 | J27: Terminal C | K27: 15 | L27: 30 | M27: 85 | N27: 60 | O27: 10 | P27: 50 | S27: =S26+1 -> 25
A28: CA4 | B28: 140 | C28: Terminal C | D28: Terminal A | E28: 0.63888889 | F28: 0.73611111 | G28: =VLOOKUP(D28,$J$11:$L$14,3,FALSE) -> 30 | H28: =ROUND(E28*1440,0) -> 920 | I28: =ROUND(F28*1440,0) -> 1060 | J28: Terminal D | K28: 15 | L28: 30 | M28: 95 | N28: 65 | O28: 50 | P28: 10 | S28: =S27+1 -> 26
A29: CA5 | B29: 140 | C29: Terminal C | D29: Terminal A | E29: 0.72222222 | F29: 0.81944444 | G29: =VLOOKUP(D29,$J$11:$L$14,3,FALSE) -> 30 | H29: =ROUND(E29*1440,0) -> 1040 | I29: =ROUND(F29*1440,0) -> 1180 | S29: =S28+1 -> 27
A30: CD1 | B30: 270 | C30: Terminal C | D30: Terminal D | E30: 0.3125 | F30: 0.5 | G30: =VLOOKUP(D30,$J$11:$L$14,3,FALSE) -> 30 | H30: =ROUND(E30*1440,0) -> 450 | I30: =ROUND(F30*1440,0) -> 720 | S30: =S29+1 -> 28
A31: DA1 | B31: 210 | C31: Terminal D | D31: Terminal A | E31: 0.59722222 | F31: 0.74305556 | G31: =VLOOKUP(D31,$J$11:$L$14,3,FALSE) -> 30 | H31: =ROUND(E31*1440,0) -> 860 | I31: =ROUND(F31*1440,0) -> 1070 | J31: Terminal | K31: Min_Layover | L31: Duration to CS1 | M31: Duration to CS1a | N31: Duration to CS2b | O31: Duration to CS3c | P31: Duration to CS4d | S31: =S30+1 -> 29
A32: DC1 | B32: 270 | C32: Terminal D | D32: Terminal C | E32: 0.5625 | F32: 0.75 | G32: =VLOOKUP(D32,$J$11:$L$14,3,FALSE) -> 30 | H32: =ROUND(E32*1440,0) -> 810 | I32: =ROUND(F32*1440,0) -> 1080 | J32: Terminal A | K32: 15 | L32: 30 | M32: 10 | N32: 75 | O32: 75 | P32: 75 | S32: =S31+1 -> 30
A33: CS1 | B33: 50 | C33: - | D33: - | E33: - | F33: - | G33: 0 | J33: Terminal B | K33: 15 | L33: 30 | M33: 75 | N33: 10 | O33: 75 | P33: 75 | S33: =S32+1 -> 31
A34: CS1a | B34: 50 | C34: Terminal A | D34: Terminal A | E34: - | F34: - | G34: 0 | J34: Terminal C | K34: 15 | L34: 30 | M34: 75 | N34: 75 | O34: 10 | P34: 75 | S34: =S33+1 -> 32
A35: CS2b | B35: 50 | C35: Terminal B | D35: Terminal B | E35: - | F35: - | G35: 0 | J35: Terminal D | K35: 15 | L35: 30 | M35: 75 | N35: 75 | O35: 75 | P35: 10 | S35: =S34+1 -> 33
A36: CS3c | B36: 50 | C36: Terminal C | D36: Terminal C | E36: - | F36: - | G36: 0
A37: CS4d | B37: 50 | C37: Terminal D | D37: Terminal D | E37: - | F37: - | G37: 0
A40: RESULTS
A41: ID | B41: Trips | F41: CPLEX | G41: Solution
A42: 0 | B42: DEPOT | G42: 0 | H42: 14 | I42: 29 | J42: 31 | K42: 13 | L42: 33 | M42: 18 | N42: 0
...

Sheet Recharged_Feasible_matv3
A1: phi | C1: DEPOT | D1: AB1 | E1: AB2 | F1: AB3 | G1: AB4 | H1: AB5 | I1: AB6 | J1: AB7 | K1: AB8 | L1: AC1 | M1: AC2 | N1: AC3 | O1: AC4 | P1: AC5 | Q1: AD1 | R1: BA1 | S1: BA2 | T1: BA3 | U1: BA4 | V1: BA5 | W1: BA6 | X1: BA7 | Y1: BA8 | Z1: CA1 | AA1: CA2 | AB1: CA3 | AC1: CA4 | AD1: CA5 | AE1: CD1 | AF1: DA1 | AG1: DC1
A2: CS1 | B2: DEPOT | C2: 0 | D2: 0 | E2: 0 | F2: 0 | G2: 0 | H2: 0 | I2: 0 | J2: 0 | K2: 0 | L2: 0 | M2: 0 | N2: 0 | O2: 0 | P2: 0 | Q2: 0 | R2: 0 | S2: 0 | T2: 0 | U2: 0 | V2: 0 | W2: 0 | X2: 0 | Y2: 0 | Z2: 0 | AA2: 0 | AB2: 0 | AC2: 0 | AD2: 0 | AE2: 0 | AF2: 0 | AG2: 0
A3: CS1 | B3: AB1 | C3: 0 | D3: =IF(AND(VLOOKUP(D$1,test!$A$3:$I$32,8,FALSE) - VLOOKUP($B3,test!$A$3:$I$32,9,FALSE) >= (test!$B$33+VLOOKUP(VLOOKUP($B3,test!$A$2:$I$32,4,FALSE),test!$J$10:$P$14,3,FALSE))),1,0) -> 0 | E3: =IF(AND(VLOOKUP(E$1,test!$A$3:$I$32,8,FALSE) - VLOOKUP($B3,test!$A$3:$I$32,9,FALSE) >= (test!$B$33+VLOOKUP(VLOOKUP($B3,test!$A$2:$I$32,4,FALSE),test!$J$10:$P$14,3,FALSE))),1,0) -> 0 | F3: =IF(AND(VLOOKUP(F$1,test!$A$3:$I$32,8,FALSE) - VLOOKUP($B3,test!$A$3:$I$32,9,FALSE) >= (test!$B$33+VLOOKUP(VLOOKUP($B3,test!$A$2:$I$32,4,FALSE),test!$J$10:$P$14,3,FALSE))),1,0) -> 1 | G3: =IF(AND(VLOOKUP(G$1,test!$A$3:$I$32,8,FALSE) - VLOOKUP($B3,test!$A$3:$I$32,9,FALSE) >= (test!$B$33+VLOOKUP(VLOOKUP($B3,test!$A$2:$I$32,4,FALSE),test!$J$10:$P$14,3,FALSE))),1,0) -> 1 | H3: =IF(AND(VLOOKUP(H$1,test!$A$3:$I$32,8,FALSE) - VLOOKUP($B3,test!$A$3:$I$32,9,FALSE) >= (test!$B$33+VLOOKUP(VLOOKUP($B3,test!$A$2:$I$32,4,FALSE),test!$J$10:$P$14,3,FALSE))),1,0) -> 1 | I3: =IF(AND(VLOOKUP(I$1,test!$A$3:$I$32,8,FALSE) - VLOOKUP($B3,test!$A$3:$I$32,9,FALSE) >= (test!$B$33+VLOOKUP(VLOOKUP($B3,test!$A$2:$I$32,4,FALSE),test!$J$10:$P$14,3,FALSE))),1,0) -> 1 | J3: =IF(AND(VLOOKUP(J$1,test!$A$3:$I$32,8,FALSE) - VLOOKUP($B3,test!$A$3:$I$32,9,FALSE) >= (test!$B$33+VLOOKUP(VLOOKUP($B3,test!$A$2:$I$32,4,FALSE),test!$J$10:$P$14,3,FALSE))),1,0) -> 1 | K3: =IF(AND(VLOOKUP(K$1,test!$A$3:$I$32,8,FALSE) - VLOOKUP($B3,test!$A$3:$I$32,9,FALSE) >= (test!$B$33+VLOOKUP(VLOOKUP($B3,test!$A$2:$I$32,4,FALSE),test!$J$10:$P$14,3,FALSE))),1,0) -> 1 | ... AG3: =IF(AND(VLOOKUP(AG$1,test!$A$3:$I$32,8,FALSE) - VLOOKUP($B3,test!$A$3:$I$32,9,FALSE) >= (test!$B$33+VLOOKUP(VLOOKUP($B3,test!$A$2:$I$32,4,FALSE),test!$J$10:$P$14,3,FALSE))),1,0) -> 1
A4: CS1 | B4: AB2 | C4: 0 | D4: =IF(AND(VLOOKUP(D$1,test!$A$3:$I$32,8,FALSE) - VLOOKUP($B4,test!$A$3:$I$32,9,FALSE) >= (test!$B$33+VLOOKUP(VLOOKUP($B4,test!$A$2:$I$32,4,FALSE),test!$J$10:$P$14,3,FALSE))),1,0) -> 0 | E4: =IF(AND(VLOOKUP(E$1,test!$A$3:$I$32,8,FALSE) - VLOOKUP($B4,test!$A$3:$I$32,9,FALSE) >= (test!$B$33+VLOOKUP(VLOOKUP($B4,test!$A$2:$I$32,4,FALSE),test!$J$10:$P$14,3,FALSE))),1,0) -> 0 | F4: =IF(AND(VLOOKUP(F$1,test!$A$3:$I$32,8,FALSE) - VLOOKUP($B4,test!$A$3:$I$32,9,FALSE) >= (test!$B$33+VLOOKUP(VLOOKUP($B4,test!$A$2:$I$32,4,FALSE),test!$J$10:$P$14,3,FALSE))),1,0) -> 0 | G4: =IF(AND(VLOOKUP(G$1,test!$A$3:$I$32,8,FALSE) - VLOOKUP($B4,test!$A$3:$I$32,9,FALSE) >= (test!$B$33+VLOOKUP(VLOOKUP($B4,test!$A$2:$I$32,4,FALSE),test!$J$10:$P$14,3,FALSE))),1,0) -> 0 | H4: =IF(AND(VLOOKUP(H$1,test!$A$3:$I$32,8,FALSE) - VLOOKUP($B4,test!$A$3:$I$32,9,FALSE) >= (test!$B$33+VLOOKUP(VLOOKUP($B4,test!$A$2:$I$32,4,FALSE),test!$J$10:$P$14,3,FALSE))),1,0) -> 1 | I4: =IF(AND(VLOOKUP(I$1,test!$A$3:$I$32,8,FALSE) - VLOOKUP($B4,test!$A$3:$I$32,9,FALSE) >= (test!$B$33+VLOOKUP(VLOOKUP($B4,test!$A$2:$I$32,4,FALSE),test!$J$10:$P$14,3,FALSE))),1,0) -> 1 | J4: =IF(AND(VLOOKUP(J$1,test!$A$3:$I$32,8,FALSE) - VLOOKUP($B4,test!$A$3:$I$32,9,FALSE) >= (test!$B$33+VLOOKUP(VLOOKUP($B4,test!$A$2:$I$32,4,FALSE),test!$J$10:$P$14,3,FALSE))),1,0) -> 1 | K4: =IF(AND(VLOOKUP(K$1,test!$A$3:$I$32,8,FALSE) - VLOOKUP($B4,test!$A$3:$I$32,9,FALSE) >= (test!$B$33+VLOOKUP(VLOOKUP($B4,test!$A$2:$I$32,4,FALSE),test!$J$10:$P$14,3,FALSE))),1,0) -> 1 | ... AG4: =IF(AND(VLOOKUP(AG$1,test!$A$3:$I$32,8,FALSE) - VLOOKUP($B4,test!$A$3:$I$32,9,FALSE) >= (test!$B$33+VLOOKUP(VLOOKUP($B4,test!$A$2:$I$32,4,FALSE),test!$J$10:$P$14,3,FALSE))),1,0) -> 0
A5: CS1 | B5: AB3 | C5: 0 | D5: =IF(AND(VLOOKUP(D$1,test!$A$3:$I$32,8,FALSE) - VLOOKUP($B5,test!$A$3:$I$32,9,FALSE) >= (test!$B$33+VLOOKUP(VLOOKUP($B5,test!$A$2:$I$32,4,FALSE),test!$J$10:$P$14,3,FALSE))),1,0) -> 0 | E5: =IF(AND(VLOOKUP(E$1,test!$A$3:$I$32,8,FALSE) - VLOOKUP($B5,test!$A$3:$I$32,9,FALSE) >= (test!$B$33+VLOOKUP(VLOOKUP($B5,test!$A$2:$I$32,4,FALSE),test!$J$10:$P$14,3,FALSE))),1,0) -> 0 | F5: =IF(AND(VLOOKUP(F$1,test!$A$3:$I$32,8,FALSE) - VLOOKUP($B5,test!$A$3:$I$32,9,FALSE) >= (test!$B$33+VLOOKUP(VLOOKUP($B5,test!$A$2:$I$32,4,FALSE),test!$J$10:$P$14,3,FALSE))),1,0) -> 0 | G5: =IF(AND(VLOOKUP(G$1,test!$A$3:$I$32,8,FALSE) - VLOOKUP($B5,test!$A$3:$I$32,9,FALSE) >= (test!$B$33+VLOOKUP(VLOOKUP($B5,test!$A$2:$I$32,4,FALSE),test!$J$10:$P$14,3,FALSE))),1,0) -> 0 | H5: =IF(AND(VLOOKUP(H$1,test!$A$3:$I$32,8,FALSE) - VLOOKUP($B5,test!$A$3:$I$32,9,FALSE) >= (test!$B$33+VLOOKUP(VLOOKUP($B5,test!$A$2:$I$32,4,FALSE),test!$J$10:$P$14,3,FALSE))),1,0) -> 0 | I5: =IF(AND(VLOOKUP(I$1,test!$A$3:$I$32,8,FALSE) - VLOOKUP($B5,test!$A$3:$I$32,9,FALSE) >= (test!$B$33+VLOOKUP(VLOOKUP($B5,test!$A$2:$I$32,4,FALSE),test!$J$10:$P$14,3,FALSE))),1,0) -> 0 | J5: =IF(AND(VLOOKUP(J$1,test!$A$3:$I$32,8,FALSE) - VLOOKUP($B5,test!$A$3:$I$32,9,FALSE) >= (test!$B$33+VLOOKUP(VLOOKUP($B5,test!$A$2:$I$32,4,FALSE),test!$J$10:$P$14,3,FALSE))),1,0) -> 1 | K5: =IF(AND(VLOOKUP(K$1,test!$A$3:$I$32,8,FALSE) - VLOOKUP($B5,test!$A$3:$I$32,9,FALSE) >= (test!$B$33+VLOOKUP(VLOOKUP($B5,test!$A$2:$I$32,4,FALSE),test!$J$10:$P$14,3,FALSE))),1,0) -> 1 | ... AG5: =IF(AND(VLOOKUP(AG$1,test!$A$3:$I$32,8,FALSE) - VLOOKUP($B5,test!$A$3:$I$32,9,FALSE) >= (test!$B$33+VLOOKUP(VLOOKUP($B5,test!$A$2:$I$32,4,FALSE),test!$J$10:$P$14,3,FALSE))),1,0) -> 0
A6: CS1 | B6: AB4 | C6: 0 | D6: =IF(AND(VLOOKUP(D$1,test!$A$3:$I$32,8,FALSE) - VLOOKUP($B6,test!$A$3:$I$32,9,FALSE) >= (test!$B$33+VLOOKUP(VLOOKUP($B6,test!$A$2:$I$32,4,FALSE),test!$J$10:$P$14,3,FALSE))),1,0) -> 0 | E6: =IF(AND(VLOOKUP(E$1,test!$A$3:$I$32,8,FALSE) - VLOOKUP($B6,test!$A$3:$I$32,9,FALSE) >= (test!$B$33+VLOOKUP(VLOOKUP($B6,test!$A$2:$I$32,4,FALSE),test!$J$10:$P$14,3,FALSE))),1,0) -> 0 | F6: =IF(AND(VLOOKUP(F$1,test!$A$3:$I$32,8,FALSE) - VLOOKUP($B6,test!$A$3:$I$32,9,FALSE) >= (test!$B$33+VLOOKUP(VLOOKUP($B6,test!$A$2:$I$32,4,FALSE),test!$J$10:$P$14,3,FALSE))),1,0) -> 0 | G6: =IF(AND(VLOOKUP(G$1,test!$A$3:$I$32,8,FALSE) - VLOOKUP($B6,test!$A$3:$I$32,9,FALSE) >= (test!$B$33+VLOOKUP(VLOOKUP($B6,test!$A$2:$I$32,4,FALSE),test!$J$10:$P$14,3,FALSE))),1,0) -> 0 | H6: =IF(AND(VLOOKUP(H$1,test!$A$3:$I$32,8,FALSE) - VLOOKUP($B6,test!$A$3:$I$32,9,FALSE) >= (test!$B$33+VLOOKUP(VLOOKUP($B6,test!$A$2:$I$32,4,FALSE),test!$J$10:$P$14,3,FALSE))),1,0) -> 0 | I6: =IF(AND(VLOOKUP(I$1,test!$A$3:$I$32,8,FALSE) - VLOOKUP($B6,test!$A$3:$I$32,9,FALSE) >= (test!$B$33+VLOOKUP(VLOOKUP($B6,test!$A$2:$I$32,4,FALSE),test!$J$10:$P$14,3,FALSE))),1,0) -> 0 | J6: =IF(AND(VLOOKUP(J$1,test!$A$3:$I$32,8,FALSE) - VLOOKUP($B6,test!$A$3:$I$32,9,FALSE) >= (test!$B$33+VLOOKUP(VLOOKUP($B6,test!$A$2:$I$32,4,FALSE),test!$J$10:$P$14,3,FALSE))),1,0) -> 0 | K6: =IF(AND(VLOOKUP(K$1,test!$A$3:$I$32,8,FALSE) - VLOOKUP($B6,test!$A$3:$I$32,9,FALSE) >= (test!$B$33+VLOOKUP(VLOOKUP($B6,test!$A$2:$I$32,4,FALSE),test!$J$10:$P$14,3,FALSE))),1,0) -> 1 | ... AG6: =IF(AND(VLOOKUP(AG$1,test!$A$3:$I$32,8,FALSE) - VLOOKUP($B6,test!$A$3:$I$32,9,FALSE) >= (test!$B$33+VLOOKUP(VLOOKUP($B6,test!$A$2:$I$32,4,FALSE),test!$J$10:$P$14,3,FALSE))),1,0) -> 0
A7: CS1 | B7: AB5 | C7: 0 | D7: =IF(AND(VLOOKUP(D$1,test!$A$3:$I$32,8,FALSE) - VLOOKUP($B7,test!$A$3:$I$32,9,FALSE) >= (test!$B$33+VLOOKUP(VLOOKUP($B7,test!$A$2:$I$32,4,FALSE),test!$J$10:$P$14,3,FALSE))),1,0) -> 0 | E7: =IF(AND(VLOOKUP(E$1,test!$A$3:$I$32,8,FALSE) - VLOOKUP($B7,test!$A$3:$I$32,9,FALSE) >= (test!$B$33+VLOOKUP(VLOOKUP($B7,test!$A$2:$I$32,4,FALSE),test!$J$10:$P$14,3,FALSE))),1,0) -> 0 | F7: =IF(AND(VLOOKUP(F$1,test!$A$3:$I$32,8,FALSE) - VLOOKUP($B7,test!$A$3:$I$32,9,FALSE) >= (test!$B$33+VLOOKUP(VLOOKUP($B7,test!$A$2:$I$32,4,FALSE),test!$J$10:$P$14,3,FALSE))),1,0) -> 0 | G7: =IF(AND(VLOOKUP(G$1,test!$A$3:$I$32,8,FALSE) - VLOOKUP($B7,test!$A$3:$I$32,9,FALSE) >= (test!$B$33+VLOOKUP(VLOOKUP($B7,test!$A$2:$I$32,4,FALSE),test!$J$10:$P$14,3,FALSE))),1,0) -> 0 | H7: =IF(AND(VLOOKUP(H$1,test!$A$3:$I$32,8,FALSE) - VLOOKUP($B7,test!$A$3:$I$32,9,FALSE) >= (test!$B$33+VLOOKUP(VLOOKUP($B7,test!$A$2:$I$32,4,FALSE),test!$J$10:$P$14,3,FALSE))),1,0) -> 0 | I7: =IF(AND(VLOOKUP(I$1,test!$A$3:$I$32,8,FALSE) - VLOOKUP($B7,test!$A$3:$I$32,9,FALSE) >= (test!$B$33+VLOOKUP(VLOOKUP($B7,test!$A$2:$I$32,4,FALSE),test!$J$10:$P$14,3,FALSE))),1,0) -> 0 | J7: =IF(AND(VLOOKUP(J$1,test!$A$3:$I$32,8,FALSE) - VLOOKUP($B7,test!$A$3:$I$32,9,FALSE) >= (test!$B$33+VLOOKUP(VLOOKUP($B7,test!$A$2:$I$32,4,FALSE),test!$J$10:$P$14,3,FALSE))),1,0) -> 0 | K7: =IF(AND(VLOOKUP(K$1,test!$A$3:$I$32,8,FALSE) - VLOOKUP($B7,test!$A$3:$I$32,9,FALSE) >= (test!$B$33+VLOOKUP(VLOOKUP($B7,test!$A$2:$I$32,4,FALSE),test!$J$10:$P$14,3,FALSE))),1,0) -> 0 | ... AG7: =IF(AND(VLOOKUP(AG$1,test!$A$3:$I$32,8,FALSE) - VLOOKUP($B7,test!$A$3:$I$32,9,FALSE) >= (test!$B$33+VLOOKUP(VLOOKUP($B7,test!$A$2:$I$32,4,FALSE),test!$J$10:$P$14,3,FALSE))),1,0) -> 0
A8: CS1 | B8: AB6 | C8: 0 | D8: =IF(AND(VLOOKUP(D$1,test!$A$3:$I$32,8,FALSE) - VLOOKUP($B8,test!$A$3:$I$32,9,FALSE) >= (test!$B$33+VLOOKUP(VLOOKUP($B8,test!$A$2:$I$32,4,FALSE),test!$J$10:$P$14,3,FALSE))),1,0) -> 0 | E8: =IF(AND(VLOOKUP(E$1,test!$A$3:$I$32,8,FALSE) - VLOOKUP($B8,test!$A$3:$I$32,9,FALSE) >= (test!$B$33+VLOOKUP(VLOOKUP($B8,test!$A$2:$I$32,4,FALSE),test!$J$10:$P$14,3,FALSE))),1,0) -> 0 | F8: =IF(AND(VLOOKUP(F$1,test!$A$3:$I$32,8,FALSE) - VLOOKUP($B8,test!$A$3:$I$32,9,FALSE) >= (test!$B$33+VLOOKUP(VLOOKUP($B8,test!$A$2:$I$32,4,FALSE),test!$J$10:$P$14,3,FALSE))),1,0) -> 0 | G8: =IF(AND(VLOOKUP(G$1,test!$A$3:$I$32,8,FALSE) - VLOOKUP($B8,test!$A$3:$I$32,9,FALSE) >= (test!$B$33+VLOOKUP(VLOOKUP($B8,test!$A$2:$I$32,4,FALSE),test!$J$10:$P$14,3,FALSE))),1,0) -> 0 | H8: =IF(AND(VLOOKUP(H$1,test!$A$3:$I$32,8,FALSE) - VLOOKUP($B8,test!$A$3:$I$32,9,FALSE) >= (test!$B$33+VLOOKUP(VLOOKUP($B8,test!$A$2:$I$32,4,FALSE),test!$J$10:$P$14,3,FALSE))),1,0) -> 0 | I8: =IF(AND(VLOOKUP(I$1,test!$A$3:$I$32,8,FALSE) - VLOOKUP($B8,test!$A$3:$I$32,9,FALSE) >= (test!$B$33+VLOOKUP(VLOOKUP($B8,test!$A$2:$I$32,4,FALSE),test!$J$10:$P$14,3,FALSE))),1,0) -> 0 | J8: =IF(AND(VLOOKUP(J$1,test!$A$3:$I$32,8,FALSE) - VLOOKUP($B8,test!$A$3:$I$32,9,FALSE) >= (test!$B$33+VLOOKUP(VLOOKUP($B8,test!$A$2:$I$32,4,FALSE),test!$J$10:$P$14,3,FALSE))),1,0) -> 0 | K8: =IF(AND(VLOOKUP(K$1,test!$A$3:$I$32,8,FALSE) - VLOOKUP($B8,test!$A$3:$I$32,9,FALSE) >= (test!$B$33+VLOOKUP(VLOOKUP($B8,test!$A$2:$I$32,4,FALSE),test!$J$10:$P$14,3,FALSE))),1,0) -> 0 | ... AG8: =IF(AND(VLOOKUP(AG$1,test!$A$3:$I$32,8,FALSE) - VLOOKUP($B8,test!$A$3:$I$32,9,FALSE) >= (test!$B$33+VLOOKUP(VLOOKUP($B8,test!$A$2:$I$32,4,FALSE),test!$J$10:$P$14,3,FALSE))),1,0) -> 0
A9: CS1 | B9: AB7 | C9: 0 | D9: =IF(AND(VLOOKUP(D$1,test!$A$3:$I$32,8,FALSE) - VLOOKUP($B9,test!$A$3:$I$32,9,FALSE) >= (test!$B$33+VLOOKUP(VLOOKUP($B9,test!$A$2:$I$32,4,FALSE),test!$J$10:$P$14,3,FALSE))),1,0) -> 0 | E9: =IF(AND(VLOOKUP(E$1,test!$A$3:$I$32,8,FALSE) - VLOOKUP($B9,test!$A$3:$I$32,9,FALSE) >= (test!$B$33+VLOOKUP(VLOOKUP($B9,test!$A$2:$I$32,4,FALSE),test!$J$10:$P$14,3,FALSE))),1,0) -> 0 | F9: =IF(AND(VLOOKUP(F$1,test!$A$3:$I$32,8,FALSE) - VLOOKUP($B9,test!$A$3:$I$32,9,FALSE) >= (test!$B$33+VLOOKUP(VLOOKUP($B9,test!$A$2:$I$32,4,FALSE),test!$J$10:$P$14,3,FALSE))),1,0) -> 0 | G9: =IF(AND(VLOOKUP(G$1,test!$A$3:$I$32,8,FALSE) - VLOOKUP($B9,test!$A$3:$I$32,9,FALSE) >= (test!$B$33+VLOOKUP(VLOOKUP($B9,test!$A$2:$I$32,4,FALSE),test!$J$10:$P$14,3,FALSE))),1,0) -> 0 | H9: =IF(AND(VLOOKUP(H$1,test!$A$3:$I$32,8,FALSE) - VLOOKUP($B9,test!$A$3:$I$32,9,FALSE) >= (test!$B$33+VLOOKUP(VLOOKUP($B9,test!$A$2:$I$32,4,FALSE),test!$J$10:$P$14,3,FALSE))),1,0) -> 0 | I9: =IF(AND(VLOOKUP(I$1,test!$A$3:$I$32,8,FALSE) - VLOOKUP($B9,test!$A$3:$I$32,9,FALSE) >= (test!$B$33+VLOOKUP(VLOOKUP($B9,test!$A$2:$I$32,4,FALSE),test!$J$10:$P$14,3,FALSE))),1,0) -> 0 | J9: =IF(AND(VLOOKUP(J$1,test!$A$3:$I$32,8,FALSE) - VLOOKUP($B9,test!$A$3:$I$32,9,FALSE) >= (test!$B$33+VLOOKUP(VLOOKUP($B9,test!$A$2:$I$32,4,FALSE),test!$J$10:$P$14,3,FALSE))),1,0) -> 0 | K9: =IF(AND(VLOOKUP(K$1,test!$A$3:$I$32,8,FALSE) - VLOOKUP($B9,test!$A$3:$I$32,9,FALSE) >= (test!$B$33+VLOOKUP(VLOOKUP($B9,test!$A$2:$I$32,4,FALSE),test!$J$10:$P$14,3,FALSE))),1,0) -> 0 | ... AG9: =IF(AND(VLOOKUP(AG$1,test!$A$3:$I$32,8,FALSE) - VLOOKUP($B9,test!$A$3:$I$32,9,FALSE) >= (test!$B$33+VLOOKUP(VLOOKUP($B9,test!$A$2:$I$32,4,FALSE),test!$J$10:$P$14,3,FALSE))),1,0) -> 0
A10: CS1 | B10: AB8 | C10: 0 | D10: =IF(AND(VLOOKUP(D$1,test!$A$3:$I$32,8,FALSE) - VLOOKUP($B10,test!$A$3:$I$32,9,FALSE) >= (test!$B$33+VLOOKUP(VLOOKUP($B10,test!$A$2:$I$32,4,FALSE),test!$J$10:$P$14,3,FALSE))),1,0) -> 0 | E10: =IF(AND(VLOOKUP(E$1,test!$A$3:$I$32,8,FALSE) - VLOOKUP($B10,test!$A$3:$I$32,9,FALSE) >= (test!$B$33+VLOOKUP(VLOOKUP($B10,test!$A$2:$I$32,4,FALSE),test!$J$10:$P$14,3,FALSE))),1,0) -> 0 | F10: =IF(AND(VLOOKUP(F$1,test!$A$3:$I$32,8,FALSE) - VLOOKUP($B10,test!$A$3:$I$32,9,FALSE) >= (test!$B$33+VLOOKUP(VLOOKUP($B10,test!$A$2:$I$32,4,FALSE),test!$J$10:$P$14,3,FALSE))),1,0) -> 0 | G10: =IF(AND(VLOOKUP(G$1,test!$A$3:$I$32,8,FALSE) - VLOOKUP($B10,test!$A$3:$I$32,9,FALSE) >= (test!$B$33+VLOOKUP(VLOOKUP($B10,test!$A$2:$I$32,4,FALSE),test!$J$10:$P$14,3,FALSE))),1,0) -> 0 | H10: =IF(AND(VLOOKUP(H$1,test!$A$3:$I$32,8,FALSE) - VLOOKUP($B10,test!$A$3:$I$32,9,FALSE) >= (test!$B$33+VLOOKUP(VLOOKUP($B10,test!$A$2:$I$32,4,FALSE),test!$J$10:$P$14,3,FALSE))),1,0) -> 0 | I10: =IF(AND(VLOOKUP(I$1,test!$A$3:$I$32,8,FALSE) - VLOOKUP($B10,test!$A$3:$I$32,9,FALSE) >= (test!$B$33+VLOOKUP(VLOOKUP($B10,test!$A$2:$I$32,4,FALSE),test!$J$10:$P$14,3,FALSE))),1,0) -> 0 | J10: =IF(AND(VLOOKUP(J$1,test!$A$3:$I$32,8,FALSE) - VLOOKUP($B10,test!$A$3:$I$32,9,FALSE) >= (test!$B$33+VLOOKUP(VLOOKUP($B10,test!$A$2:$I$32,4,FALSE),test!$J$10:$P$14,3,FALSE))),1,0) -> 0 | K10: =IF(AND(VLOOKUP(K$1,test!$A$3:$I$32,8,FALSE) - VLOOKUP($B10,test!$A$3:$I$32,9,FALSE) >= (test!$B$33+VLOOKUP(VLOOKUP($B10,test!$A$2:$I$32,4,FALSE),test!$J$10:$P$14,3,FALSE))),1,0) -> 0 | ... AG10: =IF(AND(VLOOKUP(AG$1,test!$A$3:$I$32,8,FALSE) - VLOOKUP($B10,test!$A$3:$I$32,9,FALSE) >= (test!$B$33+VLOOKUP(VLOOKUP($B10,test!$A$2:$I$32,4,FALSE),test!$J$10:$P$14,3,FALSE))),1,0) -> 0
A11: CS1 | B11: AC1 | C11: 0 | D11: =IF(AND(VLOOKUP(D$1,test!$A$3:$I$32,8,FALSE) - VLOOKUP($B11,test!$A$3:$I$32,9,FALSE) >= (test!$B$33+VLOOKUP(VLOOKUP($B11,test!$A$2:$I$32,4,FALSE),test!$J$10:$P$14,3,FALSE))),1,0) -> 0 | E11: =IF(AND(VLOOKUP(E$1,test!$A$3:$I$32,8,FALSE) - VLOOKUP($B11,test!$A$3:$I$32,9,FALSE) >= (test!$B$33+VLOOKUP(VLOOKUP($B11,test!$A$2:$I$32,4,FALSE),test!$J$10:$P$14,3,FALSE))),1,0) -> 0 | F11: =IF(AND(VLOOKUP(F$1,test!$A$3:$I$32,8,FALSE) - VLOOKUP($B11,test!$A$3:$I$32,9,FALSE) >= (test!$B$33+VLOOKUP(VLOOKUP($B11,test!$A$2:$I$32,4,FALSE),test!$J$10:$P$14,3,FALSE))),1,0) -> 1 | G11: =IF(AND(VLOOKUP(G$1,test!$A$3:$I$32,8,FALSE) - VLOOKUP($B11,test!$A$3:$I$32,9,FALSE) >= (test!$B$33+VLOOKUP(VLOOKUP($B11,test!$A$2:$I$32,4,FALSE),test!$J$10:$P$14,3,FALSE))),1,0) -> 1 | H11: =IF(AND(VLOOKUP(H$1,test!$A$3:$I$32,8,FALSE) - VLOOKUP($B11,test!$A$3:$I$32,9,FALSE) >= (test!$B$33+VLOOKUP(VLOOKUP($B11,test!$A$2:$I$32,4,FALSE),test!$J$10:$P$14,3,FALSE))),1,0) -> 1 | I11: =IF(AND(VLOOKUP(I$1,test!$A$3:$I$32,8,FALSE) - VLOOKUP($B11,test!$A$3:$I$32,9,FALSE) >= (test!$B$33+VLOOKUP(VLOOKUP($B11,test!$A$2:$I$32,4,FALSE),test!$J$10:$P$14,3,FALSE))),1,0) -> 1 | J11: =IF(AND(VLOOKUP(J$1,test!$A$3:$I$32,8,FALSE) - VLOOKUP($B11,test!$A$3:$I$32,9,FALSE) >= (test!$B$33+VLOOKUP(VLOOKUP($B11,test!$A$2:$I$32,4,FALSE),test!$J$10:$P$14,3,FALSE))),1,0) -> 1 | K11: =IF(AND(VLOOKUP(K$1,test!$A$3:$I$32,8,FALSE) - VLOOKUP($B11,test!$A$3:$I$32,9,FALSE) >= (test!$B$33+VLOOKUP(VLOOKUP($B11,test!$A$2:$I$32,4,FALSE),test!$J$10:$P$14,3,FALSE))),1,0) -> 1 | ... AG11: =IF(AND(VLOOKUP(AG$1,test!$A$3:$I$32,8,FALSE) - VLOOKUP($B11,test!$A$3:$I$32,9,FALSE) >= (test!$B$33+VLOOKUP(VLOOKUP($B11,test!$A$2:$I$32,4,FALSE),test!$J$10:$P$14,3,FALSE))),1,0) -> 1
A12: CS1 | B12: AC2 | C12: 0 | D12: =IF(AND(VLOOKUP(D$1,test!$A$3:$I$32,8,FALSE) - VLOOKUP($B12,test!$A$3:$I$32,9,FALSE) >= (test!$B$33+VLOOKUP(VLOOKUP($B12,test!$A$2:$I$32,4,FALSE),test!$J$10:$P$14,3,FALSE))),1,0) -> 0 | E12: =IF(AND(VLOOKUP(E$1,test!$A$3:$I$32,8,FALSE) - VLOOKUP($B12,test!$A$3:$I$32,9,FALSE) >= (test!$B$33+VLOOKUP(VLOOKUP($B12,test!$A$2:$I$32,4,FALSE),test!$J$10:$P$14,3,FALSE))),1,0) -> 0 | F12: =IF(AND(VLOOKUP(F$1,test!$A$3:$I$32,8,FALSE) - VLOOKUP($B12,test!$A$3:$I$32,9,FALSE) >= (test!$B$33+VLOOKUP(VLOOKUP($B12,test!$A$2:$I$32,4,FALSE),test!$J$10:$P$14,3,FALSE))),1,0) -> 0 | G12: =IF(AND(VLOOKUP(G$1,test!$A$3:$I$32,8,FALSE) - VLOOKUP($B12,test!$A$3:$I$32,9,FALSE) >= (test!$B$33+VLOOKUP(VLOOKUP($B12,test!$A$2:$I$32,4,FALSE),test!$J$10:$P$14,3,FALSE))),1,0) -> 1 | H12: =IF(AND(VLOOKUP(H$1,test!$A$3:$I$32,8,FALSE) - VLOOKUP($B12,test!$A$3:$I$32,9,FALSE) >= (test!$B$33+VLOOKUP(VLOOKUP($B12,test!$A$2:$I$32,4,FALSE),test!$J$10:$P$14,3,FALSE))),1,0) -> 1 | I12: =IF(AND(VLOOKUP(I$1,test!$A$3:$I$32,8,FALSE) - VLOOKUP($B12,test!$A$3:$I$32,9,FALSE) >= (test!$B$33+VLOOKUP(VLOOKUP($B12,test!$A$2:$I$32,4,FALSE),test!$J$10:$P$14,3,FALSE))),1,0) -> 1 | J12: =IF(AND(VLOOKUP(J$1,test!$A$3:$I$32,8,FALSE) - VLOOKUP($B12,test!$A$3:$I$32,9,FALSE) >= (test!$B$33+VLOOKUP(VLOOKUP($B12,test!$A$2:$I$32,4,FALSE),test!$J$10:$P$14,3,FALSE))),1,0) -> 1 | K12: =IF(AND(VLOOKUP(K$1,test!$A$3:$I$32,8,FALSE) - VLOOKUP($B12,test!$A$3:$I$32,9,FALSE) >= (test!$B$33+VLOOKUP(VLOOKUP($B12,test!$A$2:$I$32,4,FALSE),test!$J$10:$P$14,3,FALSE))),1,0) -> 1 | ... AG12: =IF(AND(VLOOKUP(AG$1,test!$A$3:$I$32,8,FALSE) - VLOOKUP($B12,test!$A$3:$I$32,9,FALSE) >= (test!$B$33+VLOOKUP(VLOOKUP($B12,test!$A$2:$I$32,4,FALSE),test!$J$10:$P$14,3,FALSE))),1,0) -> 0
A13: CS1 | B13: AC3 | C13: 0 | D13: =IF(AND(VLOOKUP(D$1,test!$A$3:$I$32,8,FALSE) - VLOOKUP($B13,test!$A$3:$I$32,9,FALSE) >= (test!$B$33+VLOOKUP(VLOOKUP($B13,test!$A$2:$I$32,4,FALSE),test!$J$10:$P$14,3,FALSE))),1,0) -> 0 | E13: =IF(AND(VLOOKUP(E$1,test!$A$3:$I$32,8,FALSE) - VLOOKUP($B13,test!$A$3:$I$32,9,FALSE) >= (test!$B$33+VLOOKUP(VLOOKUP($B13,test!$A$2:$I$32,4,FALSE),test!$J$10:$P$14,3,FALSE))),1,0) -> 0 | F13: =IF(AND(VLOOKUP(F$1,test!$A$3:$I$32,8,FALSE) - VLOOKUP($B13,test!$A$3:$I$32,9,FALSE) >= (test!$B$33+VLOOKUP(VLOOKUP($B13,test!$A$2:$I$32,4,FALSE),test!$J$10:$P$14,3,FALSE))),1,0) -> 0 | G13: =IF(AND(VLOOKUP(G$1,test!$A$3:$I$32,8,FALSE) - VLOOKUP($B13,test!$A$3:$I$32,9,FALSE) >= (test!$B$33+VLOOKUP(VLOOKUP($B13,test!$A$2:$I$32,4,FALSE),test!$J$10:$P$14,3,FALSE))),1,0) -> 0 | H13: =IF(AND(VLOOKUP(H$1,test!$A$3:$I$32,8,FALSE) - VLOOKUP($B13,test!$A$3:$I$32,9,FALSE) >= (test!$B$33+VLOOKUP(VLOOKUP($B13,test!$A$2:$I$32,4,FALSE),test!$J$10:$P$14,3,FALSE))),1,0) -> 0 | I13: =IF(AND(VLOOKUP(I$1,test!$A$3:$I$32,8,FALSE) - VLOOKUP($B13,test!$A$3:$I$32,9,FALSE) >= (test!$B$33+VLOOKUP(VLOOKUP($B13,test!$A$2:$I$32,4,FALSE),test!$J$10:$P$14,3,FALSE))),1,0) -> 1 | J13: =IF(AND(VLOOKUP(J$1,test!$A$3:$I$32,8,FALSE) - VLOOKUP($B13,test!$A$3:$I$32,9,FALSE) >= (test!$B$33+VLOOKUP(VLOOKUP($B13,test!$A$2:$I$32,4,FALSE),test!$J$10:$P$14,3,FALSE))),1,0) -> 1 | K13: =IF(AND(VLOOKUP(K$1,test!$A$3:$I$32,8,FALSE) - VLOOKUP($B13,test!$A$3:$I$32,9,FALSE) >= (test!$B$33+VLOOKUP(VLOOKUP($B13,test!$A$2:$I$32,4,FALSE),test!$J$10:$P$14,3,FALSE))),1,0) -> 1 | ... AG13: =IF(AND(VLOOKUP(AG$1,test!$A$3:$I$32,8,FALSE) - VLOOKUP($B13,test!$A$3:$I$32,9,FALSE) >= (test!$B$33+VLOOKUP(VLOOKUP($B13,test!$A$2:$I$32,4,FALSE),test!$J$10:$P$14,3,FALSE))),1,0) -> 0
A14: CS1 | B14: AC4 | C14: 0 | D14: =IF(AND(VLOOKUP(D$1,test!$A$3:$I$32,8,FALSE) - VLOOKUP($B14,test!$A$3:$I$32,9,FALSE) >= (test!$B$33+VLOOKUP(VLOOKUP($B14,test!$A$2:$I$32,4,FALSE),test!$J$10:$P$14,3,FALSE))),1,0) -> 0 | E14: =IF(AND(VLOOKUP(E$1,test!$A$3:$I$32,8,FALSE) - VLOOKUP($B14,test!$A$3:$I$32,9,FALSE) >= (test!$B$33+VLOOKUP(VLOOKUP($B14,test!$A$2:$I$32,4,FALSE),test!$J$10:$P$14,3,FALSE))),1,0) -> 0 | F14: =IF(AND(VLOOKUP(F$1,test!$A$3:$I$32,8,FALSE) - VLOOKUP($B14,test!$A$3:$I$32,9,FALSE) >= (test!$B$33+VLOOKUP(VLOOKUP($B14,test!$A$2:$I$32,4,FALSE),test!$J$10:$P$14,3,FALSE))),1,0) -> 0 | G14: =IF(AND(VLOOKUP(G$1,test!$A$3:$I$32,8,FALSE) - VLOOKUP($B14,test!$A$3:$I$32,9,FALSE) >= (test!$B$33+VLOOKUP(VLOOKUP($B14,test!$A$2:$I$32,4,FALSE),test!$J$10:$P$14,3,FALSE))),1,0) -> 0 | H14: =IF(AND(VLOOKUP(H$1,test!$A$3:$I$32,8,FALSE) - VLOOKUP($B14,test!$A$3:$I$32,9,FALSE) >= (test!$B$33+VLOOKUP(VLOOKUP($B14,test!$A$2:$I$32,4,FALSE),test!$J$10:$P$14,3,FALSE))),1,0) -> 0 | I14: =IF(AND(VLOOKUP(I$1,test!$A$3:$I$32,8,FALSE) - VLOOKUP($B14,test!$A$3:$I$32,9,FALSE) >= (test!$B$33+VLOOKUP(VLOOKUP($B14,test!$A$2:$I$32,4,FALSE),test!$J$10:$P$14,3,FALSE))),1,0) -> 0 | J14: =IF(AND(VLOOKUP(J$1,test!$A$3:$I$32,8,FALSE) - VLOOKUP($B14,test!$A$3:$I$32,9,FALSE) >= (test!$B$33+VLOOKUP(VLOOKUP($B14,test!$A$2:$I$32,4,FALSE),test!$J$10:$P$14,3,FALSE))),1,0) -> 0 | K14: =IF(AND(VLOOKUP(K$1,test!$A$3:$I$32,8,FALSE) - VLOOKUP($B14,test!$A$3:$I$32,9,FALSE) >= (test!$B$33+VLOOKUP(VLOOKUP($B14,test!$A$2:$I$32,4,FALSE),test!$J$10:$P$14,3,FALSE))),1,0) -> 0 | ... AG14: =IF(AND(VLOOKUP(AG$1,test!$A$3:$I$32,8,FALSE) - VLOOKUP($B14,test!$A$3:$I$32,9,FALSE) >= (test!$B$33+VLOOKUP(VLOOKUP($B14,test!$A$2:$I$32,4,FALSE),test!$J$10:$P$14,3,FALSE))),1,0) -> 0
... A32: CS1 | B32: DC1 | C32: 0 | D32: =IF(AND(VLOOKUP(D$1,test!$A$3:$I$32,8,FALSE) - VLOOKUP($B32,test!$A$3:$I$32,9,FALSE) >= (test!$B$33+VLOOKUP(VLOOKUP($B32,test!$A$2:$I$32,4,FALSE),test!$J$10:$P$14,3,FALSE))),1,0) -> 0 | E32: =IF(AND(VLOOKUP(E$1,test!$A$3:$I$32,8,FALSE) - VLOOKUP($B32,test!$A$3:$I$32,9,FALSE) >= (test!$B$33+VLOOKUP(VLOOKUP($B32,test!$A$2:$I$32,4,FALSE),test!$J$10:$P$14,3,FALSE))),1,0) -> 0 | F32: =IF(AND(VLOOKUP(F$1,test!$A$3:$I$32,8,FALSE) - VLOOKUP($B32,test!$A$3:$I$32,9,FALSE) >= (test!$B$33+VLOOKUP(VLOOKUP($B32,test!$A$2:$I$32,4,FALSE),test!$J$10:$P$14,3,FALSE))),1,0) -> 0 | G32: =IF(AND(VLOOKUP(G$1,test!$A$3:$I$32,8,FALSE) - VLOOKUP($B32,test!$A$3:$I$32,9,FALSE) >= (test!$B$33+VLOOKUP(VLOOKUP($B32,test!$A$2:$I$32,4,FALSE),test!$J$10:$P$14,3,FALSE))),1,0) -> 0 | H32: =IF(AND(VLOOKUP(H$1,test!$A$3:$I$32,8,FALSE) - VLOOKUP($B32,test!$A$3:$I$32,9,FALSE) >= (test!$B$33+VLOOKUP(VLOOKUP($B32,test!$A$2:$I$32,4,FALSE),test!$J$10:$P$14,3,FALSE))),1,0) -> 0 | I32: =IF(AND(VLOOKUP(I$1,test!$A$3:$I$32,8,FALSE) - VLOOKUP($B32,test!$A$3:$I$32,9,FALSE) >= (test!$B$33+VLOOKUP(VLOOKUP($B32,test!$A$2:$I$32,4,FALSE),test!$J$10:$P$14,3,FALSE))),1,0) -> 0 | J32: =IF(AND(VLOOKUP(J$1,test!$A$3:$I$32,8,FALSE) - VLOOKUP($B32,test!$A$3:$I$32,9,FALSE) >= (test!$B$33+VLOOKUP(VLOOKUP($B32,test!$A$2:$I$32,4,FALSE),test!$J$10:$P$14,3,FALSE))),1,0) -> 0 | K32: =IF(AND(VLOOKUP(K$1,test!$A$3:$I$32,8,FALSE) - VLOOKUP($B32,test!$A$3:$I$32,9,FALSE) >= (test!$B$33+VLOOKUP(VLOOKUP($B32,test!$A$2:$I$32,4,FALSE),test!$J$10:$P$14,3,FALSE))),1,0) -> 1 | ... AG32: =IF(AND(VLOOKUP(AG$1,test!$A$3:$I$32,8,FALSE) - VLOOKUP($B32,test!$A$3:$I$32,9,FALSE) >= (test!$B$33+VLOOKUP(VLOOKUP($B32,test!$A$2:$I$32,4,FALSE),test!$J$10:$P$14,3,FALSE))),1,0) -> 0
A33: CS1a | B33: DEPOT | C33: 0 | D33: 0 | E33: 0 | F33: 0 | G33: 0 | H33: 0 | I33: 0 | J33: 0 | K33: 0 | L33: 0 | M33: 0 | N33: 0 | O33: 0 | P33: 0 | Q33: 0 | R33: 0 | S33: 0 | T33: 0 | U33: 0 | V33: 0 | W33: 0 | X33: 0 | Y33: 0 | Z33: 0 | AA33: 0 | AB33: 0 | AC33: 0 | AD33: 0 | AE33: 0 | AF33: 0 | AG33: 0
A34: CS1a | B34: AB1 | C34: 0 | D34: =IF(AND(feasible_mat!C3=1, VLOOKUP(Recharged_Feasible_matv3!$A34,test!$A$34:$G$37, 3,FALSE)=VLOOKUP(D$1,test!$A$3:$I$32,3,FALSE)),1,0) -> 0 | E34: =IF(AND(feasible_mat!D3=1, VLOOKUP(Recharged_Feasible_matv3!$A34,test!$A$34:$G$37, 3,FALSE)=VLOOKUP(E$1,test!$A$3:$I$32,3,FALSE)),1,0) -> 1 | F34: =IF(AND(feasible_mat!E3=1, VLOOKUP(Recharged_Feasible_matv3!$A34,test!$A$34:$G$37, 3,FALSE)=VLOOKUP(F$1,test!$A$3:$I$32,3,FALSE)),1,0) -> 1 | G34: =IF(AND(feasible_mat!F3=1, VLOOKUP(Recharged_Feasible_matv3!$A34,test!$A$34:$G$37, 3,FALSE)=VLOOKUP(G$1,test!$A$3:$I$32,3,FALSE)),1,0) -> 1 | H34: =IF(AND(feasible_mat!G3=1, VLOOKUP(Recharged_Feasible_matv3!$A34,test!$A$34:$G$37, 3,FALSE)=VLOOKUP(H$1,test!$A$3:$I$32,3,FALSE)),1,0) -> 1 | I34: =IF(AND(feasible_mat!H3=1, VLOOKUP(Recharged_Feasible_matv3!$A34,test!$A$34:$G$37, 3,FALSE)=VLOOKUP(I$1,test!$A$3:$I$32,3,FALSE)),1,0) -> 1 | J34: =IF(AND(feasible_mat!I3=1, VLOOKUP(Recharged_Feasible_matv3!$A34,test!$A$34:$G$37, 3,FALSE)=VLOOKUP(J$1,test!$A$3:$I$32,3,FALSE)),1,0) -> 1 | K34: =IF(AND(feasible_mat!J3=1, VLOOKUP(Recharged_Feasible_matv3!$A34,test!$A$34:$G$37, 3,FALSE)=VLOOKUP(K$1,test!$A$3:$I$32,3,FALSE)),1,0) -> 1 | ... AG34: =IF(AND(feasible_mat!AF3=1, VLOOKUP(Recharged_Feasible_matv3!$A34,test!$A$34:$G$37, 3,FALSE)=VLOOKUP(AG$1,test!$A$3:$I$32,3,FALSE)),1,0) -> 0
A35: CS1a | B35: AB2 | C35: 0 | D35: =IF(AND(feasible_mat!C4=1, VLOOKUP(Recharged_Feasible_matv3!$A35,test!$A$34:$G$37, 3,FALSE)=VLOOKUP(D$1,test!$A$3:$I$32,3,FALSE)),1,0) -> 0 | E35: =IF(AND(feasible_mat!D4=1, VLOOKUP(Recharged_Feasible_matv3!$A35,test!$A$34:$G$37, 3,FALSE)=VLOOKUP(E$1,test!$A$3:$I$32,3,FALSE)),1,0) -> 0 | F35: =IF(AND(feasible_mat!E4=1, VLOOKUP(Recharged_Feasible_matv3!$A35,test!$A$34:$G$37, 3,FALSE)=VLOOKUP(F$1,test!$A$3:$I$32,3,FALSE)),1,0) -> 0 | G35: =IF(AND(feasible_mat!F4=1, VLOOKUP(Recharged_Feasible_matv3!$A35,test!$A$34:$G$37, 3,FALSE)=VLOOKUP(G$1,test!$A$3:$I$32,3,FALSE)),1,0) -> 1 | H35: =IF(AND(feasible_mat!G4=1, VLOOKUP(Recharged_Feasible_matv3!$A35,test!$A$34:$G$37, 3,FALSE)=VLOOKUP(H$1,test!$A$3:$I$32,3,FALSE)),1,0) -> 1 | I35: =IF(AND(feasible_mat!H4=1, VLOOKUP(Recharged_Feasible_matv3!$A35,test!$A$34:$G$37, 3,FALSE)=VLOOKUP(I$1,test!$A$3:$I$32,3,FALSE)),1,0) -> 1 | J35: =IF(AND(feasible_mat!I4=1, VLOOKUP(Recharged_Feasible_matv3!$A35,test!$A$34:$G$37, 3,FALSE)=VLOOKUP(J$1,test!$A$3:$I$32,3,FALSE)),1,0) -> 1 | K35: =IF(AND(feasible_mat!J4=1, VLOOKUP(Recharged_Feasible_matv3!$A35,test!$A$34:$G$37, 3,FALSE)=VLOOKUP(K$1,test!$A$3:$I$32,3,FALSE)),1,0) -> 1 | ... AG35: =IF(AND(feasible_mat!AF4=1, VLOOKUP(Recharged_Feasible_matv3!$A35,test!$A$34:$G$37, 3,FALSE)=VLOOKUP(AG$1,test!$A$3:$I$32,3,FALSE)),1,0) -> 0
A36: CS1a | B36: AB3 | C36: 0 | D36: =IF(AND(feasible_mat!C5=1, VLOOKUP(Recharged_Feasible_matv3!$A36,test!$A$34:$G$37, 3,FALSE)=VLOOKUP(D$1,test!$A$3:$I$32,3,FALSE)),1,0) -> 0 | E36: =IF(AND(feasible_mat!D5=1, VLOOKUP(Recharged_Feasible_matv3!$A36,test!$A$34:$G$37, 3,FALSE)=VLOOKUP(E$1,test!$A$3:$I$32,3,FALSE)),1,0) -> 0 | F36: =IF(AND(feasible_mat!E5=1, VLOOKUP(Recharged_Feasible_matv3!$A36,test!$A$34:$G$37, 3,FALSE)=VLOOKUP(F$1,test!$A$3:$I$32,3,FALSE)),1,0) -> 0 | G36: =IF(AND(feasible_mat!F5=1, VLOOKUP(Recharged_Feasible_matv3!$A36,test!$A$34:$G$37, 3,FALSE)=VLOOKUP(G$1,test!$A$3:$I$32,3,FALSE)),1,0) -> 0 | H36: =IF(AND(feasible_mat!G5=1, VLOOKUP(Recharged_Feasible_matv3!$A36,test!$A$34:$G$37, 3,FALSE)=VLOOKUP(H$1,test!$A$3:$I$32,3,FALSE)),1,0) -> 1 | I36: =IF(AND(feasible_mat!H5=1, VLOOKUP(Recharged_Feasible_matv3!$A36,test!$A$34:$G$37, 3,FALSE)=VLOOKUP(I$1,test!$A$3:$I$32,3,FALSE)),1,0) -> 1 | J36: =IF(AND(feasible_mat!I5=1, VLOOKUP(Recharged_Feasible_matv3!$A36,test!$A$34:$G$37, 3,FALSE)=VLOOKUP(J$1,test!$A$3:$I$32,3,FALSE)),1,0) -> 1 | K36: =IF(AND(feasible_mat!J5=1, VLOOKUP(Recharged_Feasible_matv3!$A36,test!$A$34:$G$37, 3,FALSE)=VLOOKUP(K$1,test!$A$3:$I$32,3,FALSE)),1,0) -> 1 | ... AG36: =IF(AND(feasible_mat!AF5=1, VLOOKUP(Recharged_Feasible_matv3!$A36,test!$A$34:$G$37, 3,FALSE)=VLOOKUP(AG$1,test!$A$3:$I$32,3,FALSE)),1,0) -> 0
A37: CS1a | B37: AB4 | C37: 0 | D37: =IF(AND(feasible_mat!C6=1, VLOOKUP(Recharged_Feasible_matv3!$A37,test!$A$34:$G$37, 3,FALSE)=VLOOKUP(D$1,test!$A$3:$I$32,3,FALSE)),1,0) -> 0 | E37: =IF(AND(feasible_mat!D6=1, VLOOKUP(Recharged_Feasible_matv3!$A37,test!$A$34:$G$37, 3,FALSE)=VLOOKUP(E$1,test!$A$3:$I$32,3,FALSE)),1,0) -> 0 | F37: =IF(AND(feasible_mat!E6=1, VLOOKUP(Recharged_Feasible_matv3!$A37,test!$A$34:$G$37, 3,FALSE)=VLOOKUP(F$1,test!$A$3:$I$32,3,FALSE)),1,0) -> 0 | G37: =IF(AND(feasible_mat!F6=1, VLOOKUP(Recharged_Feasible_matv3!$A37,test!$A$34:$G$37, 3,FALSE)=VLOOKUP(G$1,test!$A$3:$I$32,3,FALSE)),1,0) -> 0 | H37: =IF(AND(feasible_mat!G6=1, VLOOKUP(Recharged_Feasible_matv3!$A37,test!$A$34:$G$37, 3,FALSE)=VLOOKUP(H$1,test!$A$3:$I$32,3,FALSE)),1,0) -> 0 | I37: =IF(AND(feasible_mat!H6=1, VLOOKUP(Recharged_Feasible_matv3!$A37,test!$A$34:$G$37, 3,FALSE)=VLOOKUP(I$1,test!$A$3:$I$32,3,FALSE)),1,0) -> 0 | J37: =IF(AND(feasible_mat!I6=1, VLOOKUP(Recharged_Feasible_matv3!$A37,test!$A$34:$G$37, 3,FALSE)=VLOOKUP(J$1,test!$A$3:$I$32,3,FALSE)),1,0) -> 1 | K37: =IF(AND(feasible_mat!J6=1, VLOOKUP(Recharged_Feasible_matv3!$A37,test!$A$34:$G$37, 3,FALSE)=VLOOKUP(K$1,test!$A$3:$I$32,3,FALSE)),1,0) -> 1 | ... AG37: =IF(AND(feasible_mat!AF6=1, VLOOKUP(Recharged_Feasible_matv3!$A37,test!$A$34:$G$37, 3,FALSE)=VLOOKUP(AG$1,test!$A$3:$I$32,3,FALSE)),1,0) -> 0
A38: CS1a | B38: AB5 | C38: 0 | D38: =IF(AND(feasible_mat!C7=1, VLOOKUP(Recharged_Feasible_matv3!$A38,test!$A$34:$G$37, 3,FALSE)=VLOOKUP(D$1,test!$A$3:$I$32,3,FALSE)),1,0) -> 0 | E38: =IF(AND(feasible_mat!D7=1, VLOOKUP(Recharged_Feasible_matv3!$A38,test!$A$34:$G$37, 3,FALSE)=VLOOKUP(E$1,test!$A$3:$I$32,3,FALSE)),1,0) -> 0 | F38: =IF(AND(feasible_mat!E7=1, VLOOKUP(Recharged_Feasible_matv3!$A38,test!$A$34:$G$37, 3,FALSE)=VLOOKUP(F$1,test!$A$3:$I$32,3,FALSE)),1,0) -> 0 | G38: =IF(AND(feasible_mat!F7=1, VLOOKUP(Recharged_Feasible_matv3!$A38,test!$A$34:$G$37, 3,FALSE)=VLOOKUP(G$1,test!$A$3:$I$32,3,FALSE)),1,0) -> 0 | H38: =IF(AND(feasible_mat!G7=1, VLOOKUP(Recharged_Feasible_matv3!$A38,test!$A$34:$G$37, 3,FALSE)=VLOOKUP(H$1,test!$A$3:$I$32,3,FALSE)),1,0) -> 0 | I38: =IF(AND(feasible_mat!H7=1, VLOOKUP(Recharged_Feasible_matv3!$A38,test!$A$34:$G$37, 3,FALSE)=VLOOKUP(I$1,test!$A$3:$I$32,3,FALSE)),1,0) -> 0 | J38: =IF(AND(feasible_mat!I7=1, VLOOKUP(Recharged_Feasible_matv3!$A38,test!$A$34:$G$37, 3,FALSE)=VLOOKUP(J$1,test!$A$3:$I$32,3,FALSE)),1,0) -> 0 | K38: =IF(AND(feasible_mat!J7=1, VLOOKUP(Recharged_Feasible_matv3!$A38,test!$A$34:$G$37, 3,FALSE)=VLOOKUP(K$1,test!$A$3:$I$32,3,FALSE)),1,0) -> 1 | ... AG38: =IF(AND(feasible_mat!AF7=1, VLOOKUP(Recharged_Feasible_matv3!$A38,test!$A$34:$G$37, 3,FALSE)=VLOOKUP(AG$1,test!$A$3:$I$32,3,FALSE)),1,0) -> 0
A39: CS1a | B39: AB6 | C39: 0 | D39: =IF(AND(feasible_mat!C8=1, VLOOKUP(Recharged_Feasible_matv3!$A39,test!$A$34:$G$37, 3,FALSE)=VLOOKUP(D$1,test!$A$3:$I$32,3,FALSE)),1,0) -> 0 | E39: =IF(AND(feasible_mat!D8=1, VLOOKUP(Recharged_Feasible_matv3!$A39,test!$A$34:$G$37, 3,FALSE)=VLOOKUP(E$1,test!$A$3:$I$32,3,FALSE)),1,0) -> 0 | F39: =IF(AND(feasible_mat!E8=1, VLOOKUP(Recharged_Feasible_matv3!$A39,test!$A$34:$G$37, 3,FALSE)=VLOOKUP(F$1,test!$A$3:$I$32,3,FALSE)),1,0) -> 0 | G39: =IF(AND(feasible_mat!F8=1, VLOOKUP(Recharged_Feasible_matv3!$A39,test!$A$34:$G$37, 3,FALSE)=VLOOKUP(G$1,test!$A$3:$I$32,3,FALSE)),1,0) -> 0 | H39: =IF(AND(feasible_mat!G8=1, VLOOKUP(Recharged_Feasible_matv3!$A39,test!$A$34:$G$37, 3,FALSE)=VLOOKUP(H$1,test!$A$3:$I$32,3,FALSE)),1,0) -> 0 | I39: =IF(AND(feasible_mat!H8=1, VLOOKUP(Recharged_Feasible_matv3!$A39,test!$A$34:$G$37, 3,FALSE)=VLOOKUP(I$1,test!$A$3:$I$32,3,FALSE)),1,0) -> 0 | J39: =IF(AND(feasible_mat!I8=1, VLOOKUP(Recharged_Feasible_matv3!$A39,test!$A$34:$G$37, 3,FALSE)=VLOOKUP(J$1,test!$A$3:$I$32,3,FALSE)),1,0) -> 0 | K39: =IF(AND(feasible_mat!J8=1, VLOOKUP(Recharged_Feasible_matv3!$A39,test!$A$34:$G$37, 3,FALSE)=VLOOKUP(K$1,test!$A$3:$I$32,3,FALSE)),1,0) -> 1 | ... AG39: =IF(AND(feasible_mat!AF8=1, VLOOKUP(Recharged_Feasible_matv3!$A39,test!$A$34:$G$37, 3,FALSE)=VLOOKUP(AG$1,test!$A$3:$I$32,3,FALSE)),1,0) -> 0
A40: CS1a | B40: AB7 | C40: 0 | D40: =IF(AND(feasible_mat!C9=1, VLOOKUP(Recharged_Feasible_matv3!$A40,test!$A$34:$G$37, 3,FALSE)=VLOOKUP(D$1,test!$A$3:$I$32,3,FALSE)),1,0) -> 0 | E40: =IF(AND(feasible_mat!D9=1, VLOOKUP(Recharged_Feasible_matv3!$A40,test!$A$34:$G$37, 3,FALSE)=VLOOKUP(E$1,test!$A$3:$I$32,3,FALSE)),1,0) -> 0 | F40: =IF(AND(feasible_mat!E9=1, VLOOKUP(Recharged_Feasible_matv3!$A40,test!$A$34:$G$37, 3,FALSE)=VLOOKUP(F$1,test!$A$3:$I$32,3,FALSE)),1,0) -> 0 | G40: =IF(AND(feasible_mat!F9=1, VLOOKUP(Recharged_Feasible_matv3!$A40,test!$A$34:$G$37, 3,FALSE)=VLOOKUP(G$1,test!$A$3:$I$32,3,FALSE)),1,0) -> 0 | H40: =IF(AND(feasible_mat!G9=1, VLOOKUP(Recharged_Feasible_matv3!$A40,test!$A$34:$G$37, 3,FALSE)=VLOOKUP(H$1,test!$A$3:$I$32,3,FALSE)),1,0) -> 0 | I40: =IF(AND(feasible_mat!H9=1, VLOOKUP(Recharged_Feasible_matv3!$A40,test!$A$34:$G$37, 3,FALSE)=VLOOKUP(I$1,test!$A$3:$I$32,3,FALSE)),1,0) -> 0 | J40: =IF(AND(feasible_mat!I9=1, VLOOKUP(Recharged_Feasible_matv3!$A40,test!$A$34:$G$37, 3,FALSE)=VLOOKUP(J$1,test!$A$3:$I$32,3,FALSE)),1,0) -> 0 | K40: =IF(AND(feasible_mat!J9=1, VLOOKUP(Recharged_Feasible_matv3!$A40,test!$A$34:$G$37, 3,FALSE)=VLOOKUP(K$1,test!$A$3:$I$32,3,FALSE)),1,0) -> 0 | ... AG40: =IF(AND(feasible_mat!AF9=1, VLOOKUP(Recharged_Feasible_matv3!$A40,test!$A$34:$G$37, 3,FALSE)=VLOOKUP(AG$1,test!$A$3:$I$32,3,FALSE)),1,0) -> 0
A41: CS1a | B41: AB8 | C41: 0 | D41: =IF(AND(feasible_mat!C10=1, VLOOKUP(Recharged_Feasible_matv3!$A41,test!$A$34:$G$37, 3,FALSE)=VLOOKUP(D$1,test!$A$3:$I$32,3,FALSE)),1,0) -> 0 | E41: =IF(AND(feasible_mat!D10=1, VLOOKUP(Recharged_Feasible_matv3!$A41,test!$A$34:$G$37, 3,FALSE)=VLOOKUP(E$1,test!$A$3:$I$32,3,FALSE)),1,0) -> 0 | F41: =IF(AND(feasible_mat!E10=1, VLOOKUP(Recharged_Feasible_matv3!$A41,test!$A$34:$G$37, 3,FALSE)=VLOOKUP(F$1,test!$A$3:$I$32,3,FALSE)),1,0) -> 0 | G41: =IF(AND(feasible_mat!F10=1, VLOOKUP(Recharged_Feasible_matv3!$A41,test!$A$34:$G$37, 3,FALSE)=VLOOKUP(G$1,test!$A$3:$I$32,3,FALSE)),1,0) -> 0 | H41: =IF(AND(feasible_mat!G10=1, VLOOKUP(Recharged_Feasible_matv3!$A41,test!$A$34:$G$37, 3,FALSE)=VLOOKUP(H$1,test!$A$3:$I$32,3,FALSE)),1,0) -> 0 | I41: =IF(AND(feasible_mat!H10=1, VLOOKUP(Recharged_Feasible_matv3!$A41,test!$A$34:$G$37, 3,FALSE)=VLOOKUP(I$1,test!$A$3:$I$32,3,FALSE)),1,0) -> 0 | J41: =IF(AND(feasible_mat!I10=1, VLOOKUP(Recharged_Feasible_matv3!$A41,test!$A$34:$G$37, 3,FALSE)=VLOOKUP(J$1,test!$A$3:$I$32,3,FALSE)),1,0) -> 0 | K41: =IF(AND(feasible_mat!J10=1, VLOOKUP(Recharged_Feasible_matv3!$A41,test!$A$34:$G$37, 3,FALSE)=VLOOKUP(K$1,test!$A$3:$I$32,3,FALSE)),1,0) -> 0 | ... AG41: =IF(AND(feasible_mat!AF10=1, VLOOKUP(Recharged_Feasible_matv3!$A41,test!$A$34:$G$37, 3,FALSE)=VLOOKUP(AG$1,test!$A$3:$I$32,3,FALSE)),1,0) -> 0
A42: CS1a | B42: AC1 | C42: 0 | D42: =IF(AND(feasible_mat!C11=1, VLOOKUP(Recharged_Feasible_matv3!$A42,test!$A$34:$G$37, 3,FALSE)=VLOOKUP(D$1,test!$A$3:$I$32,3,FALSE)),1,0) -> 0 | E42: =IF(AND(feasible_mat!D11=1, VLOOKUP(Recharged_Feasible_matv3!$A42,test!$A$34:$G$37, 3,FALSE)=VLOOKUP(E$1,test!$A$3:$I$32,3,FALSE)),1,0) -> 1 | F42: =IF(AND(feasible_mat!E11=1, VLOOKUP(Recharged_Feasible_matv3!$A42,test!$A$34:$G$37, 3,FALSE)=VLOOKUP(F$1,test!$A$3:$I$32,3,FALSE)),1,0) -> 1 | G42: =IF(AND(feasible_mat!F11=1, VLOOKUP(Recharged_Feasible_matv3!$A42,test!$A$34:$G$37, 3,FALSE)=VLOOKUP(G$1,test!$A$3:$I$32,3,FALSE)),1,0) -> 1 | H42: =IF(AND(feasible_mat!G11=1, VLOOKUP(Recharged_Feasible_matv3!$A42,test!$A$34:$G$37, 3,FALSE)=VLOOKUP(H$1,test!$A$3:$I$32,3,FALSE)),1,0) -> 1 | I42: =IF(AND(feasible_mat!H11=1, VLOOKUP(Recharged_Feasible_matv3!$A42,test!$A$34:$G$37, 3,FALSE)=VLOOKUP(I$1,test!$A$3:$I$32,3,FALSE)),1,0) -> 1 | J42: =IF(AND(feasible_mat!I11=1, VLOOKUP(Recharged_Feasible_matv3!$A42,test!$A$34:$G$37, 3,FALSE)=VLOOKUP(J$1,test!$A$3:$I$32,3,FALSE)),1,0) -> 1 | K42: =IF(AND(feasible_mat!J11=1, VLOOKUP(Recharged_Feasible_matv3!$A42,test!$A$34:$G$37, 3,FALSE)=VLOOKUP(K$1,test!$A$3:$I$32,3,FALSE)),1,0) -> 1 | ... AG42: =IF(AND(feasible_mat!AF11=1, VLOOKUP(Recharged_Feasible_matv3!$A42,test!$A$34:$G$37, 3,FALSE)=VLOOKUP(AG$1,test!$A$3:$I$32,3,FALSE)),1,0) -> 0
A43: CS1a | B43: AC2 | C43: 0 | D43: =IF(AND(feasible_mat!C12=1, VLOOKUP(Recharged_Feasible_matv3!$A43,test!$A$34:$G$37, 3,FALSE)=VLOOKUP(D$1,test!$A$3:$I$32,3,FALSE)),1,0) -> 0 | E43: =IF(AND(feasible_mat!D12=1, VLOOKUP(Recharged_Feasible_matv3!$A43,test!$A$34:$G$37, 3,FALSE)=VLOOKUP(E$1,test!$A$3:$I$32,3,FALSE)),1,0) -> 0 | F43: =IF(AND(feasible_mat!E12=1, VLOOKUP(Recharged_Feasible_matv3!$A43,test!$A$34:$G$37, 3,FALSE)=VLOOKUP(F$1,test!$A$3:$I$32,3,FALSE)),1,0) -> 1 | G43: =IF(AND(feasible_mat!F12=1, VLOOKUP(Recharged_Feasible_matv3!$A43,test!$A$34:$G$37, 3,FALSE)=VLOOKUP(G$1,test!$A$3:$I$32,3,FALSE)),1,0) -> 1 | H43: =IF(AND(feasible_mat!G12=1, VLOOKUP(Recharged_Feasible_matv3!$A43,test!$A$34:$G$37, 3,FALSE)=VLOOKUP(H$1,test!$A$3:$I$32,3,FALSE)),1,0) -> 1 | I43: =IF(AND(feasible_mat!H12=1, VLOOKUP(Recharged_Feasible_matv3!$A43,test!$A$34:$G$37, 3,FALSE)=VLOOKUP(I$1,test!$A$3:$I$32,3,FALSE)),1,0) -> 1 | J43: =IF(AND(feasible_mat!I12=1, VLOOKUP(Recharged_Feasible_matv3!$A43,test!$A$34:$G$37, 3,FALSE)=VLOOKUP(J$1,test!$A$3:$I$32,3,FALSE)),1,0) -> 1 | K43: =IF(AND(feasible_mat!J12=1, VLOOKUP(Recharged_Feasible_matv3!$A43,test!$A$34:$G$37, 3,FALSE)=VLOOKUP(K$1,test!$A$3:$I$32,3,FALSE)),1,0) -> 1 | ... AG43: =IF(AND(feasible_mat!AF12=1, VLOOKUP(Recharged_Feasible_matv3!$A43,test!$A$34:$G$37, 3,FALSE)=VLOOKUP(AG$1,test!$A$3:$I$32,3,FALSE)),1,0) -> 0
A44: CS1a | B44: AC3 | C44: 0 | D44: =IF(AND(feasible_mat!C13=1, VLOOKUP(Recharged_Feasible_matv3!$A44,test!$A$34:$G$37, 3,FALSE)=VLOOKUP(D$1,test!$A$3:$I$32,3,FALSE)),1,0) -> 0 | E44: =IF(AND(feasible_mat!D13=1, VLOOKUP(Recharged_Feasible_matv3!$A44,test!$A$34:$G$37, 3,FALSE)=VLOOKUP(E$1,test!$A$3:$I$32,3,FALSE)),1,0) -> 0 | F44: =IF(AND(feasible_mat!E13=1, VLOOKUP(Recharged_Feasible_matv3!$A44,test!$A$34:$G$37, 3,FALSE)=VLOOKUP(F$1,test!$A$3:$I$32,3,FALSE)),1,0) -> 0 | G44: =IF(AND(feasible_mat!F13=1, VLOOKUP(Recharged_Feasible_matv3!$A44,test!$A$34:$G$37, 3,FALSE)=VLOOKUP(G$1,test!$A$3:$I$32,3,FALSE)),1,0) -> 0 | H44: =IF(AND(feasible_mat!G13=1, VLOOKUP(Recharged_Feasible_matv3!$A44,test!$A$34:$G$37, 3,FALSE)=VLOOKUP(H$1,test!$A$3:$I$32,3,FALSE)),1,0) -> 1 | I44: =IF(AND(feasible_mat!H13=1, VLOOKUP(Recharged_Feasible_matv3!$A44,test!$A$34:$G$37, 3,FALSE)=VLOOKUP(I$1,test!$A$3:$I$32,3,FALSE)),1,0) -> 1 | J44: =IF(AND(feasible_mat!I13=1, VLOOKUP(Recharged_Feasible_matv3!$A44,test!$A$34:$G$37, 3,FALSE)=VLOOKUP(J$1,test!$A$3:$I$32,3,FALSE)),1,0) -> 1 | K44: =IF(AND(feasible_mat!J13=1, VLOOKUP(Recharged_Feasible_matv3!$A44,test!$A$34:$G$37, 3,FALSE)=VLOOKUP(K$1,test!$A$3:$I$32,3,FALSE)),1,0) -> 1 | ... AG44: =IF(AND(feasible_mat!AF13=1, VLOOKUP(Recharged_Feasible_matv3!$A44,test!$A$34:$G$37, 3,FALSE)=VLOOKUP(AG$1,test!$A$3:$I$32,3,FALSE)),1,0) -> 0
A45: CS1a | B45: AC4 | C45: 0 | D45: =IF(AND(feasible_mat!C14=1, VLOOKUP(Recharged_Feasible_matv3!$A45,test!$A$34:$G$37, 3,FALSE)=VLOOKUP(D$1,test!$A$3:$I$32,3,FALSE)),1,0) -> 0 | E45: =IF(AND(feasible_mat!D14=1, VLOOKUP(Recharged_Feasible_matv3!$A45,test!$A$34:$G$37, 3,FALSE)=VLOOKUP(E$1,test!$A$3:$I$32,3,FALSE)),1,0) -> 0 | F45: =IF(AND(feasible_mat!E14=1, VLOOKUP(Recharged_Feasible_matv3!$A45,test!$A$34:$G$37, 3,FALSE)=VLOOKUP(F$1,test!$A$3:$I$32,3,FALSE)),1,0) -> 0 | G45: =IF(AND(feasible_mat!F14=1, VLOOKUP(Recharged_Feasible_matv3!$A45,test!$A$34:$G$37, 3,FALSE)=VLOOKUP(G$1,test!$A$3:$I$32,3,FALSE)),1,0) -> 0 | H45: =IF(AND(feasible_mat!G14=1, VLOOKUP(Recharged_Feasible_matv3!$A45,test!$A$34:$G$37, 3,FALSE)=VLOOKUP(H$1,test!$A$3:$I$32,3,FALSE)),1,0) -> 0 | I45: =IF(AND(feasible_mat!H14=1, VLOOKUP(Recharged_Feasible_matv3!$A45,test!$A$34:$G$37, 3,FALSE)=VLOOKUP(I$1,test!$A$3:$I$32,3,FALSE)),1,0) -> 0 | J45: =IF(AND(feasible_mat!I14=1, VLOOKUP(Recharged_Feasible_matv3!$A45,test!$A$34:$G$37, 3,FALSE)=VLOOKUP(J$1,test!$A$3:$I$32,3,FALSE)),1,0) -> 0 | K45: =IF(AND(feasible_mat!J14=1, VLOOKUP(Recharged_Feasible_matv3!$A45,test!$A$34:$G$37, 3,FALSE)=VLOOKUP(K$1,test!$A$3:$I$32,3,FALSE)),1,0) -> 0 | ... AG45: =IF(AND(feasible_mat!AF14=1, VLOOKUP(Recharged_Feasible_matv3!$A45,test!$A$34:$G$37, 3,FALSE)=VLOOKUP(AG$1,test!$A$3:$I$32,3,FALSE)),1,0) -> 0
... A63: CS1a | B63: DC1 | C63: 0 | D63: =IF(AND(feasible_mat!C32=1, VLOOKUP(Recharged_Feasible_matv3!$A63,test!$A$34:$G$37, 3,FALSE)=VLOOKUP(D$1,test!$A$3:$I$32,3,FALSE)),1,0) -> 0 | E63: =IF(AND(feasible_mat!D32=1, VLOOKUP(Recharged_Feasible_matv3!$A63,test!$A$34:$G$37, 3,FALSE)=VLOOKUP(E$1,test!$A$3:$I$32,3,FALSE)),1,0) -> 0 | F63: =IF(AND(feasible_mat!E32=1, VLOOKUP(Recharged_Feasible_matv3!$A63,test!$A$34:$G$37, 3,FALSE)=VLOOKUP(F$1,test!$A$3:$I$32,3,FALSE)),1,0) -> 0 | G63: =IF(AND(feasible_mat!F32=1, VLOOKUP(Recharged_Feasible_matv3!$A63,test!$A$34:$G$37, 3,FALSE)=VLOOKUP(G$1,test!$A$3:$I$32,3,FALSE)),1,0) -> 0 | H63: =IF(AND(feasible_mat!G32=1, VLOOKUP(Recharged_Feasible_matv3!$A63,test!$A$34:$G$37, 3,FALSE)=VLOOKUP(H$1,test!$A$3:$I$32,3,FALSE)),1,0) -> 0 | I63: =IF(AND(feasible_mat!H32=1, VLOOKUP(Recharged_Feasible_matv3!$A63,test!$A$34:$G$37, 3,FALSE)=VLOOKUP(I$1,test!$A$3:$I$32,3,FALSE)),1,0) -> 0 | J63: =IF(AND(feasible_mat!I32=1, VLOOKUP(Recharged_Feasible_matv3!$A63,test!$A$34:$G$37, 3,FALSE)=VLOOKUP(J$1,test!$A$3:$I$32,3,FALSE)),1,0) -> 1 | K63: =IF(AND(feasible_mat!J32=1, VLOOKUP(Recharged_Feasible_matv3!$A63,test!$A$34:$G$37, 3,FALSE)=VLOOKUP(K$1,test!$A$3:$I$32,3,FALSE)),1,0) -> 1 | ... AG63: =IF(AND(feasible_mat!AF32=1, VLOOKUP(Recharged_Feasible_matv3!$A63,test!$A$34:$G$37, 3,FALSE)=VLOOKUP(AG$1,test!$A$3:$I$32,3,FALSE)),1,0) -> 0
A64: CS2b | B64: DEPOT | C64: 0 | D64: 0 | E64: 0 | F64: 0 | G64: 0 | H64: 0 | I64: 0 | J64: 0 | K64: 0 | L64: 0 | M64: 0 | N64: 0 | O64: 0 | P64: 0 | Q64: 0 | R64: 0 | S64: 0 | T64: 0 | U64: 0 | V64: 0 | W64: 0 | X64: 0 | Y64: 0 | Z64: 0 | AA64: 0 | AB64: 0 | AC64: 0 | AD64: 0 | AE64: 0 | AF64: 0 | AG64: 0
A65: CS2b | B65: AB1 | C65: 0 | D65: =IF(AND(feasible_mat!C3, VLOOKUP(Recharged_Feasible_matv3!$A65,test!$A$34:$G$37, 3,FALSE)=VLOOKUP(D$1,test!$A$3:$I$32,3,FALSE)),1,0) -> 0 | E65: =IF(AND(feasible_mat!D3, VLOOKUP(Recharged_Feasible_matv3!$A65,test!$A$34:$G$37, 3,FALSE)=VLOOKUP(E$1,test!$A$3:$I$32,3,FALSE)),1,0) -> 0 | F65: =IF(AND(feasible_mat!E3, VLOOKUP(Recharged_Feasible_matv3!$A65,test!$A$34:$G$37, 3,FALSE)=VLOOKUP(F$1,test!$A$3:$I$32,3,FALSE)),1,0) -> 0 | G65: =IF(AND(feasible_mat!F3, VLOOKUP(Recharged_Feasible_matv3!$A65,test!$A$34:$G$37, 3,FALSE)=VLOOKUP(G$1,test!$A$3:$I$32,3,FALSE)),1,0) -> 0 | H65: =IF(AND(feasible_mat!G3, VLOOKUP(Recharged_Feasible_matv3!$A65,test!$A$34:$G$37, 3,FALSE)=VLOOKUP(H$1,test!$A$3:$I$32,3,FALSE)),1,0) -> 0 | I65: =IF(AND(feasible_mat!H3, VLOOKUP(Recharged_Feasible_matv3!$A65,test!$A$34:$G$37, 3,FALSE)=VLOOKUP(I$1,test!$A$3:$I$32,3,FALSE)),1,0) -> 0 | J65: =IF(AND(feasible_mat!I3, VLOOKUP(Recharged_Feasible_matv3!$A65,test!$A$34:$G$37, 3,FALSE)=VLOOKUP(J$1,test!$A$3:$I$32,3,FALSE)),1,0) -> 0 | K65: =IF(AND(feasible_mat!J3, VLOOKUP(Recharged_Feasible_matv3!$A65,test!$A$34:$G$37, 3,FALSE)=VLOOKUP(K$1,test!$A$3:$I$32,3,FALSE)),1,0) -> 0 | ... AG65: =IF(AND(feasible_mat!AF3, VLOOKUP(Recharged_Feasible_matv3!$A65,test!$A$34:$G$37, 3,FALSE)=VLOOKUP(AG$1,test!$A$3:$I$32,3,FALSE)),1,0) -> 0
A66: CS2b | B66: AB2 | C66: 0 | D66: =IF(AND(feasible_mat!C4, VLOOKUP(Recharged_Feasible_matv3!$A66,test!$A$34:$G$37, 3,FALSE)=VLOOKUP(D$1,test!$A$3:$I$32,3,FALSE)),1,0) -> 0 | E66: =IF(AND(feasible_mat!D4, VLOOKUP(Recharged_Feasible_matv3!$A66,test!$A$34:$G$37, 3,FALSE)=VLOOKUP(E$1,test!$A$3:$I$32,3,FALSE)),1,0) -> 0 | F66: =IF(AND(feasible_mat!E4, VLOOKUP(Recharged_Feasible_matv3!$A66,test!$A$34:$G$37, 3,FALSE)=VLOOKUP(F$1,test!$A$3:$I$32,3,FALSE)),1,0) -> 0 | G66: =IF(AND(feasible_mat!F4, VLOOKUP(Recharged_Feasible_matv3!$A66,test!$A$34:$G$37, 3,FALSE)=VLOOKUP(G$1,test!$A$3:$I$32,3,FALSE)),1,0) -> 0 | H66: =IF(AND(feasible_mat!G4, VLOOKUP(Recharged_Feasible_matv3!$A66,test!$A$34:$G$37, 3,FALSE)=VLOOKUP(H$1,test!$A$3:$I$32,3,FALSE)),1,0) -> 0 | I66: =IF(AND(feasible_mat!H4, VLOOKUP(Recharged_Feasible_matv3!$A66,test!$A$34:$G$37, 3,FALSE)=VLOOKUP(I$1,test!$A$3:$I$32,3,FALSE)),1,0) -> 0 | J66: =IF(AND(feasible_mat!I4, VLOOKUP(Recharged_Feasible_matv3!$A66,test!$A$34:$G$37, 3,FALSE)=VLOOKUP(J$1,test!$A$3:$I$32,3,FALSE)),1,0) -> 0 | K66: =IF(AND(feasible_mat!J4, VLOOKUP(Recharged_Feasible_matv3!$A66,test!$A$34:$G$37, 3,FALSE)=VLOOKUP(K$1,test!$A$3:$I$32,3,FALSE)),1,0) -> 0 | ... AG66: =IF(AND(feasible_mat!AF4, VLOOKUP(Recharged_Feasible_matv3!$A66,test!$A$34:$G$37, 3,FALSE)=VLOOKUP(AG$1,test!$A$3:$I$32,3,FALSE)),1,0) -> 0
A67: CS2b | B67: AB3 | C67: 0 | D67: =IF(AND(feasible_mat!C5, VLOOKUP(Recharged_Feasible_matv3!$A67,test!$A$34:$G$37, 3,FALSE)=VLOOKUP(D$1,test!$A$3:$I$32,3,FALSE)),1,0) -> 0 | E67: =IF(AND(feasible_mat!D5, VLOOKUP(Recharged_Feasible_matv3!$A67,test!$A$34:$G$37, 3,FALSE)=VLOOKUP(E$1,test!$A$3:$I$32,3,FALSE)),1,0) -> 0 | F67: =IF(AND(feasible_mat!E5, VLOOKUP(Recharged_Feasible_matv3!$A67,test!$A$34:$G$37, 3,FALSE)=VLOOKUP(F$1,test!$A$3:$I$32,3,FALSE)),1,0) -> 0 | G67: =IF(AND(feasible_mat!F5, VLOOKUP(Recharged_Feasible_matv3!$A67,test!$A$34:$G$37, 3,FALSE)=VLOOKUP(G$1,test!$A$3:$I$32,3,FALSE)),1,0) -> 0 | H67: =IF(AND(feasible_mat!G5, VLOOKUP(Recharged_Feasible_matv3!$A67,test!$A$34:$G$37, 3,FALSE)=VLOOKUP(H$1,test!$A$3:$I$32,3,FALSE)),1,0) -> 0 | I67: =IF(AND(feasible_mat!H5, VLOOKUP(Recharged_Feasible_matv3!$A67,test!$A$34:$G$37, 3,FALSE)=VLOOKUP(I$1,test!$A$3:$I$32,3,FALSE)),1,0) -> 0 | J67: =IF(AND(feasible_mat!I5, VLOOKUP(Recharged_Feasible_matv3!$A67,test!$A$34:$G$37, 3,FALSE)=VLOOKUP(J$1,test!$A$3:$I$32,3,FALSE)),1,0) -> 0 | K67: =IF(AND(feasible_mat!J5, VLOOKUP(Recharged_Feasible_matv3!$A67,test!$A$34:$G$37, 3,FALSE)=VLOOKUP(K$1,test!$A$3:$I$32,3,FALSE)),1,0) -> 0 | ... AG67: =IF(AND(feasible_mat!AF5, VLOOKUP(Recharged_Feasible_matv3!$A67,test!$A$34:$G$37, 3,FALSE)=VLOOKUP(AG$1,test!$A$3:$I$32,3,FALSE)),1,0) -> 0
A68: CS2b | B68: AB4 | C68: 0 | D68: =IF(AND(feasible_mat!C6, VLOOKUP(Recharged_Feasible_matv3!$A68,test!$A$34:$G$37, 3,FALSE)=VLOOKUP(D$1,test!$A$3:$I$32,3,FALSE)),1,0) -> 0 | E68: =IF(AND(feasible_mat!D6, VLOOKUP(Recharged_Feasible_matv3!$A68,test!$A$34:$G$37, 3,FALSE)=VLOOKUP(E$1,test!$A$3:$I$32,3,FALSE)),1,0) -> 0 | F68: =IF(AND(feasible_mat!E6, VLOOKUP(Recharged_Feasible_matv3!$A68,test!$A$34:$G$37, 3,FALSE)=VLOOKUP(F$1,test!$A$3:$I$32,3,FALSE)),1,0) -> 0 | G68: =IF(AND(feasible_mat!F6, VLOOKUP(Recharged_Feasible_matv3!$A68,test!$A$34:$G$37, 3,FALSE)=VLOOKUP(G$1,test!$A$3:$I$32,3,FALSE)),1,0) -> 0 | H68: =IF(AND(feasible_mat!G6, VLOOKUP(Recharged_Feasible_matv3!$A68,test!$A$34:$G$37, 3,FALSE)=VLOOKUP(H$1,test!$A$3:$I$32,3,FALSE)),1,0) -> 0 | I68: =IF(AND(feasible_mat!H6, VLOOKUP(Recharged_Feasible_matv3!$A68,test!$A$34:$G$37, 3,FALSE)=VLOOKUP(I$1,test!$A$3:$I$32,3,FALSE)),1,0) -> 0 | J68: =IF(AND(feasible_mat!I6, VLOOKUP(Recharged_Feasible_matv3!$A68,test!$A$34:$G$37, 3,FALSE)=VLOOKUP(J$1,test!$A$3:$I$32,3,FALSE)),1,0) -> 0 | K68: =IF(AND(feasible_mat!J6, VLOOKUP(Recharged_Feasible_matv3!$A68,test!$A$34:$G$37, 3,FALSE)=VLOOKUP(K$1,test!$A$3:$I$32,3,FALSE)),1,0) -> 0 | ... AG68: =IF(AND(feasible_mat!AF6, VLOOKUP(Recharged_Feasible_matv3!$A68,test!$A$34:$G$37, 3,FALSE)=VLOOKUP(AG$1,test!$A$3:$I$32,3,FALSE)),1,0) -> 0
A69: CS2b | B69: AB5 | C69: 0 | D69: =IF(AND(feasible_mat!C7, VLOOKUP(Recharged_Feasible_matv3!$A69,test!$A$34:$G$37, 3,FALSE)=VLOOKUP(D$1,test!$A$3:$I$32,3,FALSE)),1,0) -> 0 | E69: =IF(AND(feasible_mat!D7, VLOOKUP(Recharged_Feasible_matv3!$A69,test!$A$34:$G$37, 3,FALSE)=VLOOKUP(E$1,test!$A$3:$I$32,3,FALSE)),1,0) -> 0 | F69: =IF(AND(feasible_mat!E7, VLOOKUP(Recharged_Feasible_matv3!$A69,test!$A$34:$G$37, 3,FALSE)=VLOOKUP(F$1,test!$A$3:$I$32,3,FALSE)),1,0) -> 0 | G69: =IF(AND(feasible_mat!F7, VLOOKUP(Recharged_Feasible_matv3!$A69,test!$A$34:$G$37, 3,FALSE)=VLOOKUP(G$1,test!$A$3:$I$32,3,FALSE)),1,0) -> 0 | H69: =IF(AND(feasible_mat!G7, VLOOKUP(Recharged_Feasible_matv3!$A69,test!$A$34:$G$37, 3,FALSE)=VLOOKUP(H$1,test!$A$3:$I$32,3,FALSE)),1,0) -> 0 | I69: =IF(AND(feasible_mat!H7, VLOOKUP(Recharged_Feasible_matv3!$A69,test!$A$34:$G$37, 3,FALSE)=VLOOKUP(I$1,test!$A$3:$I$32,3,FALSE)),1,0) -> 0 | J69: =IF(AND(feasible_mat!I7, VLOOKUP(Recharged_Feasible_matv3!$A69,test!$A$34:$G$37, 3,FALSE)=VLOOKUP(J$1,test!$A$3:$I$32,3,FALSE)),1,0) -> 0 | K69: =IF(AND(feasible_mat!J7, VLOOKUP(Recharged_Feasible_matv3!$A69,test!$A$34:$G$37, 3,FALSE)=VLOOKUP(K$1,test!$A$3:$I$32,3,FALSE)),1,0) -> 0 | ... AG69: =IF(AND(feasible_mat!AF7, VLOOKUP(Recharged_Feasible_matv3!$A69,test!$A$34:$G$37, 3,FALSE)=VLOOKUP(AG$1,test!$A$3:$I$32,3,FALSE)),1,0) -> 0
A70: CS2b | B70: AB6 | C70: 0 | D70: =IF(AND(feasible_mat!C8, VLOOKUP(Recharged_Feasible_matv3!$A70,test!$A$34:$G$37, 3,FALSE)=VLOOKUP(D$1,test!$A$3:$I$32,3,FALSE)),1,0) -> 0 | E70: =IF(AND(feasible_mat!D8, VLOOKUP(Recharged_Feasible_matv3!$A70,test!$A$34:$G$37, 3,FALSE)=VLOOKUP(E$1,test!$A$3:$I$32,3,FALSE)),1,0) -> 0 | F70: =IF(AND(feasible_mat!E8, VLOOKUP(Recharged_Feasible_matv3!$A70,test!$A$34:$G$37, 3,FALSE)=VLOOKUP(F$1,test!$A$3:$I$32,3,FALSE)),1,0) -> 0 | G70: =IF(AND(feasible_mat!F8, VLOOKUP(Recharged_Feasible_matv3!$A70,test!$A$34:$G$37, 3,FALSE)=VLOOKUP(G$1,test!$A$3:$I$32,3,FALSE)),1,0) -> 0 | H70: =IF(AND(feasible_mat!G8, VLOOKUP(Recharged_Feasible_matv3!$A70,test!$A$34:$G$37, 3,FALSE)=VLOOKUP(H$1,test!$A$3:$I$32,3,FALSE)),1,0) -> 0 | I70: =IF(AND(feasible_mat!H8, VLOOKUP(Recharged_Feasible_matv3!$A70,test!$A$34:$G$37, 3,FALSE)=VLOOKUP(I$1,test!$A$3:$I$32,3,FALSE)),1,0) -> 0 | J70: =IF(AND(feasible_mat!I8, VLOOKUP(Recharged_Feasible_matv3!$A70,test!$A$34:$G$37, 3,FALSE)=VLOOKUP(J$1,test!$A$3:$I$32,3,FALSE)),1,0) -> 0 | K70: =IF(AND(feasible_mat!J8, VLOOKUP(Recharged_Feasible_matv3!$A70,test!$A$34:$G$37, 3,FALSE)=VLOOKUP(K$1,test!$A$3:$I$32,3,FALSE)),1,0) -> 0 | ... AG70: =IF(AND(feasible_mat!AF8, VLOOKUP(Recharged_Feasible_matv3!$A70,test!$A$34:$G$37, 3,FALSE)=VLOOKUP(AG$1,test!$A$3:$I$32,3,FALSE)),1,0) -> 0
