Workbook

Sheet main
A1: ID | B1: trip_id | C1: type | D1: duration | E1: dep_time | F1: arr_time | G1: dep_term | H1: arr_term
A2: 0 | B2: DEPOT | C2: depot | D2: 0 | E2: 0 | F2: 1440 | G2: - | H2: -
A3: 1 | B3: AB1 | C3: trip | D3: 135 | E3: 430 | F3: 565 | G3: Terminal A | H3: Terminal B
A4: 2 | B4: AB2 | C4: trip | D4: 135 | E4: 560 | F4: 695 | G4: Terminal A | H4: Terminal B
A5: 3 | B5: AB3 | C5: trip | D5: 135 | E5: 720 | F5: 855 | G5: Terminal A | H5: Terminal B
A6: 4 | B6: AB4 | C6: trip | D6: 135 | E6: 740 | F6: 875 | G6: Terminal A | H6: Terminal B
A7: 5 | B7: AB5 | C7: trip | D7: 135 | E7: 830 | F7: 965 | G7: Terminal A | H7: Terminal B
A8: 6 | B8: AB6 | C8: trip | D8: 135 | E8: 920 | F8: 1055 | G8: Terminal A | H8: Terminal B | J8: TMAX | K8: 1355
A9: 7 | B9: AB7 | C9: trip | D9: 135 | E9: 980 | F9: 1115 | G9: Terminal A | H9: Terminal B
A10: 8 | B10: AB8 | C10: trip | D10: 135 | E10: 1040 | F10: 1175 | G10: Terminal A | H10: Terminal B
A11: 9 | B11: AB9 | C11: trip | D11: 135 | E11: 1100 | F11: 1235 | G11: Terminal A | H11: Terminal B
A12: 10 | B12: AB10 | C12: trip | D12: 135 | E12: 1190 | F12: 1325 | G12: Terminal A | H12: Terminal B | K12: TMAX | L12: =MAX(F3:F102) -> 1355
A13: 11 | B13: AC1 | C13: trip | D13: 140 | E13: 555 | F13: 695 | G13: Terminal A | H13: Terminal C | K13: DMAX | L13: 350
A14: 12 | B14: AC2 | C14: trip | D14: 140 | E14: 568 | F14: 708 | G14: Terminal A | H14: Terminal C
A15: 13 | B15: AC3 | C15: trip | D15: 140 | E15: 600 | F15: 740 | G15: Terminal A | H15: Terminal C
A16: 14 | B16: AC4 | C16: trip | D16: 140 | E16: 675 | F16: 815 | G16: Terminal A | H16: Terminal C
A17: 15 | B17: AC5 | C17: trip | D17: 140 | E17: 755 | F17: 895 | G17: Terminal A | H17: Terminal C
A18: 16 | B18: AC6 | C18: trip | D18: 140 | E18: 795 | F18: 935 | G18: Terminal A | H18: Terminal C | L18: Terminal A | M18: Terminal B | N18: Terminal C | O18: Terminal D
A19: 17 | B19: AC7 | C19: trip | D19: 140 | E19: 920 | F19: 1060 | G19: Terminal A | H19: Terminal C | K19: Terminal A | L19: 0 | M19: 25 | N19: 30 | O19: 35
A20: 18 | B20: AC8 | C20: trip | D20: 140 | E20: 1000 | F20: 1140 | G20: Terminal A | H20: Terminal C | K20: Terminal B | L20: 25 | M20: 0 | N20: 28 | O20: 40
A21: 19 | B21: AC9 | C21: trip | D21: 140 | E21: 1155 | F21: 1295 | G21: Terminal A | H21: Terminal C | K21: Terminal C | L21: 30 | M21: 28 | N21: 0 | O21: 33
A22: 20 | B22: AC10 | C22: trip | D22: 140 | E22: 1215 | F22: 1355 | G22: Terminal A | H22: Terminal C | K22: Terminal D | L22: 35 | M22: 40 | N22: 33 | O22: 0
A23: 21 | B23: AD1 | C23: trip | D23: 140 | E23: 560 | F23: 700 | G23: Terminal A | H23: Terminal D
A24: 22 | B24: AD2 | C24: trip | D24: 140 | E24: 630 | F24: 770 | G24: Terminal A | H24: Terminal D
A25: 23 | B25: AD3 | C25: trip | D25: 135 | E25: 790 | F25: 925 | G25: Terminal A | H25: Terminal D | K25: Terminal | L25: Min_Layover | M25: Duration to CS1 | N25: Duration to CS1a | O25: Duration to CS2b | P25: Duration to CS3c | Q25: Duration to CS4d
A26: 24 | B26: AD4 | C26: trip | D26: 140 | E26: 970 | F26: 1110 | G26: Terminal A | H26: Terminal D | K26: Terminal A | L26: 15 | M26: 30 | N26: 10 | O26: 75 | P26: 75 | Q26: 75
A27: 25 | B27: AD5 | C27: trip | D27: 140 | E27: 1120 | F27: 1240 | G27: Terminal A | H27: Terminal D | K27: Terminal B | L27: 15 | M27: 30 | N27: 75 | O27: 10 | P27: 75 | Q27: 75
A28: 26 | B28: AD6 | C28: trip | D28: 140 | E28: 480 | F28: 620 | G28: Terminal A | H28: Terminal D | K28: Terminal C | L28: 15 | M28: 30 | N28: 75 | O28: 75 | P28: 10 | Q28: 75
A29: 27 | B29: AD7 | C29: trip | D29: 140 | E29: 500 | F29: 640 | G29: Terminal A | H29: Terminal D | K29: Terminal D | L29: 15 | M29: 30 | N29: 75 | O29: 75 | P29: 75 | Q29: 10
A30: 28 | B30: AD8 | C30: trip | D30: 135 | E30: 750 | F30: 885 | G30: Terminal A | H30: Terminal D
A31: 29 | B31: AD9 | C31: trip | D31: 140 | E31: 930 | F31: 1070 | G31: Terminal A | H31: Terminal D
A32: 30 | B32: AD10 | C32: trip | D32: 100 | E32: 1100 | F32: 1200 | G32: Terminal A | H32: Terminal D
A33: 31 | B33: BA1 | C33: trip | D33: 135 | E33: 540 | F33: 675 | G33: Terminal B | H33: Terminal A
A34: 32 | B34: BA2 | C34: trip | D34: 135 | E34: 630 | F34: 765 | G34: Terminal B | H34: Terminal A
A35: 33 | B35: BA3 | C35: trip | D35: 135 | E35: 720 | F35: 855 | G35: Terminal B | H35: Terminal A
A36: 34 | B36: BA4 | C36: trip | D36: 135 | E36: 810 | F36: 945 | G36: Terminal B | H36: Terminal A
A37: 35 | B37: BA5 | C37: trip | D37: 135 | E37: 900 | F37: 1035 | G37: Terminal B | H37: Terminal A
A38: 36 | B38: BA6 | C38: trip | D38: 135 | E38: 990 | F38: 1125 | G38: Terminal B | H38: Terminal A
A39: 37 | B39: BA7 | C39: trip | D39: 135 | E39: 1080 | F39: 1215 | G39: Terminal B | H39: Terminal A
A40: 38 | B40: BA8 | C40: trip | D40: 135 | E40: 1140 | F40: 1275 | G40: Terminal B | H40: Terminal A
...

Sheet gamma
B1: 0 | C1: 1 | D1: 2 | E1: 3 | F1: 4 | G1: 5 | H1: 6 | I1: 7 | J1: 8 | K1: 9 | L1: 10 | M1: 11 | N1: 12 | O1: 13 | P1: 14 | Q1: 15 | R1: 16 | S1: 17 | T1: 18 | U1: 19 | V1: 20 | W1: 21 | X1: 22 | Y1: 23 | Z1: 24 | AA1: 25 | AB1: 26 | AC1: 27 | AD1: 28 | AE1: 29 | AF1: 30 | AG1: 31 | AH1: 32 | AI1: 33 | AJ1: 34 | AK1: 35 | AL1: 36 | AM1: 37 | AN1: 38 | AO1: 39 | AP1: 40 | AQ1: 41 | AR1: 42 | AS1: 43 | AT1: 44 | AU1: 45 | AV1: 46 | AW1: 47 | AX1: 48 | AY1: 49 | AZ1: 50 | BA1: 51 | BB1: 52 | BC1: 53 | BD1: 54 | BE1: 55 | BF1: 56 | BG1: 57 | BH1: 58 | BI1: 59 | BJ1: 60 | BK1: 61 | BL1: 62 | BM1: 63 | BN1: 64 | BO1: 65 | BP1: 66 | BQ1: 67 | BR1: 68 | BS1: 69 | BT1: 70 | BU1: 71 | BV1: 72 | BW1: 73 | BX1: 74 | BY1: 75 | BZ1: 76 | CA1: 77 | CB1: 78 | CC1: 79 | CD1: 80 | CE1: 81 | CF1: 82 | CG1: 83 | CH1: 84 | CI1: 85 | CJ1: 86 | CK1: 87 | CL1: 88 | CM1: 89 | CN1: 90 | CO1: 91 | CP1: 92 | CQ1: 93 | CR1: 94 | CS1: 95 | CT1: 96 | CU1: 97 | CV1: 98 | CW1: 99 | CX1: 100
A2: 0 | B2: 0 | C2: 1 | D2: 1 | E2: 1 | F2: 1 | G2: 1 | H2: 1 | I2: 1 | J2: 1 | K2: 1 | L2: 1 | M2: 1 | N2: 1 | O2: 1 | P2: 1 | Q2: 1 | R2: 1 | S2: 1 | T2: 1 | U2: 1 | V2: 1 | W2: 1 | X2: 1 | Y2: 1 | Z2: 1 | AA2: 1 | AB2: 1 | AC2: 1 | AD2: 1 | AE2: 1 | AF2: 1 | AG2: 1 | AH2: 1 | AI2: 1 | AJ2: 1 | AK2: 1 | AL2: 1 | AM2: 1 | AN2: 1 | AO2: 1 | AP2: 1 | AQ2: 1 | AR2: 1 | AS2: 1 | AT2: 1 | AU2: 1 | AV2: 1 | AW2: 1 | AX2: 1 | AY2: 1 | AZ2: 1 | BA2: 1 | BB2: 1 | BC2: 1 | BD2: 1 | BE2: 1 | BF2: 1 | BG2: 1 | BH2: 1 | BI2: 1 | BJ2: 1 | BK2: 1 | BL2: 1 | BM2: 1 | BN2: 1 | BO2: 1 | BP2: 1 | BQ2: 1 | BR2: 1 | BS2: 1 | BT2: 1 | BU2: 1 | BV2: 1 | BW2: 1 | BX2: 1 | BY2: 1 | BZ2: 1 | CA2: 1 | CB2: 1 | CC2: 1 | CD2: 1 | CE2: 1 | CF2: 1 | CG2: 1 | CH2: 1 | CI2: 1 | CJ2: 1 | CK2: 1 | CL2: 1 | CM2: 1 | CN2: 1 | CO2: 1 | CP2: 1 | CQ2: 1 | CR2: 1 | CS2: 1 | CT2: 1 | CU2: 1 | CV2: 1 | CW2: 1 | CX2: 1
A3: 1 | B3: 1 | C3: =IF((AND(VLOOKUP(C$1,main!$A$3:$H$102,5,FALSE)-VLOOKUP($A3,main!$A$3:$H$102,6,FALSE)>=(VLOOKUP(VLOOKUP(C$1,main!$A$3:$H$102,8,FALSE),main!$K$26:$M$29,2,FALSE)+VLOOKUP(VLOOKUP(C$1,main!$A$3:$H$102,7,FALSE),main!$K$19:$O$22,MATCH(VLOOKUP($A3,main!$A$3:$H$102,8,FALSE),main!$K$18:$O$18,0))))),1,0) -> 0 | D3: =IF((AND(VLOOKUP(D$1,main!$A$3:$H$102,5,FALSE)-VLOOKUP($A3,main!$A$3:$H$102,6,FALSE)>=(VLOOKUP(VLOOKUP(D$1,main!$A$3:$H$102,8,FALSE),main!$K$26:$M$29,2,FALSE)+VLOOKUP(VLOOKUP(D$1,main!$A$3:$H$102,7,FALSE),main!$K$19:$O$22,MATCH(VLOOKUP($A3,main!$A$3:$H$102,8,FALSE),main!$K$18:$O$18,0))))),1,0) -> 0 | E3: =IF((AND(VLOOKUP(E$1,main!$A$3:$H$102,5,FALSE)-VLOOKUP($A3,main!$A$3:$H$102,6,FALSE)>=(VLOOKUP(VLOOKUP(E$1,main!$A$3:$H$102,8,FALSE),main!$K$26:$M$29,2,FALSE)+VLOOKUP(VLOOKUP(E$1,main!$A$3:$H$102,7,FALSE),main!$K$19:$O$22,MATCH(VLOOKUP($A3,main!$A$3:$H$102,8,FALSE),main!$K$18:$O$18,0))))),1,0) -> 1 | F3: =IF((AND(VLOOKUP(F$1,main!$A$3:$H$102,5,FALSE)-VLOOKUP($A3,main!$A$3:$H$102,6,FALSE)>=(VLOOKUP(VLOOKUP(F$1,main!$A$3:$H$102,8,FALSE),main!$K$26:$M$29,2,FALSE)+VLOOKUP(VLOOKUP(F$1,main!$A$3:$H$102,7,FALSE),main!$K$19:$O$22,MATCH(VLOOKUP($A3,main!$A$3:$H$102,8,FALSE),main!$K$18:$O$18,0))))),1,0) -> 1 | G3: =IF((AND(VLOOKUP(G$1,main!$A$3:$H$102,5,FALSE)-VLOOKUP($A3,main!$A$3:$H$102,6,FALSE)>=(VLOOKUP(VLOOKUP(G$1,main!$A$3:$H$102,8,FALSE),main!$K$26:$M$29,2,FALSE)+VLOOKUP(VLOOKUP(G$1,main!$A$3:$H$102,7,FALSE),main!$K$19:$O$22,MATCH(VLOOKUP($A3,main!$A$3:$H$102,8,FALSE),main!$K$18:$O$18,0))))),1,0) -> 1 | H3: =IF((AND(VLOOKUP(H$1,main!$A$3:$H$102,5,FALSE)-VLOOKUP($A3,main!$A$3:$H$102,6,FALSE)>=(VLOOKUP(VLOOKUP(H$1,main!$A$3:$H$102,8,FALSE),main!$K$26:$M$29,2,FALSE)+VLOOKUP(VLOOKUP(H$1,main!$A$3:$H$102,7,FALSE),main!$K$19:$O$22,MATCH(VLOOKUP($A3,main!$A$3:$H$102,8,FALSE),main!$K$18:$O$18,0))))),1,0) -> 1 | I3: =IF((AND(VLOOKUP(I$1,main!$A$3:$H$102,5,FALSE)-VLOOKUP($A3,main!$A$3:$H$102,6,FALSE)>=(VLOOKUP(VLOOKUP(I$1,main!$A$3:$H$102,8,FALSE),main!$K$26:$M$29,2,FALSE)+VLOOKUP(VLOOKUP(I$1,main!$A$3:$H$102,7,FALSE),main!$K$19:$O$22,MATCH(VLOOKUP($A3,main!$A$3:$H$102,8,FALSE),main!$K$18:$O$18,0))))),1,0) -> 1 | J3: =IF((AND(VLOOKUP(J$1,main!$A$3:$H$102,5,FALSE)-VLOOKUP($A3,main!$A$3:$H$102,6,FALSE)>=(VLOOKUP(VLOOKUP(J$1,main!$A$3:$H$102,8,FALSE),main!$K$26:$M$29,2,FALSE)+VLOOKUP(VLOOKUP(J$1,main!$A$3:$H$102,7,FALSE),main!$K$19:$O$22,MATCH(VLOOKUP($A3,main!$A$3:$H$102,8,FALSE),main!$K$18:$O$18,0))))),1,0) -> 1 | ... CX3: =IF((AND(VLOOKUP(CX$1,main!$A$3:$H$102,5,FALSE)-VLOOKUP($A3,main!$A$3:$H$102,6,FALSE)>=(VLOOKUP(VLOOKUP(CX$1,main!$A$3:$H$102,8,FALSE),main!$K$26:$M$29,2,FALSE)+VLOOKUP(VLOOKUP(CX$1,main!$A$3:$H$102,7,FALSE),main!$K$19:$O$22,MATCH(VLOOKUP($A3,main!$A$3:$H$102,8,FALSE),main!$K$18:$O$18,0))))),1,0) -> 1
A4: 2 | B4: 1 | C4: =IF((AND(VLOOKUP(C$1,main!$A$3:$H$102,5,FALSE)-VLOOKUP($A4,main!$A$3:$H$102,6,FALSE)>=(VLOOKUP(VLOOKUP(C$1,main!$A$3:$H$102,8,FALSE),main!$K$26:$M$29,2,FALSE)+VLOOKUP(VLOOKUP(C$1,main!$A$3:$H$102,7,FALSE),main!$K$19:$O$22,MATCH(VLOOKUP($A4,main!$A$3:$H$102,8,FALSE),main!$K$18:$O$18,0))))),1,0) -> 0 | D4: =IF((AND(VLOOKUP(D$1,main!$A$3:$H$102,5,FALSE)-VLOOKUP($A4,main!$A$3:$H$102,6,FALSE)>=(VLOOKUP(VLOOKUP(D$1,main!$A$3:$H$102,8,FALSE),main!$K$26:$M$29,2,FALSE)+VLOOKUP(VLOOKUP(D$1,main!$A$3:$H$102,7,FALSE),main!$K$19:$O$22,MATCH(VLOOKUP($A4,main!$A$3:$H$102,8,FALSE),main!$K$18:$O$18,0))))),1,0) -> 0 | E4: =IF((AND(VLOOKUP(E$1,main!$A$3:$H$102,5,FALSE)-VLOOKUP($A4,main!$A$3:$H$102,6,FALSE)>=(VLOOKUP(VLOOKUP(E$1,main!$A$3:$H$102,8,FALSE),main!$K$26:$M$29,2,FALSE)+VLOOKUP(VLOOKUP(E$1,main!$A$3:$H$102,7,FALSE),main!$K$19:$O$22,MATCH(VLOOKUP($A4,main!$A$3:$H$102,8,FALSE),main!$K$18:$O$18,0))))),1,0) -> 0 | F4: =IF((AND(VLOOKUP(F$1,main!$A$3:$H$102,5,FALSE)-VLOOKUP($A4,main!$A$3:$H$102,6,FALSE)>=(VLOOKUP(VLOOKUP(F$1,main!$A$3:$H$102,8,FALSE),main!$K$26:$M$29,2,FALSE)+VLOOKUP(VLOOKUP(F$1,main!$A$3:$H$102,7,FALSE),main!$K$19:$O$22,MATCH(VLOOKUP($A4,main!$A$3:$H$102,8,FALSE),main!$K$18:$O$18,0))))),1,0) -> 1 | G4: =IF((AND(VLOOKUP(G$1,main!$A$3:$H$102,5,FALSE)-VLOOKUP($A4,main!$A$3:$H$102,6,FALSE)>=(VLOOKUP(VLOOKUP(G$1,main!$A$3:$H$102,8,FALSE),main!$K$26:$M$29,2,FALSE)+VLOOKUP(VLOOKUP(G$1,main!$A$3:$H$102,7,FALSE),main!$K$19:$O$22,MATCH(VLOOKUP($A4,main!$A$3:$H$102,8,FALSE),main!$K$18:$O$18,0))))),1,0) -> 1 | H4: =IF((AND(VLOOKUP(H$1,main!$A$3:$H$102,5,FALSE)-VLOOKUP($A4,main!$A$3:$H$102,6,FALSE)>=(VLOOKUP(VLOOKUP(H$1,main!$A$3:$H$102,8,FALSE),main!$K$26:$M$29,2,FALSE)+VLOOKUP(VLOOKUP(H$1,main!$A$3:$H$102,7,FALSE),main!$K$19:$O$22,MATCH(VLOOKUP($A4,main!$A$3:$H$102,8,FALSE),main!$K$18:$O$18,0))))),1,0) -> 1 | I4: =IF((AND(VLOOKUP(I$1,main!$A$3:$H$102,5,FALSE)-VLOOKUP($A4,main!$A$3:$H$102,6,FALSE)>=(VLOOKUP(VLOOKUP(I$1,main!$A$3:$H$102,8,FALSE),main!$K$26:$M$29,2,FALSE)+VLOOKUP(VLOOKUP(I$1,main!$A$3:$H$102,7,FALSE),main!$K$19:$O$22,MATCH(VLOOKUP($A4,main!$A$3:$H$102,8,FALSE),main!$K$18:$O$18,0))))),1,0) -> 1 | J4: =IF((AND(VLOOKUP(J$1,main!$A$3:$H$102,5,FALSE)-VLOOKUP($A4,main!$A$3:$H$102,6,FALSE)>=(VLOOKUP(VLOOKUP(J$1,main!$A$3:$H$102,8,FALSE),main!$K$26:$M$29,2,FALSE)+VLOOKUP(VLOOKUP(J$1,main!$A$3:$H$102,7,FALSE),main!$K$19:$O$22,MATCH(VLOOKUP($A4,main!$A$3:$H$102,8,FALSE),main!$K$18:$O$18,0))))),1,0) -> 1 | ... CX4: =IF((AND(VLOOKUP(CX$1,main!$A$3:$H$102,5,FALSE)-VLOOKUP($A4,main!$A$3:$H$102,6,FALSE)>=(VLOOKUP(VLOOKUP(CX$1,main!$A$3:$H$102,8,FALSE),main!$K$26:$M$29,2,FALSE)+VLOOKUP(VLOOKUP(CX$1,main!$A$3:$H$102,7,FALSE),main!$K$19:$O$22,MATCH(VLOOKUP($A4,main!$A$3:$H$102,8,FALSE),main!$K$18:$O$18,0))))),1,0) -> 1
A5: 3 | B5: 1 | C5: =IF((AND(VLOOKUP(C$1,main!$A$3:$H$102,5,FALSE)-VLOOKUP($A5,main!$A$3:$H$102,6,FALSE)>=(VLOOKUP(VLOOKUP(C$1,main!$A$3:$H$102,8,FALSE),main!$K$26:$M$29,2,FALSE)+VLOOKUP(VLOOKUP(C$1,main!$A$3:$H$102,7,FALSE),main!$K$19:$O$22,MATCH(VLOOKUP($A5,main!$A$3:$H$102,8,FALSE),main!$K$18:$O$18,0))))),1,0) -> 0 | D5: =IF((AND(VLOOKUP(D$1,main!$A$3:$H$102,5,FALSE)-VLOOKUP($A5,main!$A$3:$H$102,6,FALSE)>=(VLOOKUP(VLOOKUP(D$1,main!$A$3:$H$102,8,FALSE),main!$K$26:$M$29,2,FALSE)+VLOOKUP(VLOOKUP(D$1,main!$A$3:$H$102,7,FALSE),main!$K$19:$O$22,MATCH(VLOOKUP($A5,main!$A$3:$H$102,8,FALSE),main!$K$18:$O$18,0))))),1,0) -> 0 | E5: =IF((AND(VLOOKUP(E$1,main!$A$3:$H$102,5,FALSE)-VLOOKUP($A5,main!$A$3:$H$102,6,FALSE)>=(VLOOKUP(VLOOKUP(E$1,main!$A$3:$H$102,8,FALSE),main!$K$26:$M$29,2,FALSE)+VLOOKUP(VLOOKUP(E$1,main!$A$3:$H$102,7,FALSE),main!$K$19:$O$22,MATCH(VLOOKUP($A5,main!$A$3:$H$102,8,FALSE),main!$K$18:$O$18,0))))),1,0) -> 0 | F5: =IF((AND(VLOOKUP(F$1,main!$A$3:$H$102,5,FALSE)-VLOOKUP($A5,main!$A$3:$H$102,6,FALSE)>=(VLOOKUP(VLOOKUP(F$1,main!$A$3:$H$102,8,FALSE),main!$K$26:$M$29,2,FALSE)+VLOOKUP(VLOOKUP(F$1,main!$A$3:$H$102,7,FALSE),main!$K$19:$O$22,MATCH(VLOOKUP($A5,main!$A$3:$H$102,8,FALSE),main!$K$18:$O$18,0))))),1,0) -> 0 | G5: =IF((AND(VLOOKUP(G$1,main!$A$3:$H$102,5,FALSE)-VLOOKUP($A5,main!$A$3:$H$102,6,FALSE)>=(VLOOKUP(VLOOKUP(G$1,main!$A$3:$H$102,8,FALSE),main!$K$26:$M$29,2,FALSE)+VLOOKUP(VLOOKUP(G$1,main!$A$3:$H$102,7,FALSE),main!$K$19:$O$22,MATCH(VLOOKUP($A5,main!$A$3:$H$102,8,FALSE),main!$K$18:$O$18,0))))),1,0) -> 0 | H5: =IF((AND(VLOOKUP(H$1,main!$A$3:$H$102,5,FALSE)-VLOOKUP($A5,main!$A$3:$H$102,6,FALSE)>=(VLOOKUP(VLOOKUP(H$1,main!$A$3:$H$102,8,FALSE),main!$K$26:$M$29,2,FALSE)+VLOOKUP(VLOOKUP(H$1,main!$A$3:$H$102,7,FALSE),main!$K$19:$O$22,MATCH(VLOOKUP($A5,main!$A$3:$H$102,8,FALSE),main!$K$18:$O$18,0))))),1,0) -> 1 | I5: =IF((AND(VLOOKUP(I$1,main!$A$3:$H$102,5,FALSE)-VLOOKUP($A5,main!$A$3:$H$102,6,FALSE)>=(VLOOKUP(VLOOKUP(I$1,main!$A$3:$H$102,8,FALSE),main!$K$26:$M$29,2,FALSE)+VLOOKUP(VLOOKUP(I$1,main!$A$3:$H$102,7,FALSE),main!$K$19:$O$22,MATCH(VLOOKUP($A5,main!$A$3:$H$102,8,FALSE),main!$K$18:$O$18,0))))),1,0) -> 1 | J5: =IF((AND(VLOOKUP(J$1,main!$A$3:$H$102,5,FALSE)-VLOOKUP($A5,main!$A$3:$H$102,6,FALSE)>=(VLOOKUP(VLOOKUP(J$1,main!$A$3:$H$102,8,FALSE),main!$K$26:$M$29,2,FALSE)+VLOOKUP(VLOOKUP(J$1,main!$A$3:$H$102,7,FALSE),main!$K$19:$O$22,MATCH(VLOOKUP($A5,main!$A$3:$H$102,8,FALSE),main!$K$18:$O$18,0))))),1,0) -> 1 | ... CX5: =IF((AND(VLOOKUP(CX$1,main!$A$3:$H$102,5,FALSE)-VLOOKUP($A5,main!$A$3:$H$102,6,FALSE)>=(VLOOKUP(VLOOKUP(CX$1,main!$A$3:$H$102,8,FALSE),main!$K$26:$M$29,2,FALSE)+VLOOKUP(VLOOKUP(CX$1,main!$A$3:$H$102,7,FALSE),main!$K$19:$O$22,MATCH(VLOOKUP($A5,main!$A$3:$H$102,8,FALSE),main!$K$18:$O$18,0))))),1,0) -> 1
A6: 4 | B6: 1 | C6: =IF((AND(VLOOKUP(C$1,main!$A$3:$H$102,5,FALSE)-VLOOKUP($A6,main!$A$3:$H$102,6,FALSE)>=(VLOOKUP(VLOOKUP(C$1,main!$A$3:$H$102,8,FALSE),main!$K$26:$M$29,2,FALSE)+VLOOKUP(VLOOKUP(C$1,main!$A$3:$H$102,7,FALSE),main!$K$19:$O$22,MATCH(VLOOKUP($A6,main!$A$3:$H$102,8,FALSE),main!$K$18:$O$18,0))))),1,0) -> 0 | D6: =IF((AND(VLOOKUP(D$1,main!$A$3:$H$102,5,FALSE)-VLOOKUP($A6,main!$A$3:$H$102,6,FALSE)>=(VLOOKUP(VLOOKUP(D$1,main!$A$3:$H$102,8,FALSE),main!$K$26:$M$29,2,FALSE)+VLOOKUP(VLOOKUP(D$1,main!$A$3:$H$102,7,FALSE),main!$K$19:$O$22,MATCH(VLOOKUP($A6,main!$A$3:$H$102,8,FALSE),main!$K$18:$O$18,0))))),1,0) -> 0 | E6: =IF((AND(VLOOKUP(E$1,main!$A$3:$H$102,5,FALSE)-VLOOKUP($A6,main!$A$3:$H$102,6,FALSE)>=(VLOOKUP(VLOOKUP(E$1,main!$A$3:$H$102,8,FALSE),main!$K$26:$M$29,2,FALSE)+VLOOKUP(VLOOKUP(E$1,main!$A$3:$H$102,7,FALSE),main!$K$19:$O$22,MATCH(VLOOKUP($A6,main!$A$3:$H$102,8,FALSE),main!$K$18:$O$18,0))))),1,0) -> 0 | F6: =IF((AND(VLOOKUP(F$1,main!$A$3:$H$102,5,FALSE)-VLOOKUP($A6,main!$A$3:$H$102,6,FALSE)>=(VLOOKUP(VLOOKUP(F$1,main!$A$3:$H$102,8,FALSE),main!$K$26:$M$29,2,FALSE)+VLOOKUP(VLOOKUP(F$1,main!$A$3:$H$102,7,FALSE),main!$K$19:$O$22,MATCH(VLOOKUP($A6,main!$A$3:$H$102,8,FALSE),main!$K$18:$O$18,0))))),1,0) -> 0 | G6: =IF((AND(VLOOKUP(G$1,main!$A$3:$H$102,5,FALSE)-VLOOKUP($A6,main!$A$3:$H$102,6,FALSE)>=(VLOOKUP(VLOOKUP(G$1,main!$A$3:$H$102,8,FALSE),main!$K$26:$M$29,2,FALSE)+VLOOKUP(VLOOKUP(G$1,main!$A$3:$H$102,7,FALSE),main!$K$19:$O$22,MATCH(VLOOKUP($A6,main!$A$3:$H$102,8,FALSE),main!$K$18:$O$18,0))))),1,0) -> 0 | H6: =IF((AND(VLOOKUP(H$1,main!$A$3:$H$102,5,FALSE)-VLOOKUP($A6,main!$A$3:$H$102,6,FALSE)>=(VLOOKUP(VLOOKUP(H$1,main!$A$3:$H$102,8,FALSE),main!$K$26:$M$29,2,FALSE)+VLOOKUP(VLOOKUP(H$1,main!$A$3:$H$102,7,FALSE),main!$K$19:$O$22,MATCH(VLOOKUP($A6,main!$A$3:$H$102,8,FALSE),main!$K$18:$O$18,0))))),1,0) -> 1 | I6: =IF((AND(VLOOKUP(I$1,main!$A$3:$H$102,5,FALSE)-VLOOKUP($A6,main!$A$3:$H$102,6,FALSE)>=(VLOOKUP(VLOOKUP(I$1,main!$A$3:$H$102,8,FALSE),main!$K$26:$M$29,2,FALSE)+VLOOKUP(VLOOKUP(I$1,main!$A$3:$H$102,7,FALSE),main!$K$19:$O$22,MATCH(VLOOKUP($A6,main!$A$3:$H$102,8,FALSE),main!$K$18:$O$18,0))))),1,0) -> 1 | J6: =IF((AND(VLOOKUP(J$1,main!$A$3:$H$102,5,FALSE)-VLOOKUP($A6,main!$A$3:$H$102,6,FALSE)>=(VLOOKUP(VLOOKUP(J$1,main!$A$3:$H$102,8,FALSE),main!$K$26:$M$29,2,FALSE)+VLOOKUP(VLOOKUP(J$1,main!$A$3:$H$102,7,FALSE),main!$K$19:$O$22,MATCH(VLOOKUP($A6,main!$A$3:$H$102,8,FALSE),main!$K$18:$O$18,0))))),1,0) -> 1 | ... CX6: =IF((AND(VLOOKUP(CX$1,main!$A$3:$H$102,5,FALSE)-VLOOKUP($A6,main!$A$3:$H$102,6,FALSE)>=(VLOOKUP(VLOOKUP(CX$1,main!$A$3:$H$102,8,FALSE),main!$K$26:$M$29,2,FALSE)+VLOOKUP(VLOOKUP(CX$1,main!$A$3:$H$102,7,FALSE),main!$K$19:$O$22,MATCH(VLOOKUP($A6,main!$A$3:$H$102,8,FALSE),main!$K$18:$O$18,0))))),1,0) -> 1
A7: 5 | B7: 1 | C7: =IF((AND(VLOOKUP(C$1,main!$A$3:$H$102,5,FALSE)-VLOOKUP($A7,main!$A$3:$H$102,6,FALSE)>=(VLOOKUP(VLOOKUP(C$1,main!$A$3:$H$102,8,FALSE),main!$K$26:$M$29,2,FALSE)+VLOOKUP(VLOOKUP(C$1,main!$A$3:$H$102,7,FALSE),main!$K$19:$O$22,MATCH(VLOOKUP($A7,main!$A$3:$H$102,8,FALSE),main!$K$18:$O$18,0))))),1,0) -> 0 | D7: =IF((AND(VLOOKUP(D$1,main!$A$3:$H$102,5,FALSE)-VLOOKUP($A7,main!$A$3:$H$102,6,FALSE)>=(VLOOKUP(VLOOKUP(D$1,main!$A$3:$H$102,8,FALSE),main!$K$26:$M$29,2,FALSE)+VLOOKUP(VLOOKUP(D$1,main!$A$3:$H$102,7,FALSE),main!$K$19:$O$22,MATCH(VLOOKUP($A7,main!$A$3:$H$102,8,FALSE),main!$K$18:$O$18,0))))),1,0) -> 0 | E7: =IF((AND(VLOOKUP(E$1,main!$A$3:$H$102,5,FALSE)-VLOOKUP($A7,main!$A$3:$H$102,6,FALSE)>=(VLOOKUP(VLOOKUP(E$1,main!$A$3:$H$102,8,FALSE),main!$K$26:$M$29,2,FALSE)+VLOOKUP(VLOOKUP(E$1,main!$A$3:$H$102,7,FALSE),main!$K$19:$O$22,MATCH(VLOOKUP($A7,main!$A$3:$H$102,8,FALSE),main!$K$18:$O$18,0))))),1,0) -> 0 | F7: =IF((AND(VLOOKUP(F$1,main!$A$3:$H$102,5,FALSE)-VLOOKUP($A7,main!$A$3:$H$102,6,FALSE)>=(VLOOKUP(VLOOKUP(F$1,main!$A$3:$H$102,8,FALSE),main!$K$26:$M$29,2,FALSE)+VLOOKUP(VLOOKUP(F$1,main!$A$3:$H$102,7,FALSE),main!$K$19:$O$22,MATCH(VLOOKUP($A7,main!$A$3:$H$102,8,FALSE),main!$K$18:$O$18,0))))),1,0) -> 0 | G7: =IF((AND(VLOOKUP(G$1,main!$A$3:$H$102,5,FALSE)-VLOOKUP($A7,main!$A$3:$H$102,6,FALSE)>=(VLOOKUP(VLOOKUP(G$1,main!$A$3:$H$102,8,FALSE),main!$K$26:$M$29,2,FALSE)+VLOOKUP(VLOOKUP(G$1,main!$A$3:$H$102,7,FALSE),main!$K$19:$O$22,MATCH(VLOOKUP($A7,main!$A$3:$H$102,8,FALSE),main!$K$18:$O$18,0))))),1,0) -> 0 | H7: =IF((AND(VLOOKUP(H$1,main!$A$3:$H$102,5,FALSE)-VLOOKUP($A7,main!$A$3:$H$102,6,FALSE)>=(VLOOKUP(VLOOKUP(H$1,main!$A$3:$H$102,8,FALSE),main!$K$26:$M$29,2,FALSE)+VLOOKUP(VLOOKUP(H$1,main!$A$3:$H$102,7,FALSE),main!$K$19:$O$22,MATCH(VLOOKUP($A7,main!$A$3:$H$102,8,FALSE),main!$K$18:$O$18,0))))),1,0) -> 0 | I7: =IF((AND(VLOOKUP(I$1,main!$A$3:$H$102,5,FALSE)-VLOOKUP($A7,main!$A$3:$H$102,6,FALSE)>=(VLOOKUP(VLOOKUP(I$1,main!$A$3:$H$102,8,FALSE),main!$K$26:$M$29,2,FALSE)+VLOOKUP(VLOOKUP(I$1,main!$A$3:$H$102,7,FALSE),main!$K$19:$O$22,MATCH(VLOOKUP($A7,main!$A$3:$H$102,8,FALSE),main!$K$18:$O$18,0))))),1,0) -> 0 | J7: =IF((AND(VLOOKUP(J$1,main!$A$3:$H$102,5,FALSE)-VLOOKUP($A7,main!$A$3:$H$102,6,FALSE)>=(VLOOKUP(VLOOKUP(J$1,main!$A$3:$H$102,8,FALSE),main!$K$26:$M$29,2,FALSE)+VLOOKUP(VLOOKUP(J$1,main!$A$3:$H$102,7,FALSE),main!$K$19:$O$22,MATCH(VLOOKUP($A7,main!$A$3:$H$102,8,FALSE),main!$K$18:$O$18,0))))),1,0) -> 1 | ... CX7: =IF((AND(VLOOKUP(CX$1,main!$A$3:$H$102,5,FALSE)-VLOOKUP($A7,main!$A$3:$H$102,6,FALSE)>=(VLOOKUP(VLOOKUP(CX$1,main!$A$3:$H$102,8,FALSE),main!$K$26:$M$29,2,FALSE)+VLOOKUP(VLOOKUP(CX$1,main!$A$3:$H$102,7,FALSE),main!$K$19:$O$22,MATCH(VLOOKUP($A7,main!$A$3:$H$102,8,FALSE),main!$K$18:$O$18,0))))),1,0) -> 0
A8: 6 | B8: 1 | C8: =IF((AND(VLOOKUP(C$1,main!$A$3:$H$102,5,FALSE)-VLOOKUP($A8,main!$A$3:$H$102,6,FALSE)>=(VLOOKUP(VLOOKUP(C$1,main!$A$3:$H$102,8,FALSE),main!$K$26:$M$29,2,FALSE)+VLOOKUP(VLOOKUP(C$1,main!$A$3:$H$102,7,FALSE),main!$K$19:$O$22,MATCH(VLOOKUP($A8,main!$A$3:$H$102,8,FALSE),main!$K$18:$O$18,0))))),1,0) -> 0 | D8: =IF((AND(VLOOKUP(D$1,main!$A$3:$H$102,5,FALSE)-VLOOKUP($A8,main!$A$3:$H$102,6,FALSE)>=(VLOOKUP(VLOOKUP(D$1,main!$A$3:$H$102,8,FALSE),main!$K$26:$M$29,2,FALSE)+VLOOKUP(VLOOKUP(D$1,main!$A$3:$H$102,7,FALSE),main!$K$19:$O$22,MATCH(VLOOKUP($A8,main!$A$3:$H$102,8,FALSE),main!$K$18:$O$18,0))))),1,0) -> 0 | E8: =IF((AND(VLOOKUP(E$1,main!$A$3:$H$102,5,FALSE)-VLOOKUP($A8,main!$A$3:$H$102,6,FALSE)>=(VLOOKUP(VLOOKUP(E$1,main!$A$3:$H$102,8,FALSE),main!$K$26:$M$29,2,FALSE)+VLOOKUP(VLOOKUP(E$1,main!$A$3:$H$102,7,FALSE),main!$K$19:$O$22,MATCH(VLOOKUP($A8,main!$A$3:$H$102,8,FALSE),main!$K$18:$O$18,0))))),1,0) -> 0 | F8: =IF((AND(VLOOKUP(F$1,main!$A$3:$H$102,5,FALSE)-VLOOKUP($A8,main!$A$3:$H$102,6,FALSE)>=(VLOOKUP(VLOOKUP(F$1,main!$A$3:$H$102,8,FALSE),main!$K$26:$M$29,2,FALSE)+VLOOKUP(VLOOKUP(F$1,main!$A$3:$H$102,7,FALSE),main!$K$19:$O$22,MATCH(VLOOKUP($A8,main!$A$3:$H$102,8,FALSE),main!$K$18:$O$18,0))))),1,0) -> 0 | G8: =IF((AND(VLOOKUP(G$1,main!$A$3:$H$102,5,FALSE)-VLOOKUP($A8,main!$A$3:$H$102,6,FALSE)>=(VLOOKUP(VLOOKUP(G$1,main!$A$3:$H$102,8,FALSE),main!$K$26:$M$29,2,FALSE)+VLOOKUP(VLOOKUP(G$1,main!$A$3:$H$102,7,FALSE),main!$K$19:$O$22,MATCH(VLOOKUP($A8,main!$A$3:$H$102,8,FALSE),main!$K$18:$O$18,0))))),1,0) -> 0 | H8: =IF((AND(VLOOKUP(H$1,main!$A$3:$H$102,5,FALSE)-VLOOKUP($A8,main!$A$3:$H$102,6,FALSE)>=(VLOOKUP(VLOOKUP(H$1,main!$A$3:$H$102,8,FALSE),main!$K$26:$M$29,2,FALSE)+VLOOKUP(VLOOKUP(H$1,main!$A$3:$H$102,7,FALSE),main!$K$19:$O$22,MATCH(VLOOKUP($A8,main!$A$3:$H$102,8,FALSE),main!$K$18:$O$18,0))))),1,0) -> 0 | I8: =IF((AND(VLOOKUP(I$1,main!$A$3:$H$102,5,FALSE)-VLOOKUP($A8,main!$A$3:$H$102,6,FALSE)>=(VLOOKUP(VLOOKUP(I$1,main!$A$3:$H$102,8,FALSE),main!$K$26:$M$29,2,FALSE)+VLOOKUP(VLOOKUP(I$1,main!$A$3:$H$102,7,FALSE),main!$K$19:$O$22,MATCH(VLOOKUP($A8,main!$A$3:$H$102,8,FALSE),main!$K$18:$O$18,0))))),1,0) -> 0 | J8: =IF((AND(VLOOKUP(J$1,main!$A$3:$H$102,5,FALSE)-VLOOKUP($A8,main!$A$3:$H$102,6,FALSE)>=(VLOOKUP(VLOOKUP(J$1,main!$A$3:$H$102,8,FALSE),main!$K$26:$M$29,2,FALSE)+VLOOKUP(VLOOKUP(J$1,main!$A$3:$H$102,7,FALSE),main!$K$19:$O$22,MATCH(VLOOKUP($A8,main!$A$3:$H$102,8,FALSE),main!$K$18:$O$18,0))))),1,0) -> 0 | ... CX8: =IF((AND(VLOOKUP(CX$1,main!$A$3:$H$102,5,FALSE)-VLOOKUP($A8,main!$A$3:$H$102,6,FALSE)>=(VLOOKUP(VLOOKUP(CX$1,main!$A$3:$H$102,8,FALSE),main!$K$26:$M$29,2,FALSE)+VLOOKUP(VLOOKUP(CX$1,main!$A$3:$H$102,7,FALSE),main!$K$19:$O$22,MATCH(VLOOKUP($A8,main!$A$3:$H$102,8,FALSE),main!$K$18:$O$18,0))))),1,0) -> 0
A9: 7 | B9: 1 | C9: =IF((AND(VLOOKUP(C$1,main!$A$3:$H$102,5,FALSE)-VLOOKUP($A9,main!$A$3:$H$102,6,FALSE)>=(VLOOKUP(VLOOKUP(C$1,main!$A$3:$H$102,8,FALSE),main!$K$26:$M$29,2,FALSE)+VLOOKUP(VLOOKUP(C$1,main!$A$3:$H$102,7,FALSE),main!$K$19:$O$22,MATCH(VLOOKUP($A9,main!$A$3:$H$102,8,FALSE),main!$K$18:$O$18,0))))),1,0) -> 0 | D9: =IF((AND(VLOOKUP(D$1,main!$A$3:$H$102,5,FALSE)-VLOOKUP($A9,main!$A$3:$H$102,6,FALSE)>=(VLOOKUP(VLOOKUP(D$1,main!$A$3:$H$102,8,FALSE),main!$K$26:$M$29,2,FALSE)+VLOOKUP(VLOOKUP(D$1,main!$A$3:$H$102,7,FALSE),main!$K$19:$O$22,MATCH(VLOOKUP($A9,main!$A$3:$H$102,8,FALSE),main!$K$18:$O$18,0))))),1,0) -> 0 | E9: =IF((AND(VLOOKUP(E$1,main!$A$3:$H$102,5,FALSE)-VLOOKUP($A9,main!$A$3:$H$102,6,FALSE)>=(VLOOKUP(VLOOKUP(E$1,main!$A$3:$H$102,8,FALSE),main!$K$26:$M$29,2,FALSE)+VLOOKUP(VLOOKUP(E$1,main!$A$3:$H$102,7,FALSE),main!$K$19:$O$22,MATCH(VLOOKUP($A9,main!$A$3:$H$102,8,FALSE),main!$K$18:$O$18,0))))),1,0) -> 0 | F9: =IF((AND(VLOOKUP(F$1,main!$A$3:$H$102,5,FALSE)-VLOOKUP($A9,main!$A$3:$H$102,6,FALSE)>=(VLOOKUP(VLOOKUP(F$1,main!$A$3:$H$102,8,FALSE),main!$K$26:$M$29,2,FALSE)+VLOOKUP(VLOOKUP(F$1,main!$A$3:$H$102,7,FALSE),main!$K$19:$O$22,MATCH(VLOOKUP($A9,main!$A$3:$H$102,8,FALSE),main!$K$18:$O$18,0))))),1,0) -> 0 | G9: =IF((AND(VLOOKUP(G$1,main!$A$3:$H$102,5,FALSE)-VLOOKUP($A9,main!$A$3:$H$102,6,FALSE)>=(VLOOKUP(VLOOKUP(G$1,main!$A$3:$H$102,8,FALSE),main!$K$26:$M$29,2,FALSE)+VLOOKUP(VLOOKUP(G$1,main!$A$3:$H$102,7,FALSE),main!$K$19:$O$22,MATCH(VLOOKUP($A9,main!$A$3:$H$102,8,FALSE),main!$K$18:$O$18,0))))),1,0) -> 0 | H9: =IF((AND(VLOOKUP(H$1,main!$A$3:$H$102,5,FALSE)-VLOOKUP($A9,main!$A$3:$H$102,6,FALSE)>=(VLOOKUP(VLOOKUP(H$1,main!$A$3:$H$102,8,FALSE),main!$K$26:$M$29,2,FALSE)+VLOOKUP(VLOOKUP(H$1,main!$A$3:$H$102,7,FALSE),main!$K$19:$O$22,MATCH(VLOOKUP($A9,main!$A$3:$H$102,8,FALSE),main!$K$18:$O$18,0))))),1,0) -> 0 | I9: =IF((AND(VLOOKUP(I$1,main!$A$3:$H$102,5,FALSE)-VLOOKUP($A9,main!$A$3:$H$102,6,FALSE)>=(VLOOKUP(VLOOKUP(I$1,main!$A$3:$H$102,8,FALSE),main!$K$26:$M$29,2,FALSE)+VLOOKUP(VLOOKUP(I$1,main!$A$3:$H$102,7,FALSE),main!$K$19:$O$22,MATCH(VLOOKUP($A9,main!$A$3:$H$102,8,FALSE),main!$K$18:$O$18,0))))),1,0) -> 0 | J9: =IF((AND(VLOOKUP(J$1,main!$A$3:$H$102,5,FALSE)-VLOOKUP($A9,main!$A$3:$H$102,6,FALSE)>=(VLOOKUP(VLOOKUP(J$1,main!$A$3:$H$102,8,FALSE),main!$K$26:$M$29,2,FALSE)+VLOOKUP(VLOOKUP(J$1,main!$A$3:$H$102,7,FALSE),main!$K$19:$O$22,MATCH(VLOOKUP($A9,main!$A$3:$H$102,8,FALSE),main!$K$18:$O$18,0))))),1,0) -> 0 | ... CX9: =IF((AND(VLOOKUP(CX$1,main!$A$3:$H$102,5,FALSE)-VLOOKUP($A9,main!$A$3:$H$102,6,FALSE)>=(VLOOKUP(VLOOKUP(CX$1,main!$A$3:$H$102,8,FALSE),main!$K$26:$M$29,2,FALSE)+VLOOKUP(VLOOKUP(CX$1,main!$A$3:$H$102,7,FALSE),main!$K$19:$O$22,MATCH(VLOOKUP($A9,main!$A$3:$H$102,8,FALSE),main!$K$18:$O$18,0))))),1,0) -> 0
A10: 8 | B10: 1 | C10: =IF((AND(VLOOKUP(C$1,main!$A$3:$H$102,5,FALSE)-VLOOKUP($A10,main!$A$3:$H$102,6,FALSE)>=(VLOOKUP(VLOOKUP(C$1,main!$A$3:$H$102,8,FALSE),main!$K$26:$M$29,2,FALSE)+VLOOKUP(VLOOKUP(C$1,main!$A$3:$H$102,7,FALSE),main!$K$19:$O$22,MATCH(VLOOKUP($A10,main!$A$3:$H$102,8,FALSE),main!$K$18:$O$18,0))))),1,0) -> 0 | D10: =IF((AND(VLOOKUP(D$1,main!$A$3:$H$102,5,FALSE)-VLOOKUP($A10,main!$A$3:$H$102,6,FALSE)>=(VLOOKUP(VLOOKUP(D$1,main!$A$3:$H$102,8,FALSE),main!$K$26:$M$29,2,FALSE)+VLOOKUP(VLOOKUP(D$1,main!$A$3:$H$102,7,FALSE),main!$K$19:$O$22,MATCH(VLOOKUP($A10,main!$A$3:$H$102,8,FALSE),main!$K$18:$O$18,0))))),1,0) -> 0 | E10: =IF((AND(VLOOKUP(E$1,main!$A$3:$H$102,5,FALSE)-VLOOKUP($A10,main!$A$3:$H$102,6,FALSE)>=(VLOOKUP(VLOOKUP(E$1,main!$A$3:$H$102,8,FALSE),main!$K$26:$M$29,2,FALSE)+VLOOKUP(VLOOKUP(E$1,main!$A$3:$H$102,7,FALSE),main!$K$19:$O$22,MATCH(VLOOKUP($A10,main!$A$3:$H$102,8,FALSE),main!$K$18:$O$18,0))))),1,0) -> 0 | F10: =IF((AND(VLOOKUP(F$1,main!$A$3:$H$102,5,FALSE)-VLOOKUP($A10,main!$A$3:$H$102,6,FALSE)>=(VLOOKUP(VLOOKUP(F$1,main!$A$3:$H$102,8,FALSE),main!$K$26:$M$29,2,FALSE)+VLOOKUP(VLOOKUP(F$1,main!$A$3:$H$102,7,FALSE),main!$K$19:$O$22,MATCH(VLOOKUP($A10,main!$A$3:$H$102,8,FALSE),main!$K$18:$O$18,0))))),1,0) -> 0 | G10: =IF((AND(VLOOKUP(G$1,main!$A$3:$H$102,5,FALSE)-VLOOKUP($A10,main!$A$3:$H$102,6,FALSE)>=(VLOOKUP(VLOOKUP(G$1,main!$A$3:$H$102,8,FALSE),main!$K$26:$M$29,2,FALSE)+VLOOKUP(VLOOKUP(G$1,main!$A$3:$H$102,7,FALSE),main!$K$19:$O$22,MATCH(VLOOKUP($A10,main!$A$3:$H$102,8,FALSE),main!$K$18:$O$18,0))))),1,0) -> 0 | H10: =IF((AND(VLOOKUP(H$1,main!$A$3:$H$102,5,FALSE)-VLOOKUP($A10,main!$A$3:$H$102,6,FALSE)>=(VLOOKUP(VLOOKUP(H$1,main!$A$3:$H$102,8,FALSE),main!$K$26:$M$29,2,FALSE)+VLOOKUP(VLOOKUP(H$1,main!$A$3:$H$102,7,FALSE),main!$K$19:$O$22,MATCH(VLOOKUP($A10,main!$A$3:$H$102,8,FALSE),main!$K$18:$O$18,0))))),1,0) -> 0 | I10: =IF((AND(VLOOKUP(I$1,main!$A$3:$H$102,5,FALSE)-VLOOKUP($A10,main!$A$3:$H$102,6,FALSE)>=(VLOOKUP(VLOOKUP(I$1,main!$A$3:$H$102,8,FALSE),main!$K$26:$M$29,2,FALSE)+VLOOKUP(VLOOKUP(I$1,main!$A$3:$H$102,7,FALSE),main!$K$19:$O$22,MATCH(VLOOKUP($A10,main!$A$3:$H$102,8,FALSE),main!$K$18:$O$18,0))))),1,0) -> 0 | J10: =IF((AND(VLOOKUP(J$1,main!$A$3:$H$102,5,FALSE)-VLOOKUP($A10,main!$A$3:$H$102,6,FALSE)>=(VLOOKUP(VLOOKUP(J$1,main!$A$3:$H$102,8,FALSE),main!$K$26:$M$29,2,FALSE)+VLOOKUP(VLOOKUP(J$1,main!$A$3:$H$102,7,FALSE),main!$K$19:$O$22,MATCH(VLOOKUP($A10,main!$A$3:$H$102,8,FALSE),main!$K$18:$O$18,0))))),1,0) -> 0 | ... CX10: =IF((AND(VLOOKUP(CX$1,main!$A$3:$H$102,5,FALSE)-VLOOKUP($A10,main!$A$3:$H$102,6,FALSE)>=(VLOOKUP(VLOOKUP(CX$1,main!$A$3:$H$102,8,FALSE),main!$K$26:$M$29,2,FALSE)+VLOOKUP(VLOOKUP(CX$1,main!$A$3:$H$102,7,FALSE),main!$K$19:$O$22,MATCH(VLOOKUP($A10,main!$A$3:$H$102,8,FALSE),main!$K$18:$O$18,0))))),1,0) -> 0
A11: 9 | B11: 1 | C11: =IF((AND(VLOOKUP(C$1,main!$A$3:$H$102,5,FALSE)-VLOOKUP($A11,main!$A$3:$H$102,6,FALSE)>=(VLOOKUP(VLOOKUP(C$1,main!$A$3:$H$102,8,FALSE),main!$K$26:$M$29,2,FALSE)+VLOOKUP(VLOOKUP(C$1,main!$A$3:$H$102,7,FALSE),main!$K$19:$O$22,MATCH(VLOOKUP($A11,main!$A$3:$H$102,8,FALSE),main!$K$18:$O$18,0))))),1,0) -> 0 | D11: =IF((AND(VLOOKUP(D$1,main!$A$3:$H$102,5,FALSE)-VLOOKUP($A11,main!$A$3:$H$102,6,FALSE)>=(VLOOKUP(VLOOKUP(D$1,main!$A$3:$H$102,8,FALSE),main!$K$26:$M$29,2,FALSE)+VLOOKUP(VLOOKUP(D$1,main!$A$3:$H$102,7,FALSE),main!$K$19:$O$22,MATCH(VLOOKUP($A11,main!$A$3:$H$102,8,FALSE),main!$K$18:$O$18,0))))),1,0) -> 0 | E11: =IF((AND(VLOOKUP(E$1,main!$A$3:$H$102,5,FALSE)-VLOOKUP($A11,main!$A$3:$H$102,6,FALSE)>=(VLOOKUP(VLOOKUP(E$1,main!$A$3:$H$102,8,FALSE),main!$K$26:$M$29,2,FALSE)+VLOOKUP(VLOOKUP(E$1,main!$A$3:$H$102,7,FALSE),main!$K$19:$O$22,MATCH(VLOOKUP($A11,main!$A$3:$H$102,8,FALSE),main!$K$18:$O$18,0))))),1,0) -> 0 | F11: =IF((AND(VLOOKUP(F$1,main!$A$3:$H$102,5,FALSE)-VLOOKUP($A11,main!$A$3:$H$102,6,FALSE)>=(VLOOKUP(VLOOKUP(F$1,main!$A$3:$H$102,8,FALSE),main!$K$26:$M$29,2,FALSE)+VLOOKUP(VLOOKUP(F$1,main!$A$3:$H$102,7,FALSE),main!$K$19:$O$22,MATCH(VLOOKUP($A11,main!$A$3:$H$102,8,FALSE),main!$K$18:$O$18,0))))),1,0) -> 0 | G11: =IF((AND(VLOOKUP(G$1,main!$A$3:$H$102,5,FALSE)-VLOOKUP($A11,main!$A$3:$H$102,6,FALSE)>=(VLOOKUP(VLOOKUP(G$1,main!$A$3:$H$102,8,FALSE),main!$K$26:$M$29,2,FALSE)+VLOOKUP(VLOOKUP(G$1,main!$A$3:$H$102,7,FALSE),main!$K$19:$O$22,MATCH(VLOOKUP($A11,main!$A$3:$H$102,8,FALSE),main!$K$18:$O$18,0))))),1,0) -> 0 | H11: =IF((AND(VLOOKUP(H$1,main!$A$3:$H$102,5,FALSE)-VLOOKUP($A11,main!$A$3:$H$102,6,FALSE)>=(VLOOKUP(VLOOKUP(H$1,main!$A$3:$H$102,8,FALSE),main!$K$26:$M$29,2,FALSE)+VLOOKUP(VLOOKUP(H$1,main!$A$3:$H$102,7,FALSE),main!$K$19:$O$22,MATCH(VLOOKUP($A11,main!$A$3:$H$102,8,FALSE),main!$K$18:$O$18,0))))),1,0) -> 0 | I11: =IF((AND(VLOOKUP(I$1,main!$A$3:$H$102,5,FALSE)-VLOOKUP($A11,main!$A$3:$H$102,6,FALSE)>=(VLOOKUP(VLOOKUP(I$1,main!$A$3:$H$102,8,FALSE),main!$K$26:$M$29,2,FALSE)+VLOOKUP(VLOOKUP(I$1,main!$A$3:$H$102,7,FALSE),main!$K$19:$O$22,MATCH(VLOOKUP($A11,main!$A$3:$H$102,8,FALSE),main!$K$18:$O$18,0))))),1,0) -> 0 | J11: =IF((AND(VLOOKUP(J$1,main!$A$3:$H$102,5,FALSE)-VLOOKUP($A11,main!$A$3:$H$102,6,FALSE)>=(VLOOKUP(VLOOKUP(J$1,main!$A$3:$H$102,8,FALSE),main!$K$26:$M$29,2,FALSE)+VLOOKUP(VLOOKUP(J$1,main!$A$3:$H$102,7,FALSE),main!$K$19:$O$22,MATCH(VLOOKUP($A11,main!$A$3:$H$102,8,FALSE),main!$K$18:$O$18,0))))),1,0) -> 0 | ... CX11: =IF((AND(VLOOKUP(CX$1,main!$A$3:$H$102,5,FALSE)-VLOOKUP($A11,main!$A$3:$H$102,6,FALSE)>=(VLOOKUP(VLOOKUP(CX$1,main!$A$3:$H$102,8,FALSE),main!$K$26:$M$29,2,FALSE)+VLOOKUP(VLOOKUP(CX$1,main!$A$3:$H$102,7,FALSE),main!$K$19:$O$22,MATCH(VLOOKUP($A11,main!$A$3:$H$102,8,FALSE),main!$K$18:$O$18,0))))),1,0) -> 0
A12: 10 | B12: 1 | C12: =IF((AND(VLOOKUP(C$1,main!$A$3:$H$102,5,FALSE)-VLOOKUP($A12,main!$A$3:$H$102,6,FALSE)>=(VLOOKUP(VLOOKUP(C$1,main!$A$3:$H$102,8,FALSE),main!$K$26:$M$29,2,FALSE)+VLOOKUP(VLOOKUP(C$1,main!$A$3:$H$102,7,FALSE),main!$K$19:$O$22,MATCH(VLOOKUP($A12,main!$A$3:$H$102,8,FALSE),main!$K$18:$O$18,0))))),1,0) -> 0 | D12: =IF((AND(VLOOKUP(D$1,main!$A$3:$H$102,5,FALSE)-VLOOKUP($A12,main!$A$3:$H$102,6,FALSE)>=(VLOOKUP(VLOOKUP(D$1,main!$A$3:$H$102,8,FALSE),main!$K$26:$M$29,2,FALSE)+VLOOKUP(VLOOKUP(D$1,main!$A$3:$H$102,7,FALSE),main!$K$19:$O$22,MATCH(VLOOKUP($A12,main!$A$3:$H$102,8,FALSE),main!$K$18:$O$18,0))))),1,0) -> 0 | E12: =IF((AND(VLOOKUP(E$1,main!$A$3:$H$102,5,FALSE)-VLOOKUP($A12,main!$A$3:$H$102,6,FALSE)>=(VLOOKUP(VLOOKUP(E$1,main!$A$3:$H$102,8,FALSE),main!$K$26:$M$29,2,FALSE)+VLOOKUP(VLOOKUP(E$1,main!$A$3:$H$102,7,FALSE),main!$K$19:$O$22,MATCH(VLOOKUP($A12,main!$A$3:$H$102,8,FALSE),main!$K$18:$O$18,0))))),1,0) -> 0 | F12: =IF((AND(VLOOKUP(F$1,main!$A$3:$H$102,5,FALSE)-VLOOKUP($A12,main!$A$3:$H$102,6,FALSE)>=(VLOOKUP(VLOOKUP(F$1,main!$A$3:$H$102,8,FALSE),main!$K$26:$M$29,2,FALSE)+VLOOKUP(VLOOKUP(F$1,main!$A$3:$H$102,7,FALSE),main!$K$19:$O$22,MATCH(VLOOKUP($A12,main!$A$3:$H$102,8,FALSE),main!$K$18:$O$18,0))))),1,0) -> 0 | G12: =IF((AND(VLOOKUP(G$1,main!$A$3:$H$102,5,FALSE)-VLOOKUP($A12,main!$A$3:$H$102,6,FALSE)>=(VLOOKUP(VLOOKUP(G$1,main!$A$3:$H$102,8,FALSE),main!$K$26:$M$29,2,FALSE)+VLOOKUP(VLOOKUP(G$1,main!$A$3:$H$102,7,FALSE),main!$K$19:$O$22,MATCH(VLOOKUP($A12,main!$A$3:$H$102,8,FALSE),main!$K$18:$O$18,0))))),1,0) -> 0 | H12: =IF((AND(VLOOKUP(H$1,main!$A$3:$H$102,5,FALSE)-VLOOKUP($A12,main!$A$3:$H$102,6,FALSE)>=(VLOOKUP(VLOOKUP(H$1,main!$A$3:$H$102,8,FALSE),main!$K$26:$M$29,2,FALSE)+VLOOKUP(VLOOKUP(H$1,main!$A$3:$H$102,7,FALSE),main!$K$19:$O$22,MATCH(VLOOKUP($A12,main!$A$3:$H$102,8,FALSE),main!$K$18:$O$18,0))))),1,0) -> 0 | I12: =IF((AND(VLOOKUP(I$1,main!$A$3:$H$102,5,FALSE)-VLOOKUP($A12,main!$A$3:$H$102,6,FALSE)>=(VLOOKUP(VLOOKUP(I$1,main!$A$3:$H$102,8,FALSE),main!$K$26:$M$29,2,FALSE)+VLOOKUP(VLOOKUP(I$1,main!$A$3:$H$102,7,FALSE),main!$K$19:$O$22,MATCH(VLOOKUP($A12,main!$A$3:$H$102,8,FALSE),main!$K$18:$O$18,0))))),1,0) -> 0 | J12: =IF((AND(VLOOKUP(J$1,main!$A$3:$H$102,5,FALSE)-VLOOKUP($A12,main!$A$3:$H$102,6,FALSE)>=(VLOOKUP(VLOOKUP(J$1,main!$A$3:$H$102,8,FALSE),main!$K$26:$M$29,2,FALSE)+VLOOKUP(VLOOKUP(J$1,main!$A$3:$H$102,7,FALSE),main!$K$19:$O$22,MATCH(VLOOKUP($A12,main!$A$3:$H$102,8,FALSE),main!$K$18:$O$18,0))))),1,0) -> 0 | ... CX12: =IF((AND(VLOOKUP(CX$1,main!$A$3:$H$102,5,FALSE)-VLOOKUP($A12,main!$A$3:$H$102,6,FALSE)>=(VLOOKUP(VLOOKUP(CX$1,main!$A$3:$H$102,8,FALSE),main!$K$26:$M$29,2,FALSE)+VLOOKUP(VLOOKUP(CX$1,main!$A$3:$H$102,7,FALSE),main!$K$19:$O$22,MATCH(VLOOKUP($A12,main!$A$3:$H$102,8,FALSE),main!$K$18:$O$18,0))))),1,0) -> 0
A13: 11 | B13: 1 | C13: =IF((AND(VLOOKUP(C$1,main!$A$3:$H$102,5,FALSE)-VLOOKUP($A13,main!$A$3:$H$102,6,FALSE)>=(VLOOKUP(VLOOKUP(C$1,main!$A$3:$H$102,8,FALSE),main!$K$26:$M$29,2,FALSE)+VLOOKUP(VLOOKUP(C$1,main!$A$3:$H$102,7,FALSE),main!$K$19:$O$22,MATCH(VLOOKUP($A13,main!$A$3:$H$102,8,FALSE),main!$K$18:$O$18,0))))),1,0) -> 0 | D13: =IF((AND(VLOOKUP(D$1,main!$A$3:$H$102,5,FALSE)-VLOOKUP($A13,main!$A$3:$H$102,6,FALSE)>=(VLOOKUP(VLOOKUP(D$1,main!$A$3:$H$102,8,FALSE),main!$K$26:$M$29,2,FALSE)+VLOOKUP(VLOOKUP(D$1,main!$A$3:$H$102,7,FALSE),main!$K$19:$O$22,MATCH(VLOOKUP($A13,main!$A$3:$H$102,8,FALSE),main!$K$18:$O$18,0))))),1,0) -> 0 | E13: =IF((AND(VLOOKUP(E$1,main!$A$3:$H$102,5,FALSE)-VLOOKUP($A13,main!$A$3:$H$102,6,FALSE)>=(VLOOKUP(VLOOKUP(E$1,main!$A$3:$H$102,8,FALSE),main!$K$26:$M$29,2,FALSE)+VLOOKUP(VLOOKUP(E$1,main!$A$3:$H$102,7,FALSE),main!$K$19:$O$22,MATCH(VLOOKUP($A13,main!$A$3:$H$102,8,FALSE),main!$K$18:$O$18,0))))),1,0) -> 0 | F13: =IF((AND(VLOOKUP(F$1,main!$A$3:$H$102,5,FALSE)-VLOOKUP($A13,main!$A$3:$H$102,6,FALSE)>=(VLOOKUP(VLOOKUP(F$1,main!$A$3:$H$102,8,FALSE),main!$K$26:$M$29,2,FALSE)+VLOOKUP(VLOOKUP(F$1,main!$A$3:$H$102,7,FALSE),main!$K$19:$O$22,MATCH(VLOOKUP($A13,main!$A$3:$H$102,8,FALSE),main!$K$18:$O$18,0))))),1,0) -> 1 | G13: =IF((AND(VLOOKUP(G$1,main!$A$3:$H$102,5,FALSE)-VLOOKUP($A13,main!$A$3:$H$102,6,FALSE)>=(VLOOKUP(VLOOKUP(G$1,main!$A$3:$H$102,8,FALSE),main!$K$26:$M$29,2,FALSE)+VLOOKUP(VLOOKUP(G$1,main!$A$3:$H$102,7,FALSE),main!$K$19:$O$22,MATCH(VLOOKUP($A13,main!$A$3:$H$102,8,FALSE),main!$K$18:$O$18,0))))),1,0) -> 1 | H13: =IF((AND(VLOOKUP(H$1,main!$A$3:$H$102,5,FALSE)-VLOOKUP($A13,main!$A$3:$H$102,6,FALSE)>=(VLOOKUP(VLOOKUP(H$1,main!$A$3:$H$102,8,FALSE),main!$K$26:$M$29,2,FALSE)+VLOOKUP(VLOOKUP(H$1,main!$A$3:$H$102,7,FALSE),main!$K$19:$O$22,MATCH(VLOOKUP($A13,main!$A$3:$H$102,8,FALSE),main!$K$18:$O$18,0))))),1,0) -> 1 | I13: =IF((AND(VLOOKUP(I$1,main!$A$3:$H$102,5,FALSE)-VLOOKUP($A13,main!$A$3:$H$102,6,FALSE)>=(VLOOKUP(VLOOKUP(I$1,main!$A$3:$H$102,8,FALSE),main!$K$26:$M$29,2,FALSE)+VLOOKUP(VLOOKUP(I$1,main!$A$3:$H$102,7,FALSE),main!$K$19:$O$22,MATCH(VLOOKUP($A13,main!$A$3:$H$102,8,FALSE),main!$K$18:$O$18,0))))),1,0) -> 1 | J13: =IF((AND(VLOOKUP(J$1,main!$A$3:$H$102,5,FALSE)-VLOOKUP($A13,main!$A$3:$H$102,6,FALSE)>=(VLOOKUP(VLOOKUP(J$1,main!$A$3:$H$102,8,FALSE),main!$K$26:$M$29,2,FALSE)+VLOOKUP(VLOOKUP(J$1,main!$A$3:$H$102,7,FALSE),main!$K$19:$O$22,MATCH(VLOOKUP($A13,main!$A$3:$H$102,8,FALSE),main!$K$18:$O$18,0))))),1,0) -> 1 | ... CX13: =IF((AND(VLOOKUP(CX$1,main!$A$3:$H$102,5,FALSE)-VLOOKUP($A13,main!$A$3:$H$102,6,FALSE)>=(VLOOKUP(VLOOKUP(CX$1,main!$A$3:$H$102,8,FALSE),main!$K$26:$M$29,2,FALSE)+VLOOKUP(VLOOKUP(CX$1,main!$A$3:$H$102,7,FALSE),main!$K$19:$O$22,MATCH(VLOOKUP($A13,main!$A$3:$H$102,8,FALSE),main!$K$18:$O$18,0))))),1,0) -> 1
A14: 12 | B14: 1 | C14: =IF((AND(VLOOKUP(C$1,main!$A$3:$H$102,5,FALSE)-VLOOKUP($A14,main!$A$3:$H$102,6,FALSE)>=(VLOOKUP(VLOOKUP(C$1,main!$A$3:$H$102,8,FALSE),main!$K$26:$M$29,2,FALSE)+VLOOKUP(VLOOKUP(C$1,main!$A$3:$H$102,7,FALSE),main!$K$19:$O$22,MATCH(VLOOKUP($A14,main!$A$3:$H$102,8,FALSE),main!$K$18:$O$18,0))))),1,0) -> 0 | D14: =IF((AND(VLOOKUP(D$1,main!$A$3:$H$102,5,FALSE)-VLOOKUP($A14,main!$A$3:$H$102,6,FALSE)>=(VLOOKUP(VLOOKUP(D$1,main!$A$3:$H$102,8,FALSE),main!$K$26:$M$29,2,FALSE)+VLOOKUP(VLOOKUP(D$1,main!$A$3:$H$102,7,FALSE),main!$K$19:$O$22,MATCH(VLOOKUP($A14,main!$A$3:$H$102,8,FALSE),main!$K$18:$O$18,0))))),1,0) -> 0 | E14: =IF((AND(VLOOKUP(E$1,main!$A$3:$H$102,5,FALSE)-VLOOKUP($A14,main!$A$3:$H$102,6,FALSE)>=(VLOOKUP(VLOOKUP(E$1,main!$A$3:$H$102,8,FALSE),main!$K$26:$M$29,2,FALSE)+VLOOKUP(VLOOKUP(E$1,main!$A$3:$H$102,7,FALSE),main!$K$19:$O$22,MATCH(VLOOKUP($A14,main!$A$3:$H$102,8,FALSE),main!$K$18:$O$18,0))))),1,0) -> 0 | F14: =IF((AND(VLOOKUP(F$1,main!$A$3:$H$102,5,FALSE)-VLOOKUP($A14,main!$A$3:$H$102,6,FALSE)>=(VLOOKUP(VLOOKUP(F$1,main!$A$3:$H$102,8,FALSE),main!$K$26:$M$29,2,FALSE)+VLOOKUP(VLOOKUP(F$1,main!$A$3:$H$102,7,FALSE),main!$K$19:$O$22,MATCH(VLOOKUP($A14,main!$A$3:$H$102,8,FALSE),main!$K$18:$O$18,0))))),1,0) -> 0 | G14: =IF((AND(VLOOKUP(G$1,main!$A$3:$H$102,5,FALSE)-VLOOKUP($A14,main!$A$3:$H$102,6,FALSE)>=(VLOOKUP(VLOOKUP(G$1,main!$A$3:$H$102,8,FALSE),main!$K$26:$M$29,2,FALSE)+VLOOKUP(VLOOKUP(G$1,main!$A$3:$H$102,7,FALSE),main!$K$19:$O$22,MATCH(VLOOKUP($A14,main!$A$3:$H$102,8,FALSE),main!$K$18:$O$18,0))))),1,0) -> 1 | H14: =IF((AND(VLOOKUP(H$1,main!$A$3:$H$102,5,FALSE)-VLOOKUP($A14,main!$A$3:$H$102,6,FALSE)>=(VLOOKUP(VLOOKUP(H$1,main!$A$3:$H$102,8,FALSE),main!$K$26:$M$29,2,FALSE)+VLOOKUP(VLOOKUP(H$1,main!$A$3:$H$102,7,FALSE),main!$K$19:$O$22,MATCH(VLOOKUP($A14,main!$A$3:$H$102,8,FALSE),main!$K$18:$O$18,0))))),1,0) -> 1 | I14: =IF((AND(VLOOKUP(I$1,main!$A$3:$H$102,5,FALSE)-VLOOKUP($A14,main!$A$3:$H$102,6,FALSE)>=(VLOOKUP(VLOOKUP(I$1,main!$A$3:$H$102,8,FALSE),main!$K$26:$M$29,2,FALSE)+VLOOKUP(VLOOKUP(I$1,main!$A$3:$H$102,7,FALSE),main!$K$19:$O$22,MATCH(VLOOKUP($A14,main!$A$3:$H$102,8,FALSE),main!$K$18:$O$18,0))))),1,0) -> 1 | J14: =IF((AND(VLOOKUP(J$1,main!$A$3:$H$102,5,FALSE)-VLOOKUP($A14,main!$A$3:$H$102,6,FALSE)>=(VLOOKUP(VLOOKUP(J$1,main!$A$3:$H$102,8,FALSE),main!$K$26:$M$29,2,FALSE)+VLOOKUP(VLOOKUP(J$1,main!$A$3:$H$102,7,FALSE),main!$K$19:$O$22,MATCH(VLOOKUP($A14,main!$A$3:$H$102,8,FALSE),main!$K$18:$O$18,0))))),1,0) -> 1 | ... CX14: =IF((AND(VLOOKUP(CX$1,main!$A$3:$H$102,5,FALSE)-VLOOKUP($A14,main!$A$3:$H$102,6,FALSE)>=(VLOOKUP(VLOOKUP(CX$1,main!$A$3:$H$102,8,FALSE),main!$K$26:$M$29,2,FALSE)+VLOOKUP(VLOOKUP(CX$1,main!$A$3:$H$102,7,FALSE),main!$K$19:$O$22,MATCH(VLOOKUP($A14,main!$A$3:$H$102,8,FALSE),main!$K$18:$O$18,0))))),1,0) -> 1
... A102: 100 | B102: 1 | C102: =IF((AND(VLOOKUP(C$1,main!$A$3:$H$102,5,FALSE)-VLOOKUP($A102,main!$A$3:$H$102,6,FALSE)>=(VLOOKUP(VLOOKUP(C$1,main!$A$3:$H$102,8,FALSE),main!$K$26:$M$29,2,FALSE)+VLOOKUP(VLOOKUP(C$1,main!$A$3:$H$102,7,FALSE),main!$K$19:$O$22,MATCH(VLOOKUP($A102,main!$A$3:$H$102,8,FALSE),main!$K$18:$O$18,0))))),1,0) -> 0 | D102: =IF((AND(VLOOKUP(D$1,main!$A$3:$H$102,5,FALSE)-VLOOKUP($A102,main!$A$3:$H$102,6,FALSE)>=(VLOOKUP(VLOOKUP(D$1,main!$A$3:$H$102,8,FALSE),main!$K$26:$M$29,2,FALSE)+VLOOKUP(VLOOKUP(D$1,main!$A$3:$H$102,7,FALSE),main!$K$19:$O$22,MATCH(VLOOKUP($A102,main!$A$3:$H$102,8,FALSE),main!$K$18:$O$18,0))))),1,0) -> 0 | E102: =IF((AND(VLOOKUP(E$1,main!$A$3:$H$102,5,FALSE)-VLOOKUP($A102,main!$A$3:$H$102,6,FALSE)>=(VLOOKUP(VLOOKUP(E$1,main!$A$3:$H$102,8,FALSE),main!$K$26:$M$29,2,FALSE)+VLOOKUP(VLOOKUP(E$1,main!$A$3:$H$102,7,FALSE),main!$K$19:$O$22,MATCH(VLOOKUP($A102,main!$A$3:$H$102,8,FALSE),main!$K$18:$O$18,0))))),1,0) -> 0 | F102: =IF((AND(VLOOKUP(F$1,main!$A$3:$H$102,5,FALSE)-VLOOKUP($A102,main!$A$3:$H$102,6,FALSE)>=(VLOOKUP(VLOOKUP(F$1,main!$A$3:$H$102,8,FALSE),main!$K$26:$M$29,2,FALSE)+VLOOKUP(VLOOKUP(F$1,main!$A$3:$H$102,7,FALSE),main!$K$19:$O$22,MATCH(VLOOKUP($A102,main!$A$3:$H$102,8,FALSE),main!$K$18:$O$18,0))))),1,0) -> 0 | G102: =IF((AND(VLOOKUP(G$1,main!$A$3:$H$102,5,FALSE)-VLOOKUP($A102,main!$A$3:$H$102,6,FALSE)>=(VLOOKUP(VLOOKUP(G$1,main!$A$3:$H$102,8,FALSE),main!$K$26:$M$29,2,FALSE)+VLOOKUP(VLOOKUP(G$1,main!$A$3:$H$102,7,FALSE),main!$K$19:$O$22,MATCH(VLOOKUP($A102,main!$A$3:$H$102,8,FALSE),main!$K$18:$O$18,0))))),1,0) -> 0 | H102: =IF((AND(VLOOKUP(H$1,main!$A$3:$H$102,5,FALSE)-VLOOKUP($A102,main!$A$3:$H$102,6,FALSE)>=(VLOOKUP(VLOOKUP(H$1,main!$A$3:$H$102,8,FALSE),main!$K$26:$M$29,2,FALSE)+VLOOKUP(VLOOKUP(H$1,main!$A$3:$H$102,7,FALSE),main!$K$19:$O$22,MATCH(VLOOKUP($A102,main!$A$3:$H$102,8,FALSE),main!$K$18:$O$18,0))))),1,0) -> 0 | I102: =IF((AND(VLOOKUP(I$1,main!$A$3:$H$102,5,FALSE)-VLOOKUP($A102,main!$A$3:$H$102,6,FALSE)>=(VLOOKUP(VLOOKUP(I$1,main!$A$3:$H$102,8,FALSE),main!$K$26:$M$29,2,FALSE)+VLOOKUP(VLOOKUP(I$1,main!$A$3:$H$102,7,FALSE),main!$K$19:$O$22,MATCH(VLOOKUP($A102,main!$A$3:$H$102,8,FALSE),main!$K$18:$O$18,0))))),1,0) -> 0 | J102: =IF((AND(VLOOKUP(J$1,main!$A$3:$H$102,5,FALSE)-VLOOKUP($A102,main!$A$3:$H$102,6,FALSE)>=(VLOOKUP(VLOOKUP(J$1,main!$A$3:$H$102,8,FALSE),main!$K$26:$M$29,2,FALSE)+VLOOKUP(VLOOKUP(J$1,main!$A$3:$H$102,7,FALSE),main!$K$19:$O$22,MATCH(VLOOKUP($A102,main!$A$3:$H$102,8,FALSE),main!$K$18:$O$18,0))))),1,0) -> 0 | ... CX102: =IF((AND(VLOOKUP(CX$1,main!$A$3:$H$102,5,FALSE)-VLOOKUP($A102,main!$A$3:$H$102,6,FALSE)>=(VLOOKUP(VLOOKUP(CX$1,main!$A$3:$H$102,8,FALSE),main!$K$26:$M$29,2,FALSE)+VLOOKUP(VLOOKUP(CX$1,main!$A$3:$H$102,7,FALSE),main!$K$19:$O$22,MATCH(VLOOKUP($A102,main!$A$3:$H$102,8,FALSE),main!$K$18:$O$18,0))))),1,0) -> 0

Sheet delta
B1: 0 | C1: 1 | D1: 2 | E1: 3 | F1: 4 | G1: 5 | H1: 6 | I1: 7 | J1: 8 | K1: 9 | L1: 10 | M1: 11 | N1: 12 | O1: 13 | P1: 14 | Q1: 15 | R1: 16 | S1: 17 | T1: 18 | U1: 19 | V1: 20 | W1: 21 | X1: 22 | Y1: 23 | Z1: 24 | AA1: 25 | AB1: 26 | AC1: 27 | AD1: 28 | AE1: 29 | AF1: 30 | AG1: 31 | AH1: 32 | AI1: 33 | AJ1: 34 | AK1: 35 | AL1: 36 | AM1: 37 | AN1: 38 | AO1: 39 | AP1: 40 | AQ1: 41 | AR1: 42 | AS1: 43 | AT1: 44 | AU1: 45 | AV1: 46 | AW1: 47 | AX1: 48 | AY1: 49 | AZ1: 50 | BA1: 51 | BB1: 52 | BC1: 53 | BD1: 54 | BE1: 55 | BF1: 56 | BG1: 57 | BH1: 58 | BI1: 59 | BJ1: 60 | BK1: 61 | BL1: 62 | BM1: 63 | BN1: 64 | BO1: 65 | BP1: 66 | BQ1: 67 | BR1: 68 | BS1: 69 | BT1: 70 | BU1: 71 | BV1: 72 | BW1: 73 | BX1: 74 | BY1: 75 | BZ1: 76 | CA1: 77 | CB1: 78 | CC1: 79 | CD1: 80 | CE1: 81 | CF1: 82 | CG1: 83 | CH1: 84 | CI1: 85 | CJ1: 86 | CK1: 87 | CL1: 88 | CM1: 89 | CN1: 90 | CO1: 91 | CP1: 92 | CQ1: 93 | CR1: 94 | CS1: 95 | CT1: 96 | CU1: 97 | CV1: 98 | CW1: 99 | CX1: 100 | CY1: 101 | CZ1: 102 | DA1: 103
A2: 0 | B2: 0 | C2: 0 | D2: 0 | E2: 0 | F2: 0 | G2: 0 | H2: 0 | I2: 0 | J2: 0 | K2: 0 | L2: 0 | M2: 0 | N2: 0 | O2: 0 | P2: 0 | Q2: 0 | R2: 0 | S2: 0 | T2: 0 | U2: 0 | V2: 0 | W2: 0 | X2: 0 | Y2: 0 | Z2: 0 | AA2: 0 | AB2: 0 | AC2: 0 | AD2: 0 | AE2: 0 | AF2: 0 | AG2: 0 | AH2: 0 | AI2: 0 | AJ2: 0 | AK2: 0 | AL2: 0 | AM2: 0 | AN2: 0 | AO2: 0 | AP2: 0 | AQ2: 0 | AR2: 0 | AS2: 0 | AT2: 0 | AU2: 0 | AV2: 0 | AW2: 0 | AX2: 0 | AY2: 0 | AZ2: 0 | BA2: 0 | BB2: 0 | BC2: 0 | BD2: 0 | BE2: 0 | BF2: 0 | BG2: 0 | BH2: 0 | BI2: 0 | BJ2: 0 | BK2: 0 | BL2: 0 | BM2: 0 | BN2: 0 | BO2: 0 | BP2: 0 | BQ2: 0 | BR2: 0 | BS2: 0 | BT2: 0 | BU2: 0 | BV2: 0 | BW2: 0 | BX2: 0 | BY2: 0 | BZ2: 0 | CA2: 0 | CB2: 0 | CC2: 0 | CD2: 0 | CE2: 0 | CF2: 0 | CG2: 0 | CH2: 0 | CI2: 0 | CJ2: 0 | CK2: 0 | CL2: 0 | CM2: 0 | CN2: 0 | CO2: 0 | CP2: 0 | CQ2: 0 | CR2: 0 | CS2: 0 | CT2: 0 | CU2: 0 | CV2: 0 | CW2: 0 | CX2: 0 | CY2: 0 | CZ2: 0 | DA2: 0
A3: 1 | B3: 0 | C3: =IF((gamma!C3),IF(VLOOKUP(C$1,main!$A$3:$H$102,7,FALSE)=VLOOKUP($A3,main!$A$3:$H$102,8,FALSE),VLOOKUP(C$1,main!$A$3:$H$102,4,FALSE),VLOOKUP(C$1,main!$A$3:$H$102,4,FALSE)+VLOOKUP($A3,main!$A$3:$H$102,4,FALSE)+(VLOOKUP(VLOOKUP(C$1,main!$A$3:$H$102,8,FALSE),main!$K$19:$O$22,MATCH(VLOOKUP($A3,main!$A$3:$H$102,7,FALSE),main!$K$18:$O$18,0),0))),0) -> 0 | D3: =IF((gamma!D3),IF(VLOOKUP(D$1,main!$A$3:$H$102,7,FALSE)=VLOOKUP($A3,main!$A$3:$H$102,8,FALSE),VLOOKUP(D$1,main!$A$3:$H$102,4,FALSE),VLOOKUP(D$1,main!$A$3:$H$102,4,FALSE)+VLOOKUP($A3,main!$A$3:$H$102,4,FALSE)+(VLOOKUP(VLOOKUP(D$1,main!$A$3:$H$102,8,FALSE),main!$K$19:$O$22,MATCH(VLOOKUP($A3,main!$A$3:$H$102,7,FALSE),main!$K$18:$O$18,0),0))),0) -> 0 | E3: =IF((gamma!E3),IF(VLOOKUP(E$1,main!$A$3:$H$102,7,FALSE)=VLOOKUP($A3,main!$A$3:$H$102,8,FALSE),VLOOKUP(E$1,main!$A$3:$H$102,4,FALSE),VLOOKUP(E$1,main!$A$3:$H$102,4,FALSE)+VLOOKUP($A3,main!$A$3:$H$102,4,FALSE)+(VLOOKUP(VLOOKUP(E$1,main!$A$3:$H$102,8,FALSE),main!$K$19:$O$22,MATCH(VLOOKUP($A3,main!$A$3:$H$102,7,FALSE),main!$K$18:$O$18,0),0))),0) -> 295 | F3: =IF((gamma!F3),IF(VLOOKUP(F$1,main!$A$3:$H$102,7,FALSE)=VLOOKUP($A3,main!$A$3:$H$102,8,FALSE),VLOOKUP(F$1,main!$A$3:$H$102,4,FALSE),VLOOKUP(F$1,main!$A$3:$H$102,4,FALSE)+VLOOKUP($A3,main!$A$3:$H$102,4,FALSE)+(VLOOKUP(VLOOKUP(F$1,main!$A$3:$H$102,8,FALSE),main!$K$19:$O$22,MATCH(VLOOKUP($A3,main!$A$3:$H$102,7,FALSE),main!$K$18:$O$18,0),0))),0) -> 295 | G3: =IF((gamma!G3),IF(VLOOKUP(G$1,main!$A$3:$H$102,7,FALSE)=VLOOKUP($A3,main!$A$3:$H$102,8,FALSE),VLOOKUP(G$1,main!$A$3:$H$102,4,FALSE),VLOOKUP(G$1,main!$A$3:$H$102,4,FALSE)+VLOOKUP($A3,main!$A$3:$H$102,4,FALSE)+(VLOOKUP(VLOOKUP(G$1,main!$A$3:$H$102,8,FALSE),main!$K$19:$O$22,MATCH(VLOOKUP($A3,main!$A$3:$H$102,7,FALSE),main!$K$18:$O$18,0),0))),0) -> 295 | H3: =IF((gamma!H3),IF(VLOOKUP(H$1,main!$A$3:$H$102,7,FALSE)=VLOOKUP($A3,main!$A$3:$H$102,8,FALSE),VLOOKUP(H$1,main!$A$3:$H$102,4,FALSE),VLOOKUP(H$1,main!$A$3:$H$102,4,FALSE)+VLOOKUP($A3,main!$A$3:$H$102,4,FALSE)+(VLOOKUP(VLOOKUP(H$1,main!$A$3:$H$102,8,FALSE),main!$K$19:$O$22,MATCH(VLOOKUP($A3,main!$A$3:$H$102,7,FALSE),main!$K$18:$O$18,0),0))),0) -> 295 | I3: =IF((gamma!I3),IF(VLOOKUP(I$1,main!$A$3:$H$102,7,FALSE)=VLOOKUP($A3,main!$A$3:$H$102,8,FALSE),VLOOKUP(I$1,main!$A$3:$H$102,4,FALSE),VLOOKUP(I$1,main!$A$3:$H$102,4,FALSE)+VLOOKUP($A3,main!$A$3:$H$102,4,FALSE)+(VLOOKUP(VLOOKUP(I$1,main!$A$3:$H$102,8,FALSE),main!$K$19:$O$22,MATCH(VLOOKUP($A3,main!$A$3:$H$102,7,FALSE),main!$K$18:$O$18,0),0))),0) -> 295 | J3: =IF((gamma!J3),IF(VLOOKUP(J$1,main!$A$3:$H$102,7,FALSE)=VLOOKUP($A3,main!$A$3:$H$102,8,FALSE),VLOOKUP(J$1,main!$A$3:$H$102,4,FALSE),VLOOKUP(J$1,main!$A$3:$H$102,4,FALSE)+VLOOKUP($A3,main!$A$3:$H$102,4,FALSE)+(VLOOKUP(VLOOKUP(J$1,main!$A$3:$H$102,8,FALSE),main!$K$19:$O$22,MATCH(VLOOKUP($A3,main!$A$3:$H$102,7,FALSE),main!$K$18:$O$18,0),0))),0) -> 295 | ... CX3: =IF((gamma!CX3),IF(VLOOKUP(CX$1,main!$A$3:$H$102,7,FALSE)=VLOOKUP($A3,main!$A$3:$H$102,8,FALSE),VLOOKUP(CX$1,main!$A$3:$H$102,4,FALSE),VLOOKUP(CX$1,main!$A$3:$H$102,4,FALSE)+VLOOKUP($A3,main!$A$3:$H$102,4,FALSE)+(VLOOKUP(VLOOKUP(CX$1,main!$A$3:$H$102,8,FALSE),main!$K$19:$O$22,MATCH(VLOOKUP($A3,main!$A$3:$H$102,7,FALSE),main!$K$18:$O$18,0),0))),0) -> 250 | CY3: 0 | CZ3: 0 | DA3: 0
A4: 2 | B4: 0 | C4: =IF((gamma!C4),IF(VLOOKUP(C$1,main!$A$3:$H$102,7,FALSE)=VLOOKUP($A4,main!$A$3:$H$102,8,FALSE),VLOOKUP(C$1,main!$A$3:$H$102,4,FALSE),VLOOKUP(C$1,main!$A$3:$H$102,4,FALSE)+VLOOKUP($A4,main!$A$3:$H$102,4,FALSE)+(VLOOKUP(VLOOKUP(C$1,main!$A$3:$H$102,8,FALSE),main!$K$19:$O$22,MATCH(VLOOKUP($A4,main!$A$3:$H$102,7,FALSE),main!$K$18:$O$18,0),0))),0) -> 0 | D4: =IF((gamma!D4),IF(VLOOKUP(D$1,main!$A$3:$H$102,7,FALSE)=VLOOKUP($A4,main!$A$3:$H$102,8,FALSE),VLOOKUP(D$1,main!$A$3:$H$102,4,FALSE),VLOOKUP(D$1,main!$A$3:$H$102,4,FALSE)+VLOOKUP($A4,main!$A$3:$H$102,4,FALSE)+(VLOOKUP(VLOOKUP(D$1,main!$A$3:$H$102,8,FALSE),main!$K$19:$O$22,MATCH(VLOOKUP($A4,main!$A$3:$H$102,7,FALSE),main!$K$18:$O$18,0),0))),0) -> 0 | E4: =IF((gamma!E4),IF(VLOOKUP(E$1,main!$A$3:$H$102,7,FALSE)=VLOOKUP($A4,main!$A$3:$H$102,8,FALSE),VLOOKUP(E$1,main!$A$3:$H$102,4,FALSE),VLOOKUP(E$1,main!$A$3:$H$102,4,FALSE)+VLOOKUP($A4,main!$A$3:$H$102,4,FALSE)+(VLOOKUP(VLOOKUP(E$1,main!$A$3:$H$102,8,FALSE),main!$K$19:$O$22,MATCH(VLOOKUP($A4,main!$A$3:$H$102,7,FALSE),main!$K$18:$O$18,0),0))),0) -> 0 | F4: =IF((gamma!F4),IF(VLOOKUP(F$1,main!$A$3:$H$102,7,FALSE)=VLOOKUP($A4,main!$A$3:$H$102,8,FALSE),VLOOKUP(F$1,main!$A$3:$H$102,4,FALSE),VLOOKUP(F$1,main!$A$3:$H$102,4,FALSE)+VLOOKUP($A4,main!$A$3:$H$102,4,FALSE)+(VLOOKUP(VLOOKUP(F$1,main!$A$3:$H$102,8,FALSE),main!$K$19:$O$22,MATCH(VLOOKUP($A4,main!$A$3:$H$102,7,FALSE),main!$K$18:$O$18,0),0))),0) -> 295 | G4: =IF((gamma!G4),IF(VLOOKUP(G$1,main!$A$3:$H$102,7,FALSE)=VLOOKUP($A4,main!$A$3:$H$102,8,FALSE),VLOOKUP(G$1,main!$A$3:$H$102,4,FALSE),VLOOKUP(G$1,main!$A$3:$H$102,4,FALSE)+VLOOKUP($A4,main!$A$3:$H$102,4,FALSE)+(VLOOKUP(VLOOKUP(G$1,main!$A$3:$H$102,8,FALSE),main!$K$19:$O$22,MATCH(VLOOKUP($A4,main!$A$3:$H$102,7,FALSE),main!$K$18:$O$18,0),0))),0) -> 295 | H4: =IF((gamma!H4),IF(VLOOKUP(H$1,main!$A$3:$H$102,7,FALSE)=VLOOKUP($A4,main!$A$3:$H$102,8,FALSE),VLOOKUP(H$1,main!$A$3:$H$102,4,FALSE),VLOOKUP(H$1,main!$A$3:$H$102,4,FALSE)+VLOOKUP($A4,main!$A$3:$H$102,4,FALSE)+(VLOOKUP(VLOOKUP(H$1,main!$A$3:$H$102,8,FALSE),main!$K$19:$O$22,MATCH(VLOOKUP($A4,main!$A$3:$H$102,7,FALSE),main!$K$18:$O$18,0),0))),0) -> 295 | I4: =IF((gamma!I4),IF(VLOOKUP(I$1,main!$A$3:$H$102,7,FALSE)=VLOOKUP($A4,main!$A$3:$H$102,8,FALSE),VLOOKUP(I$1,main!$A$3:$H$102,4,FALSE),VLOOKUP(I$1,main!$A$3:$H$102,4,FALSE)+VLOOKUP($A4,main!$A$3:$H$102,4,FALSE)+(VLOOKUP(VLOOKUP(I$1,main!$A$3:$H$102,8,FALSE),main!$K$19:$O$22,MATCH(VLOOKUP($A4,main!$A$3:$H$102,7,FALSE),main!$K$18:$O$18,0),0))),0) -> 295 | J4: =IF((gamma!J4),IF(VLOOKUP(J$1,main!$A$3:$H$102,7,FALSE)=VLOOKUP($A4,main!$A$3:$H$102,8,FALSE),VLOOKUP(J$1,main!$A$3:$H$102,4,FALSE),VLOOKUP(J$1,main!$A$3:$H$102,4,FALSE)+VLOOKUP($A4,main!$A$3:$H$102,4,FALSE)+(VLOOKUP(VLOOKUP(J$1,main!$A$3:$H$102,8,FALSE),main!$K$19:$O$22,MATCH(VLOOKUP($A4,main!$A$3:$H$102,7,FALSE),main!$K$18:$O$18,0),0))),0) -> 295 | ... CX4: =IF((gamma!CX4),IF(VLOOKUP(CX$1,main!$A$3:$H$102,7,FALSE)=VLOOKUP($A4,main!$A$3:$H$102,8,FALSE),VLOOKUP(CX$1,main!$A$3:$H$102,4,FALSE),VLOOKUP(CX$1,main!$A$3:$H$102,4,FALSE)+VLOOKUP($A4,main!$A$3:$H$102,4,FALSE)+(VLOOKUP(VLOOKUP(CX$1,main!$A$3:$H$102,8,FALSE),main!$K$19:$O$22,MATCH(VLOOKUP($A4,main!$A$3:$H$102,7,FALSE),main!$K$18:$O$18,0),0))),0) -> 250 | CY4: 0 | CZ4: 0 | DA4: 0
A5: 3 | B5: 0 | C5: =IF((gamma!C5),IF(VLOOKUP(C$1,main!$A$3:$H$102,7,FALSE)=VLOOKUP($A5,main!$A$3:$H$102,8,FALSE),VLOOKUP(C$1,main!$A$3:$H$102,4,FALSE),VLOOKUP(C$1,main!$A$3:$H$102,4,FALSE)+VLOOKUP($A5,main!$A$3:$H$102,4,FALSE)+(VLOOKUP(VLOOKUP(C$1,main!$A$3:$H$102,8,FALSE),main!$K$19:$O$22,MATCH(VLOOKUP($A5,main!$A$3:$H$102,7,FALSE),main!$K$18:$O$18,0),0))),0) -> 0 | D5: =IF((gamma!D5),IF(VLOOKUP(D$1,main!$A$3:$H$102,7,FALSE)=VLOOKUP($A5,main!$A$3:$H$102,8,FALSE),VLOOKUP(D$1,main!$A$3:$H$102,4,FALSE),VLOOKUP(D$1,main!$A$3:$H$102,4,FALSE)+VLOOKUP($A5,main!$A$3:$H$102,4,FALSE)+(VLOOKUP(VLOOKUP(D$1,main!$A$3:$H$102,8,FALSE),main!$K$19:$O$22,MATCH(VLOOKUP($A5,main!$A$3:$H$102,7,FALSE),main!$K$18:$O$18,0),0))),0) -> 0 | E5: =IF((gamma!E5),IF(VLOOKUP(E$1,main!$A$3:$H$102,7,FALSE)=VLOOKUP($A5,main!$A$3:$H$102,8,FALSE),VLOOKUP(E$1,main!$A$3:$H$102,4,FALSE),VLOOKUP(E$1,main!$A$3:$H$102,4,FALSE)+VLOOKUP($A5,main!$A$3:$H$102,4,FALSE)+(VLOOKUP(VLOOKUP(E$1,main!$A$3:$H$102,8,FALSE),main!$K$19:$O$22,MATCH(VLOOKUP($A5,main!$A$3:$H$102,7,FALSE),main!$K$18:$O$18,0),0))),0) -> 0 | F5: =IF((gamma!F5),IF(VLOOKUP(F$1,main!$A$3:$H$102,7,FALSE)=VLOOKUP($A5,main!$A$3:$H$102,8,FALSE),VLOOKUP(F$1,main!$A$3:$H$102,4,FALSE),VLOOKUP(F$1,main!$A$3:$H$102,4,FALSE)+VLOOKUP($A5,main!$A$3:$H$102,4,FALSE)+(VLOOKUP(VLOOKUP(F$1,main!$A$3:$H$102,8,FALSE),main!$K$19:$O$22,MATCH(VLOOKUP($A5,main!$A$3:$H$102,7,FALSE),main!$K$18:$O$18,0),0))),0) -> 0 | G5: =IF((gamma!G5),IF(VLOOKUP(G$1,main!$A$3:$H$102,7,FALSE)=VLOOKUP($A5,main!$A$3:$H$102,8,FALSE),VLOOKUP(G$1,main!$A$3:$H$102,4,FALSE),VLOOKUP(G$1,main!$A$3:$H$102,4,FALSE)+VLOOKUP($A5,main!$A$3:$H$102,4,FALSE)+(VLOOKUP(VLOOKUP(G$1,main!$A$3:$H$102,8,FALSE),main!$K$19:$O$22,MATCH(VLOOKUP($A5,main!$A$3:$H$102,7,FALSE),main!$K$18:$O$18,0),0))),0) -> 0 | H5: =IF((gamma!H5),IF(VLOOKUP(H$1,main!$A$3:$H$102,7,FALSE)=VLOOKUP($A5,main!$A$3:$H$102,8,FALSE),VLOOKUP(H$1,main!$A$3:$H$102,4,FALSE),VLOOKUP(H$1,main!$A$3:$H$102,4,FALSE)+VLOOKUP($A5,main!$A$3:$H$102,4,FALSE)+(VLOOKUP(VLOOKUP(H$1,main!$A$3:$H$102,8,FALSE),main!$K$19:$O$22,MATCH(VLOOKUP($A5,main!$A$3:$H$102,7,FALSE),main!$K$18:$O$18,0),0))),0) -> 295 | I5: =IF((gamma!I5),IF(VLOOKUP(I$1,main!$A$3:$H$102,7,FALSE)=VLOOKUP($A5,main!$A$3:$H$102,8,FALSE),VLOOKUP(I$1,main!$A$3:$H$102,4,FALSE),VLOOKUP(I$1,main!$A$3:$H$102,4,FALSE)+VLOOKUP($A5,main!$A$3:$H$102,4,FALSE)+(VLOOKUP(VLOOKUP(I$1,main!$A$3:$H$102,8,FALSE),main!$K$19:$O$22,MATCH(VLOOKUP($A5,main!$A$3:$H$102,7,FALSE),main!$K$18:$O$18,0),0))),0) -> 295 | J5: =IF((gamma!J5),IF(VLOOKUP(J$1,main!$A$3:$H$102,7,FALSE)=VLOOKUP($A5,main!$A$3:$H$102,8,FALSE),VLOOKUP(J$1,main!$A$3:$H$102,4,FALSE),VLOOKUP(J$1,main!$A$3:$H$102,4,FALSE)+VLOOKUP($A5,main!$A$3:$H$102,4,FALSE)+(VLOOKUP(VLOOKUP(J$1,main!$A$3:$H$102,8,FALSE),main!$K$19:$O$22,MATCH(VLOOKUP($A5,main!$A$3:$H$102,7,FALSE),main!$K$18:$O$18,0),0))),0) -> 295 | ... CX5: =IF((gamma!CX5),IF(VLOOKUP(CX$1,main!$A$3:$H$102,7,FALSE)=VLOOKUP($A5,main!$A$3:$H$102,8,FALSE),VLOOKUP(CX$1,main!$A$3:$H$102,4,FALSE),VLOOKUP(CX$1,main!$A$3:$H$102,4,FALSE)+VLOOKUP($A5,main!$A$3:$H$102,4,FALSE)+(VLOOKUP(VLOOKUP(CX$1,main!$A$3:$H$102,8,FALSE),main!$K$19:$O$22,MATCH(VLOOKUP($A5,main!$A$3:$H$102,7,FALSE),main!$K$18:$O$18,0),0))),0) -> 250 | CY5: 0 | CZ5: 0 | DA5: 0
A6: 4 | B6: 0 | C6: =IF((gamma!C6),IF(VLOOKUP(C$1,main!$A$3:$H$102,7,FALSE)=VLOOKUP($A6,main!$A$3:$H$102,8,FALSE),VLOOKUP(C$1,main!$A$3:$H$102,4,FALSE),VLOOKUP(C$1,main!$A$3:$H$102,4,FALSE)+VLOOKUP($A6,main!$A$3:$H$102,4,FALSE)+(VLOOKUP(VLOOKUP(C$1,main!$A$3:$H$102,8,FALSE),main!$K$19:$O$22,MATCH(VLOOKUP($A6,main!$A$3:$H$102,7,FALSE),main!$K$18:$O$18,0),0))),0) -> 0 | D6: =IF((gamma!D6),IF(VLOOKUP(D$1,main!$A$3:$H$102,7,FALSE)=VLOOKUP($A6,main!$A$3:$H$102,8,FALSE),VLOOKUP(D$1,main!$A$3:$H$102,4,FALSE),VLOOKUP(D$1,main!$A$3:$H$102,4,FALSE)+VLOOKUP($A6,main!$A$3:$H$102,4,FALSE)+(VLOOKUP(VLOOKUP(D$1,main!$A$3:$H$102,8,FALSE),main!$K$19:$O$22,MATCH(VLOOKUP($A6,main!$A$3:$H$102,7,FALSE),main!$K$18:$O$18,0),0))),0) -> 0 | E6: =IF((gamma!E6),IF(VLOOKUP(E$1,main!$A$3:$H$102,7,FALSE)=VLOOKUP($A6,main!$A$3:$H$102,8,FALSE),VLOOKUP(E$1,main!$A$3:$H$102,4,FALSE),VLOOKUP(E$1,main!$A$3:$H$102,4,FALSE)+VLOOKUP($A6,main!$A$3:$H$102,4,FALSE)+(VLOOKUP(VLOOKUP(E$1,main!$A$3:$H$102,8,FALSE),main!$K$19:$O$22,MATCH(VLOOKUP($A6,main!$A$3:$H$102,7,FALSE),main!$K$18:$O$18,0),0))),0) -> 0 | F6: =IF((gamma!F6),IF(VLOOKUP(F$1,main!$A$3:$H$102,7,FALSE)=VLOOKUP($A6,main!$A$3:$H$102,8,FALSE),VLOOKUP(F$1,main!$A$3:$H$102,4,FALSE),VLOOKUP(F$1,main!$A$3:$H$102,4,FALSE)+VLOOKUP($A6,main!$A$3:$H$102,4,FALSE)+(VLOOKUP(VLOOKUP(F$1,main!$A$3:$H$102,8,FALSE),main!$K$19:$O$22,MATCH(VLOOKUP($A6,main!$A$3:$H$102,7,FALSE),main!$K$18:$O$18,0),0))),0) -> 0 | G6: =IF((gamma!G6),IF(VLOOKUP(G$1,main!$A$3:$H$102,7,FALSE)=VLOOKUP($A6,main!$A$3:$H$102,8,FALSE),VLOOKUP(G$1,main!$A$3:$H$102,4,FALSE),VLOOKUP(G$1,main!$A$3:$H$102,4,FALSE)+VLOOKUP($A6,main!$A$3:$H$102,4,FALSE)+(VLOOKUP(VLOOKUP(G$1,main!$A$3:$H$102,8,FALSE),main!$K$19:$O$22,MATCH(VLOOKUP($A6,main!$A$3:$H$102,7,FALSE),main!$K$18:$O$18,0),0))),0) -> 0 | H6: =IF((gamma!H6),IF(VLOOKUP(H$1,main!$A$3:$H$102,7,FALSE)=VLOOKUP($A6,main!$A$3:$H$102,8,FALSE),VLOOKUP(H$1,main!$A$3:$H$102,4,FALSE),VLOOKUP(H$1,main!$A$3:$H$102,4,FALSE)+VLOOKUP($A6,main!$A$3:$H$102,4,FALSE)+(VLOOKUP(VLOOKUP(H$1,main!$A$3:$H$102,8,FALSE),main!$K$19:$O$22,MATCH(VLOOKUP($A6,main!$A$3:$H$102,7,FALSE),main!$K$18:$O$18,0),0))),0) -> 295 | I6: =IF((gamma!I6),IF(VLOOKUP(I$1,main!$A$3:$H$102,7,FALSE)=VLOOKUP($A6,main!$A$3:$H$102,8,FALSE),VLOOKUP(I$1,main!$A$3:$H$102,4,FALSE),VLOOKUP(I$1,main!$A$3:$H$102,4,FALSE)+VLOOKUP($A6,main!$A$3:$H$102,4,FALSE)+(VLOOKUP(VLOOKUP(I$1,main!$A$3:$H$102,8,FALSE),main!$K$19:$O$22,MATCH(VLOOKUP($A6,main!$A$3:$H$102,7,FALSE),main!$K$18:$O$18,0),0))),0) -> 295 | J6: =IF((gamma!J6),IF(VLOOKUP(J$1,main!$A$3:$H$102,7,FALSE)=VLOOKUP($A6,main!$A$3:$H$102,8,FALSE),VLOOKUP(J$1,main!$A$3:$H$102,4,FALSE),VLOOKUP(J$1,main!$A$3:$H$102,4,FALSE)+VLOOKUP($A6,main!$A$3:$H$102,4,FALSE)+(VLOOKUP(VLOOKUP(J$1,main!$A$3:$H$102,8,FALSE),main!$K$19:$O$22,MATCH(VLOOKUP($A6,main!$A$3:$H$102,7,FALSE),main!$K$18:$O$18,0),0))),0) -> 295 | ... CX6: =IF((gamma!CX6),IF(VLOOKUP(CX$1,main!$A$3:$H$102,7,FALSE)=VLOOKUP($A6,main!$A$3:$H$102,8,FALSE),VLOOKUP(CX$1,main!$A$3:$H$102,4,FALSE),VLOOKUP(CX$1,main!$A$3:$H$102,4,FALSE)+VLOOKUP($A6,main!$A$3:$H$102,4,FALSE)+(VLOOKUP(VLOOKUP(CX$1,main!$A$3:$H$102,8,FALSE),main!$K$19:$O$22,MATCH(VLOOKUP($A6,main!$A$3:$H$102,7,FALSE),main!$K$18:$O$18,0),0))),0) -> 250 | CY6: 0 | CZ6: 0 | DA6: 0
