Workbook

Sheet main
A1: ID | B1: name | C1: type | D1: duration | E1: dep_time | F1: arr_time | G1: dep_term | H1: arr_term | I1: ID
A2: 0 | B2: DEPOT | C2: depot | D2: 0 | E2: 0 | F2: 1440 | G2: - | H2: - | I2: 0
A3: 1 | B3: AB1 | C3: trip | D3: 135 | E3: 560 | F3: 695 | G3: Terminal A | H3: Terminal B | I3: 1
A4: 2 | B4: AB2 | C4: trip | D4: 135 | E4: 740 | F4: 875 | G4: Terminal A | H4: Terminal B | I4: 2
A5: 3 | B5: AB3 | C5: trip | D5: 135 | E5: 830 | F5: 965 | G5: Terminal A | H5: Terminal B | I5: 3
A6: 4 | B6: AB4 | C6: trip | D6: 135 | E6: 920 | F6: 1055 | G6: Terminal A | H6: Terminal B | I6: 4
A7: 5 | B7: AB5 | C7: trip | D7: 135 | E7: 980 | F7: 1115 | G7: Terminal A | H7: Terminal B | I7: 5
A8: 6 | B8: AB6 | C8: trip | D8: 135 | E8: 1040 | F8: 1175 | G8: Terminal A | H8: Terminal B | I8: 6 | J8: TMAX | K8: 1355
A9: 7 | B9: AB7 | C9: trip | D9: 135 | E9: 1100 | F9: 1235 | G9: Terminal A | H9: Terminal B | I9: 7
A10: 8 | B10: AB8 | C10: trip | D10: 135 | E10: 1190 | F10: 1325 | G10: Terminal A | H10: Terminal B | I10: 8 | K10: Terminal | L10: Min_Layover | M10: Duration to CS1 | N10: Duration to CS1a | O10: Duration to CS2b | P10: Duration to CS3c | Q10: Duration to CS4d
A11: 9 | B11: AC1 | C11: trip | D11: 140 | E11: 555 | F11: 695 | G11: Terminal A | H11: Terminal C | I11: 9 | K11: Terminal A | L11: 15 | M11: 30 | N11: 10 | O11: 145 | P11: 150 | Q11: 220
A12: 10 | B12: AC2 | C12: trip | D12: 140 | E12: 675 | F12: 815 | G12: Terminal A | H12: Terminal C | I12: 10 | K12: Terminal B | L12: 15 | M12: 30 | N12: 145 | O12: 10 | P12: 155 | Q12: 160
A13: 11 | B13: AC3 | C13: trip | D13: 140 | E13: 795 | F13: 935 | G13: Terminal A | H13: Terminal C | I13: 11 | K13: Terminal C | L13: 15 | M13: 30 | N13: 150 | O13: 155 | P13: 10 | Q13: 280
A14: 12 | B14: AC4 | C14: trip | D14: 140 | E14: 1155 | F14: 1295 | G14: Terminal A | H14: Terminal C | I14: 12 | K14: Terminal D | L14: 15 | M14: 30 | N14: 220 | O14: 160 | P14: 280 | Q14: 10
A15: 13 | B15: AC5 | C15: trip | D15: 140 | E15: 1215 | F15: 1355 | G15: Terminal A | H15: Terminal C | I15: 13 | K15: CS | L15: 100 | M15: (MAX_DURATION == 500, time to recharge = 100 seconds)
A16: 14 | B16: AD1 | C16: trip | D16: 140 | E16: 560 | F16: 700 | G16: Terminal A | H16: Terminal D | I16: 14 | K16: MAX_DURATION | L16: 350
A17: 15 | B17: AD2 | C17: trip | D17: 140 | E17: 630 | F17: 770 | G17: Terminal A | H17: Terminal D | I17: 15
A18: 16 | B18: AD3 | C18: trip | D18: 135 | E18: 790 | F18: 925 | G18: Terminal A | H18: Terminal D | I18: 16 | L18: Terminal A | M18: Terminal B | N18: Terminal C | O18: Terminal D
A19: 17 | B19: AD4 | C19: trip | D19: 140 | E19: 970 | F19: 1110 | G19: Terminal A | H19: Terminal D | I19: 17 | K19: Terminal A | L19: 0 | M19: 25 | N19: 30 | O19: 35
A20: 18 | B20: AD5 | C20: trip | D20: 140 | E20: 1120 | F20: 1240 | G20: Terminal A | H20: Terminal D | I20: 18 | K20: Terminal B | L20: 25 | M20: 0 | N20: 28 | O20: 40
A21: 19 | B21: BA1 | C21: trip | D21: 135 | E21: 540 | F21: 675 | G21: Terminal B | H21: Terminal A | I21: 19 | K21: Terminal C | L21: 30 | M21: 28 | N21: 0 | O21: 33
A22: 20 | B22: BA2 | C22: trip | D22: 135 | E22: 630 | F22: 765 | G22: Terminal B | H22: Terminal A | I22: 20 | K22: Terminal D | L22: 35 | M22: 40 | N22: 33 | O22: 0
A23: 21 | B23: BA3 | C23: trip | D23: 135 | E23: 720 | F23: 855 | G23: Terminal B | H23: Terminal A | I23: 21
A24: 22 | B24: BA4 | C24: trip | D24: 135 | E24: 810 | F24: 945 | G24: Terminal B | H24: Terminal A | I24: 22
A25: 23 | B25: BA5 | C25: trip | D25: 135 | E25: 900 | F25: 1035 | G25: Terminal B | H25: Terminal A | I25: 23
A26: 24 | B26: BA6 | C26: trip | D26: 135 | E26: 990 | F26: 1125 | G26: Terminal B | H26: Terminal A | I26: 24
A27: 25 | B27: BA7 | C27: trip | D27: 135 | E27: 1080 | F27: 1215 | G27: Terminal B | H27: Terminal A | I27: 25
A28: 26 | B28: BA8 | C28: trip | D28: 135 | E28: 1140 | F28: 1275 | G28: Terminal B | H28: Terminal A | I28: 26
A29: 27 | B29: BC1 | C29: trip | D29: 120 | E29: 300 | F29: 420 | G29: Terminal C | H29: Terminal B | I29: 27
A30: 28 | B30: BC2 | C30: trip | D30: 140 | E30: 595 | F30: 735 | G30: Terminal B | H30: Terminal C | I30: 28
A31: 29 | B31: BC3 | C31: trip | D31: 120 | E31: 800 | F31: 920 | G31: Terminal B | H31: Terminal C | I31: 29
A32: 30 | B32: BC4 | C32: trip | D32: 130 | E32: 950 | F32: 1130 | G32: Terminal B | H32: Terminal C | I32: 30
A33: 31 | B33: CA1 | C33: trip | D33: 140 | E33: 570 | F33: 710 | G33: Terminal C | H33: Terminal A | I33: 31
A34: 32 | B34: CA2 | C34: trip | D34: 140 | E34: 740 | F34: 880 | G34: Terminal C | H34: Terminal A | I34: 32
... A61: 59 | B61: CS4d | C61: cs | D61: 50 | E61: 0 | F61: 1440 | G61: - | H61: - | I61: 59

Sheet gamma
B1: 0 | C1: 1 | D1: 2 | E1: 3 | F1: 4 | G1: 5 | H1: 6 | I1: 7 | J1: 8 | K1: 9 | L1: 10 | M1: 11 | N1: 12 | O1: 13 | P1: 14 | Q1: 15 | R1: 16 | S1: 17 | T1: 18 | U1: 19 | V1: 20 | W1: 21 | X1: 22 | Y1: 23 | Z1: 24 | AA1: 25 | AB1: 26 | AC1: 27 | AD1: 28 | AE1: 29 | AF1: 30 | AG1: 31 | AH1: 32 | AI1: 33 | AJ1: 34 | AK1: 35 | AL1: 36 | AM1: 37 | AN1: 38 | AO1: 39 | AP1: 40 | AQ1: 41 | AR1: 42 | AS1: 43 | AT1: 44 | AU1: 45 | AV1: 46 | AW1: 47 | AX1: 48 | AY1: 49 | AZ1: 50 | BA1: 51 | BB1: 52 | BC1: 53 | BD1: 54
A2: 0 | B2: 0 | C2: 1 | D2: 1 | E2: 1 | F2: 1 | G2: 1 | H2: 1 | I2: 1 | J2: 1 | K2: 1 | L2: 1 | M2: 1 | N2: 1 | O2: 1 | P2: 1 | Q2: 1 | R2: 1 | S2: 1 | T2: 1 | U2: 1 | V2: 1 | W2: 1 | X2: 1 | Y2: 1 | Z2: 1 | AA2: 1 | AB2: 1 | AC2: 1 | AD2: 1 | AE2: 1 | AF2: 1 | AG2: 1 | AH2: 1 | AI2: 1 | AJ2: 1 | AK2: 1 | AL2: 1 | AM2: 1 | AN2: 1 | AO2: 1 | AP2: 1 | AQ2: 1 | AR2: 1 | AS2: 1 | AT2: 1 | AU2: 1 | AV2: 1 | AW2: 1 | AX2: 1 | AY2: 1 | AZ2: 1 | BA2: 1 | BB2: 1 | BC2: 1 | BD2: 1
A3: =A2+1 -> 1 | B3: 1 | C3: =IF((AND(VLOOKUP(C$1,main!$A$3:$I$56,5,FALSE)-VLOOKUP($A3,main!$A$3:$I$56,6,FALSE)>=(VLOOKUP(VLOOKUP(C$1,main!$A$3:$I$56,8,FALSE),main!$K$11:$M$14,2,FALSE)+VLOOKUP(VLOOKUP(C$1,main!$A$3:$I$56,7,FALSE),main!$K$19:$O$22,MATCH(VLOOKUP($A3,main!$A$3:$I$56,8,FALSE),main!$K$18:$O$18,0))))),1,0) -> 0 | D3: =IF((AND(VLOOKUP(D$1,main!$A$3:$I$56,5,FALSE)-VLOOKUP($A3,main!$A$3:$I$56,6,FALSE)>=(VLOOKUP(VLOOKUP(D$1,main!$A$3:$I$56,8,FALSE),main!$K$11:$M$14,2,FALSE)+VLOOKUP(VLOOKUP(D$1,main!$A$3:$I$56,7,FALSE),main!$K$19:$O$22,MATCH(VLOOKUP($A3,main!$A$3:$I$56,8,FALSE),main!$K$18:$O$18,0))))),1,0) -> 1 | E3: =IF((AND(VLOOKUP(E$1,main!$A$3:$I$56,5,FALSE)-VLOOKUP($A3,main!$A$3:$I$56,6,FALSE)>=(VLOOKUP(VLOOKUP(E$1,main!$A$3:$I$56,8,FALSE),main!$K$11:$M$14,2,FALSE)+VLOOKUP(VLOOKUP(E$1,main!$A$3:$I$56,7,FALSE),main!$K$19:$O$22,MATCH(VLOOKUP($A3,main!$A$3:$I$56,8,FALSE),main!$K$18:$O$18,0))))),1,0) -> 1 | F3: =IF((AND(VLOOKUP(F$1,main!$A$3:$I$56,5,FALSE)-VLOOKUP($A3,main!$A$3:$I$56,6,FALSE)>=(VLOOKUP(VLOOKUP(F$1,main!$A$3:$I$56,8,FALSE),main!$K$11:$M$14,2,FALSE)+VLOOKUP(VLOOKUP(F$1,main!$A$3:$I$56,7,FALSE),main!$K$19:$O$22,MATCH(VLOOKUP($A3,main!$A$3:$I$56,8,FALSE),main!$K$18:$O$18,0))))),1,0) -> 1 | G3: =IF((AND(VLOOKUP(G$1,main!$A$3:$I$56,5,FALSE)-VLOOKUP($A3,main!$A$3:$I$56,6,FALSE)>=(VLOOKUP(VLOOKUP(G$1,main!$A$3:$I$56,8,FALSE),main!$K$11:$M$14,2,FALSE)+VLOOKUP(VLOOKUP(G$1,main!$A$3:$I$56,7,FALSE),main!$K$19:$O$22,MATCH(VLOOKUP($A3,main!$A$3:$I$56,8,FALSE),main!$K$18:$O$18,0))))),1,0) -> 1 | H3: =IF((AND(VLOOKUP(H$1,main!$A$3:$I$56,5,FALSE)-VLOOKUP($A3,main!$A$3:$I$56,6,FALSE)>=(VLOOKUP(VLOOKUP(H$1,main!$A$3:$I$56,8,FALSE),main!$K$11:$M$14,2,FALSE)+VLOOKUP(VLOOKUP(H$1,main!$A$3:$I$56,7,FALSE),main!$K$19:$O$22,MATCH(VLOOKUP($A3,main!$A$3:$I$56,8,FALSE),main!$K$18:$O$18,0))))),1,0) -> 1 | I3: =IF((AND(VLOOKUP(I$1,main!$A$3:$I$56,5,FALSE)-VLOOKUP($A3,main!$A$3:$I$56,6,FALSE)>=(VLOOKUP(VLOOKUP(I$1,main!$A$3:$I$56,8,FALSE),main!$K$11:$M$14,2,FALSE)+VLOOKUP(VLOOKUP(I$1,main!$A$3:$I$56,7,FALSE),main!$K$19:$O$22,MATCH(VLOOKUP($A3,main!$A$3:$I$56,8,FALSE),main!$K$18:$O$18,0))))),1,0) -> 1 | J3: =IF((AND(VLOOKUP(J$1,main!$A$3:$I$56,5,FALSE)-VLOOKUP($A3,main!$A$3:$I$56,6,FALSE)>=(VLOOKUP(VLOOKUP(J$1,main!$A$3:$I$56,8,FALSE),main!$K$11:$M$14,2,FALSE)+VLOOKUP(VLOOKUP(J$1,main!$A$3:$I$56,7,FALSE),main!$K$19:$O$22,MATCH(VLOOKUP($A3,main!$A$3:$I$56,8,FALSE),main!$K$18:$O$18,0))))),1,0) -> 1 | ... BD3: =IF((AND(VLOOKUP(BD$1,main!$A$3:$I$56,5,FALSE)-VLOOKUP($A3,main!$A$3:$I$56,6,FALSE)>=(VLOOKUP(VLOOKUP(BD$1,main!$A$3:$I$56,8,FALSE),main!$K$11:$M$14,2,FALSE)+VLOOKUP(VLOOKUP(BD$1,main!$A$3:$I$56,7,FALSE),main!$K$19:$O$22,MATCH(VLOOKUP($A3,main!$A$3:$I$56,8,FALSE),main!$K$18:$O$18,0))))),1,0) -> 1
A4: =A3+1 -> 2 | B4: 1 | C4: =IF((AND(VLOOKUP(C$1,main!$A$3:$I$56,5,FALSE)-VLOOKUP($A4,main!$A$3:$I$56,6,FALSE)>=(VLOOKUP(VLOOKUP(C$1,main!$A$3:$I$56,8,FALSE),main!$K$11:$M$14,2,FALSE)+VLOOKUP(VLOOKUP(C$1,main!$A$3:$I$56,7,FALSE),main!$K$19:$O$22,MATCH(VLOOKUP($A4,main!$A$3:$I$56,8,FALSE),main!$K$18:$O$18,0))))),1,0) -> 0 | D4: =IF((AND(VLOOKUP(D$1,main!$A$3:$I$56,5,FALSE)-VLOOKUP($A4,main!$A$3:$I$56,6,FALSE)>=(VLOOKUP(VLOOKUP(D$1,main!$A$3:$I$56,8,FALSE),main!$K$11:$M$14,2,FALSE)+VLOOKUP(VLOOKUP(D$1,main!$A$3:$I$56,7,FALSE),main!$K$19:$O$22,MATCH(VLOOKUP($A4,main!$A$3:$I$56,8,FALSE),main!$K$18:$O$18,0))))),1,0) -> 0 | E4: =IF((AND(VLOOKUP(E$1,main!$A$3:$I$56,5,FALSE)-VLOOKUP($A4,main!$A$3:$I$56,6,FALSE)>=(VLOOKUP(VLOOKUP(E$1,main!$A$3:$I$56,8,FALSE),main!$K$11:$M$14,2,FALSE)+VLOOKUP(VLOOKUP(E$1,main!$A$3:$I$56,7,FALSE),main!$K$19:$O$22,MATCH(VLOOKUP($A4,main!$A$3:$I$56,8,FALSE),main!$K$18:$O$18,0))))),1,0) -> 0 | F4: =IF((AND(VLOOKUP(F$1,main!$A$3:$I$56,5,FALSE)-VLOOKUP($A4,main!$A$3:$I$56,6,FALSE)>=(VLOOKUP(VLOOKUP(F$1,main!$A$3:$I$56,8,FALSE),main!$K$11:$M$14,2,FALSE)+VLOOKUP(VLOOKUP(F$1,main!$A$3:$I$56,7,FALSE),main!$K$19:$O$22,MATCH(VLOOKUP($A4,main!$A$3:$I$56,8,FALSE),main!$K$18:$O$18,0))))),1,0) -> 1 | G4: =IF((AND(VLOOKUP(G$1,main!$A$3:$I$56,5,FALSE)-VLOOKUP($A4,main!$A$3:$I$56,6,FALSE)>=(VLOOKUP(VLOOKUP(G$1,main!$A$3:$I$56,8,FALSE),main!$K$11:$M$14,2,FALSE)+VLOOKUP(VLOOKUP(G$1,main!$A$3:$I$56,7,FALSE),main!$K$19:$O$22,MATCH(VLOOKUP($A4,main!$A$3:$I$56,8,FALSE),main!$K$18:$O$18,0))))),1,0) -> 1 | H4: =IF((AND(VLOOKUP(H$1,main!$A$3:$I$56,5,FALSE)-VLOOKUP($A4,main!$A$3:$I$56,6,FALSE)>=(VLOOKUP(VLOOKUP(H$1,main!$A$3:$I$56,8,FALSE),main!$K$11:$M$14,2,FALSE)+VLOOKUP(VLOOKUP(H$1,main!$A$3:$I$56,7,FALSE),main!$K$19:$O$22,MATCH(VLOOKUP($A4,main!$A$3:$I$56,8,FALSE),main!$K$18:$O$18,0))))),1,0) -> 1 | I4: =IF((AND(VLOOKUP(I$1,main!$A$3:$I$56,5,FALSE)-VLOOKUP($A4,main!$A$3:$I$56,6,FALSE)>=(VLOOKUP(VLOOKUP(I$1,main!$A$3:$I$56,8,FALSE),main!$K$11:$M$14,2,FALSE)+VLOOKUP(VLOOKUP(I$1,main!$A$3:$I$56,7,FALSE),main!$K$19:$O$22,MATCH(VLOOKUP($A4,main!$A$3:$I$56,8,FALSE),main!$K$18:$O$18,0))))),1,0) -> 1 | J4: =IF((AND(VLOOKUP(J$1,main!$A$3:$I$56,5,FALSE)-VLOOKUP($A4,main!$A$3:$I$56,6,FALSE)>=(VLOOKUP(VLOOKUP(J$1,main!$A$3:$I$56,8,FALSE),main!$K$11:$M$14,2,FALSE)+VLOOKUP(VLOOKUP(J$1,main!$A$3:$I$56,7,FALSE),main!$K$19:$O$22,MATCH(VLOOKUP($A4,main!$A$3:$I$56,8,FALSE),main!$K$18:$O$18,0))))),1,0) -> 1 | ... BD4: =IF((AND(VLOOKUP(BD$1,main!$A$3:$I$56,5,FALSE)-VLOOKUP($A4,main!$A$3:$I$56,6,FALSE)>=(VLOOKUP(VLOOKUP(BD$1,main!$A$3:$I$56,8,FALSE),main!$K$11:$M$14,2,FALSE)+VLOOKUP(VLOOKUP(BD$1,main!$A$3:$I$56,7,FALSE),main!$K$19:$O$22,MATCH(VLOOKUP($A4,main!$A$3:$I$56,8,FALSE),main!$K$18:$O$18,0))))),1,0) -> 1
A5: =A4+1 -> 3 | B5: 1 | C5: =IF((AND(VLOOKUP(C$1,main!$A$3:$I$56,5,FALSE)-VLOOKUP($A5,main!$A$3:$I$56,6,FALSE)>=(VLOOKUP(VLOOKUP(C$1,main!$A$3:$I$56,8,FALSE),main!$K$11:$M$14,2,FALSE)+VLOOKUP(VLOOKUP(C$1,main!$A$3:$I$56,7,FALSE),main!$K$19:$O$22,MATCH(VLOOKUP($A5,main!$A$3:$I$56,8,FALSE),main!$K$18:$O$18,0))))),1,0) -> 0 | D5: =IF((AND(VLOOKUP(D$1,main!$A$3:$I$56,5,FALSE)-VLOOKUP($A5,main!$A$3:$I$56,6,FALSE)>=(VLOOKUP(VLOOKUP(D$1,main!$A$3:$I$56,8,FALSE),main!$K$11:$M$14,2,FALSE)+VLOOKUP(VLOOKUP(D$1,main!$A$3:$I$56,7,FALSE),main!$K$19:$O$22,MATCH(VLOOKUP($A5,main!$A$3:$I$56,8,FALSE),main!$K$18:$O$18,0))))),1,0) -> 0 | E5: =IF((AND(VLOOKUP(E$1,main!$A$3:$I$56,5,FALSE)-VLOOKUP($A5,main!$A$3:$I$56,6,FALSE)>=(VLOOKUP(VLOOKUP(E$1,main!$A$3:$I$56,8,FALSE),main!$K$11:$M$14,2,FALSE)+VLOOKUP(VLOOKUP(E$1,main!$A$3:$I$56,7,FALSE),main!$K$19:$O$22,MATCH(VLOOKUP($A5,main!$A$3:$I$56,8,FALSE),main!$K$18:$O$18,0))))),1,0) -> 0 | F5: =IF((AND(VLOOKUP(F$1,main!$A$3:$I$56,5,FALSE)-VLOOKUP($A5,main!$A$3:$I$56,6,FALSE)>=(VLOOKUP(VLOOKUP(F$1,main!$A$3:$I$56,8,FALSE),main!$K$11:$M$14,2,FALSE)+VLOOKUP(VLOOKUP(F$1,main!$A$3:$I$56,7,FALSE),main!$K$19:$O$22,MATCH(VLOOKUP($A5,main!$A$3:$I$56,8,FALSE),main!$K$18:$O$18,0))))),1,0) -> 0 | G5: =IF((AND(VLOOKUP(G$1,main!$A$3:$I$56,5,FALSE)-VLOOKUP($A5,main!$A$3:$I$56,6,FALSE)>=(VLOOKUP(VLOOKUP(G$1,main!$A$3:$I$56,8,FALSE),main!$K$11:$M$14,2,FALSE)+VLOOKUP(VLOOKUP(G$1,main!$A$3:$I$56,7,FALSE),main!$K$19:$O$22,MATCH(VLOOKUP($A5,main!$A$3:$I$56,8,FALSE),main!$K$18:$O$18,0))))),1,0) -> 0 | H5: =IF((AND(VLOOKUP(H$1,main!$A$3:$I$56,5,FALSE)-VLOOKUP($A5,main!$A$3:$I$56,6,FALSE)>=(VLOOKUP(VLOOKUP(H$1,main!$A$3:$I$56,8,FALSE),main!$K$11:$M$14,2,FALSE)+VLOOKUP(VLOOKUP(H$1,main!$A$3:$I$56,7,FALSE),main!$K$19:$O$22,MATCH(VLOOKUP($A5,main!$A$3:$I$56,8,FALSE),main!$K$18:$O$18,0))))),1,0) -> 1 | I5: =IF((AND(VLOOKUP(I$1,main!$A$3:$I$56,5,FALSE)-VLOOKUP($A5,main!$A$3:$I$56,6,FALSE)>=(VLOOKUP(VLOOKUP(I$1,main!$A$3:$I$56,8,FALSE),main!$K$11:$M$14,2,FALSE)+VLOOKUP(VLOOKUP(I$1,main!$A$3:$I$56,7,FALSE),main!$K$19:$O$22,MATCH(VLOOKUP($A5,main!$A$3:$I$56,8,FALSE),main!$K$18:$O$18,0))))),1,0) -> 1 | J5: =IF((AND(VLOOKUP(J$1,main!$A$3:$I$56,5,FALSE)-VLOOKUP($A5,main!$A$3:$I$56,6,FALSE)>=(VLOOKUP(VLOOKUP(J$1,main!$A$3:$I$56,8,FALSE),main!$K$11:$M$14,2,FALSE)+VLOOKUP(VLOOKUP(J$1,main!$A$3:$I$56,7,FALSE),main!$K$19:$O$22,MATCH(VLOOKUP($A5,main!$A$3:$I$56,8,FALSE),main!$K$18:$O$18,0))))),1,0) -> 1 | ... BD5: =IF((AND(VLOOKUP(BD$1,main!$A$3:$I$56,5,FALSE)-VLOOKUP($A5,main!$A$3:$I$56,6,FALSE)>=(VLOOKUP(VLOOKUP(BD$1,main!$A$3:$I$56,8,FALSE),main!$K$11:$M$14,2,FALSE)+VLOOKUP(VLOOKUP(BD$1,main!$A$3:$I$56,7,FALSE),main!$K$19:$O$22,MATCH(VLOOKUP($A5,main!$A$3:$I$56,8,FALSE),main!$K$18:$O$18,0))))),1,0) -> 0
A6: =A5+1 -> 4 | B6: 1 | C6: =IF((AND(VLOOKUP(C$1,main!$A$3:$I$56,5,FALSE)-VLOOKUP($A6,main!$A$3:$I$56,6,FALSE)>=(VLOOKUP(VLOOKUP(C$1,main!$A$3:$I$56,8,FALSE),main!$K$11:$M$14,2,FALSE)+VLOOKUP(VLOOKUP(C$1,main!$A$3:$I$56,7,FALSE),main!$K$19:$O$22,MATCH(VLOOKUP($A6,main!$A$3:$I$56,8,FALSE),main!$K$18:$O$18,0))))),1,0) -> 0 | D6: =IF((AND(VLOOKUP(D$1,main!$A$3:$I$56,5,FALSE)-VLOOKUP($A6,main!$A$3:$I$56,6,FALSE)>=(VLOOKUP(VLOOKUP(D$1,main!$A$3:$I$56,8,FALSE),main!$K$11:$M$14,2,FALSE)+VLOOKUP(VLOOKUP(D$1,main!$A$3:$I$56,7,FALSE),main!$K$19:$O$22,MATCH(VLOOKUP($A6,main!$A$3:$I$56,8,FALSE),main!$K$18:$O$18,0))))),1,0) -> 0 | E6: =IF((AND(VLOOKUP(E$1,main!$A$3:$I$56,5,FALSE)-VLOOKUP($A6,main!$A$3:$I$56,6,FALSE)>=(VLOOKUP(VLOOKUP(E$1,main!$A$3:$I$56,8,FALSE),main!$K$11:$M$14,2,FALSE)+VLOOKUP(VLOOKUP(E$1,main!$A$3:$I$56,7,FALSE),main!$K$19:$O$22,MATCH(VLOOKUP($A6,main!$A$3:$I$56,8,FALSE),main!$K$18:$O$18,0))))),1,0) -> 0 | F6: =IF((AND(VLOOKUP(F$1,main!$A$3:$I$56,5,FALSE)-VLOOKUP($A6,main!$A$3:$I$56,6,FALSE)>=(VLOOKUP(VLOOKUP(F$1,main!$A$3:$I$56,8,FALSE),main!$K$11:$M$14,2,FALSE)+VLOOKUP(VLOOKUP(F$1,main!$A$3:$I$56,7,FALSE),main!$K$19:$O$22,MATCH(VLOOKUP($A6,main!$A$3:$I$56,8,FALSE),main!$K$18:$O$18,0))))),1,0) -> 0 | G6: =IF((AND(VLOOKUP(G$1,main!$A$3:$I$56,5,FALSE)-VLOOKUP($A6,main!$A$3:$I$56,6,FALSE)>=(VLOOKUP(VLOOKUP(G$1,main!$A$3:$I$56,8,FALSE),main!$K$11:$M$14,2,FALSE)+VLOOKUP(VLOOKUP(G$1,main!$A$3:$I$56,7,FALSE),main!$K$19:$O$22,MATCH(VLOOKUP($A6,main!$A$3:$I$56,8,FALSE),main!$K$18:$O$18,0))))),1,0) -> 0 | H6: =IF((AND(VLOOKUP(H$1,main!$A$3:$I$56,5,FALSE)-VLOOKUP($A6,main!$A$3:$I$56,6,FALSE)>=(VLOOKUP(VLOOKUP(H$1,main!$A$3:$I$56,8,FALSE),main!$K$11:$M$14,2,FALSE)+VLOOKUP(VLOOKUP(H$1,main!$A$3:$I$56,7,FALSE),main!$K$19:$O$22,MATCH(VLOOKUP($A6,main!$A$3:$I$56,8,FALSE),main!$K$18:$O$18,0))))),1,0) -> 0 | I6: =IF((AND(VLOOKUP(I$1,main!$A$3:$I$56,5,FALSE)-VLOOKUP($A6,main!$A$3:$I$56,6,FALSE)>=(VLOOKUP(VLOOKUP(I$1,main!$A$3:$I$56,8,FALSE),main!$K$11:$M$14,2,FALSE)+VLOOKUP(VLOOKUP(I$1,main!$A$3:$I$56,7,FALSE),main!$K$19:$O$22,MATCH(VLOOKUP($A6,main!$A$3:$I$56,8,FALSE),main!$K$18:$O$18,0))))),1,0) -> 1 | J6: =IF((AND(VLOOKUP(J$1,main!$A$3:$I$56,5,FALSE)-VLOOKUP($A6,main!$A$3:$I$56,6,FALSE)>=(VLOOKUP(VLOOKUP(J$1,main!$A$3:$I$56,8,FALSE),main!$K$11:$M$14,2,FALSE)+VLOOKUP(VLOOKUP(J$1,main!$A$3:$I$56,7,FALSE),main!$K$19:$O$22,MATCH(VLOOKUP($A6,main!$A$3:$I$56,8,FALSE),main!$K$18:$O$18,0))))),1,0) -> 1 | ... BD6: =IF((AND(VLOOKUP(BD$1,main!$A$3:$I$56,5,FALSE)-VLOOKUP($A6,main!$A$3:$I$56,6,FALSE)>=(VLOOKUP(VLOOKUP(BD$1,main!$A$3:$I$56,8,FALSE),main!$K$11:$M$14,2,FALSE)+VLOOKUP(VLOOKUP(BD$1,main!$A$3:$I$56,7,FALSE),main!$K$19:$O$22,MATCH(VLOOKUP($A6,main!$A$3:$I$56,8,FALSE),main!$K$18:$O$18,0))))),1,0) -> 0
A7: =A6+1 -> 5 | B7: 1 | C7: =IF((AND(VLOOKUP(C$1,main!$A$3:$I$56,5,FALSE)-VLOOKUP($A7,main!$A$3:$I$56,6,FALSE)>=(VLOOKUP(VLOOKUP(C$1,main!$A$3:$I$56,8,FALSE),main!$K$11:$M$14,2,FALSE)+VLOOKUP(VLOOKUP(C$1,main!$A$3:$I$56,7,FALSE),main!$K$19:$O$22,MATCH(VLOOKUP($A7,main!$A$3:$I$56,8,FALSE),main!$K$18:$O$18,0))))),1,0) -> 0 | D7: =IF((AND(VLOOKUP(D$1,main!$A$3:$I$56,5,FALSE)-VLOOKUP($A7,main!$A$3:$I$56,6,FALSE)>=(VLOOKUP(VLOOKUP(D$1,main!$A$3:$I$56,8,FALSE),main!$K$11:$M$14,2,FALSE)+VLOOKUP(VLOOKUP(D$1,main!$A$3:$I$56,7,FALSE),main!$K$19:$O$22,MATCH(VLOOKUP($A7,main!$A$3:$I$56,8,FALSE),main!$K$18:$O$18,0))))),1,0) -> 0 | E7: =IF((AND(VLOOKUP(E$1,main!$A$3:$I$56,5,FALSE)-VLOOKUP($A7,main!$A$3:$I$56,6,FALSE)>=(VLOOKUP(VLOOKUP(E$1,main!$A$3:$I$56,8,FALSE),main!$K$11:$M$14,2,FALSE)+VLOOKUP(VLOOKUP(E$1,main!$A$3:$I$56,7,FALSE),main!$K$19:$O$22,MATCH(VLOOKUP($A7,main!$A$3:$I$56,8,FALSE),main!$K$18:$O$18,0))))),1,0) -> 0 | F7: =IF((AND(VLOOKUP(F$1,main!$A$3:$I$56,5,FALSE)-VLOOKUP($A7,main!$A$3:$I$56,6,FALSE)>=(VLOOKUP(VLOOKUP(F$1,main!$A$3:$I$56,8,FALSE),main!$K$11:$M$14,2,FALSE)+VLOOKUP(VLOOKUP(F$1,main!$A$3:$I$56,7,FALSE),main!$K$19:$O$22,MATCH(VLOOKUP($A7,main!$A$3:$I$56,8,FALSE),main!$K$18:$O$18,0))))),1,0) -> 0 | G7: =IF((AND(VLOOKUP(G$1,main!$A$3:$I$56,5,FALSE)-VLOOKUP($A7,main!$A$3:$I$56,6,FALSE)>=(VLOOKUP(VLOOKUP(G$1,main!$A$3:$I$56,8,FALSE),main!$K$11:$M$14,2,FALSE)+VLOOKUP(VLOOKUP(G$1,main!$A$3:$I$56,7,FALSE),main!$K$19:$O$22,MATCH(VLOOKUP($A7,main!$A$3:$I$56,8,FALSE),main!$K$18:$O$18,0))))),1,0) -> 0 | H7: =IF((AND(VLOOKUP(H$1,main!$A$3:$I$56,5,FALSE)-VLOOKUP($A7,main!$A$3:$I$56,6,FALSE)>=(VLOOKUP(VLOOKUP(H$1,main!$A$3:$I$56,8,FALSE),main!$K$11:$M$14,2,FALSE)+VLOOKUP(VLOOKUP(H$1,main!$A$3:$I$56,7,FALSE),main!$K$19:$O$22,MATCH(VLOOKUP($A7,main!$A$3:$I$56,8,FALSE),main!$K$18:$O$18,0))))),1,0) -> 0 | I7: =IF((AND(VLOOKUP(I$1,main!$A$3:$I$56,5,FALSE)-VLOOKUP($A7,main!$A$3:$I$56,6,FALSE)>=(VLOOKUP(VLOOKUP(I$1,main!$A$3:$I$56,8,FALSE),main!$K$11:$M$14,2,FALSE)+VLOOKUP(VLOOKUP(I$1,main!$A$3:$I$56,7,FALSE),main!$K$19:$O$22,MATCH(VLOOKUP($A7,main!$A$3:$I$56,8,FALSE),main!$K$18:$O$18,0))))),1,0) -> 0 | J7: =IF((AND(VLOOKUP(J$1,main!$A$3:$I$56,5,FALSE)-VLOOKUP($A7,main!$A$3:$I$56,6,FALSE)>=(VLOOKUP(VLOOKUP(J$1,main!$A$3:$I$56,8,FALSE),main!$K$11:$M$14,2,FALSE)+VLOOKUP(VLOOKUP(J$1,main!$A$3:$I$56,7,FALSE),main!$K$19:$O$22,MATCH(VLOOKUP($A7,main!$A$3:$I$56,8,FALSE),main!$K$18:$O$18,0))))),1,0) -> 1 | ... BD7: =IF((AND(VLOOKUP(BD$1,main!$A$3:$I$56,5,FALSE)-VLOOKUP($A7,main!$A$3:$I$56,6,FALSE)>=(VLOOKUP(VLOOKUP(BD$1,main!$A$3:$I$56,8,FALSE),main!$K$11:$M$14,2,FALSE)+VLOOKUP(VLOOKUP(BD$1,main!$A$3:$I$56,7,FALSE),main!$K$19:$O$22,MATCH(VLOOKUP($A7,main!$A$3:$I$56,8,FALSE),main!$K$18:$O$18,0))))),1,0) -> 0
A8: =A7+1 -> 6 | B8: 1 | C8: =IF((AND(VLOOKUP(C$1,main!$A$3:$I$56,5,FALSE)-VLOOKUP($A8,main!$A$3:$I$56,6,FALSE)>=(VLOOKUP(VLOOKUP(C$1,main!$A$3:$I$56,8,FALSE),main!$K$11:$M$14,2,FALSE)+VLOOKUP(VLOOKUP(C$1,main!$A$3:$I$56,7,FALSE),main!$K$19:$O$22,MATCH(VLOOKUP($A8,main!$A$3:$I$56,8,FALSE),main!$K$18:$O$18,0))))),1,0) -> 0 | D8: =IF((AND(VLOOKUP(D$1,main!$A$3:$I$56,5,FALSE)-VLOOKUP($A8,main!$A$3:$I$56,6,FALSE)>=(VLOOKUP(VLOOKUP(D$1,main!$A$3:$I$56,8,FALSE),main!$K$11:$M$14,2,FALSE)+VLOOKUP(VLOOKUP(D$1,main!$A$3:$I$56,7,FALSE),main!$K$19:$O$22,MATCH(VLOOKUP($A8,main!$A$3:$I$56,8,FALSE),main!$K$18:$O$18,0))))),1,0) -> 0 | E8: =IF((AND(VLOOKUP(E$1,main!$A$3:$I$56,5,FALSE)-VLOOKUP($A8,main!$A$3:$I$56,6,FALSE)>=(VLOOKUP(VLOOKUP(E$1,main!$A$3:$I$56,8,FALSE),main!$K$11:$M$14,2,FALSE)+VLOOKUP(VLOOKUP(E$1,main!$A$3:$I$56,7,FALSE),main!$K$19:$O$22,MATCH(VLOOKUP($A8,main!$A$3:$I$56,8,FALSE),main!$K$18:$O$18,0))))),1,0) -> 0 | F8: =IF((AND(VLOOKUP(F$1,main!$A$3:$I$56,5,FALSE)-VLOOKUP($A8,main!$A$3:$I$56,6,FALSE)>=(VLOOKUP(VLOOKUP(F$1,main!$A$3:$I$56,8,FALSE),main!$K$11:$M$14,2,FALSE)+VLOOKUP(VLOOKUP(F$1,main!$A$3:$I$56,7,FALSE),main!$K$19:$O$22,MATCH(VLOOKUP($A8,main!$A$3:$I$56,8,FALSE),main!$K$18:$O$18,0))))),1,0) -> 0 | G8: =IF((AND(VLOOKUP(G$1,main!$A$3:$I$56,5,FALSE)-VLOOKUP($A8,main!$A$3:$I$56,6,FALSE)>=(VLOOKUP(VLOOKUP(G$1,main!$A$3:$I$56,8,FALSE),main!$K$11:$M$14,2,FALSE)+VLOOKUP(VLOOKUP(G$1,main!$A$3:$I$56,7,FALSE),main!$K$19:$O$22,MATCH(VLOOKUP($A8,main!$A$3:$I$56,8,FALSE),main!$K$18:$O$18,0))))),1,0) -> 0 | H8: =IF((AND(VLOOKUP(H$1,main!$A$3:$I$56,5,FALSE)-VLOOKUP($A8,main!$A$3:$I$56,6,FALSE)>=(VLOOKUP(VLOOKUP(H$1,main!$A$3:$I$56,8,FALSE),main!$K$11:$M$14,2,FALSE)+VLOOKUP(VLOOKUP(H$1,main!$A$3:$I$56,7,FALSE),main!$K$19:$O$22,MATCH(VLOOKUP($A8,main!$A$3:$I$56,8,FALSE),main!$K$18:$O$18,0))))),1,0) -> 0 | I8: =IF((AND(VLOOKUP(I$1,main!$A$3:$I$56,5,FALSE)-VLOOKUP($A8,main!$A$3:$I$56,6,FALSE)>=(VLOOKUP(VLOOKUP(I$1,main!$A$3:$I$56,8,FALSE),main!$K$11:$M$14,2,FALSE)+VLOOKUP(VLOOKUP(I$1,main!$A$3:$I$56,7,FALSE),main!$K$19:$O$22,MATCH(VLOOKUP($A8,main!$A$3:$I$56,8,FALSE),main!$K$18:$O$18,0))))),1,0) -> 0 | J8: =IF((AND(VLOOKUP(J$1,main!$A$3:$I$56,5,FALSE)-VLOOKUP($A8,main!$A$3:$I$56,6,FALSE)>=(VLOOKUP(VLOOKUP(J$1,main!$A$3:$I$56,8,FALSE),main!$K$11:$M$14,2,FALSE)+VLOOKUP(VLOOKUP(J$1,main!$A$3:$I$56,7,FALSE),main!$K$19:$O$22,MATCH(VLOOKUP($A8,main!$A$3:$I$56,8,FALSE),main!$K$18:$O$18,0))))),1,0) -> 0 | ... BD8: =IF((AND(VLOOKUP(BD$1,main!$A$3:$I$56,5,FALSE)-VLOOKUP($A8,main!$A$3:$I$56,6,FALSE)>=(VLOOKUP(VLOOKUP(BD$1,main!$A$3:$I$56,8,FALSE),main!$K$11:$M$14,2,FALSE)+VLOOKUP(VLOOKUP(BD$1,main!$A$3:$I$56,7,FALSE),main!$K$19:$O$22,MATCH(VLOOKUP($A8,main!$A$3:$I$56,8,FALSE),main!$K$18:$O$18,0))))),1,0) -> 0
A9: =A8+1 -> 7 | B9: 1 | C9: =IF((AND(VLOOKUP(C$1,main!$A$3:$I$56,5,FALSE)-VLOOKUP($A9,main!$A$3:$I$56,6,FALSE)>=(VLOOKUP(VLOOKUP(C$1,main!$A$3:$I$56,8,FALSE),main!$K$11:$M$14,2,FALSE)+VLOOKUP(VLOOKUP(C$1,main!$A$3:$I$56,7,FALSE),main!$K$19:$O$22,MATCH(VLOOKUP($A9,main!$A$3:$I$56,8,FALSE),main!$K$18:$O$18,0))))),1,0) -> 0 | D9: =IF((AND(VLOOKUP(D$1,main!$A$3:$I$56,5,FALSE)-VLOOKUP($A9,main!$A$3:$I$56,6,FALSE)>=(VLOOKUP(VLOOKUP(D$1,main!$A$3:$I$56,8,FALSE),main!$K$11:$M$14,2,FALSE)+VLOOKUP(VLOOKUP(D$1,main!$A$3:$I$56,7,FALSE),main!$K$19:$O$22,MATCH(VLOOKUP($A9,main!$A$3:$I$56,8,FALSE),main!$K$18:$O$18,0))))),1,0) -> 0 | E9: =IF((AND(VLOOKUP(E$1,main!$A$3:$I$56,5,FALSE)-VLOOKUP($A9,main!$A$3:$I$56,6,FALSE)>=(VLOOKUP(VLOOKUP(E$1,main!$A$3:$I$56,8,FALSE),main!$K$11:$M$14,2,FALSE)+VLOOKUP(VLOOKUP(E$1,main!$A$3:$I$56,7,FALSE),main!$K$19:$O$22,MATCH(VLOOKUP($A9,main!$A$3:$I$56,8,FALSE),main!$K$18:$O$18,0))))),1,0) -> 0 | F9: =IF((AND(VLOOKUP(F$1,main!$A$3:$I$56,5,FALSE)-VLOOKUP($A9,main!$A$3:$I$56,6,FALSE)>=(VLOOKUP(VLOOKUP(F$1,main!$A$3:$I$56,8,FALSE),main!$K$11:$M$14,2,FALSE)+VLOOKUP(VLOOKUP(F$1,main!$A$3:$I$56,7,FALSE),main!$K$19:$O$22,MATCH(VLOOKUP($A9,main!$A$3:$I$56,8,FALSE),main!$K$18:$O$18,0))))),1,0) -> 0 | G9: =IF((AND(VLOOKUP(G$1,main!$A$3:$I$56,5,FALSE)-VLOOKUP($A9,main!$A$3:$I$56,6,FALSE)>=(VLOOKUP(VLOOKUP(G$1,main!$A$3:$I$56,8,FALSE),main!$K$11:$M$14,2,FALSE)+VLOOKUP(VLOOKUP(G$1,main!$A$3:$I$56,7,FALSE),main!$K$19:$O$22,MATCH(VLOOKUP($A9,main!$A$3:$I$56,8,FALSE),main!$K$18:$O$18,0))))),1,0) -> 0 | H9: =IF((AND(VLOOKUP(H$1,main!$A$3:$I$56,5,FALSE)-VLOOKUP($A9,main!$A$3:$I$56,6,FALSE)>=(VLOOKUP(VLOOKUP(H$1,main!$A$3:$I$56,8,FALSE),main!$K$11:$M$14,2,FALSE)+VLOOKUP(VLOOKUP(H$1,main!$A$3:$I$56,7,FALSE),main!$K$19:$O$22,MATCH(VLOOKUP($A9,main!$A$3:$I$56,8,FALSE),main!$K$18:$O$18,0))))),1,0) -> 0 | I9: =IF((AND(VLOOKUP(I$1,main!$A$3:$I$56,5,FALSE)-VLOOKUP($A9,main!$A$3:$I$56,6,FALSE)>=(VLOOKUP(VLOOKUP(I$1,main!$A$3:$I$56,8,FALSE),main!$K$11:$M$14,2,FALSE)+VLOOKUP(VLOOKUP(I$1,main!$A$3:$I$56,7,FALSE),main!$K$19:$O$22,MATCH(VLOOKUP($A9,main!$A$3:$I$56,8,FALSE),main!$K$18:$O$18,0))))),1,0) -> 0 | J9: =IF((AND(VLOOKUP(J$1,main!$A$3:$I$56,5,FALSE)-VLOOKUP($A9,main!$A$3:$I$56,6,FALSE)>=(VLOOKUP(VLOOKUP(J$1,main!$A$3:$I$56,8,FALSE),main!$K$11:$M$14,2,FALSE)+VLOOKUP(VLOOKUP(J$1,main!$A$3:$I$56,7,FALSE),main!$K$19:$O$22,MATCH(VLOOKUP($A9,main!$A$3:$I$56,8,FALSE),main!$K$18:$O$18,0))))),1,0) -> 0 | ... BD9: =IF((AND(VLOOKUP(BD$1,main!$A$3:$I$56,5,FALSE)-VLOOKUP($A9,main!$A$3:$I$56,6,FALSE)>=(VLOOKUP(VLOOKUP(BD$1,main!$A$3:$I$56,8,FALSE),main!$K$11:$M$14,2,FALSE)+VLOOKUP(VLOOKUP(BD$1,main!$A$3:$I$56,7,FALSE),main!$K$19:$O$22,MATCH(VLOOKUP($A9,main!$A$3:$I$56,8,FALSE),main!$K$18:$O$18,0))))),1,0) -> 0
A10: =A9+1 -> 8 | B10: 1 | C10: =IF((AND(VLOOKUP(C$1,main!$A$3:$I$56,5,FALSE)-VLOOKUP($A10,main!$A$3:$I$56,6,FALSE)>=(VLOOKUP(VLOOKUP(C$1,main!$A$3:$I$56,8,FALSE),main!$K$11:$M$14,2,FALSE)+VLOOKUP(VLOOKUP(C$1,main!$A$3:$I$56,7,FALSE),main!$K$19:$O$22,MATCH(VLOOKUP($A10,main!$A$3:$I$56,8,FALSE),main!$K$18:$O$18,0))))),1,0) -> 0 | D10: =IF((AND(VLOOKUP(D$1,main!$A$3:$I$56,5,FALSE)-VLOOKUP($A10,main!$A$3:$I$56,6,FALSE)>=(VLOOKUP(VLOOKUP(D$1,main!$A$3:$I$56,8,FALSE),main!$K$11:$M$14,2,FALSE)+VLOOKUP(VLOOKUP(D$1,main!$A$3:$I$56,7,FALSE),main!$K$19:$O$22,MATCH(VLOOKUP($A10,main!$A$3:$I$56,8,FALSE),main!$K$18:$O$18,0))))),1,0) -> 0 | E10: =IF((AND(VLOOKUP(E$1,main!$A$3:$I$56,5,FALSE)-VLOOKUP($A10,main!$A$3:$I$56,6,FALSE)>=(VLOOKUP(VLOOKUP(E$1,main!$A$3:$I$56,8,FALSE),main!$K$11:$M$14,2,FALSE)+VLOOKUP(VLOOKUP(E$1,main!$A$3:$I$56,7,FALSE),main!$K$19:$O$22,MATCH(VLOOKUP($A10,main!$A$3:$I$56,8,FALSE),main!$K$18:$O$18,0))))),1,0) -> 0 | F10: =IF((AND(VLOOKUP(F$1,main!$A$3:$I$56,5,FALSE)-VLOOKUP($A10,main!$A$3:$I$56,6,FALSE)>=(VLOOKUP(VLOOKUP(F$1,main!$A$3:$I$56,8,FALSE),main!$K$11:$M$14,2,FALSE)+VLOOKUP(VLOOKUP(F$1,main!$A$3:$I$56,7,FALSE),main!$K$19:$O$22,MATCH(VLOOKUP($A10,main!$A$3:$I$56,8,FALSE),main!$K$18:$O$18,0))))),1,0) -> 0 | G10: =IF((AND(VLOOKUP(G$1,main!$A$3:$I$56,5,FALSE)-VLOOKUP($A10,main!$A$3:$I$56,6,FALSE)>=(VLOOKUP(VLOOKUP(G$1,main!$A$3:$I$56,8,FALSE),main!$K$11:$M$14,2,FALSE)+VLOOKUP(VLOOKUP(G$1,main!$A$3:$I$56,7,FALSE),main!$K$19:$O$22,MATCH(VLOOKUP($A10,main!$A$3:$I$56,8,FALSE),main!$K$18:$O$18,0))))),1,0) -> 0 | H10: =IF((AND(VLOOKUP(H$1,main!$A$3:$I$56,5,FALSE)-VLOOKUP($A10,main!$A$3:$I$56,6,FALSE)>=(VLOOKUP(VLOOKUP(H$1,main!$A$3:$I$56,8,FALSE),main!$K$11:$M$14,2,FALSE)+VLOOKUP(VLOOKUP(H$1,main!$A$3:$I$56,7,FALSE),main!$K$19:$O$22,MATCH(VLOOKUP($A10,main!$A$3:$I$56,8,FALSE),main!$K$18:$O$18,0))))),1,0) -> 0 | I10: =IF((AND(VLOOKUP(I$1,main!$A$3:$I$56,5,FALSE)-VLOOKUP($A10,main!$A$3:$I$56,6,FALSE)>=(VLOOKUP(VLOOKUP(I$1,main!$A$3:$I$56,8,FALSE),main!$K$11:$M$14,2,FALSE)+VLOOKUP(VLOOKUP(I$1,main!$A$3:$I$56,7,FALSE),main!$K$19:$O$22,MATCH(VLOOKUP($A10,main!$A$3:$I$56,8,FALSE),main!$K$18:$O$18,0))))),1,0) -> 0 | J10: =IF((AND(VLOOKUP(J$1,main!$A$3:$I$56,5,FALSE)-VLOOKUP($A10,main!$A$3:$I$56,6,FALSE)>=(VLOOKUP(VLOOKUP(J$1,main!$A$3:$I$56,8,FALSE),main!$K$11:$M$14,2,FALSE)+VLOOKUP(VLOOKUP(J$1,main!$A$3:$I$56,7,FALSE),main!$K$19:$O$22,MATCH(VLOOKUP($A10,main!$A$3:$I$56,8,FALSE),main!$K$18:$O$18,0))))),1,0) -> 0 | ... BD10: =IF((AND(VLOOKUP(BD$1,main!$A$3:$I$56,5,FALSE)-VLOOKUP($A10,main!$A$3:$I$56,6,FALSE)>=(VLOOKUP(VLOOKUP(BD$1,main!$A$3:$I$56,8,FALSE),main!$K$11:$M$14,2,FALSE)+VLOOKUP(VLOOKUP(BD$1,main!$A$3:$I$56,7,FALSE),main!$K$19:$O$22,MATCH(VLOOKUP($A10,main!$A$3:$I$56,8,FALSE),main!$K$18:$O$18,0))))),1,0) -> 0
A11: =A10+1 -> 9 | B11: 1 | C11: =IF((AND(VLOOKUP(C$1,main!$A$3:$I$56,5,FALSE)-VLOOKUP($A11,main!$A$3:$I$56,6,FALSE)>=(VLOOKUP(VLOOKUP(C$1,main!$A$3:$I$56,8,FALSE),main!$K$11:$M$14,2,FALSE)+VLOOKUP(VLOOKUP(C$1,main!$A$3:$I$56,7,FALSE),main!$K$19:$O$22,MATCH(VLOOKUP($A11,main!$A$3:$I$56,8,FALSE),main!$K$18:$O$18,0))))),1,0) -> 0 | D11: =IF((AND(VLOOKUP(D$1,main!$A$3:$I$56,5,FALSE)-VLOOKUP($A11,main!$A$3:$I$56,6,FALSE)>=(VLOOKUP(VLOOKUP(D$1,main!$A$3:$I$56,8,FALSE),main!$K$11:$M$14,2,FALSE)+VLOOKUP(VLOOKUP(D$1,main!$A$3:$I$56,7,FALSE),main!$K$19:$O$22,MATCH(VLOOKUP($A11,main!$A$3:$I$56,8,FALSE),main!$K$18:$O$18,0))))),1,0) -> 1 | E11: =IF((AND(VLOOKUP(E$1,main!$A$3:$I$56,5,FALSE)-VLOOKUP($A11,main!$A$3:$I$56,6,FALSE)>=(VLOOKUP(VLOOKUP(E$1,main!$A$3:$I$56,8,FALSE),main!$K$11:$M$14,2,FALSE)+VLOOKUP(VLOOKUP(E$1,main!$A$3:$I$56,7,FALSE),main!$K$19:$O$22,MATCH(VLOOKUP($A11,main!$A$3:$I$56,8,FALSE),main!$K$18:$O$18,0))))),1,0) -> 1 | F11: =IF((AND(VLOOKUP(F$1,main!$A$3:$I$56,5,FALSE)-VLOOKUP($A11,main!$A$3:$I$56,6,FALSE)>=(VLOOKUP(VLOOKUP(F$1,main!$A$3:$I$56,8,FALSE),main!$K$11:$M$14,2,FALSE)+VLOOKUP(VLOOKUP(F$1,main!$A$3:$I$56,7,FALSE),main!$K$19:$O$22,MATCH(VLOOKUP($A11,main!$A$3:$I$56,8,FALSE),main!$K$18:$O$18,0))))),1,0) -> 1 | G11: =IF((AND(VLOOKUP(G$1,main!$A$3:$I$56,5,FALSE)-VLOOKUP($A11,main!$A$3:$I$56,6,FALSE)>=(VLOOKUP(VLOOKUP(G$1,main!$A$3:$I$56,8,FALSE),main!$K$11:$M$14,2,FALSE)+VLOOKUP(VLOOKUP(G$1,main!$A$3:$I$56,7,FALSE),main!$K$19:$O$22,MATCH(VLOOKUP($A11,main!$A$3:$I$56,8,FALSE),main!$K$18:$O$18,0))))),1,0) -> 1 | H11: =IF((AND(VLOOKUP(H$1,main!$A$3:$I$56,5,FALSE)-VLOOKUP($A11,main!$A$3:$I$56,6,FALSE)>=(VLOOKUP(VLOOKUP(H$1,main!$A$3:$I$56,8,FALSE),main!$K$11:$M$14,2,FALSE)+VLOOKUP(VLOOKUP(H$1,main!$A$3:$I$56,7,FALSE),main!$K$19:$O$22,MATCH(VLOOKUP($A11,main!$A$3:$I$56,8,FALSE),main!$K$18:$O$18,0))))),1,0) -> 1 | I11: =IF((AND(VLOOKUP(I$1,main!$A$3:$I$56,5,FALSE)-VLOOKUP($A11,main!$A$3:$I$56,6,FALSE)>=(VLOOKUP(VLOOKUP(I$1,main!$A$3:$I$56,8,FALSE),main!$K$11:$M$14,2,FALSE)+VLOOKUP(VLOOKUP(I$1,main!$A$3:$I$56,7,FALSE),main!$K$19:$O$22,MATCH(VLOOKUP($A11,main!$A$3:$I$56,8,FALSE),main!$K$18:$O$18,0))))),1,0) -> 1 | J11: =IF((AND(VLOOKUP(J$1,main!$A$3:$I$56,5,FALSE)-VLOOKUP($A11,main!$A$3:$I$56,6,FALSE)>=(VLOOKUP(VLOOKUP(J$1,main!$A$3:$I$56,8,FALSE),main!$K$11:$M$14,2,FALSE)+VLOOKUP(VLOOKUP(J$1,main!$A$3:$I$56,7,FALSE),main!$K$19:$O$22,MATCH(VLOOKUP($A11,main!$A$3:$I$56,8,FALSE),main!$K$18:$O$18,0))))),1,0) -> 1 | ... BD11: =IF((AND(VLOOKUP(BD$1,main!$A$3:$I$56,5,FALSE)-VLOOKUP($A11,main!$A$3:$I$56,6,FALSE)>=(VLOOKUP(VLOOKUP(BD$1,main!$A$3:$I$56,8,FALSE),main!$K$11:$M$14,2,FALSE)+VLOOKUP(VLOOKUP(BD$1,main!$A$3:$I$56,7,FALSE),main!$K$19:$O$22,MATCH(VLOOKUP($A11,main!$A$3:$I$56,8,FALSE),main!$K$18:$O$18,0))))),1,0) -> 1
A12: =A11+1 -> 10 | B12: 1 | C12: =IF((AND(VLOOKUP(C$1,main!$A$3:$I$56,5,FALSE)-VLOOKUP($A12,main!$A$3:$I$56,6,FALSE)>=(VLOOKUP(VLOOKUP(C$1,main!$A$3:$I$56,8,FALSE),main!$K$11:$M$14,2,FALSE)+VLOOKUP(VLOOKUP(C$1,main!$A$3:$I$56,7,FALSE),main!$K$19:$O$22,MATCH(VLOOKUP($A12,main!$A$3:$I$56,8,FALSE),main!$K$18:$O$18,0))))),1,0) -> 0 | D12: =IF((AND(VLOOKUP(D$1,main!$A$3:$I$56,5,FALSE)-VLOOKUP($A12,main!$A$3:$I$56,6,FALSE)>=(VLOOKUP(VLOOKUP(D$1,main!$A$3:$I$56,8,FALSE),main!$K$11:$M$14,2,FALSE)+VLOOKUP(VLOOKUP(D$1,main!$A$3:$I$56,7,FALSE),main!$K$19:$O$22,MATCH(VLOOKUP($A12,main!$A$3:$I$56,8,FALSE),main!$K$18:$O$18,0))))),1,0) -> 0 | E12: =IF((AND(VLOOKUP(E$1,main!$A$3:$I$56,5,FALSE)-VLOOKUP($A12,main!$A$3:$I$56,6,FALSE)>=(VLOOKUP(VLOOKUP(E$1,main!$A$3:$I$56,8,FALSE),main!$K$11:$M$14,2,FALSE)+VLOOKUP(VLOOKUP(E$1,main!$A$3:$I$56,7,FALSE),main!$K$19:$O$22,MATCH(VLOOKUP($A12,main!$A$3:$I$56,8,FALSE),main!$K$18:$O$18,0))))),1,0) -> 0 | F12: =IF((AND(VLOOKUP(F$1,main!$A$3:$I$56,5,FALSE)-VLOOKUP($A12,main!$A$3:$I$56,6,FALSE)>=(VLOOKUP(VLOOKUP(F$1,main!$A$3:$I$56,8,FALSE),main!$K$11:$M$14,2,FALSE)+VLOOKUP(VLOOKUP(F$1,main!$A$3:$I$56,7,FALSE),main!$K$19:$O$22,MATCH(VLOOKUP($A12,main!$A$3:$I$56,8,FALSE),main!$K$18:$O$18,0))))),1,0) -> 1 | G12: =IF((AND(VLOOKUP(G$1,main!$A$3:$I$56,5,FALSE)-VLOOKUP($A12,main!$A$3:$I$56,6,FALSE)>=(VLOOKUP(VLOOKUP(G$1,main!$A$3:$I$56,8,FALSE),main!$K$11:$M$14,2,FALSE)+VLOOKUP(VLOOKUP(G$1,main!$A$3:$I$56,7,FALSE),main!$K$19:$O$22,MATCH(VLOOKUP($A12,main!$A$3:$I$56,8,FALSE),main!$K$18:$O$18,0))))),1,0) -> 1 | H12: =IF((AND(VLOOKUP(H$1,main!$A$3:$I$56,5,FALSE)-VLOOKUP($A12,main!$A$3:$I$56,6,FALSE)>=(VLOOKUP(VLOOKUP(H$1,main!$A$3:$I$56,8,FALSE),main!$K$11:$M$14,2,FALSE)+VLOOKUP(VLOOKUP(H$1,main!$A$3:$I$56,7,FALSE),main!$K$19:$O$22,MATCH(VLOOKUP($A12,main!$A$3:$I$56,8,FALSE),main!$K$18:$O$18,0))))),1,0) -> 1 | I12: =IF((AND(VLOOKUP(I$1,main!$A$3:$I$56,5,FALSE)-VLOOKUP($A12,main!$A$3:$I$56,6,FALSE)>=(VLOOKUP(VLOOKUP(I$1,main!$A$3:$I$56,8,FALSE),main!$K$11:$M$14,2,FALSE)+VLOOKUP(VLOOKUP(I$1,main!$A$3:$I$56,7,FALSE),main!$K$19:$O$22,MATCH(VLOOKUP($A12,main!$A$3:$I$56,8,FALSE),main!$K$18:$O$18,0))))),1,0) -> 1 | J12: =IF((AND(VLOOKUP(J$1,main!$A$3:$I$56,5,FALSE)-VLOOKUP($A12,main!$A$3:$I$56,6,FALSE)>=(VLOOKUP(VLOOKUP(J$1,main!$A$3:$I$56,8,FALSE),main!$K$11:$M$14,2,FALSE)+VLOOKUP(VLOOKUP(J$1,main!$A$3:$I$56,7,FALSE),main!$K$19:$O$22,MATCH(VLOOKUP($A12,main!$A$3:$I$56,8,FALSE),main!$K$18:$O$18,0))))),1,0) -> 1 | ... BD12: =IF((AND(VLOOKUP(BD$1,main!$A$3:$I$56,5,FALSE)-VLOOKUP($A12,main!$A$3:$I$56,6,FALSE)>=(VLOOKUP(VLOOKUP(BD$1,main!$A$3:$I$56,8,FALSE),main!$K$11:$M$14,2,FALSE)+VLOOKUP(VLOOKUP(BD$1,main!$A$3:$I$56,7,FALSE),main!$K$19:$O$22,MATCH(VLOOKUP($A12,main!$A$3:$I$56,8,FALSE),main!$K$18:$O$18,0))))),1,0) -> 1
A13: =A12+1 -> 11 | B13: 1 | C13: =IF((AND(VLOOKUP(C$1,main!$A$3:$I$56,5,FALSE)-VLOOKUP($A13,main!$A$3:$I$56,6,FALSE)>=(VLOOKUP(VLOOKUP(C$1,main!$A$3:$I$56,8,FALSE),main!$K$11:$M$14,2,FALSE)+VLOOKUP(VLOOKUP(C$1,main!$A$3:$I$56,7,FALSE),main!$K$19:$O$22,MATCH(VLOOKUP($A13,main!$A$3:$I$56,8,FALSE),main!$K$18:$O$18,0))))),1,0) -> 0 | D13: =IF((AND(VLOOKUP(D$1,main!$A$3:$I$56,5,FALSE)-VLOOKUP($A13,main!$A$3:$I$56,6,FALSE)>=(VLOOKUP(VLOOKUP(D$1,main!$A$3:$I$56,8,FALSE),main!$K$11:$M$14,2,FALSE)+VLOOKUP(VLOOKUP(D$1,main!$A$3:$I$56,7,FALSE),main!$K$19:$O$22,MATCH(VLOOKUP($A13,main!$A$3:$I$56,8,FALSE),main!$K$18:$O$18,0))))),1,0) -> 0 | E13: =IF((AND(VLOOKUP(E$1,main!$A$3:$I$56,5,FALSE)-VLOOKUP($A13,main!$A$3:$I$56,6,FALSE)>=(VLOOKUP(VLOOKUP(E$1,main!$A$3:$I$56,8,FALSE),main!$K$11:$M$14,2,FALSE)+VLOOKUP(VLOOKUP(E$1,main!$A$3:$I$56,7,FALSE),main!$K$19:$O$22,MATCH(VLOOKUP($A13,main!$A$3:$I$56,8,FALSE),main!$K$18:$O$18,0))))),1,0) -> 0 | F13: =IF((AND(VLOOKUP(F$1,main!$A$3:$I$56,5,FALSE)-VLOOKUP($A13,main!$A$3:$I$56,6,FALSE)>=(VLOOKUP(VLOOKUP(F$1,main!$A$3:$I$56,8,FALSE),main!$K$11:$M$14,2,FALSE)+VLOOKUP(VLOOKUP(F$1,main!$A$3:$I$56,7,FALSE),main!$K$19:$O$22,MATCH(VLOOKUP($A13,main!$A$3:$I$56,8,FALSE),main!$K$18:$O$18,0))))),1,0) -> 0 | G13: =IF((AND(VLOOKUP(G$1,main!$A$3:$I$56,5,FALSE)-VLOOKUP($A13,main!$A$3:$I$56,6,FALSE)>=(VLOOKUP(VLOOKUP(G$1,main!$A$3:$I$56,8,FALSE),main!$K$11:$M$14,2,FALSE)+VLOOKUP(VLOOKUP(G$1,main!$A$3:$I$56,7,FALSE),main!$K$19:$O$22,MATCH(VLOOKUP($A13,main!$A$3:$I$56,8,FALSE),main!$K$18:$O$18,0))))),1,0) -> 1 | H13: =IF((AND(VLOOKUP(H$1,main!$A$3:$I$56,5,FALSE)-VLOOKUP($A13,main!$A$3:$I$56,6,FALSE)>=(VLOOKUP(VLOOKUP(H$1,main!$A$3:$I$56,8,FALSE),main!$K$11:$M$14,2,FALSE)+VLOOKUP(VLOOKUP(H$1,main!$A$3:$I$56,7,FALSE),main!$K$19:$O$22,MATCH(VLOOKUP($A13,main!$A$3:$I$56,8,FALSE),main!$K$18:$O$18,0))))),1,0) -> 1 | I13: =IF((AND(VLOOKUP(I$1,main!$A$3:$I$56,5,FALSE)-VLOOKUP($A13,main!$A$3:$I$56,6,FALSE)>=(VLOOKUP(VLOOKUP(I$1,main!$A$3:$I$56,8,FALSE),main!$K$11:$M$14,2,FALSE)+VLOOKUP(VLOOKUP(I$1,main!$A$3:$I$56,7,FALSE),main!$K$19:$O$22,MATCH(VLOOKUP($A13,main!$A$3:$I$56,8,FALSE),main!$K$18:$O$18,0))))),1,0) -> 1 | J13: =IF((AND(VLOOKUP(J$1,main!$A$3:$I$56,5,FALSE)-VLOOKUP($A13,main!$A$3:$I$56,6,FALSE)>=(VLOOKUP(VLOOKUP(J$1,main!$A$3:$I$56,8,FALSE),main!$K$11:$M$14,2,FALSE)+VLOOKUP(VLOOKUP(J$1,main!$A$3:$I$56,7,FALSE),main!$K$19:$O$22,MATCH(VLOOKUP($A13,main!$A$3:$I$56,8,FALSE),main!$K$18:$O$18,0))))),1,0) -> 1 | ... BD13: =IF((AND(VLOOKUP(BD$1,main!$A$3:$I$56,5,FALSE)-VLOOKUP($A13,main!$A$3:$I$56,6,FALSE)>=(VLOOKUP(VLOOKUP(BD$1,main!$A$3:$I$56,8,FALSE),main!$K$11:$M$14,2,FALSE)+VLOOKUP(VLOOKUP(BD$1,main!$A$3:$I$56,7,FALSE),main!$K$19:$O$22,MATCH(VLOOKUP($A13,main!$A$3:$I$56,8,FALSE),main!$K$18:$O$18,0))))),1,0) -> 0
A14: =A13+1 -> 12 | B14: 1 | C14: =IF((AND(VLOOKUP(C$1,main!$A$3:$I$56,5,FALSE)-VLOOKUP($A14,main!$A$3:$I$56,6,FALSE)>=(VLOOKUP(VLOOKUP(C$1,main!$A$3:$I$56,8,FALSE),main!$K$11:$M$14,2,FALSE)+VLOOKUP(VLOOKUP(C$1,main!$A$3:$I$56,7,FALSE),main!$K$19:$O$22,MATCH(VLOOKUP($A14,main!$A$3:$I$56,8,FALSE),main!$K$18:$O$18,0))))),1,0) -> 0 | D14: =IF((AND(VLOOKUP(D$1,main!$A$3:$I$56,5,FALSE)-VLOOKUP($A14,main!$A$3:$I$56,6,FALSE)>=(VLOOKUP(VLOOKUP(D$1,main!$A$3:$I$56,8,FALSE),main!$K$11:$M$14,2,FALSE)+VLOOKUP(VLOOKUP(D$1,main!$A$3:$I$56,7,FALSE),main!$K$19:$O$22,MATCH(VLOOKUP($A14,main!$A$3:$I$56,8,FALSE),main!$K$18:$O$18,0))))),1,0) -> 0 | E14: =IF((AND(VLOOKUP(E$1,main!$A$3:$I$56,5,FALSE)-VLOOKUP($A14,main!$A$3:$I$56,6,FALSE)>=(VLOOKUP(VLOOKUP(E$1,main!$A$3:$I$56,8,FALSE),main!$K$11:$M$14,2,FALSE)+VLOOKUP(VLOOKUP(E$1,main!$A$3:$I$56,7,FALSE),main!$K$19:$O$22,MATCH(VLOOKUP($A14,main!$A$3:$I$56,8,FALSE),main!$K$18:$O$18,0))))),1,0) -> 0 | F14: =IF((AND(VLOOKUP(F$1,main!$A$3:$I$56,5,FALSE)-VLOOKUP($A14,main!$A$3:$I$56,6,FALSE)>=(VLOOKUP(VLOOKUP(F$1,main!$A$3:$I$56,8,FALSE),main!$K$11:$M$14,2,FALSE)+VLOOKUP(VLOOKUP(F$1,main!$A$3:$I$56,7,FALSE),main!$K$19:$O$22,MATCH(VLOOKUP($A14,main!$A$3:$I$56,8,FALSE),main!$K$18:$O$18,0))))),1,0) -> 0 | G14: =IF((AND(VLOOKUP(G$1,main!$A$3:$I$56,5,FALSE)-VLOOKUP($A14,main!$A$3:$I$56,6,FALSE)>=(VLOOKUP(VLOOKUP(G$1,main!$A$3:$I$56,8,FALSE),main!$K$11:$M$14,2,FALSE)+VLOOKUP(VLOOKUP(G$1,main!$A$3:$I$56,7,FALSE),main!$K$19:$O$22,MATCH(VLOOKUP($A14,main!$A$3:$I$56,8,FALSE),main!$K$18:$O$18,0))))),1,0) -> 0 | H14: =IF((AND(VLOOKUP(H$1,main!$A$3:$I$56,5,FALSE)-VLOOKUP($A14,main!$A$3:$I$56,6,FALSE)>=(VLOOKUP(VLOOKUP(H$1,main!$A$3:$I$56,8,FALSE),main!$K$11:$M$14,2,FALSE)+VLOOKUP(VLOOKUP(H$1,main!$A$3:$I$56,7,FALSE),main!$K$19:$O$22,MATCH(VLOOKUP($A14,main!$A$3:$I$56,8,FALSE),main!$K$18:$O$18,0))))),1,0) -> 0 | I14: =IF((AND(VLOOKUP(I$1,main!$A$3:$I$56,5,FALSE)-VLOOKUP($A14,main!$A$3:$I$56,6,FALSE)>=(VLOOKUP(VLOOKUP(I$1,main!$A$3:$I$56,8,FALSE),main!$K$11:$M$14,2,FALSE)+VLOOKUP(VLOOKUP(I$1,main!$A$3:$I$56,7,FALSE),main!$K$19:$O$22,MATCH(VLOOKUP($A14,main!$A$3:$I$56,8,FALSE),main!$K$18:$O$18,0))))),1,0) -> 0 | J14: =IF((AND(VLOOKUP(J$1,main!$A$3:$I$56,5,FALSE)-VLOOKUP($A14,main!$A$3:$I$56,6,FALSE)>=(VLOOKUP(VLOOKUP(J$1,main!$A$3:$I$56,8,FALSE),main!$K$11:$M$14,2,FALSE)+VLOOKUP(VLOOKUP(J$1,main!$A$3:$I$56,7,FALSE),main!$K$19:$O$22,MATCH(VLOOKUP($A14,main!$A$3:$I$56,8,FALSE),main!$K$18:$O$18,0))))),1,0) -> 0 | ... BD14: =IF((AND(VLOOKUP(BD$1,main!$A$3:$I$56,5,FALSE)-VLOOKUP($A14,main!$A$3:$I$56,6,FALSE)>=(VLOOKUP(VLOOKUP(BD$1,main!$A$3:$I$56,8,FALSE),main!$K$11:$M$14,2,FALSE)+VLOOKUP(VLOOKUP(BD$1,main!$A$3:$I$56,7,FALSE),main!$K$19:$O$22,MATCH(VLOOKUP($A14,main!$A$3:$I$56,8,FALSE),main!$K$18:$O$18,0))))),1,0) -> 0
... A56: =A55+1 -> 54 | B56: 1 | C56: =IF((AND(VLOOKUP(C$1,main!$A$3:$I$56,5,FALSE)-VLOOKUP($A56,main!$A$3:$I$56,6,FALSE)>=(VLOOKUP(VLOOKUP(C$1,main!$A$3:$I$56,8,FALSE),main!$K$11:$M$14,2,FALSE)+VLOOKUP(VLOOKUP(C$1,main!$A$3:$I$56,7,FALSE),main!$K$19:$O$22,MATCH(VLOOKUP($A56,main!$A$3:$I$56,8,FALSE),main!$K$18:$O$18,0))))),1,0) -> 0 | D56: =IF((AND(VLOOKUP(D$1,main!$A$3:$I$56,5,FALSE)-VLOOKUP($A56,main!$A$3:$I$56,6,FALSE)>=(VLOOKUP(VLOOKUP(D$1,main!$A$3:$I$56,8,FALSE),main!$K$11:$M$14,2,FALSE)+VLOOKUP(VLOOKUP(D$1,main!$A$3:$I$56,7,FALSE),main!$K$19:$O$22,MATCH(VLOOKUP($A56,main!$A$3:$I$56,8,FALSE),main!$K$18:$O$18,0))))),1,0) -> 0 | E56: =IF((AND(VLOOKUP(E$1,main!$A$3:$I$56,5,FALSE)-VLOOKUP($A56,main!$A$3:$I$56,6,FALSE)>=(VLOOKUP(VLOOKUP(E$1,main!$A$3:$I$56,8,FALSE),main!$K$11:$M$14,2,FALSE)+VLOOKUP(VLOOKUP(E$1,main!$A$3:$I$56,7,FALSE),main!$K$19:$O$22,MATCH(VLOOKUP($A56,main!$A$3:$I$56,8,FALSE),main!$K$18:$O$18,0))))),1,0) -> 0 | F56: =IF((AND(VLOOKUP(F$1,main!$A$3:$I$56,5,FALSE)-VLOOKUP($A56,main!$A$3:$I$56,6,FALSE)>=(VLOOKUP(VLOOKUP(F$1,main!$A$3:$I$56,8,FALSE),main!$K$11:$M$14,2,FALSE)+VLOOKUP(VLOOKUP(F$1,main!$A$3:$I$56,7,FALSE),main!$K$19:$O$22,MATCH(VLOOKUP($A56,main!$A$3:$I$56,8,FALSE),main!$K$18:$O$18,0))))),1,0) -> 0 | G56: =IF((AND(VLOOKUP(G$1,main!$A$3:$I$56,5,FALSE)-VLOOKUP($A56,main!$A$3:$I$56,6,FALSE)>=(VLOOKUP(VLOOKUP(G$1,main!$A$3:$I$56,8,FALSE),main!$K$11:$M$14,2,FALSE)+VLOOKUP(VLOOKUP(G$1,main!$A$3:$I$56,7,FALSE),main!$K$19:$O$22,MATCH(VLOOKUP($A56,main!$A$3:$I$56,8,FALSE),main!$K$18:$O$18,0))))),1,0) -> 0 | H56: =IF((AND(VLOOKUP(H$1,main!$A$3:$I$56,5,FALSE)-VLOOKUP($A56,main!$A$3:$I$56,6,FALSE)>=(VLOOKUP(VLOOKUP(H$1,main!$A$3:$I$56,8,FALSE),main!$K$11:$M$14,2,FALSE)+VLOOKUP(VLOOKUP(H$1,main!$A$3:$I$56,7,FALSE),main!$K$19:$O$22,MATCH(VLOOKUP($A56,main!$A$3:$I$56,8,FALSE),main!$K$18:$O$18,0))))),1,0) -> 0 | I56: =IF((AND(VLOOKUP(I$1,main!$A$3:$I$56,5,FALSE)-VLOOKUP($A56,main!$A$3:$I$56,6,FALSE)>=(VLOOKUP(VLOOKUP(I$1,main!$A$3:$I$56,8,FALSE),main!$K$11:$M$14,2,FALSE)+VLOOKUP(VLOOKUP(I$1,main!$A$3:$I$56,7,FALSE),main!$K$19:$O$22,MATCH(VLOOKUP($A56,main!$A$3:$I$56,8,FALSE),main!$K$18:$O$18,0))))),1,0) -> 0 | J56: =IF((AND(VLOOKUP(J$1,main!$A$3:$I$56,5,FALSE)-VLOOKUP($A56,main!$A$3:$I$56,6,FALSE)>=(VLOOKUP(VLOOKUP(J$1,main!$A$3:$I$56,8,FALSE),main!$K$11:$M$14,2,FALSE)+VLOOKUP(VLOOKUP(J$1,main!$A$3:$I$56,7,FALSE),main!$K$19:$O$22,MATCH(VLOOKUP($A56,main!$A$3:$I$56,8,FALSE),main!$K$18:$O$18,0))))),1,0) -> 1 | ... BD56: =IF((AND(VLOOKUP(BD$1,main!$A$3:$I$56,5,FALSE)-VLOOKUP($A56,main!$A$3:$I$56,6,FALSE)>=(VLOOKUP(VLOOKUP(BD$1,main!$A$3:$I$56,8,FALSE),main!$K$11:$M$14,2,FALSE)+VLOOKUP(VLOOKUP(BD$1,main!$A$3:$I$56,7,FALSE),main!$K$19:$O$22,MATCH(VLOOKUP($A56,main!$A$3:$I$56,8,FALSE),main!$K$18:$O$18,0))))),1,0) -> 0
G62: =VLOOKUP(VLOOKUP(C$1,main!$A$3:$I$56,8,FALSE),main!$K$11:$M$14,2,FALSE) -> 15 | J62: VLOOKUP(VLOOKUP(C$1,main!$A$3:$I$56,8,FALSE),main!$K$11:$M$14,2,FALSE)
G63: =VLOOKUP(VLOOKUP(C$1,main!$A$3:$I$56,7,FALSE),main!$K$19:$O$22,MATCH(VLOOKUP($A3,main!$A$3:$I$56,8,FALSE),main!$K$18:$O$18,0)) -> 25
G65: =VLOOKUP(C$1,main!$A$3:$I$56,8,FALSE) -> Terminal B
G66: =MATCH(VLOOKUP($A3,main!$A$3:$I$56,9,FALSE),main!$K$18:$O$18,0) -> #N/A
G67: =VLOOKUP($A3,main!$A$3:$I$56,9,FALSE) -> 1

Sheet delta
B1: 0 | C1: 1 | D1: 2 | E1: 3 | F1: 4 | G1: 5 | H1: 6 | I1: 7 | J1: 8 | K1: 9 | L1: 10 | M1: 11 | N1: 12 | O1: 13 | P1: 14 | Q1: 15 | R1: 16 | S1: 17 | T1: 18 | U1: 19 | V1: 20 | W1: 21 | X1: 22 | Y1: 23 | Z1: 24 | AA1: 25 | AB1: 26 | AC1: 27 | AD1: 28 | AE1: 29 | AF1: 30 | AG1: 31 | AH1: 32 | AI1: 33 | AJ1: 34 | AK1: 35 | AL1: 36 | AM1: 37 | AN1: 38 | AO1: 39 | AP1: 40 | AQ1: 41 | AR1: 42 | AS1: 43 | AT1: 44 | AU1: 45 | AV1: 46 | AW1: 47 | AX1: 48 | AY1: 49 | AZ1: 50 | BA1: 51 | BB1: 52 | BC1: 53 | BD1: 54 | BE1: 55 | BF1: 56 | BG1: 57 | BH1: 58 | BI1: 59
A2: 0 | B2: 0 | C2: 0 | D2: 0 | E2: 0 | F2: 0 | G2: 0 | H2: 0 | I2: 0 | J2: 0 | K2: 0 | L2: 0 | M2: 0 | N2: 0 | O2: 0 | P2: 0 | Q2: 0 | R2: 0 | S2: 0 | T2: 0 | U2: 0 | V2: 0 | W2: 0 | X2: 0 | Y2: 0 | Z2: 0 | AA2: 0 | AB2: 0 | AC2: 0 | AD2: 0 | AE2: 0 | AF2: 0 | AG2: 0 | AH2: 0 | AI2: 0 | AJ2: 0 | AK2: 0 | AL2: 0 | AM2: 0 | AN2: 0 | AO2: 0 | AP2: 0 | AQ2: 0 | AR2: 0 | AS2: 0 | AT2: 0 | AU2: 0 | AV2: 0 | AW2: 0 | AX2: 0 | AY2: 0 | AZ2: 0 | BA2: 0 | BB2: 0 | BC2: 0 | BD2: 0 | BE2: 0 | BF2: 0 | BG2: 0 | BH2: 0 | BI2: 0
A3: =A2+1 -> 1 | B3: 0 | C3: =IF((gamma!C3),IF(VLOOKUP(C$1,main!$A$3:$I$56,7,FALSE)=VLOOKUP($A3,main!$A$3:$I$56,8,FALSE),VLOOKUP(C$1,main!$A$3:$I$56,4,FALSE),VLOOKUP(C$1,main!$A$3:$I$56,4,FALSE)+VLOOKUP($A3,main!$A$3:$I$56,4,FALSE)+(VLOOKUP(VLOOKUP(C$1,main!$A$3:$I$56,8,FALSE),main!$K$19:$O$22,MATCH(VLOOKUP($A3,main!$A$3:$I$56,7,FALSE),main!$K$18:$O$18,0),0))),0) -> 0 | D3: =IF((gamma!D3),IF(VLOOKUP(D$1,main!$A$3:$I$56,7,FALSE)=VLOOKUP($A3,main!$A$3:$I$56,8,FALSE),VLOOKUP(D$1,main!$A$3:$I$56,4,FALSE),VLOOKUP(D$1,main!$A$3:$I$56,4,FALSE)+VLOOKUP($A3,main!$A$3:$I$56,4,FALSE)+(VLOOKUP(VLOOKUP(D$1,main!$A$3:$I$56,8,FALSE),main!$K$19:$O$22,MATCH(VLOOKUP($A3,main!$A$3:$I$56,7,FALSE),main!$K$18:$O$18,0),0))),0) -> 295 | E3: =IF((gamma!E3),IF(VLOOKUP(E$1,main!$A$3:$I$56,7,FALSE)=VLOOKUP($A3,main!$A$3:$I$56,8,FALSE),VLOOKUP(E$1,main!$A$3:$I$56,4,FALSE),VLOOKUP(E$1,main!$A$3:$I$56,4,FALSE)+VLOOKUP($A3,main!$A$3:$I$56,4,FALSE)+(VLOOKUP(VLOOKUP(E$1,main!$A$3:$I$56,8,FALSE),main!$K$19:$O$22,MATCH(VLOOKUP($A3,main!$A$3:$I$56,7,FALSE),main!$K$18:$O$18,0),0))),0) -> 295 | F3: =IF((gamma!F3),IF(VLOOKUP(F$1,main!$A$3:$I$56,7,FALSE)=VLOOKUP($A3,main!$A$3:$I$56,8,FALSE),VLOOKUP(F$1,main!$A$3:$I$56,4,FALSE),VLOOKUP(F$1,main!$A$3:$I$56,4,FALSE)+VLOOKUP($A3,main!$A$3:$I$56,4,FALSE)+(VLOOKUP(VLOOKUP(F$1,main!$A$3:$I$56,8,FALSE),main!$K$19:$O$22,MATCH(VLOOKUP($A3,main!$A$3:$I$56,7,FALSE),main!$K$18:$O$18,0),0))),0) -> 295 | G3: =IF((gamma!G3),IF(VLOOKUP(G$1,main!$A$3:$I$56,7,FALSE)=VLOOKUP($A3,main!$A$3:$I$56,8,FALSE),VLOOKUP(G$1,main!$A$3:$I$56,4,FALSE),VLOOKUP(G$1,main!$A$3:$I$56,4,FALSE)+VLOOKUP($A3,main!$A$3:$I$56,4,FALSE)+(VLOOKUP(VLOOKUP(G$1,main!$A$3:$I$56,8,FALSE),main!$K$19:$O$22,MATCH(VLOOKUP($A3,main!$A$3:$I$56,7,FALSE),main!$K$18:$O$18,0),0))),0) -> 295 | H3: =IF((gamma!H3),IF(VLOOKUP(H$1,main!$A$3:$I$56,7,FALSE)=VLOOKUP($A3,main!$A$3:$I$56,8,FALSE),VLOOKUP(H$1,main!$A$3:$I$56,4,FALSE),VLOOKUP(H$1,main!$A$3:$I$56,4,FALSE)+VLOOKUP($A3,main!$A$3:$I$56,4,FALSE)+(VLOOKUP(VLOOKUP(H$1,main!$A$3:$I$56,8,FALSE),main!$K$19:$O$22,MATCH(VLOOKUP($A3,main!$A$3:$I$56,7,FALSE),main!$K$18:$O$18,0),0))),0) -> 295 | I3: =IF((gamma!I3),IF(VLOOKUP(I$1,main!$A$3:$I$56,7,FALSE)=VLOOKUP($A3,main!$A$3:$I$56,8,FALSE),VLOOKUP(I$1,main!$A$3:$I$56,4,FALSE),VLOOKUP(I$1,main!$A$3:$I$56,4,FALSE)+VLOOKUP($A3,main!$A$3:$I$56,4,FALSE)+(VLOOKUP(VLOOKUP(I$1,main!$A$3:$I$56,8,FALSE),main!$K$19:$O$22,MATCH(VLOOKUP($A3,main!$A$3:$I$56,7,FALSE),main!$K$18:$O$18,0),0))),0) -> 295 | J3: =IF((gamma!J3),IF(VLOOKUP(J$1,main!$A$3:$I$56,7,FALSE)=VLOOKUP($A3,main!$A$3:$I$56,8,FALSE),VLOOKUP(J$1,main!$A$3:$I$56,4,FALSE),VLOOKUP(J$1,main!$A$3:$I$56,4,FALSE)+VLOOKUP($A3,main!$A$3:$I$56,4,FALSE)+(VLOOKUP(VLOOKUP(J$1,main!$A$3:$I$56,8,FALSE),main!$K$19:$O$22,MATCH(VLOOKUP($A3,main!$A$3:$I$56,7,FALSE),main!$K$18:$O$18,0),0))),0) -> 295 | ... BD3: =IF((gamma!BD3),IF(VLOOKUP(BD$1,main!$A$3:$I$56,7,FALSE)=VLOOKUP($A3,main!$A$3:$I$56,8,FALSE),VLOOKUP(BD$1,main!$A$3:$I$56,4,FALSE),VLOOKUP(BD$1,main!$A$3:$I$56,4,FALSE)+VLOOKUP($A3,main!$A$3:$I$56,4,FALSE)+(VLOOKUP(VLOOKUP(BD$1,main!$A$3:$I$56,8,FALSE),main!$K$19:$O$22,MATCH(VLOOKUP($A3,main!$A$3:$I$56,7,FALSE),main!$K$18:$O$18,0),0))),0) -> 300 | BE3: 0 | BF3: 0 | BG3: 0 | BH3: 0 | BI3: 0
A4: =A3+1 -> 2 | B4: 0 | C4: =IF((gamma!C4),IF(VLOOKUP(C$1,main!$A$3:$I$56,7,FALSE)=VLOOKUP($A4,main!$A$3:$I$56,8,FALSE),VLOOKUP(C$1,main!$A$3:$I$56,4,FALSE),VLOOKUP(C$1,main!$A$3:$I$56,4,FALSE)+VLOOKUP($A4,main!$A$3:$I$56,4,FALSE)+(VLOOKUP(VLOOKUP(C$1,main!$A$3:$I$56,8,FALSE),main!$K$19:$O$22,MATCH(VLOOKUP($A4,main!$A$3:$I$56,7,FALSE),main!$K$18:$O$18,0),0))),0) -> 0 | D4: =IF((gamma!D4),IF(VLOOKUP(D$1,main!$A$3:$I$56,7,FALSE)=VLOOKUP($A4,main!$A$3:$I$56,8,FALSE),VLOOKUP(D$1,main!$A$3:$I$56,4,FALSE),VLOOKUP(D$1,main!$A$3:$I$56,4,FALSE)+VLOOKUP($A4,main!$A$3:$I$56,4,FALSE)+(VLOOKUP(VLOOKUP(D$1,main!$A$3:$I$56,8,FALSE),main!$K$19:$O$22,MATCH(VLOOKUP($A4,main!$A$3:$I$56,7,FALSE),main!$K$18:$O$18,0),0))),0) -> 0 | E4: =IF((gamma!E4),IF(VLOOKUP(E$1,main!$A$3:$I$56,7,FALSE)=VLOOKUP($A4,main!$A$3:$I$56,8,FALSE),VLOOKUP(E$1,main!$A$3:$I$56,4,FALSE),VLOOKUP(E$1,main!$A$3:$I$56,4,FALSE)+VLOOKUP($A4,main!$A$3:$I$56,4,FALSE)+(VLOOKUP(VLOOKUP(E$1,main!$A$3:$I$56,8,FALSE),main!$K$19:$O$22,MATCH(VLOOKUP($A4,main!$A$3:$I$56,7,FALSE),main!$K$18:$O$18,0),0))),0) -> 0 | F4: =IF((gamma!F4),IF(VLOOKUP(F$1,main!$A$3:$I$56,7,FALSE)=VLOOKUP($A4,main!$A$3:$I$56,8,FALSE),VLOOKUP(F$1,main!$A$3:$I$56,4,FALSE),VLOOKUP(F$1,main!$A$3:$I$56,4,FALSE)+VLOOKUP($A4,main!$A$3:$I$56,4,FALSE)+(VLOOKUP(VLOOKUP(F$1,main!$A$3:$I$56,8,FALSE),main!$K$19:$O$22,MATCH(VLOOKUP($A4,main!$A$3:$I$56,7,FALSE),main!$K$18:$O$18,0),0))),0) -> 295 | G4: =IF((gamma!G4),IF(VLOOKUP(G$1,main!$A$3:$I$56,7,FALSE)=VLOOKUP($A4,main!$A$3:$I$56,8,FALSE),VLOOKUP(G$1,main!$A$3:$I$56,4,FALSE),VLOOKUP(G$1,main!$A$3:$I$56,4,FALSE)+VLOOKUP($A4,main!$A$3:$I$56,4,FALSE)+(VLOOKUP(VLOOKUP(G$1,main!$A$3:$I$56,8,FALSE),main!$K$19:$O$22,MATCH(VLOOKUP($A4,main!$A$3:$I$56,7,FALSE),main!$K$18:$O$18,0),0))),0) -> 295 | H4: =IF((gamma!H4),IF(VLOOKUP(H$1,main!$A$3:$I$56,7,FALSE)=VLOOKUP($A4,main!$A$3:$I$56,8,FALSE),VLOOKUP(H$1,main!$A$3:$I$56,4,FALSE),VLOOKUP(H$1,main!$A$3:$I$56,4,FALSE)+VLOOKUP($A4,main!$A$3:$I$56,4,FALSE)+(VLOOKUP(VLOOKUP(H$1,main!$A$3:$I$56,8,FALSE),main!$K$19:$O$22,MATCH(VLOOKUP($A4,main!$A$3:$I$56,7,FALSE),main!$K$18:$O$18,0),0))),0) -> 295 | I4: =IF((gamma!I4),IF(VLOOKUP(I$1,main!$A$3:$I$56,7,FALSE)=VLOOKUP($A4,main!$A$3:$I$56,8,FALSE),VLOOKUP(I$1,main!$A$3:$I$56,4,FALSE),VLOOKUP(I$1,main!$A$3:$I$56,4,FALSE)+VLOOKUP($A4,main!$A$3:$I$56,4,FALSE)+(VLOOKUP(VLOOKUP(I$1,main!$A$3:$I$56,8,FALSE),main!$K$19:$O$22,MATCH(VLOOKUP($A4,main!$A$3:$I$56,7,FALSE),main!$K$18:$O$18,0),0))),0) -> 295 | J4: =IF((gamma!J4),IF(VLOOKUP(J$1,main!$A$3:$I$56,7,FALSE)=VLOOKUP($A4,main!$A$3:$I$56,8,FALSE),VLOOKUP(J$1,main!$A$3:$I$56,4,FALSE),VLOOKUP(J$1,main!$A$3:$I$56,4,FALSE)+VLOOKUP($A4,main!$A$3:$I$56,4,FALSE)+(VLOOKUP(VLOOKUP(J$1,main!$A$3:$I$56,8,FALSE),main!$K$19:$O$22,MATCH(VLOOKUP($A4,main!$A$3:$I$56,7,FALSE),main!$K$18:$O$18,0),0))),0) -> 295 | ... BD4: =IF((gamma!BD4),IF(VLOOKUP(BD$1,main!$A$3:$I$56,7,FALSE)=VLOOKUP($A4,main!$A$3:$I$56,8,FALSE),VLOOKUP(BD$1,main!$A$3:$I$56,4,FALSE),VLOOKUP(BD$1,main!$A$3:$I$56,4,FALSE)+VLOOKUP($A4,main!$A$3:$I$56,4,FALSE)+(VLOOKUP(VLOOKUP(BD$1,main!$A$3:$I$56,8,FALSE),main!$K$19:$O$22,MATCH(VLOOKUP($A4,main!$A$3:$I$56,7,FALSE),main!$K$18:$O$18,0),0))),0) -> 300 | BE4: 0 | BF4: 0 | BG4: 0 | BH4: 0 | BI4: 0
A5: =A4+1 -> 3 | B5: 0 | C5: =IF((gamma!C5),IF(VLOOKUP(C$1,main!$A$3:$I$56,7,FALSE)=VLOOKUP($A5,main!$A$3:$I$56,8,FALSE),VLOOKUP(C$1,main!$A$3:$I$56,4,FALSE),VLOOKUP(C$1,main!$A$3:$I$56,4,FALSE)+VLOOKUP($A5,main!$A$3:$I$56,4,FALSE)+(VLOOKUP(VLOOKUP(C$1,main!$A$3:$I$56,8,FALSE),main!$K$19:$O$22,MATCH(VLOOKUP($A5,main!$A$3:$I$56,7,FALSE),main!$K$18:$O$18,0),0))),0) -> 0 | D5: =IF((gamma!D5),IF(VLOOKUP(D$1,main!$A$3:$I$56,7,FALSE)=VLOOKUP($A5,main!$A$3:$I$56,8,FALSE),VLOOKUP(D$1,main!$A$3:$I$56,4,FALSE),VLOOKUP(D$1,main!$A$3:$I$56,4,FALSE)+VLOOKUP($A5,main!$A$3:$I$56,4,FALSE)+(VLOOKUP(VLOOKUP(D$1,main!$A$3:$I$56,8,FALSE),main!$K$19:$O$22,MATCH(VLOOKUP($A5,main!$A$3:$I$56,7,FALSE),main!$K$18:$O$18,0),0))),0) -> 0 | E5: =IF((gamma!E5),IF(VLOOKUP(E$1,main!$A$3:$I$56,7,FALSE)=VLOOKUP($A5,main!$A$3:$I$56,8,FALSE),VLOOKUP(E$1,main!$A$3:$I$56,4,FALSE),VLOOKUP(E$1,main!$A$3:$I$56,4,FALSE)+VLOOKUP($A5,main!$A$3:$I$56,4,FALSE)+(VLOOKUP(VLOOKUP(E$1,main!$A$3:$I$56,8,FALSE),main!$K$19:$O$22,MATCH(VLOOKUP($A5,main!$A$3:$I$56,7,FALSE),main!$K$18:$O$18,0),0))),0) -> 0 | F5: =IF((gamma!F5),IF(VLOOKUP(F$1,main!$A$3:$I$56,7,FALSE)=VLOOKUP($A5,main!$A$3:$I$56,8,FALSE),VLOOKUP(F$1,main!$A$3:$I$56,4,FALSE),VLOOKUP(F$1,main!$A$3:$I$56,4,FALSE)+VLOOKUP($A5,main!$A$3:$I$56,4,FALSE)+(VLOOKUP(VLOOKUP(F$1,main!$A$3:$I$56,8,FALSE),main!$K$19:$O$22,MATCH(VLOOKUP($A5,main!$A$3:$I$56,7,FALSE),main!$K$18:$O$18,0),0))),0) -> 0 | G5: =IF((gamma!G5),IF(VLOOKUP(G$1,main!$A$3:$I$56,7,FALSE)=VLOOKUP($A5,main!$A$3:$I$56,8,FALSE),VLOOKUP(G$1,main!$A$3:$I$56,4,FALSE),VLOOKUP(G$1,main!$A$3:$I$56,4,FALSE)+VLOOKUP($A5,main!$A$3:$I$56,4,FALSE)+(VLOOKUP(VLOOKUP(G$1,main!$A$3:$I$56,8,FALSE),main!$K$19:$O$22,MATCH(VLOOKUP($A5,main!$A$3:$I$56,7,FALSE),main!$K$18:$O$18,0),0))),0) -> 0 | H5: =IF((gamma!H5),IF(VLOOKUP(H$1,main!$A$3:$I$56,7,FALSE)=VLOOKUP($A5,main!$A$3:$I$56,8,FALSE),VLOOKUP(H$1,main!$A$3:$I$56,4,FALSE),VLOOKUP(H$1,main!$A$3:$I$56,4,FALSE)+VLOOKUP($A5,main!$A$3:$I$56,4,FALSE)+(VLOOKUP(VLOOKUP(H$1,main!$A$3:$I$56,8,FALSE),main!$K$19:$O$22,MATCH(VLOOKUP($A5,main!$A$3:$I$56,7,FALSE),main!$K$18:$O$18,0),0))),0) -> 295 | I5: =IF((gamma!I5),IF(VLOOKUP(I$1,main!$A$3:$I$56,7,FALSE)=VLOOKUP($A5,main!$A$3:$I$56,8,FALSE),VLOOKUP(I$1,main!$A$3:$I$56,4,FALSE),VLOOKUP(I$1,main!$A$3:$I$56,4,FALSE)+VLOOKUP($A5,main!$A$3:$I$56,4,FALSE)+(VLOOKUP(VLOOKUP(I$1,main!$A$3:$I$56,8,FALSE),main!$K$19:$O$22,MATCH(VLOOKUP($A5,main!$A$3:$I$56,7,FALSE),main!$K$18:$O$18,0),0))),0) -> 295 | J5: =IF((gamma!J5),IF(VLOOKUP(J$1,main!$A$3:$I$56,7,FALSE)=VLOOKUP($A5,main!$A$3:$I$56,8,FALSE),VLOOKUP(J$1,main!$A$3:$I$56,4,FALSE),VLOOKUP(J$1,main!$A$3:$I$56,4,FALSE)+VLOOKUP($A5,main!$A$3:$I$56,4,FALSE)+(VLOOKUP(VLOOKUP(J$1,main!$A$3:$I$56,8,FALSE),main!$K$19:$O$22,MATCH(VLOOKUP($A5,main!$A$3:$I$56,7,FALSE),main!$K$18:$O$18,0),0))),0) -> 295 | ... BD5: =IF((gamma!BD5),IF(VLOOKUP(BD$1,main!$A$3:$I$56,7,FALSE)=VLOOKUP($A5,main!$A$3:$I$56,8,FALSE),VLOOKUP(BD$1,main!$A$3:$I$56,4,FALSE),VLOOKUP(BD$1,main!$A$3:$I$56,4,FALSE)+VLOOKUP($A5,main!$A$3:$I$56,4,FALSE)+(VLOOKUP(VLOOKUP(BD$1,main!$A$3:$I$56,8,FALSE),main!$K$19:$O$22,MATCH(VLOOKUP($A5,main!$A$3:$I$56,7,FALSE),main!$K$18:$O$18,0),0))),0) -> 0 | BE5: 0 | BF5: 0 | BG5: 0 | BH5: 0 | BI5: 0
A6: =A5+1 -> 4 | B6: 0 | C6: =IF((gamma!C6),IF(VLOOKUP(C$1,main!$A$3:$I$56,7,FALSE)=VLOOKUP($A6,main!$A$3:$I$56,8,FALSE),VLOOKUP(C$1,main!$A$3:$I$56,4,FALSE),VLOOKUP(C$1,main!$A$3:$I$56,4,FALSE)+VLOOKUP($A6,main!$A$3:$I$56,4,FALSE)+(VLOOKUP(VLOOKUP(C$1,main!$A$3:$I$56,8,FALSE),main!$K$19:$O$22,MATCH(VLOOKUP($A6,main!$A$3:$I$56,7,FALSE),main!$K$18:$O$18,0),0))),0) -> 0 | D6: =IF((gamma!D6),IF(VLOOKUP(D$1,main!$A$3:$I$56,7,FALSE)=VLOOKUP($A6,main!$A$3:$I$56,8,FALSE),VLOOKUP(D$1,main!$A$3:$I$56,4,FALSE),VLOOKUP(D$1,main!$A$3:$I$56,4,FALSE)+VLOOKUP($A6,main!$A$3:$I$56,4,FALSE)+(VLOOKUP(VLOOKUP(D$1,main!$A$3:$I$56,8,FALSE),main!$K$19:$O$22,MATCH(VLOOKUP($A6,main!$A$3:$I$56,7,FALSE),main!$K$18:$O$18,0),0))),0) -> 0 | E6: =IF((gamma!E6),IF(VLOOKUP(E$1,main!$A$3:$I$56,7,FALSE)=VLOOKUP($A6,main!$A$3:$I$56,8,FALSE),VLOOKUP(E$1,main!$A$3:$I$56,4,FALSE),VLOOKUP(E$1,main!$A$3:$I$56,4,FALSE)+VLOOKUP($A6,main!$A$3:$I$56,4,FALSE)+(VLOOKUP(VLOOKUP(E$1,main!$A$3:$I$56,8,FALSE),main!$K$19:$O$22,MATCH(VLOOKUP($A6,main!$A$3:$I$56,7,FALSE),main!$K$18:$O$18,0),0))),0) -> 0 | F6: =IF((gamma!F6),IF(VLOOKUP(F$1,main!$A$3:$I$56,7,FALSE)=VLOOKUP($A6,main!$A$3:$I$56,8,FALSE),VLOOKUP(F$1,main!$A$3:$I$56,4,FALSE),VLOOKUP(F$1,main!$A$3:$I$56,4,FALSE)+VLOOKUP($A6,main!$A$3:$I$56,4,FALSE)+(VLOOKUP(VLOOKUP(F$1,main!$A$3:$I$56,8,FALSE),main!$K$19:$O$22,MATCH(VLOOKUP($A6,main!$A$3:$I$56,7,FALSE),main!$K$18:$O$18,0),0))),0) -> 0 | G6: =IF((gamma!G6),IF(VLOOKUP(G$1,main!$A$3:$I$56,7,FALSE)=VLOOKUP($A6,main!$A$3:$I$56,8,FALSE),VLOOKUP(G$1,main!$A$3:$I$56,4,FALSE),VLOOKUP(G$1,main!$A$3:$I$56,4,FALSE)+VLOOKUP($A6,main!$A$3:$I$56,4,FALSE)+(VLOOKUP(VLOOKUP(G$1,main!$A$3:$I$56,8,FALSE),main!$K$19:$O$22,MATCH(VLOOKUP($A6,main!$A$3:$I$56,7,FALSE),main!$K$18:$O$18,0),0))),0) -> 0 | H6: =IF((gamma!H6),IF(VLOOKUP(H$1,main!$A$3:$I$56,7,FALSE)=VLOOKUP($A6,main!$A$3:$I$56,8,FALSE),VLOOKUP(H$1,main!$A$3:$I$56,4,FALSE),VLOOKUP(H$1,main!$A$3:$I$56,4,FALSE)+VLOOKUP($A6,main!$A$3:$I$56,4,FALSE)+(VLOOKUP(VLOOKUP(H$1,main!$A$3:$I$56,8,FALSE),main!$K$19:$O$22,MATCH(VLOOKUP($A6,main!$A$3:$I$56,7,FALSE),main!$K$18:$O$18,0),0))),0) -> 0 | I6: =IF((gamma!I6),IF(VLOOKUP(I$1,main!$A$3:$I$56,7,FALSE)=VLOOKUP($A6,main!$A$3:$I$56,8,FALSE),VLOOKUP(I$1,main!$A$3:$I$56,4,FALSE),VLOOKUP(I$1,main!$A$3:$I$56,4,FALSE)+VLOOKUP($A6,main!$A$3:$I$56,4,FALSE)+(VLOOKUP(VLOOKUP(I$1,main!$A$3:$I$56,8,FALSE),main!$K$19:$O$22,MATCH(VLOOKUP($A6,main!$A$3:$I$56,7,FALSE),main!$K$18:$O$18,0),0))),0) -> 295 | J6: =IF((gamma!J6),IF(VLOOKUP(J$1,main!$A$3:$I$56,7,FALSE)=VLOOKUP($A6,main!$A$3:$I$56,8,FALSE),VLOOKUP(J$1,main!$A$3:$I$56,4,FALSE),VLOOKUP(J$1,main!$A$3:$I$56,4,FALSE)+VLOOKUP($A6,main!$A$3:$I$56,4,FALSE)+(VLOOKUP(VLOOKUP(J$1,main!$A$3:$I$56,8,FALSE),main!$K$19:$O$22,MATCH(VLOOKUP($A6,main!$A$3:$I$56,7,FALSE),main!$K$18:$O$18,0),0))),0) -> 295 | ... BD6: =IF((gamma!BD6),IF(VLOOKUP(BD$1,main!$A$3:$I$56,7,FALSE)=VLOOKUP($A6,main!$A$3:$I$56,8,FALSE),VLOOKUP(BD$1,main!$A$3:$I$56,4,FALSE),VLOOKUP(BD$1,main!$A$3:$I$56,4,FALSE)+VLOOKUP($A6,main!$A$3:$I$56,4,FALSE)+(VLOOKUP(VLOOKUP(BD$1,main!$A$3:$I$56,8,FALSE),main!$K$19:$O$22,MATCH(VLOOKUP($A6,main!$A$3:$I$56,7,FALSE),main!$K$18:$O$18,0),0))),0) -> 0 | BE6: 0 | BF6: 0 | BG6: 0 | BH6: 0 | BI6: 0
A7: =A6+1 -> 5 | B7: 0 | C7: =IF((gamma!C7),IF(VLOOKUP(C$1,main!$A$3:$I$56,7,FALSE)=VLOOKUP($A7,main!$A$3:$I$56,8,FALSE),VLOOKUP(C$1,main!$A$3:$I$56,4,FALSE),VLOOKUP(C$1,main!$A$3:$I$56,4,FALSE)+VLOOKUP($A7,main!$A$3:$I$56,4,FALSE)+(VLOOKUP(VLOOKUP(C$1,main!$A$3:$I$56,8,FALSE),main!$K$19:$O$22,MATCH(VLOOKUP($A7,main!$A$3:$I$56,7,FALSE),main!$K$18:$O$18,0),0))),0) -> 0 | D7: =IF((gamma!D7),IF(VLOOKUP(D$1,main!$A$3:$I$56,7,FALSE)=VLOOKUP($A7,main!$A$3:$I$56,8,FALSE),VLOOKUP(D$1,main!$A$3:$I$56,4,FALSE),VLOOKUP(D$1,main!$A$3:$I$56,4,FALSE)+VLOOKUP($A7,main!$A$3:$I$56,4,FALSE)+(VLOOKUP(VLOOKUP(D$1,main!$A$3:$I$56,8,FALSE),main!$K$19:$O$22,MATCH(VLOOKUP($A7,main!$A$3:$I$56,7,FALSE),main!$K$18:$O$18,0),0))),0) -> 0 | E7: =IF((gamma!E7),IF(VLOOKUP(E$1,main!$A$3:$I$56,7,FALSE)=VLOOKUP($A7,main!$A$3:$I$56,8,FALSE),VLOOKUP(E$1,main!$A$3:$I$56,4,FALSE),VLOOKUP(E$1,main!$A$3:$I$56,4,FALSE)+VLOOKUP($A7,main!$A$3:$I$56,4,FALSE)+(VLOOKUP(VLOOKUP(E$1,main!$A$3:$I$56,8,FALSE),main!$K$19:$O$22,MATCH(VLOOKUP($A7,main!$A$3:$I$56,7,FALSE),main!$K$18:$O$18,0),0))),0) -> 0 | F7: =IF((gamma!F7),IF(VLOOKUP(F$1,main!$A$3:$I$56,7,FALSE)=VLOOKUP($A7,main!$A$3:$I$56,8,FALSE),VLOOKUP(F$1,main!$A$3:$I$56,4,FALSE),VLOOKUP(F$1,main!$A$3:$I$56,4,FALSE)+VLOOKUP($A7,main!$A$3:$I$56,4,FALSE)+(VLOOKUP(VLOOKUP(F$1,main!$A$3:$I$56,8,FALSE),main!$K$19:$O$22,MATCH(VLOOKUP($A7,main!$A$3:$I$56,7,FALSE),main!$K$18:$O$18,0),0))),0) -> 0 | G7: =IF((gamma!G7),IF(VLOOKUP(G$1,main!$A$3:$I$56,7,FALSE)=VLOOKUP($A7,main!$A$3:$I$56,8,FALSE),VLOOKUP(G$1,main!$A$3:$I$56,4,FALSE),VLOOKUP(G$1,main!$A$3:$I$56,4,FALSE)+VLOOKUP($A7,main!$A$3:$I$56,4,FALSE)+(VLOOKUP(VLOOKUP(G$1,main!$A$3:$I$56,8,FALSE),main!$K$19:$O$22,MATCH(VLOOKUP($A7,main!$A$3:$I$56,7,FALSE),main!$K$18:$O$18,0),0))),0) -> 0 | H7: =IF((gamma!H7),IF(VLOOKUP(H$1,main!$A$3:$I$56,7,FALSE)=VLOOKUP($A7,main!$A$3:$I$56,8,FALSE),VLOOKUP(H$1,main!$A$3:$I$56,4,FALSE),VLOOKUP(H$1,main!$A$3:$I$56,4,FALSE)+VLOOKUP($A7,main!$A$3:$I$56,4,FALSE)+(VLOOKUP(VLOOKUP(H$1,main!$A$3:$I$56,8,FALSE),main!$K$19:$O$22,MATCH(VLOOKUP($A7,main!$A$3:$I$56,7,FALSE),main!$K$18:$O$18,0),0))),0) -> 0 | I7: =IF((gamma!I7),IF(VLOOKUP(I$1,main!$A$3:$I$56,7,FALSE)=VLOOKUP($A7,main!$A$3:$I$56,8,FALSE),VLOOKUP(I$1,main!$A$3:$I$56,4,FALSE),VLOOKUP(I$1,main!$A$3:$I$56,4,FALSE)+VLOOKUP($A7,main!$A$3:$I$56,4,FALSE)+(VLOOKUP(VLOOKUP(I$1,main!$A$3:$I$56,8,FALSE),main!$K$19:$O$22,MATCH(VLOOKUP($A7,main!$A$3:$I$56,7,FALSE),main!$K$18:$O$18,0),0))),0) -> 0 | J7: =IF((gamma!J7),IF(VLOOKUP(J$1,main!$A$3:$I$56,7,FALSE)=VLOOKUP($A7,main!$A$3:$I$56,8,FALSE),VLOOKUP(J$1,main!$A$3:$I$56,4,FALSE),VLOOKUP(J$1,main!$A$3:$I$56,4,FALSE)+VLOOKUP($A7,main!$A$3:$I$56,4,FALSE)+(VLOOKUP(VLOOKUP(J$1,main!$A$3:$I$56,8,FALSE),main!$K$19:$O$22,MATCH(VLOOKUP($A7,main!$A$3:$I$56,7,FALSE),main!$K$18:$O$18,0),0))),0) -> 295 | ... BD7: =IF((gamma!BD7),IF(VLOOKUP(BD$1,main!$A$3:$I$56,7,FALSE)=VLOOKUP($A7,main!$A$3:$I$56,8,FALSE),VLOOKUP(BD$1,main!$A$3:$I$56,4,FALSE),VLOOKUP(BD$1,main!$A$3:$I$56,4,FALSE)+VLOOKUP($A7,main!$A$3:$I$56,4,FALSE)+(VLOOKUP(VLOOKUP(BD$1,main!$A$3:$I$56,8,FALSE),main!$K$19:$O$22,MATCH(VLOOKUP($A7,main!$A$3:$I$56,7,FALSE),main!$K$18:$O$18,0),0))),0) -> 0 | BE7: 0 | BF7: 0 | BG7: 0 | BH7: 0 | BI7: 0
