Workbook

Sheet test
A1: trip_id | B1: duration | C1: dep_terminal | D1: arr_terminal | E1: dep_time | F1: arr_time | G1: cost_to_cs | H1: dep_min | I1: arr_min
A2: DEPOT | B2: 0 | C2: - | D2: - | E2: - | F2: - | G2: 20 | H2: - | I2: -
A3: AB1 | B3: 135 | C3: Terminal A | D3: Terminal B | E3: 0.38888889 | F3: 0.48263889 | G3: =VLOOKUP(D3,$J$11:$L$14,3,FALSE) -> 20 | H3: =ROUND(E3*1440,0) -> 560 | I3: =ROUND(F3*1440,0) -> 695 | U3: 1
A4: AB2 | B4: 135 | C4: Terminal A | D4: Terminal B | E4: 0.51388889 | F4: 0.60763889 | G4: =VLOOKUP(D4,$J$11:$L$14,3,FALSE) -> 20 | H4: =ROUND(E4*1440,0) -> 740 | I4: =ROUND(F4*1440,0) -> 875 | U4: =U3+1 -> 2
A5: AB3 | B5: 135 | C5: Terminal A | D5: Terminal B | E5: 0.57638889 | F5: 0.67013889 | G5: =VLOOKUP(D5,$J$11:$L$14,3,FALSE) -> 20 | H5: =ROUND(E5*1440,0) -> 830 | I5: =ROUND(F5*1440,0) -> 965 | U5: =U4+1 -> 3
A6: AB4 | B6: 135 | C6: Terminal A | D6: Terminal B | E6: 0.63888889 | F6: 0.73263889 | G6: =VLOOKUP(D6,$J$11:$L$14,3,FALSE) -> 20 | H6: =ROUND(E6*1440,0) -> 920 | I6: =ROUND(F6*1440,0) -> 1055 | U6: =U5+1 -> 4
A7: AB5 | B7: 135 | C7: Terminal A | D7: Terminal B | E7: 0.68055556 | F7: 0.77430556 | G7: =VLOOKUP(D7,$J$11:$L$14,3,FALSE) -> 20 | H7: =ROUND(E7*1440,0) -> 980 | I7: =ROUND(F7*1440,0) -> 1115 | U7: =U6+1 -> 5
A8: AB6 | B8: 135 | C8: Terminal A | D8: Terminal B | E8: 0.72222222 | F8: 0.81597222 | G8: =VLOOKUP(D8,$J$11:$L$14,3,FALSE) -> 20 | H8: =ROUND(E8*1440,0) -> 1040 | I8: =ROUND(F8*1440,0) -> 1175 | J8: TMAX | K8: =MAX(F3:F32)*1440 -> 1355 | U8: =U7+1 -> 6
A9: AB7 | B9: 135 | C9: Terminal A | D9: Terminal B | E9: 0.76388889 | F9: 0.85763889 | G9: =VLOOKUP(D9,$J$11:$L$14,3,FALSE) -> 20 | H9: =ROUND(E9*1440,0) -> 1100 | I9: =ROUND(F9*1440,0) -> 1235 | U9: =U8+1 -> 7
A10: AB8 | B10: 135 | C10: Terminal A | D10: Terminal B | E10: 0.82638889 | F10: 0.92013889 | G10: =VLOOKUP(D10,$J$11:$L$14,3,FALSE) -> 20 | H10: =ROUND(E10*1440,0) -> 1190 | I10: =ROUND(F10*1440,0) -> 1325 | J10: Terminal | K10: Min_Layover | L10: Duration to CS | U10: =U9+1 -> 8
A11: AC1 | B11: 140 | C11: Terminal A | D11: Terminal C | E11: 0.38541667 | F11: 0.48263889 | G11: =VLOOKUP(D11,$J$11:$L$14,3,FALSE) -> 20 | H11: =ROUND(E11*1440,0) -> 555 | I11: =ROUND(F11*1440,0) -> 695 | J11: Terminal A | K11: 15 | L11: 20 | U11: =U10+1 -> 9
A12: AC2 | B12: 140 | C12: Terminal A | D12: Terminal C | E12: 0.46875 | F12: 0.56597222 | G12: =VLOOKUP(D12,$J$11:$L$14,3,FALSE) -> 20 | H12: =ROUND(E12*1440,0) -> 675 | I12: =ROUND(F12*1440,0) -> 815 | J12: Terminal B | K12: 15 | L12: 20 | U12: =U11+1 -> 10
A13: AC3 | B13: 140 | C13: Terminal A | D13: Terminal C | E13: 0.55208333 | F13: 0.64930556 | G13: =VLOOKUP(D13,$J$11:$L$14,3,FALSE) -> 20 | H13: =ROUND(E13*1440,0) -> 795 | I13: =ROUND(F13*1440,0) -> 935 | J13: Terminal C | K13: 15 | L13: 20 | U13: =U12+1 -> 11
A14: AC4 | B14: 140 | C14: Terminal A | D14: Terminal C | E14: 0.80208333 | F14: 0.89930556 | G14: =VLOOKUP(D14,$J$11:$L$14,3,FALSE) -> 20 | H14: =ROUND(E14*1440,0) -> 1155 | I14: =ROUND(F14*1440,0) -> 1295 | J14: Terminal D | K14: 15 | L14: 20 | U14: =U13+1 -> 12
A15: AC5 | B15: 140 | C15: Terminal A | D15: Terminal C | E15: 0.84375 | F15: 0.94097222 | G15: =VLOOKUP(D15,$J$11:$L$14,3,FALSE) -> 20 | H15: =ROUND(E15*1440,0) -> 1215 | I15: =ROUND(F15*1440,0) -> 1355 | J15: CS | K15: 100 | L15: (MAX_DURATION == 500, time to recharge = 100 seconds) | U15: =U14+1 -> 13
A16: AD1 | B16: 210 | C16: Terminal A | D16: Terminal D | E16: 0.38888889 | F16: 0.53472222 | G16: =VLOOKUP(D16,$J$11:$L$14,3,FALSE) -> 20 | H16: =ROUND(E16*1440,0) -> 560 | I16: =ROUND(F16*1440,0) -> 770 | J16: MAX_DURATION | K16: 350 | U16: =U15+1 -> 14
A17: BA1 | B17: 135 | C17: Terminal B | D17: Terminal A | E17: 0.375 | F17: 0.46875 | G17: =VLOOKUP(D17,$J$11:$L$14,3,FALSE) -> 20 | H17: =ROUND(E17*1440,0) -> 540 | I17: =ROUND(F17*1440,0) -> 675 | U17: =U16+1 -> 15
A18: BA2 | B18: 135 | C18: Terminal B | D18: Terminal A | E18: 0.4375 | F18: 0.53125 | G18: =VLOOKUP(D18,$J$11:$L$14,3,FALSE) -> 20 | H18: =ROUND(E18*1440,0) -> 630 | I18: =ROUND(F18*1440,0) -> 765 | U18: =U17+1 -> 16
A19: BA3 | B19: 135 | C19: Terminal B | D19: Terminal A | E19: 0.5 | F19: 0.59375 | G19: =VLOOKUP(D19,$J$11:$L$14,3,FALSE) -> 20 | H19: =ROUND(E19*1440,0) -> 720 | I19: =ROUND(F19*1440,0) -> 855 | U19: =U18+1 -> 17
A20: BA4 | B20: 135 | C20: Terminal B | D20: Terminal A | E20: 0.5625 | F20: 0.65625 | G20: =VLOOKUP(D20,$J$11:$L$14,3,FALSE) -> 20 | H20: =ROUND(E20*1440,0) -> 810 | I20: =ROUND(F20*1440,0) -> 945 | N20: =VLOOKUP($A5,test!$A$3:$I$32,9,FALSE) -> 965 | U20: =U19+1 -> 18
A21: BA5 | B21: 135 | C21: Terminal B | D21: Terminal A | E21: 0.625 | F21: 0.71875 | G21: =VLOOKUP(D21,$J$11:$L$14,3,FALSE) -> 20 | H21: =ROUND(E21*1440,0) -> 900 | I21: =ROUND(F21*1440,0) -> 1035 | N21: =VLOOKUP("BA6",test!$A$3:$I$32,8,FALSE) -> 990 | U21: =U20+1 -> 19
A22: BA6 | B22: 135 | C22: Terminal B | D22: Terminal A | E22: 0.6875 | F22: 0.78125 | G22: =VLOOKUP(D22,$J$11:$L$14,3,FALSE) -> 20 | H22: =ROUND(E22*1440,0) -> 990 | I22: =ROUND(F22*1440,0) -> 1125 | U22: =U21+1 -> 20
A23: BA7 | B23: 135 | C23: Terminal B | D23: Terminal A | E23: 0.75 | F23: 0.84375 | G23: =VLOOKUP(D23,$J$11:$L$14,3,FALSE) -> 20 | H23: =ROUND(E23*1440,0) -> 1080 | I23: =ROUND(F23*1440,0) -> 1215 | U23: =U22+1 -> 21
A24: BA8 | B24: 135 | C24: Terminal B | D24: Terminal A | E24: 0.79166667 | F24: 0.88541667 | G24: =VLOOKUP(D24,$J$11:$L$14,3,FALSE) -> 20 | H24: =ROUND(E24*1440,0) -> 1140 | I24: =ROUND(F24*1440,0) -> 1275 | U24: =U23+1 -> 22
A25: CA1 | B25: 140 | C25: Terminal C | D25: Terminal A | E25: 0.39583333 | F25: 0.49305556 | G25: =VLOOKUP(D25,$J$11:$L$14,3,FALSE) -> 20 | H25: =ROUND(E25*1440,0) -> 570 | I25: =ROUND(F25*1440,0) -> 710 | U25: =U24+1 -> 23
A26: CA2 | B26: 140 | C26: Terminal C | D26: Terminal A | E26: 0.51388889 | F26: 0.61111111 | G26: =VLOOKUP(D26,$J$11:$L$14,3,FALSE) -> 20 | H26: =ROUND(E26*1440,0) -> 740 | I26: =ROUND(F26*1440,0) -> 880 | U26: =U25+1 -> 24
A27: CA3 | B27: 140 | C27: Terminal C | D27: Terminal A | E27: 0.59722222 | F27: 0.69444444 | G27: =VLOOKUP(D27,$J$11:$L$14,3,FALSE) -> 20 | H27: =ROUND(E27*1440,0) -> 860 | I27: =ROUND(F27*1440,0) -> 1000 | U27: =U26+1 -> 25
A28: CA4 | B28: 140 | C28: Terminal C | D28: Terminal A | E28: 0.63888889 | F28: 0.73611111 | G28: =VLOOKUP(D28,$J$11:$L$14,3,FALSE) -> 20 | H28: =ROUND(E28*1440,0) -> 920 | I28: =ROUND(F28*1440,0) -> 1060 | U28: =U27+1 -> 26
A29: CA5 | B29: 140 | C29: Terminal C | D29: Terminal A | E29: 0.72222222 | F29: 0.81944444 | G29: =VLOOKUP(D29,$J$11:$L$14,3,FALSE) -> 20 | H29: =ROUND(E29*1440,0) -> 1040 | I29: =ROUND(F29*1440,0) -> 1180 | U29: =U28+1 -> 27
A30: CD1 | B30: 270 | C30: Terminal C | D30: Terminal D | E30: 0.3125 | F30: 0.5 | G30: =VLOOKUP(D30,$J$11:$L$14,3,FALSE) -> 20 | H30: =ROUND(E30*1440,0) -> 450 | I30: =ROUND(F30*1440,0) -> 720 | U30: =U29+1 -> 28
A31: DA1 | B31: 210 | C31: Terminal D | D31: Terminal A | E31: 0.59722222 | F31: 0.74305556 | G31: =VLOOKUP(D31,$J$11:$L$14,3,FALSE) -> 20 | H31: =ROUND(E31*1440,0) -> 860 | I31: =ROUND(F31*1440,0) -> 1070 | U31: =U30+1 -> 29
A32: DC1 | B32: 270 | C32: Terminal D | D32: Terminal C | E32: 0.5625 | F32: 0.75 | G32: =VLOOKUP(D32,$J$11:$L$14,3,FALSE) -> 20 | H32: =ROUND(E32*1440,0) -> 810 | I32: =ROUND(F32*1440,0) -> 1080 | U32: =U31+1 -> 30
A33: CS1 | B33: 60 | C33: - | D33: - | E33: - | F33: - | G33: 0
A34: CS2 | B34: 75 | C34: - | D34: - | E34: - | F34: - | G34: 0
A35: CS3 | B35: 60 | C35: - | D35: - | E35: - | F35: - | G35: 0
A40: RESULTS
A41: ID | B41: Trips | F41: CPLEX | G41: Solution
A42: 0 | B42: DEPOT | G42: 0 | H42: 10 | I42: 26 | J42: 0
A43: =A42+1 -> 1 | B43: AB1 | G43: DEPOT | H43: =VLOOKUP(H42,$A$42:$B$73,2,FALSE) -> AC2 | I43: =VLOOKUP(I42,$A$42:$B$73,2,FALSE) -> CA4 | J43: =VLOOKUP(J42,$A$42:$B$73,2,FALSE) -> DEPOT
A44: =A43+1 -> 2 | B44: AB2 | G44: 0 | H44: 1 | I44: 18 | J44: 31 | K44: 13 | L44: 0
...

Sheet Result
A1: RESULTS
A2: ID | B2: Trips | F2: CPLEX | G2: Solution
A3: 0 | B3: DEPOT | G3: 0 | H3: 10 | I3: 26 | J3: 0
A4: =A3+1 -> 1 | B4: AB1 | G4: DEPOT | H4: =VLOOKUP(H3,$A$3:$B$34,2,FALSE) -> AC2 | I4: =VLOOKUP(I3,$A$3:$B$34,2,FALSE) -> CA4 | J4: =VLOOKUP(J3,$A$3:$B$34,2,FALSE) -> DEPOT
A5: =A4+1 -> 2 | B5: AB2 | G5: 0 | H5: 1 | I5: 18 | J5: 31 | K5: 13 | L5: 0
A6: =A5+1 -> 3 | B6: AB3 | G6: =VLOOKUP(G5,$A$3:$B$34,2,FALSE) -> DEPOT | H6: =VLOOKUP(H5,$A$3:$B$34,2,FALSE) -> AB1 | I6: =VLOOKUP(I5,$A$3:$B$34,2,FALSE) -> BA4 | J6: =VLOOKUP(J5,$A$3:$B$34,2,FALSE) -> CS1 | K6: =VLOOKUP(K5,$A$3:$B$34,2,FALSE) -> AC5 | L6: =VLOOKUP(L5,$A$3:$B$34,2,FALSE) -> DEPOT
A7: =A6+1 -> 4 | B7: AB4 | G7: 0 | H7: 2 | I7: 19 | J7: 31 | K7: 8 | L7: 0
A8: =A7+1 -> 5 | B8: AB5 | G8: =VLOOKUP(G7,$A$3:$B$34,2,FALSE) -> DEPOT | H8: =VLOOKUP(H7,$A$3:$B$34,2,FALSE) -> AB2 | I8: =VLOOKUP(I7,$A$3:$B$34,2,FALSE) -> BA5 | J8: =VLOOKUP(J7,$A$3:$B$34,2,FALSE) -> CS1 | K8: =VLOOKUP(K7,$A$3:$B$34,2,FALSE) -> AB8 | L8: =VLOOKUP(L7,$A$3:$B$34,2,FALSE) -> DEPOT
A9: =A8+1 -> 6 | B9: AB6 | G9: 0 | H9: 9 | I9: 31 | J9: 25 | K9: 0
A10: =A9+1 -> 7 | B10: AB7 | G10: =VLOOKUP(G9,$A$3:$B$34,2,FALSE) -> DEPOT | H10: =VLOOKUP(H9,$A$3:$B$34,2,FALSE) -> AC1 | I10: =VLOOKUP(I9,$A$3:$B$34,2,FALSE) -> CS1 | J10: =VLOOKUP(J9,$A$3:$B$34,2,FALSE) -> CA3 | K10: =VLOOKUP(K9,$A$3:$B$34,2,FALSE) -> DEPOT
A11: =A10+1 -> 8 | B11: AB8 | G11: 0 | H11: 11 | I11: 27 | J11: 0
A12: =A11+1 -> 9 | B12: AC1 | G12: =VLOOKUP(G11,$A$3:$B$34,2,FALSE) -> DEPOT | H12: =VLOOKUP(H11,$A$3:$B$34,2,FALSE) -> AC3 | I12: =VLOOKUP(I11,$A$3:$B$34,2,FALSE) -> CA5 | J12: =VLOOKUP(J11,$A$3:$B$34,2,FALSE) -> DEPOT
A13: =A12+1 -> 10 | B13: AC2 | G13: 0 | H13: 14 | I13: 30 | J13: 0
A14: =A13+1 -> 11 | B14: AC3 | G14: =VLOOKUP(G13,$A$3:$B$34,2,FALSE) -> DEPOT | H14: =VLOOKUP(H13,$A$3:$B$34,2,FALSE) -> AD1 | I14: =VLOOKUP(I13,$A$3:$B$34,2,FALSE) -> DC1 | J14: =VLOOKUP(J13,$A$3:$B$34,2,FALSE) -> DEPOT
A15: =A14+1 -> 12 | B15: AC4 | G15: 0 | H15: 15 | I15: 31 | J15: 3 | K15: 20 | L15: 0
A16: =A15+1 -> 13 | B16: AC5 | G16: =VLOOKUP(G15,$A$3:$B$34,2,FALSE) -> DEPOT | H16: =VLOOKUP(H15,$A$3:$B$34,2,FALSE) -> BA1 | I16: =VLOOKUP(I15,$A$3:$B$34,2,FALSE) -> CS1 | J16: =VLOOKUP(J15,$A$3:$B$34,2,FALSE) -> AB3 | K16: =VLOOKUP(K15,$A$3:$B$34,2,FALSE) -> BA6 | L16: =VLOOKUP(L15,$A$3:$B$34,2,FALSE) -> DEPOT
A17: =A16+1 -> 14 | B17: AD1 | G17: 0 | H17: 16 | I17: 31 | J17: 5 | K17: 22 | L17: 0
A18: =A17+1 -> 15 | B18: BA1 | G18: =VLOOKUP(G17,$A$3:$B$34,2,FALSE) -> DEPOT | H18: =VLOOKUP(H17,$A$3:$B$34,2,FALSE) -> BA2 | I18: =VLOOKUP(I17,$A$3:$B$34,2,FALSE) -> CS1 | J18: =VLOOKUP(J17,$A$3:$B$34,2,FALSE) -> AB5 | K18: =VLOOKUP(K17,$A$3:$B$34,2,FALSE) -> BA8 | L18: =VLOOKUP(L17,$A$3:$B$34,2,FALSE) -> DEPOT
A19: =A18+1 -> 16 | B19: BA2 | G19: 0 | H19: 17 | I19: 6 | J19: 0
A20: =A19+1 -> 17 | B20: BA3 | G20: =VLOOKUP(G19,$A$3:$B$34,2,FALSE) -> DEPOT | H20: =VLOOKUP(H19,$A$3:$B$34,2,FALSE) -> BA3 | I20: =VLOOKUP(I19,$A$3:$B$34,2,FALSE) -> AB6 | J20: =VLOOKUP(J19,$A$3:$B$34,2,FALSE) -> DEPOT
A21: =A20+1 -> 18 | B21: BA4 | G21: 0 | H21: 23 | I21: 31 | J21: 4 | K21: 21 | L21: 0
A22: =A21+1 -> 19 | B22: BA5 | G22: =VLOOKUP(G21,$A$3:$B$34,2,FALSE) -> DEPOT | H22: =VLOOKUP(H21,$A$3:$B$34,2,FALSE) -> CA1 | I22: =VLOOKUP(I21,$A$3:$B$34,2,FALSE) -> CS1 | J22: =VLOOKUP(J21,$A$3:$B$34,2,FALSE) -> AB4 | K22: =VLOOKUP(K21,$A$3:$B$34,2,FALSE) -> BA7 | L22: =VLOOKUP(L21,$A$3:$B$34,2,FALSE) -> DEPOT
A23: =A22+1 -> 20 | B23: BA6 | G23: 0 | H23: 24 | I23: 31 | J23: 12 | K23: 0
A24: =A23+1 -> 21 | B24: BA7 | G24: =VLOOKUP(G23,$A$3:$B$34,2,FALSE) -> DEPOT | H24: =VLOOKUP(H23,$A$3:$B$34,2,FALSE) -> CA2 | I24: =VLOOKUP(I23,$A$3:$B$34,2,FALSE) -> CS1 | J24: =VLOOKUP(J23,$A$3:$B$34,2,FALSE) -> AC4 | K24: =VLOOKUP(K23,$A$3:$B$34,2,FALSE) -> DEPOT
A25: =A24+1 -> 22 | B25: BA8 | G25: 0 | H25: 28 | I25: 31 | J25: 29 | K25: 7 | L25: 0
A26: =A25+1 -> 23 | B26: CA1 | G26: =VLOOKUP(G25,$A$3:$B$34,2,FALSE) -> DEPOT | H26: =VLOOKUP(H25,$A$3:$B$34,2,FALSE) -> CD1 | I26: =VLOOKUP(I25,$A$3:$B$34,2,FALSE) -> CS1 | J26: =VLOOKUP(J25,$A$3:$B$34,2,FALSE) -> DA1 | K26: =VLOOKUP(K25,$A$3:$B$34,2,FALSE) -> AB7 | L26: =VLOOKUP(L25,$A$3:$B$34,2,FALSE) -> DEPOT
A27: =A26+1 -> 24 | B27: CA2
A28: =A27+1 -> 25 | B28: CA3
A29: =A28+1 -> 26 | B29: CA4
A30: =A29+1 -> 27 | B30: CA5
A31: =A30+1 -> 28 | B31: CD1
A32: =A31+1 -> 29 | B32: DA1
A33: =A32+1 -> 30 | B33: DC1
A34: =A33+1 -> 31 | B34: CS1

Sheet 10Trips
A1: trip_id | B1: duration | C1: dep_terminal | D1: arr_terminal | E1: dep_time | F1: arr_time | G1: cost_to_cs | H1: ID
A2: DEPOT | B2: 0 | C2: - | D2: - | E2: - | F2: - | G2: - | H2: 0
A3: AC1 | B3: 140 | C3: Terminal A | D3: Terminal C | E3: 0.38541667 | F3: 0.48263889 | G3: =VLOOKUP(D3,$J$11:$L$12,3,FALSE) -> 20 | H3: =H2+1 -> 1 | J3: =E3*1440 -> 555
A4: AC2 | B4: 140 | C4: Terminal A | D4: Terminal C | E4: 0.46875 | F4: 0.56597222 | G4: =VLOOKUP(D4,$J$11:$L$12,3,FALSE) -> 20 | H4: =H3+1 -> 2
A5: AC3 | B5: 140 | C5: Terminal A | D5: Terminal C | E5: 0.55208333 | F5: 0.64930556 | G5: =VLOOKUP(D5,$J$11:$L$12,3,FALSE) -> 20 | H5: =H4+1 -> 3 | J5: =F7*1440 -> 1355
A6: AC4 | B6: 140 | C6: Terminal A | D6: Terminal C | E6: 0.80208333 | F6: 0.89930556 | G6: =VLOOKUP(D6,$J$11:$L$12,3,FALSE) -> 20 | H6: =H5+1 -> 4
A7: AC5 | B7: 140 | C7: Terminal A | D7: Terminal C | E7: 0.84375 | F7: 0.94097222 | G7: =VLOOKUP(D7,$J$11:$L$12,3,FALSE) -> 20 | H7: =H6+1 -> 5
A8: CA1 | B8: 140 | C8: Terminal C | D8: Terminal A | E8: 0.39583333 | F8: 0.49305556 | G8: =VLOOKUP(D8,$J$11:$L$12,3,FALSE) -> 20 | H8: =H7+1 -> 6 | J8: TMAX | K8: =MAX(F3:F12)*1440 -> 1355
A9: CA2 | B9: 140 | C9: Terminal C | D9: Terminal A | E9: 0.51388889 | F9: 0.61111111 | G9: =VLOOKUP(D9,$J$11:$L$12,3,FALSE) -> 20 | H9: =H8+1 -> 7
A10: CA3 | B10: 140 | C10: Terminal C | D10: Terminal A | E10: 0.59722222 | F10: 0.69444444 | G10: =VLOOKUP(D10,$J$11:$L$12,3,FALSE) -> 20 | H10: =H9+1 -> 8 | J10: Terminal | K10: Min_Layover | L10: Duration to CS
A11: CA4 | B11: 140 | C11: Terminal C | D11: Terminal A | E11: 0.63888889 | F11: 0.73611111 | G11: =VLOOKUP(D11,$J$11:$L$12,3,FALSE) -> 20 | H11: =H10+1 -> 9 | J11: Terminal A | K11: 15 | L11: 20
A12: CA5 | B12: 140 | C12: Terminal C | D12: Terminal A | E12: 0.72222222 | F12: 0.81944444 | G12: =VLOOKUP(D12,$J$11:$L$12,3,FALSE) -> 20 | H12: =H11+1 -> 10 | J12: Terminal C | K12: 15 | L12: 20
A13: CS1 | B13: 60 | C13: - | D13: - | E13: - | F13: - | G13: - | H13: =H12+1 -> 11 | J13: 100 | K13: (MAX_DURATION == 500, time to recharge = 100mins)
A14: CS2 | B14: 75 | C14: - | D14: - | E14: - | F14: - | G14: - | H14: 12 | J14: MAX_DURATION | K14: 350
A16: \gamma | B16: DEPOT | C16: AC1 | D16: AC2 | E16: AC3 | F16: AC4 | G16: AC5 | H16: CA1 | I16: CA2 | J16: CA3 | K16: CA4 | L16: CA5 | O16: \delta | P16: DEPOT | Q16: AC1 | R16: AC2 | S16: AC3 | T16: AC4 | U16: AC5 | V16: CA1 | W16: CA2 | X16: CA3 | Y16: CA4 | Z16: CA5 | AA16: CS1 | AB16: CS2
A17: DEPOT | B17: 0 | C17: 1 | D17: 1 | E17: 1 | F17: 1 | G17: 1 | H17: 1 | I17: 1 | J17: 1 | K17: 1 | L17: 1 | O17: DEPOT | P17: 0 | Q17: 0 | R17: 0 | S17: 0 | T17: 0 | U17: 0 | V17: 0 | W17: 0 | X17: 0 | Y17: 0 | Z17: 0 | AA17: 0 | AB17: 0
A18: AC1 | B18: 1 | C18: =IF(AND(VLOOKUP(C$16,$A$3:$G$12,5,FALSE) - VLOOKUP($A18,$A$3:$G$12,6,FALSE)>=VLOOKUP(VLOOKUP(C$16,$A$3:$G$12,3,FALSE), $J$11:$L$12, 2, FALSE)/1440, VLOOKUP($A18,$A$3:$G$12,4,FALSE)=VLOOKUP(C$16,$A$3:$G$12,3,FALSE)),1,0) -> 0 | D18: =IF(AND(VLOOKUP(D$16,$A$3:$G$12,5,FALSE) - VLOOKUP($A18,$A$3:$G$12,6,FALSE)>=VLOOKUP(VLOOKUP(D$16,$A$3:$G$12,3,FALSE), $J$11:$L$12, 2, FALSE)/1440, VLOOKUP($A18,$A$3:$G$12,4,FALSE)=VLOOKUP(D$16,$A$3:$G$12,3,FALSE)),1,0) -> 0 | E18: =IF(AND(VLOOKUP(E$16,$A$3:$G$12,5,FALSE) - VLOOKUP($A18,$A$3:$G$12,6,FALSE)>=VLOOKUP(VLOOKUP(E$16,$A$3:$G$12,3,FALSE), $J$11:$L$12, 2, FALSE)/1440, VLOOKUP($A18,$A$3:$G$12,4,FALSE)=VLOOKUP(E$16,$A$3:$G$12,3,FALSE)),1,0) -> 0 | F18: =IF(AND(VLOOKUP(F$16,$A$3:$G$12,5,FALSE) - VLOOKUP($A18,$A$3:$G$12,6,FALSE)>=VLOOKUP(VLOOKUP(F$16,$A$3:$G$12,3,FALSE), $J$11:$L$12, 2, FALSE)/1440, VLOOKUP($A18,$A$3:$G$12,4,FALSE)=VLOOKUP(F$16,$A$3:$G$12,3,FALSE)),1,0) -> 0 | G18: =IF(AND(VLOOKUP(G$16,$A$3:$G$12,5,FALSE) - VLOOKUP($A18,$A$3:$G$12,6,FALSE)>=VLOOKUP(VLOOKUP(G$16,$A$3:$G$12,3,FALSE), $J$11:$L$12, 2, FALSE)/1440, VLOOKUP($A18,$A$3:$G$12,4,FALSE)=VLOOKUP(G$16,$A$3:$G$12,3,FALSE)),1,0) -> 0 | H18: =IF(AND(VLOOKUP(H$16,$A$3:$G$12,5,FALSE) - VLOOKUP($A18,$A$3:$G$12,6,FALSE)>=VLOOKUP(VLOOKUP(H$16,$A$3:$G$12,3,FALSE), $J$11:$L$12, 2, FALSE)/1440, VLOOKUP($A18,$A$3:$G$12,4,FALSE)=VLOOKUP(H$16,$A$3:$G$12,3,FALSE)),1,0) -> 0 | I18: =IF(AND(VLOOKUP(I$16,$A$3:$G$12,5,FALSE) - VLOOKUP($A18,$A$3:$G$12,6,FALSE)>=VLOOKUP(VLOOKUP(I$16,$A$3:$G$12,3,FALSE), $J$11:$L$12, 2, FALSE)/1440, VLOOKUP($A18,$A$3:$G$12,4,FALSE)=VLOOKUP(I$16,$A$3:$G$12,3,FALSE)),1,0) -> 1 | J18: =IF(AND(VLOOKUP(J$16,$A$3:$G$12,5,FALSE) - VLOOKUP($A18,$A$3:$G$12,6,FALSE)>=VLOOKUP(VLOOKUP(J$16,$A$3:$G$12,3,FALSE), $J$11:$L$12, 2, FALSE)/1440, VLOOKUP($A18,$A$3:$G$12,4,FALSE)=VLOOKUP(J$16,$A$3:$G$12,3,FALSE)),1,0) -> 1 | ... L18: =IF(AND(VLOOKUP(L$16,$A$3:$G$12,5,FALSE) - VLOOKUP($A18,$A$3:$G$12,6,FALSE)>=VLOOKUP(VLOOKUP(L$16,$A$3:$G$12,3,FALSE), $J$11:$L$12, 2, FALSE)/1440, VLOOKUP($A18,$A$3:$G$12,4,FALSE)=VLOOKUP(L$16,$A$3:$G$12,3,FALSE)),1,0) -> 1 | O18: AC1 | P18: 0 | Q18: 0 | R18: =IF(AND(SUM(VLOOKUP($O18,$A$3:$G$12,2,FALSE),VLOOKUP(R$16,$A$3:$G$12,2,FALSE))<$K$14,$O18<>R$16,D18=1),SUM(VLOOKUP($O18,$A$3:$G$12,2,FALSE),VLOOKUP(R$16,$A$3:$G$12,2,FALSE)),0) -> 0 | S18: =IF(AND(SUM(VLOOKUP($O18,$A$3:$G$12,2,FALSE),VLOOKUP(S$16,$A$3:$G$12,2,FALSE))<$K$14,$O18<>S$16,E18=1),SUM(VLOOKUP($O18,$A$3:$G$12,2,FALSE),VLOOKUP(S$16,$A$3:$G$12,2,FALSE)),0) -> 0 | T18: =IF(AND(SUM(VLOOKUP($O18,$A$3:$G$12,2,FALSE),VLOOKUP(T$16,$A$3:$G$12,2,FALSE))<$K$14,$O18<>T$16,F18=1),SUM(VLOOKUP($O18,$A$3:$G$12,2,FALSE),VLOOKUP(T$16,$A$3:$G$12,2,FALSE)),0) -> 0 | U18: =IF(AND(SUM(VLOOKUP($O18,$A$3:$G$12,2,FALSE),VLOOKUP(U$16,$A$3:$G$12,2,FALSE))<$K$14,$O18<>U$16,G18=1),SUM(VLOOKUP($O18,$A$3:$G$12,2,FALSE),VLOOKUP(U$16,$A$3:$G$12,2,FALSE)),0) -> 0 | V18: =IF(AND(SUM(VLOOKUP($O18,$A$3:$G$12,2,FALSE),VLOOKUP(V$16,$A$3:$G$12,2,FALSE))<$K$14,$O18<>V$16,H18=1),SUM(VLOOKUP($O18,$A$3:$G$12,2,FALSE),VLOOKUP(V$16,$A$3:$G$12,2,FALSE)),0) -> 0 | W18: 280 | X18: 280 | Y18: 280 | Z18: 280 | AA18: 60 | AB18: 75 | AG18: \zeta | AH18: DEPOT | AI18: AC1 | AJ18: AC2 | AK18: AC3 | AL18: AC4 | AM18: AC5 | AN18: CA1 | AO18: CA2 | AP18: CA3 | AQ18: CA4 | AR18: CA5 | AS18: CS1 | AT18: CS2
A19: AC2 | B19: 1 | C19: =IF(AND(VLOOKUP(C$16,$A$3:$G$12,5,FALSE) - VLOOKUP($A19,$A$3:$G$12,6,FALSE)>=VLOOKUP(VLOOKUP(C$16,$A$3:$G$12,3,FALSE), $J$11:$L$12, 2, FALSE)/1440, VLOOKUP($A19,$A$3:$G$12,4,FALSE)=VLOOKUP(C$16,$A$3:$G$12,3,FALSE)),1,0) -> 0 | D19: =IF(AND(VLOOKUP(D$16,$A$3:$G$12,5,FALSE) - VLOOKUP($A19,$A$3:$G$12,6,FALSE)>=VLOOKUP(VLOOKUP(D$16,$A$3:$G$12,3,FALSE), $J$11:$L$12, 2, FALSE)/1440, VLOOKUP($A19,$A$3:$G$12,4,FALSE)=VLOOKUP(D$16,$A$3:$G$12,3,FALSE)),1,0) -> 0 | E19: =IF(AND(VLOOKUP(E$16,$A$3:$G$12,5,FALSE) - VLOOKUP($A19,$A$3:$G$12,6,FALSE)>=VLOOKUP(VLOOKUP(E$16,$A$3:$G$12,3,FALSE), $J$11:$L$12, 2, FALSE)/1440, VLOOKUP($A19,$A$3:$G$12,4,FALSE)=VLOOKUP(E$16,$A$3:$G$12,3,FALSE)),1,0) -> 0 | F19: =IF(AND(VLOOKUP(F$16,$A$3:$G$12,5,FALSE) - VLOOKUP($A19,$A$3:$G$12,6,FALSE)>=VLOOKUP(VLOOKUP(F$16,$A$3:$G$12,3,FALSE), $J$11:$L$12, 2, FALSE)/1440, VLOOKUP($A19,$A$3:$G$12,4,FALSE)=VLOOKUP(F$16,$A$3:$G$12,3,FALSE)),1,0) -> 0 | G19: =IF(AND(VLOOKUP(G$16,$A$3:$G$12,5,FALSE) - VLOOKUP($A19,$A$3:$G$12,6,FALSE)>=VLOOKUP(VLOOKUP(G$16,$A$3:$G$12,3,FALSE), $J$11:$L$12, 2, FALSE)/1440, VLOOKUP($A19,$A$3:$G$12,4,FALSE)=VLOOKUP(G$16,$A$3:$G$12,3,FALSE)),1,0) -> 0 | H19: =IF(AND(VLOOKUP(H$16,$A$3:$G$12,5,FALSE) - VLOOKUP($A19,$A$3:$G$12,6,FALSE)>=VLOOKUP(VLOOKUP(H$16,$A$3:$G$12,3,FALSE), $J$11:$L$12, 2, FALSE)/1440, VLOOKUP($A19,$A$3:$G$12,4,FALSE)=VLOOKUP(H$16,$A$3:$G$12,3,FALSE)),1,0) -> 0 | I19: =IF(AND(VLOOKUP(I$16,$A$3:$G$12,5,FALSE) - VLOOKUP($A19,$A$3:$G$12,6,FALSE)>=VLOOKUP(VLOOKUP(I$16,$A$3:$G$12,3,FALSE), $J$11:$L$12, 2, FALSE)/1440, VLOOKUP($A19,$A$3:$G$12,4,FALSE)=VLOOKUP(I$16,$A$3:$G$12,3,FALSE)),1,0) -> 0 | J19: =IF(AND(VLOOKUP(J$16,$A$3:$G$12,5,FALSE) - VLOOKUP($A19,$A$3:$G$12,6,FALSE)>=VLOOKUP(VLOOKUP(J$16,$A$3:$G$12,3,FALSE), $J$11:$L$12, 2, FALSE)/1440, VLOOKUP($A19,$A$3:$G$12,4,FALSE)=VLOOKUP(J$16,$A$3:$G$12,3,FALSE)),1,0) -> 1 | ... L19: =IF(AND(VLOOKUP(L$16,$A$3:$G$12,5,FALSE) - VLOOKUP($A19,$A$3:$G$12,6,FALSE)>=VLOOKUP(VLOOKUP(L$16,$A$3:$G$12,3,FALSE), $J$11:$L$12, 2, FALSE)/1440, VLOOKUP($A19,$A$3:$G$12,4,FALSE)=VLOOKUP(L$16,$A$3:$G$12,3,FALSE)),1,0) -> 1 | O19: AC2 | P19: 0 | Q19: =IF(AND(SUM(VLOOKUP($O19,$A$3:$G$12,2,FALSE),VLOOKUP(Q$16,$A$3:$G$12,2,FALSE))<$K$14,$O19<>Q$16,C19=1),SUM(VLOOKUP($O19,$A$3:$G$12,2,FALSE),VLOOKUP(Q$16,$A$3:$G$12,2,FALSE)),0) -> 0 | R19: =IF(AND(SUM(VLOOKUP($O19,$A$3:$G$12,2,FALSE),VLOOKUP(R$16,$A$3:$G$12,2,FALSE))<$K$14,$O19<>R$16,D19=1),SUM(VLOOKUP($O19,$A$3:$G$12,2,FALSE),VLOOKUP(R$16,$A$3:$G$12,2,FALSE)),0) -> 0 | S19: =IF(AND(SUM(VLOOKUP($O19,$A$3:$G$12,2,FALSE),VLOOKUP(S$16,$A$3:$G$12,2,FALSE))<$K$14,$O19<>S$16,E19=1),SUM(VLOOKUP($O19,$A$3:$G$12,2,FALSE),VLOOKUP(S$16,$A$3:$G$12,2,FALSE)),0) -> 0 | T19: =IF(AND(SUM(VLOOKUP($O19,$A$3:$G$12,2,FALSE),VLOOKUP(T$16,$A$3:$G$12,2,FALSE))<$K$14,$O19<>T$16,F19=1),SUM(VLOOKUP($O19,$A$3:$G$12,2,FALSE),VLOOKUP(T$16,$A$3:$G$12,2,FALSE)),0) -> 0 | U19: =IF(AND(SUM(VLOOKUP($O19,$A$3:$G$12,2,FALSE),VLOOKUP(U$16,$A$3:$G$12,2,FALSE))<$K$14,$O19<>U$16,G19=1),SUM(VLOOKUP($O19,$A$3:$G$12,2,FALSE),VLOOKUP(U$16,$A$3:$G$12,2,FALSE)),0) -> 0 | V19: =IF(AND(SUM(VLOOKUP($O19,$A$3:$G$12,2,FALSE),VLOOKUP(V$16,$A$3:$G$12,2,FALSE))<$K$14,$O19<>V$16,H19=1),SUM(VLOOKUP($O19,$A$3:$G$12,2,FALSE),VLOOKUP(V$16,$A$3:$G$12,2,FALSE)),0) -> 0 | W19: =IF(AND(SUM(VLOOKUP($O19,$A$3:$G$12,2,FALSE),VLOOKUP(W$16,$A$3:$G$12,2,FALSE))<$K$14,$O19<>W$16,I19=1),SUM(VLOOKUP($O19,$A$3:$G$12,2,FALSE),VLOOKUP(W$16,$A$3:$G$12,2,FALSE)),0) -> 0 | X19: 280 | Y19: 280 | Z19: 280 | AA19: 60 | AB19: 75 | AG19: DEPOT | AH19: 0 | AI19: 0 | AJ19: 0 | AK19: 0 | AL19: 0 | AM19: 0 | AN19: 0 | AO19: 0 | AP19: 0 | AQ19: 0 | AR19: 0 | AS19: 10 | AT19: 15
A20: AC3 | B20: 1 | C20: =IF(AND(VLOOKUP(C$16,$A$3:$G$12,5,FALSE) - VLOOKUP($A20,$A$3:$G$12,6,FALSE)>=VLOOKUP(VLOOKUP(C$16,$A$3:$G$12,3,FALSE), $J$11:$L$12, 2, FALSE)/1440, VLOOKUP($A20,$A$3:$G$12,4,FALSE)=VLOOKUP(C$16,$A$3:$G$12,3,FALSE)),1,0) -> 0 | D20: =IF(AND(VLOOKUP(D$16,$A$3:$G$12,5,FALSE) - VLOOKUP($A20,$A$3:$G$12,6,FALSE)>=VLOOKUP(VLOOKUP(D$16,$A$3:$G$12,3,FALSE), $J$11:$L$12, 2, FALSE)/1440, VLOOKUP($A20,$A$3:$G$12,4,FALSE)=VLOOKUP(D$16,$A$3:$G$12,3,FALSE)),1,0) -> 0 | E20: =IF(AND(VLOOKUP(E$16,$A$3:$G$12,5,FALSE) - VLOOKUP($A20,$A$3:$G$12,6,FALSE)>=VLOOKUP(VLOOKUP(E$16,$A$3:$G$12,3,FALSE), $J$11:$L$12, 2, FALSE)/1440, VLOOKUP($A20,$A$3:$G$12,4,FALSE)=VLOOKUP(E$16,$A$3:$G$12,3,FALSE)),1,0) -> 0 | F20: =IF(AND(VLOOKUP(F$16,$A$3:$G$12,5,FALSE) - VLOOKUP($A20,$A$3:$G$12,6,FALSE)>=VLOOKUP(VLOOKUP(F$16,$A$3:$G$12,3,FALSE), $J$11:$L$12, 2, FALSE)/1440, VLOOKUP($A20,$A$3:$G$12,4,FALSE)=VLOOKUP(F$16,$A$3:$G$12,3,FALSE)),1,0) -> 0 | G20: =IF(AND(VLOOKUP(G$16,$A$3:$G$12,5,FALSE) - VLOOKUP($A20,$A$3:$G$12,6,FALSE)>=VLOOKUP(VLOOKUP(G$16,$A$3:$G$12,3,FALSE), $J$11:$L$12, 2, FALSE)/1440, VLOOKUP($A20,$A$3:$G$12,4,FALSE)=VLOOKUP(G$16,$A$3:$G$12,3,FALSE)),1,0) -> 0 | H20: =IF(AND(VLOOKUP(H$16,$A$3:$G$12,5,FALSE) - VLOOKUP($A20,$A$3:$G$12,6,FALSE)>=VLOOKUP(VLOOKUP(H$16,$A$3:$G$12,3,FALSE), $J$11:$L$12, 2, FALSE)/1440, VLOOKUP($A20,$A$3:$G$12,4,FALSE)=VLOOKUP(H$16,$A$3:$G$12,3,FALSE)),1,0) -> 0 | I20: =IF(AND(VLOOKUP(I$16,$A$3:$G$12,5,FALSE) - VLOOKUP($A20,$A$3:$G$12,6,FALSE)>=VLOOKUP(VLOOKUP(I$16,$A$3:$G$12,3,FALSE), $J$11:$L$12, 2, FALSE)/1440, VLOOKUP($A20,$A$3:$G$12,4,FALSE)=VLOOKUP(I$16,$A$3:$G$12,3,FALSE)),1,0) -> 0 | J20: =IF(AND(VLOOKUP(J$16,$A$3:$G$12,5,FALSE) - VLOOKUP($A20,$A$3:$G$12,6,FALSE)>=VLOOKUP(VLOOKUP(J$16,$A$3:$G$12,3,FALSE), $J$11:$L$12, 2, FALSE)/1440, VLOOKUP($A20,$A$3:$G$12,4,FALSE)=VLOOKUP(J$16,$A$3:$G$12,3,FALSE)),1,0) -> 0 | ... L20: =IF(AND(VLOOKUP(L$16,$A$3:$G$12,5,FALSE) - VLOOKUP($A20,$A$3:$G$12,6,FALSE)>=VLOOKUP(VLOOKUP(L$16,$A$3:$G$12,3,FALSE), $J$11:$L$12, 2, FALSE)/1440, VLOOKUP($A20,$A$3:$G$12,4,FALSE)=VLOOKUP(L$16,$A$3:$G$12,3,FALSE)),1,0) -> 1 | O20: AC3 | P20: 0 | Q20: =IF(AND(SUM(VLOOKUP($O20,$A$3:$G$12,2,FALSE),VLOOKUP(Q$16,$A$3:$G$12,2,FALSE))<$K$14,$O20<>Q$16,C20=1),SUM(VLOOKUP($O20,$A$3:$G$12,2,FALSE),VLOOKUP(Q$16,$A$3:$G$12,2,FALSE)),0) -> 0 | R20: =IF(AND(SUM(VLOOKUP($O20,$A$3:$G$12,2,FALSE),VLOOKUP(R$16,$A$3:$G$12,2,FALSE))<$K$14,$O20<>R$16,D20=1),SUM(VLOOKUP($O20,$A$3:$G$12,2,FALSE),VLOOKUP(R$16,$A$3:$G$12,2,FALSE)),0) -> 0 | S20: =IF(AND(SUM(VLOOKUP($O20,$A$3:$G$12,2,FALSE),VLOOKUP(S$16,$A$3:$G$12,2,FALSE))<$K$14,$O20<>S$16,E20=1),SUM(VLOOKUP($O20,$A$3:$G$12,2,FALSE),VLOOKUP(S$16,$A$3:$G$12,2,FALSE)),0) -> 0 | T20: =IF(AND(SUM(VLOOKUP($O20,$A$3:$G$12,2,FALSE),VLOOKUP(T$16,$A$3:$G$12,2,FALSE))<$K$14,$O20<>T$16,F20=1),SUM(VLOOKUP($O20,$A$3:$G$12,2,FALSE),VLOOKUP(T$16,$A$3:$G$12,2,FALSE)),0) -> 0 | U20: =IF(AND(SUM(VLOOKUP($O20,$A$3:$G$12,2,FALSE),VLOOKUP(U$16,$A$3:$G$12,2,FALSE))<$K$14,$O20<>U$16,G20=1),SUM(VLOOKUP($O20,$A$3:$G$12,2,FALSE),VLOOKUP(U$16,$A$3:$G$12,2,FALSE)),0) -> 0 | V20: =IF(AND(SUM(VLOOKUP($O20,$A$3:$G$12,2,FALSE),VLOOKUP(V$16,$A$3:$G$12,2,FALSE))<$K$14,$O20<>V$16,H20=1),SUM(VLOOKUP($O20,$A$3:$G$12,2,FALSE),VLOOKUP(V$16,$A$3:$G$12,2,FALSE)),0) -> 0 | W20: =IF(AND(SUM(VLOOKUP($O20,$A$3:$G$12,2,FALSE),VLOOKUP(W$16,$A$3:$G$12,2,FALSE))<$K$14,$O20<>W$16,I20=1),SUM(VLOOKUP($O20,$A$3:$G$12,2,FALSE),VLOOKUP(W$16,$A$3:$G$12,2,FALSE)),0) -> 0 | X20: =IF(AND(SUM(VLOOKUP($O20,$A$3:$G$12,2,FALSE),VLOOKUP(X$16,$A$3:$G$12,2,FALSE))<$K$14,$O20<>X$16,J20=1),SUM(VLOOKUP($O20,$A$3:$G$12,2,FALSE),VLOOKUP(X$16,$A$3:$G$12,2,FALSE)),0) -> 0 | Y20: =IF(AND(SUM(VLOOKUP($O20,$A$3:$G$12,2,FALSE),VLOOKUP(Y$16,$A$3:$G$12,2,FALSE))<$K$14,$O20<>Y$16,K20=1),SUM(VLOOKUP($O20,$A$3:$G$12,2,FALSE),VLOOKUP(Y$16,$A$3:$G$12,2,FALSE)),0) -> 0 | Z20: 280 | AA20: 60 | AB20: 75 | AG20: AC1 | AH20: 0 | AI20: =IF(AND(SUM(VLOOKUP($AG20,$A$2:$H$12,2,FALSE),VLOOKUP(AI$18,$A$2:$H$12,2,FALSE))<$K$14,$AG20<>AI$18,C18=1),(VLOOKUP(AI$18,$A$2:$H$12,5,FALSE)*1440)-(VLOOKUP($AG20,$A$2:$H$12,6,FALSE))*1440,0) -> 0 | AJ20: =IF(AND(SUM(VLOOKUP($AG20,$A$2:$H$12,2,FALSE),VLOOKUP(AJ$18,$A$2:$H$12,2,FALSE))<$K$14,$AG20<>AJ$18,D18=1),(VLOOKUP(AJ$18,$A$2:$H$12,5,FALSE)*1440)-(VLOOKUP($AG20,$A$2:$H$12,6,FALSE))*1440,0) -> 0 | AK20: =IF(AND(SUM(VLOOKUP($AG20,$A$2:$H$12,2,FALSE),VLOOKUP(AK$18,$A$2:$H$12,2,FALSE))<$K$14,$AG20<>AK$18,E18=1),(VLOOKUP(AK$18,$A$2:$H$12,5,FALSE)*1440)-(VLOOKUP($AG20,$A$2:$H$12,6,FALSE))*1440,0) -> 0 | AL20: =IF(AND(SUM(VLOOKUP($AG20,$A$2:$H$12,2,FALSE),VLOOKUP(AL$18,$A$2:$H$12,2,FALSE))<$K$14,$AG20<>AL$18,F18=1),(VLOOKUP(AL$18,$A$2:$H$12,5,FALSE)*1440)-(VLOOKUP($AG20,$A$2:$H$12,6,FALSE))*1440,0) -> 0 | AM20: =IF(AND(SUM(VLOOKUP($AG20,$A$2:$H$12,2,FALSE),VLOOKUP(AM$18,$A$2:$H$12,2,FALSE))<$K$14,$AG20<>AM$18,G18=1),(VLOOKUP(AM$18,$A$2:$H$12,5,FALSE)*1440)-(VLOOKUP($AG20,$A$2:$H$12,6,FALSE))*1440,0) -> 0 | AN20: =IF(AND(SUM(VLOOKUP($AG20,$A$2:$H$12,2,FALSE),VLOOKUP(AN$18,$A$2:$H$12,2,FALSE))<$K$14,$AG20<>AN$18,H18=1),(VLOOKUP(AN$18,$A$2:$H$12,5,FALSE)*1440)-(VLOOKUP($AG20,$A$2:$H$12,6,FALSE))*1440,0) -> 0 | AO20: =IF(AND(SUM(VLOOKUP($AG20,$A$2:$H$12,2,FALSE),VLOOKUP(AO$18,$A$2:$H$12,2,FALSE))<$K$14,$AG20<>AO$18,I18=1),(VLOOKUP(AO$18,$A$2:$H$12,5,FALSE)*1440)-(VLOOKUP($AG20,$A$2:$H$12,6,FALSE))*1440,0) -> 45 | AP20: =IF(AND(SUM(VLOOKUP($AG20,$A$2:$H$12,2,FALSE),VLOOKUP(AP$18,$A$2:$H$12,2,FALSE))<$K$14,$AG20<>AP$18,J18=1),(VLOOKUP(AP$18,$A$2:$H$12,5,FALSE)*1440)-(VLOOKUP($AG20,$A$2:$H$12,6,FALSE))*1440,0) -> 165 | ... AR20: =IF(AND(SUM(VLOOKUP($AG20,$A$2:$H$12,2,FALSE),VLOOKUP(AR$18,$A$2:$H$12,2,FALSE))<$K$14,$AG20<>AR$18,L18=1),(VLOOKUP(AR$18,$A$2:$H$12,5,FALSE)*1440)-(VLOOKUP($AG20,$A$2:$H$12,6,FALSE))*1440,0) -> 345 | AS20: 10 | AT20: 15
A21: AC4 | B21: 1 | C21: =IF(AND(VLOOKUP(C$16,$A$3:$G$12,5,FALSE) - VLOOKUP($A21,$A$3:$G$12,6,FALSE)>=VLOOKUP(VLOOKUP(C$16,$A$3:$G$12,3,FALSE), $J$11:$L$12, 2, FALSE)/1440, VLOOKUP($A21,$A$3:$G$12,4,FALSE)=VLOOKUP(C$16,$A$3:$G$12,3,FALSE)),1,0) -> 0 | D21: =IF(AND(VLOOKUP(D$16,$A$3:$G$12,5,FALSE) - VLOOKUP($A21,$A$3:$G$12,6,FALSE)>=VLOOKUP(VLOOKUP(D$16,$A$3:$G$12,3,FALSE), $J$11:$L$12, 2, FALSE)/1440, VLOOKUP($A21,$A$3:$G$12,4,FALSE)=VLOOKUP(D$16,$A$3:$G$12,3,FALSE)),1,0) -> 0 | E21: =IF(AND(VLOOKUP(E$16,$A$3:$G$12,5,FALSE) - VLOOKUP($A21,$A$3:$G$12,6,FALSE)>=VLOOKUP(VLOOKUP(E$16,$A$3:$G$12,3,FALSE), $J$11:$L$12, 2, FALSE)/1440, VLOOKUP($A21,$A$3:$G$12,4,FALSE)=VLOOKUP(E$16,$A$3:$G$12,3,FALSE)),1,0) -> 0 | F21: =IF(AND(VLOOKUP(F$16,$A$3:$G$12,5,FALSE) - VLOOKUP($A21,$A$3:$G$12,6,FALSE)>=VLOOKUP(VLOOKUP(F$16,$A$3:$G$12,3,FALSE), $J$11:$L$12, 2, FALSE)/1440, VLOOKUP($A21,$A$3:$G$12,4,FALSE)=VLOOKUP(F$16,$A$3:$G$12,3,FALSE)),1,0) -> 0 | G21: =IF(AND(VLOOKUP(G$16,$A$3:$G$12,5,FALSE) - VLOOKUP($A21,$A$3:$G$12,6,FALSE)>=VLOOKUP(VLOOKUP(G$16,$A$3:$G$12,3,FALSE), $J$11:$L$12, 2, FALSE)/1440, VLOOKUP($A21,$A$3:$G$12,4,FALSE)=VLOOKUP(G$16,$A$3:$G$12,3,FALSE)),1,0) -> 0 | H21: =IF(AND(VLOOKUP(H$16,$A$3:$G$12,5,FALSE) - VLOOKUP($A21,$A$3:$G$12,6,FALSE)>=VLOOKUP(VLOOKUP(H$16,$A$3:$G$12,3,FALSE), $J$11:$L$12, 2, FALSE)/1440, VLOOKUP($A21,$A$3:$G$12,4,FALSE)=VLOOKUP(H$16,$A$3:$G$12,3,FALSE)),1,0) -> 0 | I21: =IF(AND(VLOOKUP(I$16,$A$3:$G$12,5,FALSE) - VLOOKUP($A21,$A$3:$G$12,6,FALSE)>=VLOOKUP(VLOOKUP(I$16,$A$3:$G$12,3,FALSE), $J$11:$L$12, 2, FALSE)/1440, VLOOKUP($A21,$A$3:$G$12,4,FALSE)=VLOOKUP(I$16,$A$3:$G$12,3,FALSE)),1,0) -> 0 | J21: =IF(AND(VLOOKUP(J$16,$A$3:$G$12,5,FALSE) - VLOOKUP($A21,$A$3:$G$12,6,FALSE)>=VLOOKUP(VLOOKUP(J$16,$A$3:$G$12,3,FALSE), $J$11:$L$12, 2, FALSE)/1440, VLOOKUP($A21,$A$3:$G$12,4,FALSE)=VLOOKUP(J$16,$A$3:$G$12,3,FALSE)),1,0) -> 0 | ... L21: =IF(AND(VLOOKUP(L$16,$A$3:$G$12,5,FALSE) - VLOOKUP($A21,$A$3:$G$12,6,FALSE)>=VLOOKUP(VLOOKUP(L$16,$A$3:$G$12,3,FALSE), $J$11:$L$12, 2, FALSE)/1440, VLOOKUP($A21,$A$3:$G$12,4,FALSE)=VLOOKUP(L$16,$A$3:$G$12,3,FALSE)),1,0) -> 0 | O21: AC4 | P21: 0 | Q21: =IF(AND(SUM(VLOOKUP($O21,$A$3:$G$12,2,FALSE),VLOOKUP(Q$16,$A$3:$G$12,2,FALSE))<$K$14,$O21<>Q$16,C21=1),SUM(VLOOKUP($O21,$A$3:$G$12,2,FALSE),VLOOKUP(Q$16,$A$3:$G$12,2,FALSE)),0) -> 0 | R21: =IF(AND(SUM(VLOOKUP($O21,$A$3:$G$12,2,FALSE),VLOOKUP(R$16,$A$3:$G$12,2,FALSE))<$K$14,$O21<>R$16,D21=1),SUM(VLOOKUP($O21,$A$3:$G$12,2,FALSE),VLOOKUP(R$16,$A$3:$G$12,2,FALSE)),0) -> 0 | S21: =IF(AND(SUM(VLOOKUP($O21,$A$3:$G$12,2,FALSE),VLOOKUP(S$16,$A$3:$G$12,2,FALSE))<$K$14,$O21<>S$16,E21=1),SUM(VLOOKUP($O21,$A$3:$G$12,2,FALSE),VLOOKUP(S$16,$A$3:$G$12,2,FALSE)),0) -> 0 | T21: =IF(AND(SUM(VLOOKUP($O21,$A$3:$G$12,2,FALSE),VLOOKUP(T$16,$A$3:$G$12,2,FALSE))<$K$14,$O21<>T$16,F21=1),SUM(VLOOKUP($O21,$A$3:$G$12,2,FALSE),VLOOKUP(T$16,$A$3:$G$12,2,FALSE)),0) -> 0 | U21: =IF(AND(SUM(VLOOKUP($O21,$A$3:$G$12,2,FALSE),VLOOKUP(U$16,$A$3:$G$12,2,FALSE))<$K$14,$O21<>U$16,G21=1),SUM(VLOOKUP($O21,$A$3:$G$12,2,FALSE),VLOOKUP(U$16,$A$3:$G$12,2,FALSE)),0) -> 0 | V21: =IF(AND(SUM(VLOOKUP($O21,$A$3:$G$12,2,FALSE),VLOOKUP(V$16,$A$3:$G$12,2,FALSE))<$K$14,$O21<>V$16,H21=1),SUM(VLOOKUP($O21,$A$3:$G$12,2,FALSE),VLOOKUP(V$16,$A$3:$G$12,2,FALSE)),0) -> 0 | W21: =IF(AND(SUM(VLOOKUP($O21,$A$3:$G$12,2,FALSE),VLOOKUP(W$16,$A$3:$G$12,2,FALSE))<$K$14,$O21<>W$16,I21=1),SUM(VLOOKUP($O21,$A$3:$G$12,2,FALSE),VLOOKUP(W$16,$A$3:$G$12,2,FALSE)),0) -> 0 | X21: =IF(AND(SUM(VLOOKUP($O21,$A$3:$G$12,2,FALSE),VLOOKUP(X$16,$A$3:$G$12,2,FALSE))<$K$14,$O21<>X$16,J21=1),SUM(VLOOKUP($O21,$A$3:$G$12,2,FALSE),VLOOKUP(X$16,$A$3:$G$12,2,FALSE)),0) -> 0 | ... Z21: =IF(AND(SUM(VLOOKUP($O21,$A$3:$G$12,2,FALSE),VLOOKUP(Z$16,$A$3:$G$12,2,FALSE))<$K$14,$O21<>Z$16,L21=1),SUM(VLOOKUP($O21,$A$3:$G$12,2,FALSE),VLOOKUP(Z$16,$A$3:$G$12,2,FALSE)),0) -> 0 | AA21: 60 | AB21: 75 | AG21: AC2 | AH21: 0 | AI21: =IF(AND(SUM(VLOOKUP($AG21,$A$2:$H$12,2,FALSE),VLOOKUP(AI$18,$A$2:$H$12,2,FALSE))<$K$14,$AG21<>AI$18,C19=1),(VLOOKUP(AI$18,$A$2:$H$12,5,FALSE)*1440)-(VLOOKUP($AG21,$A$2:$H$12,6,FALSE))*1440,0) -> 0 | AJ21: =IF(AND(SUM(VLOOKUP($AG21,$A$2:$H$12,2,FALSE),VLOOKUP(AJ$18,$A$2:$H$12,2,FALSE))<$K$14,$AG21<>AJ$18,D19=1),(VLOOKUP(AJ$18,$A$2:$H$12,5,FALSE)*1440)-(VLOOKUP($AG21,$A$2:$H$12,6,FALSE))*1440,0) -> 0 | AK21: =IF(AND(SUM(VLOOKUP($AG21,$A$2:$H$12,2,FALSE),VLOOKUP(AK$18,$A$2:$H$12,2,FALSE))<$K$14,$AG21<>AK$18,E19=1),(VLOOKUP(AK$18,$A$2:$H$12,5,FALSE)*1440)-(VLOOKUP($AG21,$A$2:$H$12,6,FALSE))*1440,0) -> 0 | AL21: =IF(AND(SUM(VLOOKUP($AG21,$A$2:$H$12,2,FALSE),VLOOKUP(AL$18,$A$2:$H$12,2,FALSE))<$K$14,$AG21<>AL$18,F19=1),(VLOOKUP(AL$18,$A$2:$H$12,5,FALSE)*1440)-(VLOOKUP($AG21,$A$2:$H$12,6,FALSE))*1440,0) -> 0 | AM21: =IF(AND(SUM(VLOOKUP($AG21,$A$2:$H$12,2,FALSE),VLOOKUP(AM$18,$A$2:$H$12,2,FALSE))<$K$14,$AG21<>AM$18,G19=1),(VLOOKUP(AM$18,$A$2:$H$12,5,FALSE)*1440)-(VLOOKUP($AG21,$A$2:$H$12,6,FALSE))*1440,0) -> 0 | AN21: =IF(AND(SUM(VLOOKUP($AG21,$A$2:$H$12,2,FALSE),VLOOKUP(AN$18,$A$2:$H$12,2,FALSE))<$K$14,$AG21<>AN$18,H19=1),(VLOOKUP(AN$18,$A$2:$H$12,5,FALSE)*1440)-(VLOOKUP($AG21,$A$2:$H$12,6,FALSE))*1440,0) -> 0 | AO21: =IF(AND(SUM(VLOOKUP($AG21,$A$2:$H$12,2,FALSE),VLOOKUP(AO$18,$A$2:$H$12,2,FALSE))<$K$14,$AG21<>AO$18,I19=1),(VLOOKUP(AO$18,$A$2:$H$12,5,FALSE)*1440)-(VLOOKUP($AG21,$A$2:$H$12,6,FALSE))*1440,0) -> 0 | AP21: =IF(AND(SUM(VLOOKUP($AG21,$A$2:$H$12,2,FALSE),VLOOKUP(AP$18,$A$2:$H$12,2,FALSE))<$K$14,$AG21<>AP$18,J19=1),(VLOOKUP(AP$18,$A$2:$H$12,5,FALSE)*1440)-(VLOOKUP($AG21,$A$2:$H$12,6,FALSE))*1440,0) -> 45 | ... AR21: =IF(AND(SUM(VLOOKUP($AG21,$A$2:$H$12,2,FALSE),VLOOKUP(AR$18,$A$2:$H$12,2,FALSE))<$K$14,$AG21<>AR$18,L19=1),(VLOOKUP(AR$18,$A$2:$H$12,5,FALSE)*1440)-(VLOOKUP($AG21,$A$2:$H$12,6,FALSE))*1440,0) -> 225 | AS21: 10 | AT21: 15
A22: AC5 | B22: 1 | C22: =IF(AND(VLOOKUP(C$16,$A$3:$G$12,5,FALSE) - VLOOKUP($A22,$A$3:$G$12,6,FALSE)>=VLOOKUP(VLOOKUP(C$16,$A$3:$G$12,3,FALSE), $J$11:$L$12, 2, FALSE)/1440, VLOOKUP($A22,$A$3:$G$12,4,FALSE)=VLOOKUP(C$16,$A$3:$G$12,3,FALSE)),1,0) -> 0 | D22: =IF(AND(VLOOKUP(D$16,$A$3:$G$12,5,FALSE) - VLOOKUP($A22,$A$3:$G$12,6,FALSE)>=VLOOKUP(VLOOKUP(D$16,$A$3:$G$12,3,FALSE), $J$11:$L$12, 2, FALSE)/1440, VLOOKUP($A22,$A$3:$G$12,4,FALSE)=VLOOKUP(D$16,$A$3:$G$12,3,FALSE)),1,0) -> 0 | E22: =IF(AND(VLOOKUP(E$16,$A$3:$G$12,5,FALSE) - VLOOKUP($A22,$A$3:$G$12,6,FALSE)>=VLOOKUP(VLOOKUP(E$16,$A$3:$G$12,3,FALSE), $J$11:$L$12, 2, FALSE)/1440, VLOOKUP($A22,$A$3:$G$12,4,FALSE)=VLOOKUP(E$16,$A$3:$G$12,3,FALSE)),1,0) -> 0 | F22: =IF(AND(VLOOKUP(F$16,$A$3:$G$12,5,FALSE) - VLOOKUP($A22,$A$3:$G$12,6,FALSE)>=VLOOKUP(VLOOKUP(F$16,$A$3:$G$12,3,FALSE), $J$11:$L$12, 2, FALSE)/1440, VLOOKUP($A22,$A$3:$G$12,4,FALSE)=VLOOKUP(F$16,$A$3:$G$12,3,FALSE)),1,0) -> 0 | G22: =IF(AND(VLOOKUP(G$16,$A$3:$G$12,5,FALSE) - VLOOKUP($A22,$A$3:$G$12,6,FALSE)>=VLOOKUP(VLOOKUP(G$16,$A$3:$G$12,3,FALSE), $J$11:$L$12, 2, FALSE)/1440, VLOOKUP($A22,$A$3:$G$12,4,FALSE)=VLOOKUP(G$16,$A$3:$G$12,3,FALSE)),1,0) -> 0 | H22: =IF(AND(VLOOKUP(H$16,$A$3:$G$12,5,FALSE) - VLOOKUP($A22,$A$3:$G$12,6,FALSE)>=VLOOKUP(VLOOKUP(H$16,$A$3:$G$12,3,FALSE), $J$11:$L$12, 2, FALSE)/1440, VLOOKUP($A22,$A$3:$G$12,4,FALSE)=VLOOKUP(H$16,$A$3:$G$12,3,FALSE)),1,0) -> 0 | I22: =IF(AND(VLOOKUP(I$16,$A$3:$G$12,5,FALSE) - VLOOKUP($A22,$A$3:$G$12,6,FALSE)>=VLOOKUP(VLOOKUP(I$16,$A$3:$G$12,3,FALSE), $J$11:$L$12, 2, FALSE)/1440, VLOOKUP($A22,$A$3:$G$12,4,FALSE)=VLOOKUP(I$16,$A$3:$G$12,3,FALSE)),1,0) -> 0 | J22: =IF(AND(VLOOKUP(J$16,$A$3:$G$12,5,FALSE) - VLOOKUP($A22,$A$3:$G$12,6,FALSE)>=VLOOKUP(VLOOKUP(J$16,$A$3:$G$12,3,FALSE), $J$11:$L$12, 2, FALSE)/1440, VLOOKUP($A22,$A$3:$G$12,4,FALSE)=VLOOKUP(J$16,$A$3:$G$12,3,FALSE)),1,0) -> 0 | ... L22: =IF(AND(VLOOKUP(L$16,$A$3:$G$12,5,FALSE) - VLOOKUP($A22,$A$3:$G$12,6,FALSE)>=VLOOKUP(VLOOKUP(L$16,$A$3:$G$12,3,FALSE), $J$11:$L$12, 2, FALSE)/1440, VLOOKUP($A22,$A$3:$G$12,4,FALSE)=VLOOKUP(L$16,$A$3:$G$12,3,FALSE)),1,0) -> 0 | O22: AC5 | P22: 0 | Q22: =IF(AND(SUM(VLOOKUP($O22,$A$3:$G$12,2,FALSE),VLOOKUP(Q$16,$A$3:$G$12,2,FALSE))<$K$14,$O22<>Q$16,C22=1),SUM(VLOOKUP($O22,$A$3:$G$12,2,FALSE),VLOOKUP(Q$16,$A$3:$G$12,2,FALSE)),0) -> 0 | R22: =IF(AND(SUM(VLOOKUP($O22,$A$3:$G$12,2,FALSE),VLOOKUP(R$16,$A$3:$G$12,2,FALSE))<$K$14,$O22<>R$16,D22=1),SUM(VLOOKUP($O22,$A$3:$G$12,2,FALSE),VLOOKUP(R$16,$A$3:$G$12,2,FALSE)),0) -> 0 | S22: =IF(AND(SUM(VLOOKUP($O22,$A$3:$G$12,2,FALSE),VLOOKUP(S$16,$A$3:$G$12,2,FALSE))<$K$14,$O22<>S$16,E22=1),SUM(VLOOKUP($O22,$A$3:$G$12,2,FALSE),VLOOKUP(S$16,$A$3:$G$12,2,FALSE)),0) -> 0 | T22: =IF(AND(SUM(VLOOKUP($O22,$A$3:$G$12,2,FALSE),VLOOKUP(T$16,$A$3:$G$12,2,FALSE))<$K$14,$O22<>T$16,F22=1),SUM(VLOOKUP($O22,$A$3:$G$12,2,FALSE),VLOOKUP(T$16,$A$3:$G$12,2,FALSE)),0) -> 0 | U22: =IF(AND(SUM(VLOOKUP($O22,$A$3:$G$12,2,FALSE),VLOOKUP(U$16,$A$3:$G$12,2,FALSE))<$K$14,$O22<>U$16,G22=1),SUM(VLOOKUP($O22,$A$3:$G$12,2,FALSE),VLOOKUP(U$16,$A$3:$G$12,2,FALSE)),0) -> 0 | V22: =IF(AND(SUM(VLOOKUP($O22,$A$3:$G$12,2,FALSE),VLOOKUP(V$16,$A$3:$G$12,2,FALSE))<$K$14,$O22<>V$16,H22=1),SUM(VLOOKUP($O22,$A$3:$G$12,2,FALSE),VLOOKUP(V$16,$A$3:$G$12,2,FALSE)),0) -> 0 | W22: =IF(AND(SUM(VLOOKUP($O22,$A$3:$G$12,2,FALSE),VLOOKUP(W$16,$A$3:$G$12,2,FALSE))<$K$14,$O22<>W$16,I22=1),SUM(VLOOKUP($O22,$A$3:$G$12,2,FALSE),VLOOKUP(W$16,$A$3:$G$12,2,FALSE)),0) -> 0 | X22: =IF(AND(SUM(VLOOKUP($O22,$A$3:$G$12,2,FALSE),VLOOKUP(X$16,$A$3:$G$12,2,FALSE))<$K$14,$O22<>X$16,J22=1),SUM(VLOOKUP($O22,$A$3:$G$12,2,FALSE),VLOOKUP(X$16,$A$3:$G$12,2,FALSE)),0) -> 0 | ... Z22: =IF(AND(SUM(VLOOKUP($O22,$A$3:$G$12,2,FALSE),VLOOKUP(Z$16,$A$3:$G$12,2,FALSE))<$K$14,$O22<>Z$16,L22=1),SUM(VLOOKUP($O22,$A$3:$G$12,2,FALSE),VLOOKUP(Z$16,$A$3:$G$12,2,FALSE)),0) -> 0 | AA22: 60 | AB22: 75 | AG22: AC3 | AH22: 0 | AI22: =IF(AND(SUM(VLOOKUP($AG22,$A$2:$H$12,2,FALSE),VLOOKUP(AI$18,$A$2:$H$12,2,FALSE))<$K$14,$AG22<>AI$18,C20=1),(VLOOKUP(AI$18,$A$2:$H$12,5,FALSE)*1440)-(VLOOKUP($AG22,$A$2:$H$12,6,FALSE))*1440,0) -> 0 | AJ22: =IF(AND(SUM(VLOOKUP($AG22,$A$2:$H$12,2,FALSE),VLOOKUP(AJ$18,$A$2:$H$12,2,FALSE))<$K$14,$AG22<>AJ$18,D20=1),(VLOOKUP(AJ$18,$A$2:$H$12,5,FALSE)*1440)-(VLOOKUP($AG22,$A$2:$H$12,6,FALSE))*1440,0) -> 0 | AK22: =IF(AND(SUM(VLOOKUP($AG22,$A$2:$H$12,2,FALSE),VLOOKUP(AK$18,$A$2:$H$12,2,FALSE))<$K$14,$AG22<>AK$18,E20=1),(VLOOKUP(AK$18,$A$2:$H$12,5,FALSE)*1440)-(VLOOKUP($AG22,$A$2:$H$12,6,FALSE))*1440,0) -> 0 | AL22: =IF(AND(SUM(VLOOKUP($AG22,$A$2:$H$12,2,FALSE),VLOOKUP(AL$18,$A$2:$H$12,2,FALSE))<$K$14,$AG22<>AL$18,F20=1),(VLOOKUP(AL$18,$A$2:$H$12,5,FALSE)*1440)-(VLOOKUP($AG22,$A$2:$H$12,6,FALSE))*1440,0) -> 0 | AM22: =IF(AND(SUM(VLOOKUP($AG22,$A$2:$H$12,2,FALSE),VLOOKUP(AM$18,$A$2:$H$12,2,FALSE))<$K$14,$AG22<>AM$18,G20=1),(VLOOKUP(AM$18,$A$2:$H$12,5,FALSE)*1440)-(VLOOKUP($AG22,$A$2:$H$12,6,FALSE))*1440,0) -> 0 | AN22: =IF(AND(SUM(VLOOKUP($AG22,$A$2:$H$12,2,FALSE),VLOOKUP(AN$18,$A$2:$H$12,2,FALSE))<$K$14,$AG22<>AN$18,H20=1),(VLOOKUP(AN$18,$A$2:$H$12,5,FALSE)*1440)-(VLOOKUP($AG22,$A$2:$H$12,6,FALSE))*1440,0) -> 0 | AO22: =IF(AND(SUM(VLOOKUP($AG22,$A$2:$H$12,2,FALSE),VLOOKUP(AO$18,$A$2:$H$12,2,FALSE))<$K$14,$AG22<>AO$18,I20=1),(VLOOKUP(AO$18,$A$2:$H$12,5,FALSE)*1440)-(VLOOKUP($AG22,$A$2:$H$12,6,FALSE))*1440,0) -> 0 | AP22: =IF(AND(SUM(VLOOKUP($AG22,$A$2:$H$12,2,FALSE),VLOOKUP(AP$18,$A$2:$H$12,2,FALSE))<$K$14,$AG22<>AP$18,J20=1),(VLOOKUP(AP$18,$A$2:$H$12,5,FALSE)*1440)-(VLOOKUP($AG22,$A$2:$H$12,6,FALSE))*1440,0) -> 0 | ... AR22: =IF(AND(SUM(VLOOKUP($AG22,$A$2:$H$12,2,FALSE),VLOOKUP(AR$18,$A$2:$H$12,2,FALSE))<$K$14,$AG22<>AR$18,L20=1),(VLOOKUP(AR$18,$A$2:$H$12,5,FALSE)*1440)-(VLOOKUP($AG22,$A$2:$H$12,6,FALSE))*1440,0) -> 105 | AS22: 10 | AT22: 15
A23: CA1 | B23: 1 | C23: =IF(AND(VLOOKUP(C$16,$A$3:$G$12,5,FALSE) - VLOOKUP($A23,$A$3:$G$12,6,FALSE)>=VLOOKUP(VLOOKUP(C$16,$A$3:$G$12,3,FALSE), $J$11:$L$12, 2, FALSE)/1440, VLOOKUP($A23,$A$3:$G$12,4,FALSE)=VLOOKUP(C$16,$A$3:$G$12,3,FALSE)),1,0) -> 0 | D23: =IF(AND(VLOOKUP(D$16,$A$3:$G$12,5,FALSE) - VLOOKUP($A23,$A$3:$G$12,6,FALSE)>=VLOOKUP(VLOOKUP(D$16,$A$3:$G$12,3,FALSE), $J$11:$L$12, 2, FALSE)/1440, VLOOKUP($A23,$A$3:$G$12,4,FALSE)=VLOOKUP(D$16,$A$3:$G$12,3,FALSE)),1,0) -> 0 | E23: =IF(AND(VLOOKUP(E$16,$A$3:$G$12,5,FALSE) - VLOOKUP($A23,$A$3:$G$12,6,FALSE)>=VLOOKUP(VLOOKUP(E$16,$A$3:$G$12,3,FALSE), $J$11:$L$12, 2, FALSE)/1440, VLOOKUP($A23,$A$3:$G$12,4,FALSE)=VLOOKUP(E$16,$A$3:$G$12,3,FALSE)),1,0) -> 1 | F23: =IF(AND(VLOOKUP(F$16,$A$3:$G$12,5,FALSE) - VLOOKUP($A23,$A$3:$G$12,6,FALSE)>=VLOOKUP(VLOOKUP(F$16,$A$3:$G$12,3,FALSE), $J$11:$L$12, 2, FALSE)/1440, VLOOKUP($A23,$A$3:$G$12,4,FALSE)=VLOOKUP(F$16,$A$3:$G$12,3,FALSE)),1,0) -> 1 | G23: =IF(AND(VLOOKUP(G$16,$A$3:$G$12,5,FALSE) - VLOOKUP($A23,$A$3:$G$12,6,FALSE)>=VLOOKUP(VLOOKUP(G$16,$A$3:$G$12,3,FALSE), $J$11:$L$12, 2, FALSE)/1440, VLOOKUP($A23,$A$3:$G$12,4,FALSE)=VLOOKUP(G$16,$A$3:$G$12,3,FALSE)),1,0) -> 1 | H23: =IF(AND(VLOOKUP(H$16,$A$3:$G$12,5,FALSE) - VLOOKUP($A23,$A$3:$G$12,6,FALSE)>=VLOOKUP(VLOOKUP(H$16,$A$3:$G$12,3,FALSE), $J$11:$L$12, 2, FALSE)/1440, VLOOKUP($A23,$A$3:$G$12,4,FALSE)=VLOOKUP(H$16,$A$3:$G$12,3,FALSE)),1,0) -> 0 | I23: =IF(AND(VLOOKUP(I$16,$A$3:$G$12,5,FALSE) - VLOOKUP($A23,$A$3:$G$12,6,FALSE)>=VLOOKUP(VLOOKUP(I$16,$A$3:$G$12,3,FALSE), $J$11:$L$12, 2, FALSE)/1440, VLOOKUP($A23,$A$3:$G$12,4,FALSE)=VLOOKUP(I$16,$A$3:$G$12,3,FALSE)),1,0) -> 0 | J23: =IF(AND(VLOOKUP(J$16,$A$3:$G$12,5,FALSE) - VLOOKUP($A23,$A$3:$G$12,6,FALSE)>=VLOOKUP(VLOOKUP(J$16,$A$3:$G$12,3,FALSE), $J$11:$L$12, 2, FALSE)/1440, VLOOKUP($A23,$A$3:$G$12,4,FALSE)=VLOOKUP(J$16,$A$3:$G$12,3,FALSE)),1,0) -> 0 | ... L23: =IF(AND(VLOOKUP(L$16,$A$3:$G$12,5,FALSE) - VLOOKUP($A23,$A$3:$G$12,6,FALSE)>=VLOOKUP(VLOOKUP(L$16,$A$3:$G$12,3,FALSE), $J$11:$L$12, 2, FALSE)/1440, VLOOKUP($A23,$A$3:$G$12,4,FALSE)=VLOOKUP(L$16,$A$3:$G$12,3,FALSE)),1,0) -> 0 | O23: CA1 | P23: 0 | Q23: =IF(AND(SUM(VLOOKUP($O23,$A$3:$G$12,2,FALSE),VLOOKUP(Q$16,$A$3:$G$12,2,FALSE))<$K$14,$O23<>Q$16,C23=1),SUM(VLOOKUP($O23,$A$3:$G$12,2,FALSE),VLOOKUP(Q$16,$A$3:$G$12,2,FALSE)),0) -> 0 | R23: =IF(AND(SUM(VLOOKUP($O23,$A$3:$G$12,2,FALSE),VLOOKUP(R$16,$A$3:$G$12,2,FALSE))<$K$14,$O23<>R$16,D23=1),SUM(VLOOKUP($O23,$A$3:$G$12,2,FALSE),VLOOKUP(R$16,$A$3:$G$12,2,FALSE)),0) -> 0 | S23: 280 | T23: 280 | U23: 280 | V23: =IF(AND(SUM(VLOOKUP($O23,$A$3:$G$12,2,FALSE),VLOOKUP(V$16,$A$3:$G$12,2,FALSE))<$K$14,$O23<>V$16,H23=1),SUM(VLOOKUP($O23,$A$3:$G$12,2,FALSE),VLOOKUP(V$16,$A$3:$G$12,2,FALSE)),0) -> 0 | W23: =IF(AND(SUM(VLOOKUP($O23,$A$3:$G$12,2,FALSE),VLOOKUP(W$16,$A$3:$G$12,2,FALSE))<$K$14,$O23<>W$16,I23=1),SUM(VLOOKUP($O23,$A$3:$G$12,2,FALSE),VLOOKUP(W$16,$A$3:$G$12,2,FALSE)),0) -> 0 | X23: =IF(AND(SUM(VLOOKUP($O23,$A$3:$G$12,2,FALSE),VLOOKUP(X$16,$A$3:$G$12,2,FALSE))<$K$14,$O23<>X$16,J23=1),SUM(VLOOKUP($O23,$A$3:$G$12,2,FALSE),VLOOKUP(X$16,$A$3:$G$12,2,FALSE)),0) -> 0 | Y23: =IF(AND(SUM(VLOOKUP($O23,$A$3:$G$12,2,FALSE),VLOOKUP(Y$16,$A$3:$G$12,2,FALSE))<$K$14,$O23<>Y$16,K23=1),SUM(VLOOKUP($O23,$A$3:$G$12,2,FALSE),VLOOKUP(Y$16,$A$3:$G$12,2,FALSE)),0) -> 0 | Z23: =IF(AND(SUM(VLOOKUP($O23,$A$3:$G$12,2,FALSE),VLOOKUP(Z$16,$A$3:$G$12,2,FALSE))<$K$14,$O23<>Z$16,L23=1),SUM(VLOOKUP($O23,$A$3:$G$12,2,FALSE),VLOOKUP(Z$16,$A$3:$G$12,2,FALSE)),0) -> 0 | AA23: 60 | AB23: 75 | AG23: AC4 | AH23: 0 | AI23: =IF(AND(SUM(VLOOKUP($AG23,$A$2:$H$12,2,FALSE),VLOOKUP(AI$18,$A$2:$H$12,2,FALSE))<$K$14,$AG23<>AI$18,C21=1),(VLOOKUP(AI$18,$A$2:$H$12,5,FALSE)*1440)-(VLOOKUP($AG23,$A$2:$H$12,6,FALSE))*1440,0) -> 0 | AJ23: =IF(AND(SUM(VLOOKUP($AG23,$A$2:$H$12,2,FALSE),VLOOKUP(AJ$18,$A$2:$H$12,2,FALSE))<$K$14,$AG23<>AJ$18,D21=1),(VLOOKUP(AJ$18,$A$2:$H$12,5,FALSE)*1440)-(VLOOKUP($AG23,$A$2:$H$12,6,FALSE))*1440,0) -> 0 | AK23: =IF(AND(SUM(VLOOKUP($AG23,$A$2:$H$12,2,FALSE),VLOOKUP(AK$18,$A$2:$H$12,2,FALSE))<$K$14,$AG23<>AK$18,E21=1),(VLOOKUP(AK$18,$A$2:$H$12,5,FALSE)*1440)-(VLOOKUP($AG23,$A$2:$H$12,6,FALSE))*1440,0) -> 0 | AL23: =IF(AND(SUM(VLOOKUP($AG23,$A$2:$H$12,2,FALSE),VLOOKUP(AL$18,$A$2:$H$12,2,FALSE))<$K$14,$AG23<>AL$18,F21=1),(VLOOKUP(AL$18,$A$2:$H$12,5,FALSE)*1440)-(VLOOKUP($AG23,$A$2:$H$12,6,FALSE))*1440,0) -> 0 | AM23: =IF(AND(SUM(VLOOKUP($AG23,$A$2:$H$12,2,FALSE),VLOOKUP(AM$18,$A$2:$H$12,2,FALSE))<$K$14,$AG23<>AM$18,G21=1),(VLOOKUP(AM$18,$A$2:$H$12,5,FALSE)*1440)-(VLOOKUP($AG23,$A$2:$H$12,6,FALSE))*1440,0) -> 0 | AN23: =IF(AND(SUM(VLOOKUP($AG23,$A$2:$H$12,2,FALSE),VLOOKUP(AN$18,$A$2:$H$12,2,FALSE))<$K$14,$AG23<>AN$18,H21=1),(VLOOKUP(AN$18,$A$2:$H$12,5,FALSE)*1440)-(VLOOKUP($AG23,$A$2:$H$12,6,FALSE))*1440,0) -> 0 | AO23: =IF(AND(SUM(VLOOKUP($AG23,$A$2:$H$12,2,FALSE),VLOOKUP(AO$18,$A$2:$H$12,2,FALSE))<$K$14,$AG23<>AO$18,I21=1),(VLOOKUP(AO$18,$A$2:$H$12,5,FALSE)*1440)-(VLOOKUP($AG23,$A$2:$H$12,6,FALSE))*1440,0) -> 0 | AP23: =IF(AND(SUM(VLOOKUP($AG23,$A$2:$H$12,2,FALSE),VLOOKUP(AP$18,$A$2:$H$12,2,FALSE))<$K$14,$AG23<>AP$18,J21=1),(VLOOKUP(AP$18,$A$2:$H$12,5,FALSE)*1440)-(VLOOKUP($AG23,$A$2:$H$12,6,FALSE))*1440,0) -> 0 | ... AR23: =IF(AND(SUM(VLOOKUP($AG23,$A$2:$H$12,2,FALSE),VLOOKUP(AR$18,$A$2:$H$12,2,FALSE))<$K$14,$AG23<>AR$18,L21=1),(VLOOKUP(AR$18,$A$2:$H$12,5,FALSE)*1440)-(VLOOKUP($AG23,$A$2:$H$12,6,FALSE))*1440,0) -> 0 | AS23: 10 | AT23: 15
A24: CA2 | B24: 1 | C24: =IF(AND(VLOOKUP(C$16,$A$3:$G$12,5,FALSE) - VLOOKUP($A24,$A$3:$G$12,6,FALSE)>=VLOOKUP(VLOOKUP(C$16,$A$3:$G$12,3,FALSE), $J$11:$L$12, 2, FALSE)/1440, VLOOKUP($A24,$A$3:$G$12,4,FALSE)=VLOOKUP(C$16,$A$3:$G$12,3,FALSE)),1,0) -> 0 | D24: =IF(AND(VLOOKUP(D$16,$A$3:$G$12,5,FALSE) - VLOOKUP($A24,$A$3:$G$12,6,FALSE)>=VLOOKUP(VLOOKUP(D$16,$A$3:$G$12,3,FALSE), $J$11:$L$12, 2, FALSE)/1440, VLOOKUP($A24,$A$3:$G$12,4,FALSE)=VLOOKUP(D$16,$A$3:$G$12,3,FALSE)),1,0) -> 0 | E24: =IF(AND(VLOOKUP(E$16,$A$3:$G$12,5,FALSE) - VLOOKUP($A24,$A$3:$G$12,6,FALSE)>=VLOOKUP(VLOOKUP(E$16,$A$3:$G$12,3,FALSE), $J$11:$L$12, 2, FALSE)/1440, VLOOKUP($A24,$A$3:$G$12,4,FALSE)=VLOOKUP(E$16,$A$3:$G$12,3,FALSE)),1,0) -> 0 | F24: =IF(AND(VLOOKUP(F$16,$A$3:$G$12,5,FALSE) - VLOOKUP($A24,$A$3:$G$12,6,FALSE)>=VLOOKUP(VLOOKUP(F$16,$A$3:$G$12,3,FALSE), $J$11:$L$12, 2, FALSE)/1440, VLOOKUP($A24,$A$3:$G$12,4,FALSE)=VLOOKUP(F$16,$A$3:$G$12,3,FALSE)),1,0) -> 1 | G24: =IF(AND(VLOOKUP(G$16,$A$3:$G$12,5,FALSE) - VLOOKUP($A24,$A$3:$G$12,6,FALSE)>=VLOOKUP(VLOOKUP(G$16,$A$3:$G$12,3,FALSE), $J$11:$L$12, 2, FALSE)/1440, VLOOKUP($A24,$A$3:$G$12,4,FALSE)=VLOOKUP(G$16,$A$3:$G$12,3,FALSE)),1,0) -> 1 | H24: =IF(AND(VLOOKUP(H$16,$A$3:$G$12,5,FALSE) - VLOOKUP($A24,$A$3:$G$12,6,FALSE)>=VLOOKUP(VLOOKUP(H$16,$A$3:$G$12,3,FALSE), $J$11:$L$12, 2, FALSE)/1440, VLOOKUP($A24,$A$3:$G$12,4,FALSE)=VLOOKUP(H$16,$A$3:$G$12,3,FALSE)),1,0) -> 0 | I24: =IF(AND(VLOOKUP(I$16,$A$3:$G$12,5,FALSE) - VLOOKUP($A24,$A$3:$G$12,6,FALSE)>=VLOOKUP(VLOOKUP(I$16,$A$3:$G$12,3,FALSE), $J$11:$L$12, 2, FALSE)/1440, VLOOKUP($A24,$A$3:$G$12,4,FALSE)=VLOOKUP(I$16,$A$3:$G$12,3,FALSE)),1,0) -> 0 | J24: =IF(AND(VLOOKUP(J$16,$A$3:$G$12,5,FALSE) - VLOOKUP($A24,$A$3:$G$12,6,FALSE)>=VLOOKUP(VLOOKUP(J$16,$A$3:$G$12,3,FALSE), $J$11:$L$12, 2, FALSE)/1440, VLOOKUP($A24,$A$3:$G$12,4,FALSE)=VLOOKUP(J$16,$A$3:$G$12,3,FALSE)),1,0) -> 0 | ... L24: =IF(AND(VLOOKUP(L$16,$A$3:$G$12,5,FALSE) - VLOOKUP($A24,$A$3:$G$12,6,FALSE)>=VLOOKUP(VLOOKUP(L$16,$A$3:$G$12,3,FALSE), $J$11:$L$12, 2, FALSE)/1440, VLOOKUP($A24,$A$3:$G$12,4,FALSE)=VLOOKUP(L$16,$A$3:$G$12,3,FALSE)),1,0) -> 0 | O24: CA2 | P24: 0 | Q24: =IF(AND(SUM(VLOOKUP($O24,$A$3:$G$12,2,FALSE),VLOOKUP(Q$16,$A$3:$G$12,2,FALSE))<$K$14,$O24<>Q$16,C24=1),SUM(VLOOKUP($O24,$A$3:$G$12,2,FALSE),VLOOKUP(Q$16,$A$3:$G$12,2,FALSE)),0) -> 0 | R24: =IF(AND(SUM(VLOOKUP($O24,$A$3:$G$12,2,FALSE),VLOOKUP(R$16,$A$3:$G$12,2,FALSE))<$K$14,$O24<>R$16,D24=1),SUM(VLOOKUP($O24,$A$3:$G$12,2,FALSE),VLOOKUP(R$16,$A$3:$G$12,2,FALSE)),0) -> 0 | S24: =IF(AND(SUM(VLOOKUP($O24,$A$3:$G$12,2,FALSE),VLOOKUP(S$16,$A$3:$G$12,2,FALSE))<$K$14,$O24<>S$16,E24=1),SUM(VLOOKUP($O24,$A$3:$G$12,2,FALSE),VLOOKUP(S$16,$A$3:$G$12,2,FALSE)),0) -> 0 | T24: 280 | U24: 280 | V24: =IF(AND(SUM(VLOOKUP($O24,$A$3:$G$12,2,FALSE),VLOOKUP(V$16,$A$3:$G$12,2,FALSE))<$K$14,$O24<>V$16,H24=1),SUM(VLOOKUP($O24,$A$3:$G$12,2,FALSE),VLOOKUP(V$16,$A$3:$G$12,2,FALSE)),0) -> 0 | W24: =IF(AND(SUM(VLOOKUP($O24,$A$3:$G$12,2,FALSE),VLOOKUP(W$16,$A$3:$G$12,2,FALSE))<$K$14,$O24<>W$16,I24=1),SUM(VLOOKUP($O24,$A$3:$G$12,2,FALSE),VLOOKUP(W$16,$A$3:$G$12,2,FALSE)),0) -> 0 | X24: =IF(AND(SUM(VLOOKUP($O24,$A$3:$G$12,2,FALSE),VLOOKUP(X$16,$A$3:$G$12,2,FALSE))<$K$14,$O24<>X$16,J24=1),SUM(VLOOKUP($O24,$A$3:$G$12,2,FALSE),VLOOKUP(X$16,$A$3:$G$12,2,FALSE)),0) -> 0 | Y24: =IF(AND(SUM(VLOOKUP($O24,$A$3:$G$12,2,FALSE),VLOOKUP(Y$16,$A$3:$G$12,2,FALSE))<$K$14,$O24<>Y$16,K24=1),SUM(VLOOKUP($O24,$A$3:$G$12,2,FALSE),VLOOKUP(Y$16,$A$3:$G$12,2,FALSE)),0) -> 0 | Z24: =IF(AND(SUM(VLOOKUP($O24,$A$3:$G$12,2,FALSE),VLOOKUP(Z$16,$A$3:$G$12,2,FALSE))<$K$14,$O24<>Z$16,L24=1),SUM(VLOOKUP($O24,$A$3:$G$12,2,FALSE),VLOOKUP(Z$16,$A$3:$G$12,2,FALSE)),0) -> 0 | AA24: 60 | AB24: 75 | AG24: AC5 | AH24: 0 | AI24: =IF(AND(SUM(VLOOKUP($AG24,$A$2:$H$12,2,FALSE),VLOOKUP(AI$18,$A$2:$H$12,2,FALSE))<$K$14,$AG24<>AI$18,C22=1),(VLOOKUP(AI$18,$A$2:$H$12,5,FALSE)*1440)-(VLOOKUP($AG24,$A$2:$H$12,6,FALSE))*1440,0) -> 0 | AJ24: =IF(AND(SUM(VLOOKUP($AG24,$A$2:$H$12,2,FALSE),VLOOKUP(AJ$18,$A$2:$H$12,2,FALSE))<$K$14,$AG24<>AJ$18,D22=1),(VLOOKUP(AJ$18,$A$2:$H$12,5,FALSE)*1440)-(VLOOKUP($AG24,$A$2:$H$12,6,FALSE))*1440,0) -> 0 | AK24: =IF(AND(SUM(VLOOKUP($AG24,$A$2:$H$12,2,FALSE),VLOOKUP(AK$18,$A$2:$H$12,2,FALSE))<$K$14,$AG24<>AK$18,E22=1),(VLOOKUP(AK$18,$A$2:$H$12,5,FALSE)*1440)-(VLOOKUP($AG24,$A$2:$H$12,6,FALSE))*1440,0) -> 0 | AL24: =IF(AND(SUM(VLOOKUP($AG24,$A$2:$H$12,2,FALSE),VLOOKUP(AL$18,$A$2:$H$12,2,FALSE))<$K$14,$AG24<>AL$18,F22=1),(VLOOKUP(AL$18,$A$2:$H$12,5,FALSE)*1440)-(VLOOKUP($AG24,$A$2:$H$12,6,FALSE))*1440,0) -> 0 | AM24: =IF(AND(SUM(VLOOKUP($AG24,$A$2:$H$12,2,FALSE),VLOOKUP(AM$18,$A$2:$H$12,2,FALSE))<$K$14,$AG24<>AM$18,G22=1),(VLOOKUP(AM$18,$A$2:$H$12,5,FALSE)*1440)-(VLOOKUP($AG24,$A$2:$H$12,6,FALSE))*1440,0) -> 0 | AN24: =IF(AND(SUM(VLOOKUP($AG24,$A$2:$H$12,2,FALSE),VLOOKUP(AN$18,$A$2:$H$12,2,FALSE))<$K$14,$AG24<>AN$18,H22=1),(VLOOKUP(AN$18,$A$2:$H$12,5,FALSE)*1440)-(VLOOKUP($AG24,$A$2:$H$12,6,FALSE))*1440,0) -> 0 | AO24: =IF(AND(SUM(VLOOKUP($AG24,$A$2:$H$12,2,FALSE),VLOOKUP(AO$18,$A$2:$H$12,2,FALSE))<$K$14,$AG24<>AO$18,I22=1),(VLOOKUP(AO$18,$A$2:$H$12,5,FALSE)*1440)-(VLOOKUP($AG24,$A$2:$H$12,6,FALSE))*1440,0) -> 0 | AP24: =IF(AND(SUM(VLOOKUP($AG24,$A$2:$H$12,2,FALSE),VLOOKUP(AP$18,$A$2:$H$12,2,FALSE))<$K$14,$AG24<>AP$18,J22=1),(VLOOKUP(AP$18,$A$2:$H$12,5,FALSE)*1440)-(VLOOKUP($AG24,$A$2:$H$12,6,FALSE))*1440,0) -> 0 | ... AR24: =IF(AND(SUM(VLOOKUP($AG24,$A$2:$H$12,2,FALSE),VLOOKUP(AR$18,$A$2:$H$12,2,FALSE))<$K$14,$AG24<>AR$18,L22=1),(VLOOKUP(AR$18,$A$2:$H$12,5,FALSE)*1440)-(VLOOKUP($AG24,$A$2:$H$12,6,FALSE))*1440,0) -> 0 | AS24: 10 | AT24: 15
A25: CA3 | B25: 1 | C25: =IF(AND(VLOOKUP(C$16,$A$3:$G$12,5,FALSE) - VLOOKUP($A25,$A$3:$G$12,6,FALSE)>=VLOOKUP(VLOOKUP(C$16,$A$3:$G$12,3,FALSE), $J$11:$L$12, 2, FALSE)/1440, VLOOKUP($A25,$A$3:$G$12,4,FALSE)=VLOOKUP(C$16,$A$3:$G$12,3,FALSE)),1,0) -> 0 | D25: =IF(AND(VLOOKUP(D$16,$A$3:$G$12,5,FALSE) - VLOOKUP($A25,$A$3:$G$12,6,FALSE)>=VLOOKUP(VLOOKUP(D$16,$A$3:$G$12,3,FALSE), $J$11:$L$12, 2, FALSE)/1440, VLOOKUP($A25,$A$3:$G$12,4,FALSE)=VLOOKUP(D$16,$A$3:$G$12,3,FALSE)),1,0) -> 0 | E25: =IF(AND(VLOOKUP(E$16,$A$3:$G$12,5,FALSE) - VLOOKUP($A25,$A$3:$G$12,6,FALSE)>=VLOOKUP(VLOOKUP(E$16,$A$3:$G$12,3,FALSE), $J$11:$L$12, 2, FALSE)/1440, VLOOKUP($A25,$A$3:$G$12,4,FALSE)=VLOOKUP(E$16,$A$3:$G$12,3,FALSE)),1,0) -> 0 | F25: =IF(AND(VLOOKUP(F$16,$A$3:$G$12,5,FALSE) - VLOOKUP($A25,$A$3:$G$12,6,FALSE)>=VLOOKUP(VLOOKUP(F$16,$A$3:$G$12,3,FALSE), $J$11:$L$12, 2, FALSE)/1440, VLOOKUP($A25,$A$3:$G$12,4,FALSE)=VLOOKUP(F$16,$A$3:$G$12,3,FALSE)),1,0) -> 1 | G25: =IF(AND(VLOOKUP(G$16,$A$3:$G$12,5,FALSE) - VLOOKUP($A25,$A$3:$G$12,6,FALSE)>=VLOOKUP(VLOOKUP(G$16,$A$3:$G$12,3,FALSE), $J$11:$L$12, 2, FALSE)/1440, VLOOKUP($A25,$A$3:$G$12,4,FALSE)=VLOOKUP(G$16,$A$3:$G$12,3,FALSE)),1,0) -> 1 | H25: =IF(AND(VLOOKUP(H$16,$A$3:$G$12,5,FALSE) - VLOOKUP($A25,$A$3:$G$12,6,FALSE)>=VLOOKUP(VLOOKUP(H$16,$A$3:$G$12,3,FALSE), $J$11:$L$12, 2, FALSE)/1440, VLOOKUP($A25,$A$3:$G$12,4,FALSE)=VLOOKUP(H$16,$A$3:$G$12,3,FALSE)),1,0) -> 0 | I25: =IF(AND(VLOOKUP(I$16,$A$3:$G$12,5,FALSE) - VLOOKUP($A25,$A$3:$G$12,6,FALSE)>=VLOOKUP(VLOOKUP(I$16,$A$3:$G$12,3,FALSE), $J$11:$L$12, 2, FALSE)/1440, VLOOKUP($A25,$A$3:$G$12,4,FALSE)=VLOOKUP(I$16,$A$3:$G$12,3,FALSE)),1,0) -> 0 | J25: =IF(AND(VLOOKUP(J$16,$A$3:$G$12,5,FALSE) - VLOOKUP($A25,$A$3:$G$12,6,FALSE)>=VLOOKUP(VLOOKUP(J$16,$A$3:$G$12,3,FALSE), $J$11:$L$12, 2, FALSE)/1440, VLOOKUP($A25,$A$3:$G$12,4,FALSE)=VLOOKUP(J$16,$A$3:$G$12,3,FALSE)),1,0) -> 0 | ... L25: =IF(AND(VLOOKUP(L$16,$A$3:$G$12,5,FALSE) - VLOOKUP($A25,$A$3:$G$12,6,FALSE)>=VLOOKUP(VLOOKUP(L$16,$A$3:$G$12,3,FALSE), $J$11:$L$12, 2, FALSE)/1440, VLOOKUP($A25,$A$3:$G$12,4,FALSE)=VLOOKUP(L$16,$A$3:$G$12,3,FALSE)),1,0) -> 0 | O25: CA3 | P25: 0 | Q25: =IF(AND(SUM(VLOOKUP($O25,$A$3:$G$12,2,FALSE),VLOOKUP(Q$16,$A$3:$G$12,2,FALSE))<$K$14,$O25<>Q$16,C25=1),SUM(VLOOKUP($O25,$A$3:$G$12,2,FALSE),VLOOKUP(Q$16,$A$3:$G$12,2,FALSE)),0) -> 0 | R25: =IF(AND(SUM(VLOOKUP($O25,$A$3:$G$12,2,FALSE),VLOOKUP(R$16,$A$3:$G$12,2,FALSE))<$K$14,$O25<>R$16,D25=1),SUM(VLOOKUP($O25,$A$3:$G$12,2,FALSE),VLOOKUP(R$16,$A$3:$G$12,2,FALSE)),0) -> 0 | S25: =IF(AND(SUM(VLOOKUP($O25,$A$3:$G$12,2,FALSE),VLOOKUP(S$16,$A$3:$G$12,2,FALSE))<$K$14,$O25<>S$16,E25=1),SUM(VLOOKUP($O25,$A$3:$G$12,2,FALSE),VLOOKUP(S$16,$A$3:$G$12,2,FALSE)),0) -> 0 | T25: 280 | U25: 280 | V25: =IF(AND(SUM(VLOOKUP($O25,$A$3:$G$12,2,FALSE),VLOOKUP(V$16,$A$3:$G$12,2,FALSE))<$K$14,$O25<>V$16,H25=1),SUM(VLOOKUP($O25,$A$3:$G$12,2,FALSE),VLOOKUP(V$16,$A$3:$G$12,2,FALSE)),0) -> 0 | W25: =IF(AND(SUM(VLOOKUP($O25,$A$3:$G$12,2,FALSE),VLOOKUP(W$16,$A$3:$G$12,2,FALSE))<$K$14,$O25<>W$16,I25=1),SUM(VLOOKUP($O25,$A$3:$G$12,2,FALSE),VLOOKUP(W$16,$A$3:$G$12,2,FALSE)),0) -> 0 | X25: =IF(AND(SUM(VLOOKUP($O25,$A$3:$G$12,2,FALSE),VLOOKUP(X$16,$A$3:$G$12,2,FALSE))<$K$14,$O25<>X$16,J25=1),SUM(VLOOKUP($O25,$A$3:$G$12,2,FALSE),VLOOKUP(X$16,$A$3:$G$12,2,FALSE)),0) -> 0 | Y25: =IF(AND(SUM(VLOOKUP($O25,$A$3:$G$12,2,FALSE),VLOOKUP(Y$16,$A$3:$G$12,2,FALSE))<$K$14,$O25<>Y$16,K25=1),SUM(VLOOKUP($O25,$A$3:$G$12,2,FALSE),VLOOKUP(Y$16,$A$3:$G$12,2,FALSE)),0) -> 0 | Z25: =IF(AND(SUM(VLOOKUP($O25,$A$3:$G$12,2,FALSE),VLOOKUP(Z$16,$A$3:$G$12,2,FALSE))<$K$14,$O25<>Z$16,L25=1),SUM(VLOOKUP($O25,$A$3:$G$12,2,FALSE),VLOOKUP(Z$16,$A$3:$G$12,2,FALSE)),0) -> 0 | AA25: 60 | AB25: 75 | AG25: CA1 | AH25: 0 | AI25: =IF(AND(SUM(VLOOKUP($AG25,$A$2:$H$12,2,FALSE),VLOOKUP(AI$18,$A$2:$H$12,2,FALSE))<$K$14,$AG25<>AI$18,C23=1),(VLOOKUP(AI$18,$A$2:$H$12,5,FALSE)*1440)-(VLOOKUP($AG25,$A$2:$H$12,6,FALSE))*1440,0) -> 0 | AJ25: =IF(AND(SUM(VLOOKUP($AG25,$A$2:$H$12,2,FALSE),VLOOKUP(AJ$18,$A$2:$H$12,2,FALSE))<$K$14,$AG25<>AJ$18,D23=1),(VLOOKUP(AJ$18,$A$2:$H$12,5,FALSE)*1440)-(VLOOKUP($AG25,$A$2:$H$12,6,FALSE))*1440,0) -> 0 | AK25: =IF(AND(SUM(VLOOKUP($AG25,$A$2:$H$12,2,FALSE),VLOOKUP(AK$18,$A$2:$H$12,2,FALSE))<$K$14,$AG25<>AK$18,E23=1),(VLOOKUP(AK$18,$A$2:$H$12,5,FALSE)*1440)-(VLOOKUP($AG25,$A$2:$H$12,6,FALSE))*1440,0) -> 85 | AL25: =IF(AND(SUM(VLOOKUP($AG25,$A$2:$H$12,2,FALSE),VLOOKUP(AL$18,$A$2:$H$12,2,FALSE))<$K$14,$AG25<>AL$18,F23=1),(VLOOKUP(AL$18,$A$2:$H$12,5,FALSE)*1440)-(VLOOKUP($AG25,$A$2:$H$12,6,FALSE))*1440,0) -> 445 | AM25: =IF(AND(SUM(VLOOKUP($AG25,$A$2:$H$12,2,FALSE),VLOOKUP(AM$18,$A$2:$H$12,2,FALSE))<$K$14,$AG25<>AM$18,G23=1),(VLOOKUP(AM$18,$A$2:$H$12,5,FALSE)*1440)-(VLOOKUP($AG25,$A$2:$H$12,6,FALSE))*1440,0) -> 505 | AN25: =IF(AND(SUM(VLOOKUP($AG25,$A$2:$H$12,2,FALSE),VLOOKUP(AN$18,$A$2:$H$12,2,FALSE))<$K$14,$AG25<>AN$18,H23=1),(VLOOKUP(AN$18,$A$2:$H$12,5,FALSE)*1440)-(VLOOKUP($AG25,$A$2:$H$12,6,FALSE))*1440,0) -> 0 | AO25: =IF(AND(SUM(VLOOKUP($AG25,$A$2:$H$12,2,FALSE),VLOOKUP(AO$18,$A$2:$H$12,2,FALSE))<$K$14,$AG25<>AO$18,I23=1),(VLOOKUP(AO$18,$A$2:$H$12,5,FALSE)*1440)-(VLOOKUP($AG25,$A$2:$H$12,6,FALSE))*1440,0) -> 0 | AP25: =IF(AND(SUM(VLOOKUP($AG25,$A$2:$H$12,2,FALSE),VLOOKUP(AP$18,$A$2:$H$12,2,FALSE))<$K$14,$AG25<>AP$18,J23=1),(VLOOKUP(AP$18,$A$2:$H$12,5,FALSE)*1440)-(VLOOKUP($AG25,$A$2:$H$12,6,FALSE))*1440,0) -> 0 | ... AR25: =IF(AND(SUM(VLOOKUP($AG25,$A$2:$H$12,2,FALSE),VLOOKUP(AR$18,$A$2:$H$12,2,FALSE))<$K$14,$AG25<>AR$18,L23=1),(VLOOKUP(AR$18,$A$2:$H$12,5,FALSE)*1440)-(VLOOKUP($AG25,$A$2:$H$12,6,FALSE))*1440,0) -> 0 | AS25: 10 | AT25: 15
