Workbook

Sheet main
A1: tripID | B1: routeName | C1: length | D1: dep_term | E1: arr_term | F1: dep_time | G1: arr_time | H1: dep_time_mins | I1: arr_time_mins | J1: PEAK? | K1: type | L1: duration(mins)
A2: 0 | B2: - | C2: - | D2: - | E2: - | F2: - | G2: - | H2: - | I2: - | J2: - | K2: depot | L2: -
A3: 1 | B3: 77 | C3: 18.7 | D3: Bukit_Batok | E3: Marina_Center | F3: 5:45 | G3: 6:47 | H3: 345 | I3: 407 | J3: FALSE | K3: trip | L3: 62
A4: 2 | B4: 77 | C4: 18.7 | D4: Marina_Center | E4: Bukit_Batok | F4: 5:45 | G4: 6:47 | H4: 345 | I4: 407 | J4: FALSE | K4: trip | L4: 62
A5: 3 | B5: 173 | C5: 13.2 | D5: Bukit_Batok | E5: Bukit_Batok | F5: 6:00 | G5: 6:44 | H5: 360 | I5: 404 | J5: FALSE | K5: trip | L5: 44
A6: 4 | B6: 77 | C6: 18.7 | D6: Bukit_Batok | E6: Marina_Center | F6: 6:15 | G6: 7:17 | H6: 375 | I6: 437 | J6: FALSE | K6: trip | L6: 62
A7: 5 | B7: 77 | C7: 18.7 | D7: Marina_Center | E7: Bukit_Batok | F7: 6:15 | G7: 7:17 | H7: 375 | I7: 437 | J7: FALSE | K7: trip | L7: 62 | O7: Bukit_Batok | P7: Marina_Center
A8: 6 | B8: 173 | C8: 13.2 | D8: Bukit_Batok | E8: Bukit_Batok | F8: 6:30 | G8: 7:14 | H8: 390 | I8: 434 | J8: FALSE | K8: trip | L8: 44 | N8: Bukit_Batok | O8: 0 | P8: 28
A9: 7 | B9: 77 | C9: 18.7 | D9: Bukit_Batok | E9: Marina_Center | F9: 6:45 | G9: 7:47 | H9: 405 | I9: 467 | J9: FALSE | K9: trip | L9: 62 | N9: Marina_Center | O9: 22 | P9: 0
A10: 8 | B10: 77 | C10: 18.7 | D10: Marina_Center | E10: Bukit_Batok | F10: 6:45 | G10: 7:47 | H10: 405 | I10: 467 | J10: FALSE | K10: trip | L10: 62
A11: 9 | B11: 173 | C11: 13.2 | D11: Bukit_Batok | E11: Bukit_Batok | F11: 7:00 | G11: 7:44 | H11: 420 | I11: 464 | J11: TRUE | K11: trip | L11: 44
A12: 10 | B12: 77 | C12: 18.7 | D12: Bukit_Batok | E12: Marina_Center | F12: 7:15 | G12: 8:17 | H12: 435 | I12: 497 | J12: TRUE | K12: trip | L12: 62
A13: 11 | B13: 77 | C13: 18.7 | D13: Marina_Center | E13: Bukit_Batok | F13: 7:15 | G13: 8:17 | H13: 435 | I13: 497 | J13: TRUE | K13: trip | L13: 62
A14: 12 | B14: 173 | C14: 13.2 | D14: Bukit_Batok | E14: Bukit_Batok | F14: 7:30 | G14: 8:14 | H14: 450 | I14: 494 | J14: TRUE | K14: trip | L14: 44
A15: 13 | B15: 77 | C15: 18.7 | D15: Bukit_Batok | E15: Marina_Center | F15: 7:45 | G15: 8:47 | H15: 465 | I15: 527 | J15: TRUE | K15: trip | L15: 62
A16: 14 | B16: 77 | C16: 18.7 | D16: Marina_Center | E16: Bukit_Batok | F16: 7:45 | G16: 8:47 | H16: 465 | I16: 527 | J16: TRUE | K16: trip | L16: 62
A17: 15 | B17: 173 | C17: 13.2 | D17: Bukit_Batok | E17: Bukit_Batok | F17: 8:00 | G17: 8:44 | H17: 480 | I17: 524 | J17: TRUE | K17: trip | L17: 44
A18: 16 | B18: 77 | C18: 18.7 | D18: Bukit_Batok | E18: Marina_Center | F18: 8:15 | G18: 9:17 | H18: 495 | I18: 557 | J18: TRUE | K18: trip | L18: 62
A19: 17 | B19: 77 | C19: 18.7 | D19: Marina_Center | E19: Bukit_Batok | F19: 8:15 | G19: 9:17 | H19: 495 | I19: 557 | J19: TRUE | K19: trip | L19: 62
A20: 18 | B20: 173 | C20: 13.2 | D20: Bukit_Batok | E20: Bukit_Batok | F20: 8:30 | G20: 9:14 | H20: 510 | I20: 554 | J20: TRUE | K20: trip | L20: 44
A21: 19 | B21: 77 | C21: 18.7 | D21: Bukit_Batok | E21: Marina_Center | F21: 8:45 | G21: 9:47 | H21: 525 | I21: 587 | J21: TRUE | K21: trip | L21: 62
... A32: 30 | B32: 173 | C32: 13.2 | D32: Bukit_Batok | E32: Bukit_Batok | F32: 11:30 | G32: 12:14 | H32: 690 | I32: 734 | J32: FALSE | K32: trip | L32: 44
A33: 31 | B33: - | C33: - | D33: Bukit_Batok | E33: Bukit_Batok | F33: - | G33: - | H33: - | I33: - | J33: - | K33: cs | L33: 36
A34: 32 | B34: - | C34: - | D34: Marina_Center | E34: Marina_Center | F34: - | G34: - | H34: - | I34: - | J34: - | K34: cs | L34: 36

Sheet feasible_mat
B1: 0 | C1: 1 | D1: 2 | E1: 3 | F1: 4 | G1: 5 | H1: 6 | I1: 7 | J1: 8 | K1: 9 | L1: 10 | M1: 11 | N1: 12 | O1: 13 | P1: 14 | Q1: 15 | R1: 16 | S1: 17 | T1: 18 | U1: 19 | V1: 20 | W1: 21 | X1: 22 | Y1: 23 | Z1: 24 | AA1: 25 | AB1: 26 | AC1: 27 | AD1: 28 | AE1: 29 | AF1: 30
A2: 0 | B2: 0 | C2: 1 | D2: 1 | E2: 1 | F2: 1 | G2: 1 | H2: 1 | I2: 1 | J2: 1 | K2: 1 | L2: 1 | M2: 1 | N2: 1 | O2: 1 | P2: 1 | Q2: 1 | R2: 1 | S2: 1 | T2: 1 | U2: 1 | V2: 1 | W2: 1 | X2: 1 | Y2: 1 | Z2: 1 | AA2: 1 | AB2: 1 | AC2: 1 | AD2: 1 | AE2: 1 | AF2: 1
A3: 1 | B3: 1 | C3: =IF(AND(VLOOKUP(C$1,main!$A$2:$L$32,8,FALSE)-VLOOKUP($A3,main!$A$2:$L$32,9,FALSE)>=5),1,0) -> 0 | D3: =IF(AND(VLOOKUP(D$1,main!$A$2:$L$32,8,FALSE)-VLOOKUP($A3,main!$A$2:$L$32,9,FALSE)>=5),1,0) -> 0 | E3: =IF(AND(VLOOKUP(E$1,main!$A$2:$L$32,8,FALSE)-VLOOKUP($A3,main!$A$2:$L$32,9,FALSE)>=5),1,0) -> 0 | F3: =IF(AND(VLOOKUP(F$1,main!$A$2:$L$32,8,FALSE)-VLOOKUP($A3,main!$A$2:$L$32,9,FALSE)>=5),1,0) -> 0 | G3: =IF(AND(VLOOKUP(G$1,main!$A$2:$L$32,8,FALSE)-VLOOKUP($A3,main!$A$2:$L$32,9,FALSE)>=5),1,0) -> 0 | H3: =IF(AND(VLOOKUP(H$1,main!$A$2:$L$32,8,FALSE)-VLOOKUP($A3,main!$A$2:$L$32,9,FALSE)>=5),1,0) -> 0 | I3: =IF(AND(VLOOKUP(I$1,main!$A$2:$L$32,8,FALSE)-VLOOKUP($A3,main!$A$2:$L$32,9,FALSE)>=5),1,0) -> 0 | J3: =IF(AND(VLOOKUP(J$1,main!$A$2:$L$32,8,FALSE)-VLOOKUP($A3,main!$A$2:$L$32,9,FALSE)>=5),1,0) -> 0 | ... AF3: =IF(AND(VLOOKUP(AF$1,main!$A$2:$L$32,8,FALSE)-VLOOKUP($A3,main!$A$2:$L$32,9,FALSE)>=5),1,0) -> 1
A4: 2 | B4: 1 | C4: =IF(AND(VLOOKUP(C$1,main!$A$2:$L$32,8,FALSE)-VLOOKUP($A4,main!$A$2:$L$32,9,FALSE)>=5),1,0) -> 0 | D4: =IF(AND(VLOOKUP(D$1,main!$A$2:$L$32,8,FALSE)-VLOOKUP($A4,main!$A$2:$L$32,9,FALSE)>=5),1,0) -> 0 | E4: =IF(AND(VLOOKUP(E$1,main!$A$2:$L$32,8,FALSE)-VLOOKUP($A4,main!$A$2:$L$32,9,FALSE)>=5),1,0) -> 0 | F4: =IF(AND(VLOOKUP(F$1,main!$A$2:$L$32,8,FALSE)-VLOOKUP($A4,main!$A$2:$L$32,9,FALSE)>=5),1,0) -> 0 | G4: =IF(AND(VLOOKUP(G$1,main!$A$2:$L$32,8,FALSE)-VLOOKUP($A4,main!$A$2:$L$32,9,FALSE)>=5),1,0) -> 0 | H4: =IF(AND(VLOOKUP(H$1,main!$A$2:$L$32,8,FALSE)-VLOOKUP($A4,main!$A$2:$L$32,9,FALSE)>=5),1,0) -> 0 | I4: =IF(AND(VLOOKUP(I$1,main!$A$2:$L$32,8,FALSE)-VLOOKUP($A4,main!$A$2:$L$32,9,FALSE)>=5),1,0) -> 0 | J4: =IF(AND(VLOOKUP(J$1,main!$A$2:$L$32,8,FALSE)-VLOOKUP($A4,main!$A$2:$L$32,9,FALSE)>=5),1,0) -> 0 | ... AF4: =IF(AND(VLOOKUP(AF$1,main!$A$2:$L$32,8,FALSE)-VLOOKUP($A4,main!$A$2:$L$32,9,FALSE)>=5),1,0) -> 1
A5: 3 | B5: 1 | C5: =IF(AND(VLOOKUP(C$1,main!$A$2:$L$32,8,FALSE)-VLOOKUP($A5,main!$A$2:$L$32,9,FALSE)>=5),1,0) -> 0 | D5: =IF(AND(VLOOKUP(D$1,main!$A$2:$L$32,8,FALSE)-VLOOKUP($A5,main!$A$2:$L$32,9,FALSE)>=5),1,0) -> 0 | E5: =IF(AND(VLOOKUP(E$1,main!$A$2:$L$32,8,FALSE)-VLOOKUP($A5,main!$A$2:$L$32,9,FALSE)>=5),1,0) -> 0 | F5: =IF(AND(VLOOKUP(F$1,main!$A$2:$L$32,8,FALSE)-VLOOKUP($A5,main!$A$2:$L$32,9,FALSE)>=5),1,0) -> 0 | G5: =IF(AND(VLOOKUP(G$1,main!$A$2:$L$32,8,FALSE)-VLOOKUP($A5,main!$A$2:$L$32,9,FALSE)>=5),1,0) -> 0 | H5: =IF(AND(VLOOKUP(H$1,main!$A$2:$L$32,8,FALSE)-VLOOKUP($A5,main!$A$2:$L$32,9,FALSE)>=5),1,0) -> 0 | I5: =IF(AND(VLOOKUP(I$1,main!$A$2:$L$32,8,FALSE)-VLOOKUP($A5,main!$A$2:$L$32,9,FALSE)>=5),1,0) -> 0 | J5: =IF(AND(VLOOKUP(J$1,main!$A$2:$L$32,8,FALSE)-VLOOKUP($A5,main!$A$2:$L$32,9,FALSE)>=5),1,0) -> 0 | ... AF5: =IF(AND(VLOOKUP(AF$1,main!$A$2:$L$32,8,FALSE)-VLOOKUP($A5,main!$A$2:$L$32,9,FALSE)>=5),1,0) -> 1
A6: 4 | B6: 1 | C6: =IF(AND(VLOOKUP(C$1,main!$A$2:$L$32,8,FALSE)-VLOOKUP($A6,main!$A$2:$L$32,9,FALSE)>=5),1,0) -> 0 | D6: =IF(AND(VLOOKUP(D$1,main!$A$2:$L$32,8,FALSE)-VLOOKUP($A6,main!$A$2:$L$32,9,FALSE)>=5),1,0) -> 0 | E6: =IF(AND(VLOOKUP(E$1,main!$A$2:$L$32,8,FALSE)-VLOOKUP($A6,main!$A$2:$L$32,9,FALSE)>=5),1,0) -> 0 | F6: =IF(AND(VLOOKUP(F$1,main!$A$2:$L$32,8,FALSE)-VLOOKUP($A6,main!$A$2:$L$32,9,FALSE)>=5),1,0) -> 0 | G6: =IF(AND(VLOOKUP(G$1,main!$A$2:$L$32,8,FALSE)-VLOOKUP($A6,main!$A$2:$L$32,9,FALSE)>=5),1,0) -> 0 | H6: =IF(AND(VLOOKUP(H$1,main!$A$2:$L$32,8,FALSE)-VLOOKUP($A6,main!$A$2:$L$32,9,FALSE)>=5),1,0) -> 0 | I6: =IF(AND(VLOOKUP(I$1,main!$A$2:$L$32,8,FALSE)-VLOOKUP($A6,main!$A$2:$L$32,9,FALSE)>=5),1,0) -> 0 | J6: =IF(AND(VLOOKUP(J$1,main!$A$2:$L$32,8,FALSE)-VLOOKUP($A6,main!$A$2:$L$32,9,FALSE)>=5),1,0) -> 0 | ... AF6: =IF(AND(VLOOKUP(AF$1,main!$A$2:$L$32,8,FALSE)-VLOOKUP($A6,main!$A$2:$L$32,9,FALSE)>=5),1,0) -> 1
A7: 5 | B7: 1 | C7: =IF(AND(VLOOKUP(C$1,main!$A$2:$L$32,8,FALSE)-VLOOKUP($A7,main!$A$2:$L$32,9,FALSE)>=5),1,0) -> 0 | D7: =IF(AND(VLOOKUP(D$1,main!$A$2:$L$32,8,FALSE)-VLOOKUP($A7,main!$A$2:$L$32,9,FALSE)>=5),1,0) -> 0 | E7: =IF(AND(VLOOKUP(E$1,main!$A$2:$L$32,8,FALSE)-VLOOKUP($A7,main!$A$2:$L$32,9,FALSE)>=5),1,0) -> 0 | F7: =IF(AND(VLOOKUP(F$1,main!$A$2:$L$32,8,FALSE)-VLOOKUP($A7,main!$A$2:$L$32,9,FALSE)>=5),1,0) -> 0 | G7: =IF(AND(VLOOKUP(G$1,main!$A$2:$L$32,8,FALSE)-VLOOKUP($A7,main!$A$2:$L$32,9,FALSE)>=5),1,0) -> 0 | H7: =IF(AND(VLOOKUP(H$1,main!$A$2:$L$32,8,FALSE)-VLOOKUP($A7,main!$A$2:$L$32,9,FALSE)>=5),1,0) -> 0 | I7: =IF(AND(VLOOKUP(I$1,main!$A$2:$L$32,8,FALSE)-VLOOKUP($A7,main!$A$2:$L$32,9,FALSE)>=5),1,0) -> 0 | J7: =IF(AND(VLOOKUP(J$1,main!$A$2:$L$32,8,FALSE)-VLOOKUP($A7,main!$A$2:$L$32,9,FALSE)>=5),1,0) -> 0 | ... AF7: =IF(AND(VLOOKUP(AF$1,main!$A$2:$L$32,8,FALSE)-VLOOKUP($A7,main!$A$2:$L$32,9,FALSE)>=5),1,0) -> 1
A8: 6 | B8: 1 | C8: =IF(AND(VLOOKUP(C$1,main!$A$2:$L$32,8,FALSE)-VLOOKUP($A8,main!$A$2:$L$32,9,FALSE)>=5),1,0) -> 0 | D8: =IF(AND(VLOOKUP(D$1,main!$A$2:$L$32,8,FALSE)-VLOOKUP($A8,main!$A$2:$L$32,9,FALSE)>=5),1,0) -> 0 | E8: =IF(AND(VLOOKUP(E$1,main!$A$2:$L$32,8,FALSE)-VLOOKUP($A8,main!$A$2:$L$32,9,FALSE)>=5),1,0) -> 0 | F8: =IF(AND(VLOOKUP(F$1,main!$A$2:$L$32,8,FALSE)-VLOOKUP($A8,main!$A$2:$L$32,9,FALSE)>=5),1,0) -> 0 | G8: =IF(AND(VLOOKUP(G$1,main!$A$2:$L$32,8,FALSE)-VLOOKUP($A8,main!$A$2:$L$32,9,FALSE)>=5),1,0) -> 0 | H8: =IF(AND(VLOOKUP(H$1,main!$A$2:$L$32,8,FALSE)-VLOOKUP($A8,main!$A$2:$L$32,9,FALSE)>=5),1,0) -> 0 | I8: =IF(AND(VLOOKUP(I$1,main!$A$2:$L$32,8,FALSE)-VLOOKUP($A8,main!$A$2:$L$32,9,FALSE)>=5),1,0) -> 0 | J8: =IF(AND(VLOOKUP(J$1,main!$A$2:$L$32,8,FALSE)-VLOOKUP($A8,main!$A$2:$L$32,9,FALSE)>=5),1,0) -> 0 | ... AF8: =IF(AND(VLOOKUP(AF$1,main!$A$2:$L$32,8,FALSE)-VLOOKUP($A8,main!$A$2:$L$32,9,FALSE)>=5),1,0) -> 1
A9: 7 | B9: 1 | C9: =IF(AND(VLOOKUP(C$1,main!$A$2:$L$32,8,FALSE)-VLOOKUP($A9,main!$A$2:$L$32,9,FALSE)>=5),1,0) -> 0 | D9: =IF(AND(VLOOKUP(D$1,main!$A$2:$L$32,8,FALSE)-VLOOKUP($A9,main!$A$2:$L$32,9,FALSE)>=5),1,0) -> 0 | E9: =IF(AND(VLOOKUP(E$1,main!$A$2:$L$32,8,FALSE)-VLOOKUP($A9,main!$A$2:$L$32,9,FALSE)>=5),1,0) -> 0 | F9: =IF(AND(VLOOKUP(F$1,main!$A$2:$L$32,8,FALSE)-VLOOKUP($A9,main!$A$2:$L$32,9,FALSE)>=5),1,0) -> 0 | G9: =IF(AND(VLOOKUP(G$1,main!$A$2:$L$32,8,FALSE)-VLOOKUP($A9,main!$A$2:$L$32,9,FALSE)>=5),1,0) -> 0 | H9: =IF(AND(VLOOKUP(H$1,main!$A$2:$L$32,8,FALSE)-VLOOKUP($A9,main!$A$2:$L$32,9,FALSE)>=5),1,0) -> 0 | I9: =IF(AND(VLOOKUP(I$1,main!$A$2:$L$32,8,FALSE)-VLOOKUP($A9,main!$A$2:$L$32,9,FALSE)>=5),1,0) -> 0 | J9: =IF(AND(VLOOKUP(J$1,main!$A$2:$L$32,8,FALSE)-VLOOKUP($A9,main!$A$2:$L$32,9,FALSE)>=5),1,0) -> 0 | ... AF9: =IF(AND(VLOOKUP(AF$1,main!$A$2:$L$32,8,FALSE)-VLOOKUP($A9,main!$A$2:$L$32,9,FALSE)>=5),1,0) -> 1
A10: 8 | B10: 1 | C10: =IF(AND(VLOOKUP(C$1,main!$A$2:$L$32,8,FALSE)-VLOOKUP($A10,main!$A$2:$L$32,9,FALSE)>=5),1,0) -> 0 | D10: =IF(AND(VLOOKUP(D$1,main!$A$2:$L$32,8,FALSE)-VLOOKUP($A10,main!$A$2:$L$32,9,FALSE)>=5),1,0) -> 0 | E10: =IF(AND(VLOOKUP(E$1,main!$A$2:$L$32,8,FALSE)-VLOOKUP($A10,main!$A$2:$L$32,9,FALSE)>=5),1,0) -> 0 | F10: =IF(AND(VLOOKUP(F$1,main!$A$2:$L$32,8,FALSE)-VLOOKUP($A10,main!$A$2:$L$32,9,FALSE)>=5),1,0) -> 0 | G10: =IF(AND(VLOOKUP(G$1,main!$A$2:$L$32,8,FALSE)-VLOOKUP($A10,main!$A$2:$L$32,9,FALSE)>=5),1,0) -> 0 | H10: =IF(AND(VLOOKUP(H$1,main!$A$2:$L$32,8,FALSE)-VLOOKUP($A10,main!$A$2:$L$32,9,FALSE)>=5),1,0) -> 0 | I10: =IF(AND(VLOOKUP(I$1,main!$A$2:$L$32,8,FALSE)-VLOOKUP($A10,main!$A$2:$L$32,9,FALSE)>=5),1,0) -> 0 | J10: =IF(AND(VLOOKUP(J$1,main!$A$2:$L$32,8,FALSE)-VLOOKUP($A10,main!$A$2:$L$32,9,FALSE)>=5),1,0) -> 0 | ... AF10: =IF(AND(VLOOKUP(AF$1,main!$A$2:$L$32,8,FALSE)-VLOOKUP($A10,main!$A$2:$L$32,9,FALSE)>=5),1,0) -> 1
A11: 9 | B11: 1 | C11: =IF(AND(VLOOKUP(C$1,main!$A$2:$L$32,8,FALSE)-VLOOKUP($A11,main!$A$2:$L$32,9,FALSE)>=5),1,0) -> 0 | D11: =IF(AND(VLOOKUP(D$1,main!$A$2:$L$32,8,FALSE)-VLOOKUP($A11,main!$A$2:$L$32,9,FALSE)>=5),1,0) -> 0 | E11: =IF(AND(VLOOKUP(E$1,main!$A$2:$L$32,8,FALSE)-VLOOKUP($A11,main!$A$2:$L$32,9,FALSE)>=5),1,0) -> 0 | F11: =IF(AND(VLOOKUP(F$1,main!$A$2:$L$32,8,FALSE)-VLOOKUP($A11,main!$A$2:$L$32,9,FALSE)>=5),1,0) -> 0 | G11: =IF(AND(VLOOKUP(G$1,main!$A$2:$L$32,8,FALSE)-VLOOKUP($A11,main!$A$2:$L$32,9,FALSE)>=5),1,0) -> 0 | H11: =IF(AND(VLOOKUP(H$1,main!$A$2:$L$32,8,FALSE)-VLOOKUP($A11,main!$A$2:$L$32,9,FALSE)>=5),1,0) -> 0 | I11: =IF(AND(VLOOKUP(I$1,main!$A$2:$L$32,8,FALSE)-VLOOKUP($A11,main!$A$2:$L$32,9,FALSE)>=5),1,0) -> 0 | J11: =IF(AND(VLOOKUP(J$1,main!$A$2:$L$32,8,FALSE)-VLOOKUP($A11,main!$A$2:$L$32,9,FALSE)>=5),1,0) -> 0 | ... AF11: =IF(AND(VLOOKUP(AF$1,main!$A$2:$L$32,8,FALSE)-VLOOKUP($A11,main!$A$2:$L$32,9,FALSE)>=5),1,0) -> 1
A12: 10 | B12: 1 | C12: =IF(AND(VLOOKUP(C$1,main!$A$2:$L$32,8,FALSE)-VLOOKUP($A12,main!$A$2:$L$32,9,FALSE)>=5),1,0) -> 0 | D12: =IF(AND(VLOOKUP(D$1,main!$A$2:$L$32,8,FALSE)-VLOOKUP($A12,main!$A$2:$L$32,9,FALSE)>=5),1,0) -> 0 | E12: =IF(AND(VLOOKUP(E$1,main!$A$2:$L$32,8,FALSE)-VLOOKUP($A12,main!$A$2:$L$32,9,FALSE)>=5),1,0) -> 0 | F12: =IF(AND(VLOOKUP(F$1,main!$A$2:$L$32,8,FALSE)-VLOOKUP($A12,main!$A$2:$L$32,9,FALSE)>=5),1,0) -> 0 | G12: =IF(AND(VLOOKUP(G$1,main!$A$2:$L$32,8,FALSE)-VLOOKUP($A12,main!$A$2:$L$32,9,FALSE)>=5),1,0) -> 0 | H12: =IF(AND(VLOOKUP(H$1,main!$A$2:$L$32,8,FALSE)-VLOOKUP($A12,main!$A$2:$L$32,9,FALSE)>=5),1,0) -> 0 | I12: =IF(AND(VLOOKUP(I$1,main!$A$2:$L$32,8,FALSE)-VLOOKUP($A12,main!$A$2:$L$32,9,FALSE)>=5),1,0) -> 0 | J12: =IF(AND(VLOOKUP(J$1,main!$A$2:$L$32,8,FALSE)-VLOOKUP($A12,main!$A$2:$L$32,9,FALSE)>=5),1,0) -> 0 | ... AF12: =IF(AND(VLOOKUP(AF$1,main!$A$2:$L$32,8,FALSE)-VLOOKUP($A12,main!$A$2:$L$32,9,FALSE)>=5),1,0) -> 1
A13: 11 | B13: 1 | C13: =IF(AND(VLOOKUP(C$1,main!$A$2:$L$32,8,FALSE)-VLOOKUP($A13,main!$A$2:$L$32,9,FALSE)>=5),1,0) -> 0 | D13: =IF(AND(VLOOKUP(D$1,main!$A$2:$L$32,8,FALSE)-VLOOKUP($A13,main!$A$2:$L$32,9,FALSE)>=5),1,0) -> 0 | E13: =IF(AND(VLOOKUP(E$1,main!$A$2:$L$32,8,FALSE)-VLOOKUP($A13,main!$A$2:$L$32,9,FALSE)>=5),1,0) -> 0 | F13: =IF(AND(VLOOKUP(F$1,main!$A$2:$L$32,8,FALSE)-VLOOKUP($A13,main!$A$2:$L$32,9,FALSE)>=5),1,0) -> 0 | G13: =IF(AND(VLOOKUP(G$1,main!$A$2:$L$32,8,FALSE)-VLOOKUP($A13,main!$A$2:$L$32,9,FALSE)>=5),1,0) -> 0 | H13: =IF(AND(VLOOKUP(H$1,main!$A$2:$L$32,8,FALSE)-VLOOKUP($A13,main!$A$2:$L$32,9,FALSE)>=5),1,0) -> 0 | I13: =IF(AND(VLOOKUP(I$1,main!$A$2:$L$32,8,FALSE)-VLOOKUP($A13,main!$A$2:$L$32,9,FALSE)>=5),1,0) -> 0 | J13: =IF(AND(VLOOKUP(J$1,main!$A$2:$L$32,8,FALSE)-VLOOKUP($A13,main!$A$2:$L$32,9,FALSE)>=5),1,0) -> 0 | ... AF13: =IF(AND(VLOOKUP(AF$1,main!$A$2:$L$32,8,FALSE)-VLOOKUP($A13,main!$A$2:$L$32,9,FALSE)>=5),1,0) -> 1
A14: 12 | B14: 1 | C14: =IF(AND(VLOOKUP(C$1,main!$A$2:$L$32,8,FALSE)-VLOOKUP($A14,main!$A$2:$L$32,9,FALSE)>=5),1,0) -> 0 | D14: =IF(AND(VLOOKUP(D$1,main!$A$2:$L$32,8,FALSE)-VLOOKUP($A14,main!$A$2:$L$32,9,FALSE)>=5),1,0) -> 0 | E14: =IF(AND(VLOOKUP(E$1,main!$A$2:$L$32,8,FALSE)-VLOOKUP($A14,main!$A$2:$L$32,9,FALSE)>=5),1,0) -> 0 | F14: =IF(AND(VLOOKUP(F$1,main!$A$2:$L$32,8,FALSE)-VLOOKUP($A14,main!$A$2:$L$32,9,FALSE)>=5),1,0) -> 0 | G14: =IF(AND(VLOOKUP(G$1,main!$A$2:$L$32,8,FALSE)-VLOOKUP($A14,main!$A$2:$L$32,9,FALSE)>=5),1,0) -> 0 | H14: =IF(AND(VLOOKUP(H$1,main!$A$2:$L$32,8,FALSE)-VLOOKUP($A14,main!$A$2:$L$32,9,FALSE)>=5),1,0) -> 0 | I14: =IF(AND(VLOOKUP(I$1,main!$A$2:$L$32,8,FALSE)-VLOOKUP($A14,main!$A$2:$L$32,9,FALSE)>=5),1,0) -> 0 | J14: =IF(AND(VLOOKUP(J$1,main!$A$2:$L$32,8,FALSE)-VLOOKUP($A14,main!$A$2:$L$32,9,FALSE)>=5),1,0) -> 0 | ... AF14: =IF(AND(VLOOKUP(AF$1,main!$A$2:$L$32,8,FALSE)-VLOOKUP($A14,main!$A$2:$L$32,9,FALSE)>=5),1,0) -> 1
... A32: 30 | B32: 1 | C32: =IF(AND(VLOOKUP(C$1,main!$A$2:$L$32,8,FALSE)-VLOOKUP($A32,main!$A$2:$L$32,9,FALSE)>=5),1,0) -> 0 | D32: =IF(AND(VLOOKUP(D$1,main!$A$2:$L$32,8,FALSE)-VLOOKUP($A32,main!$A$2:$L$32,9,FALSE)>=5),1,0) -> 0 | E32: =IF(AND(VLOOKUP(E$1,main!$A$2:$L$32,8,FALSE)-VLOOKUP($A32,main!$A$2:$L$32,9,FALSE)>=5),1,0) -> 0 | F32: =IF(AND(VLOOKUP(F$1,main!$A$2:$L$32,8,FALSE)-VLOOKUP($A32,main!$A$2:$L$32,9,FALSE)>=5),1,0) -> 0 | G32: =IF(AND(VLOOKUP(G$1,main!$A$2:$L$32,8,FALSE)-VLOOKUP($A32,main!$A$2:$L$32,9,FALSE)>=5),1,0) -> 0 | H32: =IF(AND(VLOOKUP(H$1,main!$A$2:$L$32,8,FALSE)-VLOOKUP($A32,main!$A$2:$L$32,9,FALSE)>=5),1,0) -> 0 | I32: =IF(AND(VLOOKUP(I$1,main!$A$2:$L$32,8,FALSE)-VLOOKUP($A32,main!$A$2:$L$32,9,FALSE)>=5),1,0) -> 0 | J32: =IF(AND(VLOOKUP(J$1,main!$A$2:$L$32,8,FALSE)-VLOOKUP($A32,main!$A$2:$L$32,9,FALSE)>=5),1,0) -> 0 | ... AF32: =IF(AND(VLOOKUP(AF$1,main!$A$2:$L$32,8,FALSE)-VLOOKUP($A32,main!$A$2:$L$32,9,FALSE)>=5),1,0) -> 0

Sheet duration_mat
B1: 0 | C1: 1 | D1: 2 | E1: 3 | F1: 4 | G1: 5 | H1: 6 | I1: 7 | J1: 8 | K1: 9 | L1: 10 | M1: 11 | N1: 12 | O1: 13 | P1: 14 | Q1: 15 | R1: 16 | S1: 17 | T1: 18 | U1: 19 | V1: 20 | W1: 21 | X1: 22 | Y1: 23 | Z1: 24 | AA1: 25 | AB1: 26 | AC1: 27 | AD1: 28 | AE1: 29 | AF1: 30 | AG1: 31 | AH1: 32
A2: 0 | B2: 0 | C2: 0 | D2: 0 | E2: 0 | F2: 0 | G2: 0 | H2: 0 | I2: 0 | J2: 0 | K2: 0 | L2: 0 | M2: 0 | N2: 0 | O2: 0 | P2: 0 | Q2: 0 | R2: 0 | S2: 0 | T2: 0 | U2: 0 | V2: 0 | W2: 0 | X2: 0 | Y2: 0 | Z2: 0 | AA2: 0 | AB2: 0 | AC2: 0 | AD2: 0 | AE2: 0 | AF2: 0 | AG2: 0 | AH2: 0
A3: 1 | B3: 0 | C3: =IF(feasible_mat!C3=1,SUM(VLOOKUP($A3,main!$A$2:$L$34,12,FALSE), VLOOKUP(C$1,main!$A$2:$L$34,12,FALSE)),0) -> 0 | D3: =IF(feasible_mat!D3=1,SUM(VLOOKUP($A3,main!$A$2:$L$34,12,FALSE), VLOOKUP(D$1,main!$A$2:$L$34,12,FALSE)),0) -> 0 | E3: =IF(feasible_mat!E3=1,SUM(VLOOKUP($A3,main!$A$2:$L$34,12,FALSE), VLOOKUP(E$1,main!$A$2:$L$34,12,FALSE)),0) -> 0 | F3: =IF(feasible_mat!F3=1,SUM(VLOOKUP($A3,main!$A$2:$L$34,12,FALSE), VLOOKUP(F$1,main!$A$2:$L$34,12,FALSE)),0) -> 0 | G3: =IF(feasible_mat!G3=1,SUM(VLOOKUP($A3,main!$A$2:$L$34,12,FALSE), VLOOKUP(G$1,main!$A$2:$L$34,12,FALSE)),0) -> 0 | H3: =IF(feasible_mat!H3=1,SUM(VLOOKUP($A3,main!$A$2:$L$34,12,FALSE), VLOOKUP(H$1,main!$A$2:$L$34,12,FALSE)),0) -> 0 | I3: =IF(feasible_mat!I3=1,SUM(VLOOKUP($A3,main!$A$2:$L$34,12,FALSE), VLOOKUP(I$1,main!$A$2:$L$34,12,FALSE)),0) -> 0 | J3: =IF(feasible_mat!J3=1,SUM(VLOOKUP($A3,main!$A$2:$L$34,12,FALSE), VLOOKUP(J$1,main!$A$2:$L$34,12,FALSE)),0) -> 0 | ... AH3: =IF(feasible_mat!AH3=1,SUM(VLOOKUP($A3,main!$A$2:$L$34,12,FALSE), VLOOKUP(AH$1,main!$A$2:$L$34,12,FALSE)),0) -> 0
A4: 2 | B4: 0 | C4: =IF(feasible_mat!C4=1,SUM(VLOOKUP($A4,main!$A$2:$L$34,12,FALSE), VLOOKUP(C$1,main!$A$2:$L$34,12,FALSE)),0) -> 0 | D4: =IF(feasible_mat!D4=1,SUM(VLOOKUP($A4,main!$A$2:$L$34,12,FALSE), VLOOKUP(D$1,main!$A$2:$L$34,12,FALSE)),0) -> 0 | E4: =IF(feasible_mat!E4=1,SUM(VLOOKUP($A4,main!$A$2:$L$34,12,FALSE), VLOOKUP(E$1,main!$A$2:$L$34,12,FALSE)),0) -> 0 | F4: =IF(feasible_mat!F4=1,SUM(VLOOKUP($A4,main!$A$2:$L$34,12,FALSE), VLOOKUP(F$1,main!$A$2:$L$34,12,FALSE)),0) -> 0 | G4: =IF(feasible_mat!G4=1,SUM(VLOOKUP($A4,main!$A$2:$L$34,12,FALSE), VLOOKUP(G$1,main!$A$2:$L$34,12,FALSE)),0) -> 0 | H4: =IF(feasible_mat!H4=1,SUM(VLOOKUP($A4,main!$A$2:$L$34,12,FALSE), VLOOKUP(H$1,main!$A$2:$L$34,12,FALSE)),0) -> 0 | I4: =IF(feasible_mat!I4=1,SUM(VLOOKUP($A4,main!$A$2:$L$34,12,FALSE), VLOOKUP(I$1,main!$A$2:$L$34,12,FALSE)),0) -> 0 | J4: =IF(feasible_mat!J4=1,SUM(VLOOKUP($A4,main!$A$2:$L$34,12,FALSE), VLOOKUP(J$1,main!$A$2:$L$34,12,FALSE)),0) -> 0 | ... AH4: =IF(feasible_mat!AH4=1,SUM(VLOOKUP($A4,main!$A$2:$L$34,12,FALSE), VLOOKUP(AH$1,main!$A$2:$L$34,12,FALSE)),0) -> 0
A5: 3 | B5: 0 | C5: =IF(feasible_mat!C5=1,SUM(VLOOKUP($A5,main!$A$2:$L$34,12,FALSE), VLOOKUP(C$1,main!$A$2:$L$34,12,FALSE)),0) -> 0 | D5: =IF(feasible_mat!D5=1,SUM(VLOOKUP($A5,main!$A$2:$L$34,12,FALSE), VLOOKUP(D$1,main!$A$2:$L$34,12,FALSE)),0) -> 0 | E5: =IF(feasible_mat!E5=1,SUM(VLOOKUP($A5,main!$A$2:$L$34,12,FALSE), VLOOKUP(E$1,main!$A$2:$L$34,12,FALSE)),0) -> 0 | F5: =IF(feasible_mat!F5=1,SUM(VLOOKUP($A5,main!$A$2:$L$34,12,FALSE), VLOOKUP(F$1,main!$A$2:$L$34,12,FALSE)),0) -> 0 | G5: =IF(feasible_mat!G5=1,SUM(VLOOKUP($A5,main!$A$2:$L$34,12,FALSE), VLOOKUP(G$1,main!$A$2:$L$34,12,FALSE)),0) -> 0 | H5: =IF(feasible_mat!H5=1,SUM(VLOOKUP($A5,main!$A$2:$L$34,12,FALSE), VLOOKUP(H$1,main!$A$2:$L$34,12,FALSE)),0) -> 0 | I5: =IF(feasible_mat!I5=1,SUM(VLOOKUP($A5,main!$A$2:$L$34,12,FALSE), VLOOKUP(I$1,main!$A$2:$L$34,12,FALSE)),0) -> 0 | J5: =IF(feasible_mat!J5=1,SUM(VLOOKUP($A5,main!$A$2:$L$34,12,FALSE), VLOOKUP(J$1,main!$A$2:$L$34,12,FALSE)),0) -> 0 | ... AH5: =IF(feasible_mat!AH5=1,SUM(VLOOKUP($A5,main!$A$2:$L$34,12,FALSE), VLOOKUP(AH$1,main!$A$2:$L$34,12,FALSE)),0) -> 0
A6: 4 | B6: 0 | C6: =IF(feasible_mat!C6=1,SUM(VLOOKUP($A6,main!$A$2:$L$34,12,FALSE), VLOOKUP(C$1,main!$A$2:$L$34,12,FALSE)),0) -> 0 | D6: =IF(feasible_mat!D6=1,SUM(VLOOKUP($A6,main!$A$2:$L$34,12,FALSE), VLOOKUP(D$1,main!$A$2:$L$34,12,FALSE)),0) -> 0 | E6: =IF(feasible_mat!E6=1,SUM(VLOOKUP($A6,main!$A$2:$L$34,12,FALSE), VLOOKUP(E$1,main!$A$2:$L$34,12,FALSE)),0) -> 0 | F6: =IF(feasible_mat!F6=1,SUM(VLOOKUP($A6,main!$A$2:$L$34,12,FALSE), VLOOKUP(F$1,main!$A$2:$L$34,12,FALSE)),0) -> 0 | G6: =IF(feasible_mat!G6=1,SUM(VLOOKUP($A6,main!$A$2:$L$34,12,FALSE), VLOOKUP(G$1,main!$A$2:$L$34,12,FALSE)),0) -> 0 | H6: =IF(feasible_mat!H6=1,SUM(VLOOKUP($A6,main!$A$2:$L$34,12,FALSE), VLOOKUP(H$1,main!$A$2:$L$34,12,FALSE)),0) -> 0 | I6: =IF(feasible_mat!I6=1,SUM(VLOOKUP($A6,main!$A$2:$L$34,12,FALSE), VLOOKUP(I$1,main!$A$2:$L$34,12,FALSE)),0) -> 0 | J6: =IF(feasible_mat!J6=1,SUM(VLOOKUP($A6,main!$A$2:$L$34,12,FALSE), VLOOKUP(J$1,main!$A$2:$L$34,12,FALSE)),0) -> 0 | ... AH6: =IF(feasible_mat!AH6=1,SUM(VLOOKUP($A6,main!$A$2:$L$34,12,FALSE), VLOOKUP(AH$1,main!$A$2:$L$34,12,FALSE)),0) -> 0
A7: 5 | B7: 0 | C7: =IF(feasible_mat!C7=1,SUM(VLOOKUP($A7,main!$A$2:$L$34,12,FALSE), VLOOKUP(C$1,main!$A$2:$L$34,12,FALSE)),0) -> 0 | D7: =IF(feasible_mat!D7=1,SUM(VLOOKUP($A7,main!$A$2:$L$34,12,FALSE), VLOOKUP(D$1,main!$A$2:$L$34,12,FALSE)),0) -> 0 | E7: =IF(feasible_mat!E7=1,SUM(VLOOKUP($A7,main!$A$2:$L$34,12,FALSE), VLOOKUP(E$1,main!$A$2:$L$34,12,FALSE)),0) -> 0 | F7: =IF(feasible_mat!F7=1,SUM(VLOOKUP($A7,main!$A$2:$L$34,12,FALSE), VLOOKUP(F$1,main!$A$2:$L$34,12,FALSE)),0) -> 0 | G7: =IF(feasible_mat!G7=1,SUM(VLOOKUP($A7,main!$A$2:$L$34,12,FALSE), VLOOKUP(G$1,main!$A$2:$L$34,12,FALSE)),0) -> 0 | H7: =IF(feasible_mat!H7=1,SUM(VLOOKUP($A7,main!$A$2:$L$34,12,FALSE), VLOOKUP(H$1,main!$A$2:$L$34,12,FALSE)),0) -> 0 | I7: =IF(feasible_mat!I7=1,SUM(VLOOKUP($A7,main!$A$2:$L$34,12,FALSE), VLOOKUP(I$1,main!$A$2:$L$34,12,FALSE)),0) -> 0 | J7: =IF(feasible_mat!J7=1,SUM(VLOOKUP($A7,main!$A$2:$L$34,12,FALSE), VLOOKUP(J$1,main!$A$2:$L$34,12,FALSE)),0) -> 0 | ... AH7: =IF(feasible_mat!AH7=1,SUM(VLOOKUP($A7,main!$A$2:$L$34,12,FALSE), VLOOKUP(AH$1,main!$A$2:$L$34,12,FALSE)),0) -> 0
A8: 6 | B8: 0 | C8: =IF(feasible_mat!C8=1,SUM(VLOOKUP($A8,main!$A$2:$L$34,12,FALSE), VLOOKUP(C$1,main!$A$2:$L$34,12,FALSE)),0) -> 0 | D8: =IF(feasible_mat!D8=1,SUM(VLOOKUP($A8,main!$A$2:$L$34,12,FALSE), VLOOKUP(D$1,main!$A$2:$L$34,12,FALSE)),0) -> 0 | E8: =IF(feasible_mat!E8=1,SUM(VLOOKUP($A8,main!$A$2:$L$34,12,FALSE), VLOOKUP(E$1,main!$A$2:$L$34,12,FALSE)),0) -> 0 | F8: =IF(feasible_mat!F8=1,SUM(VLOOKUP($A8,main!$A$2:$L$34,12,FALSE), VLOOKUP(F$1,main!$A$2:$L$34,12,FALSE)),0) -> 0 | G8: =IF(feasible_mat!G8=1,SUM(VLOOKUP($A8,main!$A$2:$L$34,12,FALSE), VLOOKUP(G$1,main!$A$2:$L$34,12,FALSE)),0) -> 0 | H8: =IF(feasible_mat!H8=1,SUM(VLOOKUP($A8,main!$A$2:$L$34,12,FALSE), VLOOKUP(H$1,main!$A$2:$L$34,12,FALSE)),0) -> 0 | I8: =IF(feasible_mat!I8=1,SUM(VLOOKUP($A8,main!$A$2:$L$34,12,FALSE), VLOOKUP(I$1,main!$A$2:$L$34,12,FALSE)),0) -> 0 | J8: =IF(feasible_mat!J8=1,SUM(VLOOKUP($A8,main!$A$2:$L$34,12,FALSE), VLOOKUP(J$1,main!$A$2:$L$34,12,FALSE)),0) -> 0 | ... AH8: =IF(feasible_mat!AH8=1,SUM(VLOOKUP($A8,main!$A$2:$L$34,12,FALSE), VLOOKUP(AH$1,main!$A$2:$L$34,12,FALSE)),0) -> 0
A9: 7 | B9: 0 | C9: =IF(feasible_mat!C9=1,SUM(VLOOKUP($A9,main!$A$2:$L$34,12,FALSE), VLOOKUP(C$1,main!$A$2:$L$34,12,FALSE)),0) -> 0 | D9: =IF(feasible_mat!D9=1,SUM(VLOOKUP($A9,main!$A$2:$L$34,12,FALSE), VLOOKUP(D$1,main!$A$2:$L$34,12,FALSE)),0) -> 0 | E9: =IF(feasible_mat!E9=1,SUM(VLOOKUP($A9,main!$A$2:$L$34,12,FALSE), VLOOKUP(E$1,main!$A$2:$L$34,12,FALSE)),0) -> 0 | F9: =IF(feasible_mat!F9=1,SUM(VLOOKUP($A9,main!$A$2:$L$34,12,FALSE), VLOOKUP(F$1,main!$A$2:$L$34,12,FALSE)),0) -> 0 | G9: =IF(feasible_mat!G9=1,SUM(VLOOKUP($A9,main!$A$2:$L$34,12,FALSE), VLOOKUP(G$1,main!$A$2:$L$34,12,FALSE)),0) -> 0 | H9: =IF(feasible_mat!H9=1,SUM(VLOOKUP($A9,main!$A$2:$L$34,12,FALSE), VLOOKUP(H$1,main!$A$2:$L$34,12,FALSE)),0) -> 0 | I9: =IF(feasible_mat!I9=1,SUM(VLOOKUP($A9,main!$A$2:$L$34,12,FALSE), VLOOKUP(I$1,main!$A$2:$L$34,12,FALSE)),0) -> 0 | J9: =IF(feasible_mat!J9=1,SUM(VLOOKUP($A9,main!$A$2:$L$34,12,FALSE), VLOOKUP(J$1,main!$A$2:$L$34,12,FALSE)),0) -> 0 | ... AH9: =IF(feasible_mat!AH9=1,SUM(VLOOKUP($A9,main!$A$2:$L$34,12,FALSE), VLOOKUP(AH$1,main!$A$2:$L$34,12,FALSE)),0) -> 0
A10: 8 | B10: 0 | C10: =IF(feasible_mat!C10=1,SUM(VLOOKUP($A10,main!$A$2:$L$34,12,FALSE), VLOOKUP(C$1,main!$A$2:$L$34,12,FALSE)),0) -> 0 | D10: =IF(feasible_mat!D10=1,SUM(VLOOKUP($A10,main!$A$2:$L$34,12,FALSE), VLOOKUP(D$1,main!$A$2:$L$34,12,FALSE)),0) -> 0 | E10: =IF(feasible_mat!E10=1,SUM(VLOOKUP($A10,main!$A$2:$L$34,12,FALSE), VLOOKUP(E$1,main!$A$2:$L$34,12,FALSE)),0) -> 0 | F10: =IF(feasible_mat!F10=1,SUM(VLOOKUP($A10,main!$A$2:$L$34,12,FALSE), VLOOKUP(F$1,main!$A$2:$L$34,12,FALSE)),0) -> 0 | G10: =IF(feasible_mat!G10=1,SUM(VLOOKUP($A10,main!$A$2:$L$34,12,FALSE), VLOOKUP(G$1,main!$A$2:$L$34,12,FALSE)),0) -> 0 | H10: =IF(feasible_mat!H10=1,SUM(VLOOKUP($A10,main!$A$2:$L$34,12,FALSE), VLOOKUP(H$1,main!$A$2:$L$34,12,FALSE)),0) -> 0 | I10: =IF(feasible_mat!I10=1,SUM(VLOOKUP($A10,main!$A$2:$L$34,12,FALSE), VLOOKUP(I$1,main!$A$2:$L$34,12,FALSE)),0) -> 0 | J10: =IF(feasible_mat!J10=1,SUM(VLOOKUP($A10,main!$A$2:$L$34,12,FALSE), VLOOKUP(J$1,main!$A$2:$L$34,12,FALSE)),0) -> 0 | ... AH10: =IF(feasible_mat!AH10=1,SUM(VLOOKUP($A10,main!$A$2:$L$34,12,FALSE), VLOOKUP(AH$1,main!$A$2:$L$34,12,FALSE)),0) -> 0
A11: 9 | B11: 0 | C11: =IF(feasible_mat!C11=1,SUM(VLOOKUP($A11,main!$A$2:$L$34,12,FALSE), VLOOKUP(C$1,main!$A$2:$L$34,12,FALSE)),0) -> 0 | D11: =IF(feasible_mat!D11=1,SUM(VLOOKUP($A11,main!$A$2:$L$34,12,FALSE), VLOOKUP(D$1,main!$A$2:$L$34,12,FALSE)),0) -> 0 | E11: =IF(feasible_mat!E11=1,SUM(VLOOKUP($A11,main!$A$2:$L$34,12,FALSE), VLOOKUP(E$1,main!$A$2:$L$34,12,FALSE)),0) -> 0 | F11: =IF(feasible_mat!F11=1,SUM(VLOOKUP($A11,main!$A$2:$L$34,12,FALSE), VLOOKUP(F$1,main!$A$2:$L$34,12,FALSE)),0) -> 0 | G11: =IF(feasible_mat!G11=1,SUM(VLOOKUP($A11,main!$A$2:$L$34,12,FALSE), VLOOKUP(G$1,main!$A$2:$L$34,12,FALSE)),0) -> 0 | H11: =IF(feasible_mat!H11=1,SUM(VLOOKUP($A11,main!$A$2:$L$34,12,FALSE), VLOOKUP(H$1,main!$A$2:$L$34,12,FALSE)),0) -> 0 | I11: =IF(feasible_mat!I11=1,SUM(VLOOKUP($A11,main!$A$2:$L$34,12,FALSE), VLOOKUP(I$1,main!$A$2:$L$34,12,FALSE)),0) -> 0 | J11: =IF(feasible_mat!J11=1,SUM(VLOOKUP($A11,main!$A$2:$L$34,12,FALSE), VLOOKUP(J$1,main!$A$2:$L$34,12,FALSE)),0) -> 0 | ... AH11: =IF(feasible_mat!AH11=1,SUM(VLOOKUP($A11,main!$A$2:$L$34,12,FALSE), VLOOKUP(AH$1,main!$A$2:$L$34,12,FALSE)),0) -> 0
A12: 10 | B12: 0 | C12: =IF(feasible_mat!C12=1,SUM(VLOOKUP($A12,main!$A$2:$L$34,12,FALSE), VLOOKUP(C$1,main!$A$2:$L$34,12,FALSE)),0) -> 0 | D12: =IF(feasible_mat!D12=1,SUM(VLOOKUP($A12,main!$A$2:$L$34,12,FALSE), VLOOKUP(D$1,main!$A$2:$L$34,12,FALSE)),0) -> 0 | E12: =IF(feasible_mat!E12=1,SUM(VLOOKUP($A12,main!$A$2:$L$34,12,FALSE), VLOOKUP(E$1,main!$A$2:$L$34,12,FALSE)),0) -> 0 | F12: =IF(feasible_mat!F12=1,SUM(VLOOKUP($A12,main!$A$2:$L$34,12,FALSE), VLOOKUP(F$1,main!$A$2:$L$34,12,FALSE)),0) -> 0 | G12: =IF(feasible_mat!G12=1,SUM(VLOOKUP($A12,main!$A$2:$L$34,12,FALSE), VLOOKUP(G$1,main!$A$2:$L$34,12,FALSE)),0) -> 0 | H12: =IF(feasible_mat!H12=1,SUM(VLOOKUP($A12,main!$A$2:$L$34,12,FALSE), VLOOKUP(H$1,main!$A$2:$L$34,12,FALSE)),0) -> 0 | I12: =IF(feasible_mat!I12=1,SUM(VLOOKUP($A12,main!$A$2:$L$34,12,FALSE), VLOOKUP(I$1,main!$A$2:$L$34,12,FALSE)),0) -> 0 | J12: =IF(feasible_mat!J12=1,SUM(VLOOKUP($A12,main!$A$2:$L$34,12,FALSE), VLOOKUP(J$1,main!$A$2:$L$34,12,FALSE)),0) -> 0 | ... AH12: =IF(feasible_mat!AH12=1,SUM(VLOOKUP($A12,main!$A$2:$L$34,12,FALSE), VLOOKUP(AH$1,main!$A$2:$L$34,12,FALSE)),0) -> 0
A13: 11 | B13: 0 | C13: =IF(feasible_mat!C13=1,SUM(VLOOKUP($A13,main!$A$2:$L$34,12,FALSE), VLOOKUP(C$1,main!$A$2:$L$34,12,FALSE)),0) -> 0 | D13: =IF(feasible_mat!D13=1,SUM(VLOOKUP($A13,main!$A$2:$L$34,12,FALSE), VLOOKUP(D$1,main!$A$2:$L$34,12,FALSE)),0) -> 0 | E13: =IF(feasible_mat!E13=1,SUM(VLOOKUP($A13,main!$A$2:$L$34,12,FALSE), VLOOKUP(E$1,main!$A$2:$L$34,12,FALSE)),0) -> 0 | F13: =IF(feasible_mat!F13=1,SUM(VLOOKUP($A13,main!$A$2:$L$34,12,FALSE), VLOOKUP(F$1,main!$A$2:$L$34,12,FALSE)),0) -> 0 | G13: =IF(feasible_mat!G13=1,SUM(VLOOKUP($A13,main!$A$2:$L$34,12,FALSE), VLOOKUP(G$1,main!$A$2:$L$34,12,FALSE)),0) -> 0 | H13: =IF(feasible_mat!H13=1,SUM(VLOOKUP($A13,main!$A$2:$L$34,12,FALSE), VLOOKUP(H$1,main!$A$2:$L$34,12,FALSE)),0) -> 0 | I13: =IF(feasible_mat!I13=1,SUM(VLOOKUP($A13,main!$A$2:$L$34,12,FALSE), VLOOKUP(I$1,main!$A$2:$L$34,12,FALSE)),0) -> 0 | J13: =IF(feasible_mat!J13=1,SUM(VLOOKUP($A13,main!$A$2:$L$34,12,FALSE), VLOOKUP(J$1,main!$A$2:$L$34,12,FALSE)),0) -> 0 | ... AH13: =IF(feasible_mat!AH13=1,SUM(VLOOKUP($A13,main!$A$2:$L$34,12,FALSE), VLOOKUP(AH$1,main!$A$2:$L$34,12,FALSE)),0) -> 0
A14: 12 | B14: 0 | C14: =IF(feasible_mat!C14=1,SUM(VLOOKUP($A14,main!$A$2:$L$34,12,FALSE), VLOOKUP(C$1,main!$A$2:$L$34,12,FALSE)),0) -> 0 | D14: =IF(feasible_mat!D14=1,SUM(VLOOKUP($A14,main!$A$2:$L$34,12,FALSE), VLOOKUP(D$1,main!$A$2:$L$34,12,FALSE)),0) -> 0 | E14: =IF(feasible_mat!E14=1,SUM(VLOOKUP($A14,main!$A$2:$L$34,12,FALSE), VLOOKUP(E$1,main!$A$2:$L$34,12,FALSE)),0) -> 0 | F14: =IF(feasible_mat!F14=1,SUM(VLOOKUP($A14,main!$A$2:$L$34,12,FALSE), VLOOKUP(F$1,main!$A$2:$L$34,12,FALSE)),0) -> 0 | G14: =IF(feasible_mat!G14=1,SUM(VLOOKUP($A14,main!$A$2:$L$34,12,FALSE), VLOOKUP(G$1,main!$A$2:$L$34,12,FALSE)),0) -> 0 | H14: =IF(feasible_mat!H14=1,SUM(VLOOKUP($A14,main!$A$2:$L$34,12,FALSE), VLOOKUP(H$1,main!$A$2:$L$34,12,FALSE)),0) -> 0 | I14: =IF(feasible_mat!I14=1,SUM(VLOOKUP($A14,main!$A$2:$L$34,12,FALSE), VLOOKUP(I$1,main!$A$2:$L$34,12,FALSE)),0) -> 0 | J14: =IF(feasible_mat!J14=1,SUM(VLOOKUP($A14,main!$A$2:$L$34,12,FALSE), VLOOKUP(J$1,main!$A$2:$L$34,12,FALSE)),0) -> 0 | ... AH14: =IF(feasible_mat!AH14=1,SUM(VLOOKUP($A14,main!$A$2:$L$34,12,FALSE), VLOOKUP(AH$1,main!$A$2:$L$34,12,FALSE)),0) -> 0
... A34: 32 | B34: 0 | C34: =IF(feasible_mat!C34=1,SUM(VLOOKUP($A34,main!$A$2:$L$34,12,FALSE), VLOOKUP(C$1,main!$A$2:$L$34,12,FALSE)),0) -> 0 | D34: =IF(feasible_mat!D34=1,SUM(VLOOKUP($A34,main!$A$2:$L$34,12,FALSE), VLOOKUP(D$1,main!$A$2:$L$34,12,FALSE)),0) -> 0 | E34: =IF(feasible_mat!E34=1,SUM(VLOOKUP($A34,main!$A$2:$L$34,12,FALSE), VLOOKUP(E$1,main!$A$2:$L$34,12,FALSE)),0) -> 0 | F34: =IF(feasible_mat!F34=1,SUM(VLOOKUP($A34,main!$A$2:$L$34,12,FALSE), VLOOKUP(F$1,main!$A$2:$L$34,12,FALSE)),0) -> 0 | G34: =IF(feasible_mat!G34=1,SUM(VLOOKUP($A34,main!$A$2:$L$34,12,FALSE), VLOOKUP(G$1,main!$A$2:$L$34,12,FALSE)),0) -> 0 | H34: =IF(feasible_mat!H34=1,SUM(VLOOKUP($A34,main!$A$2:$L$34,12,FALSE), VLOOKUP(H$1,main!$A$2:$L$34,12,FALSE)),0) -> 0 | I34: =IF(feasible_mat!I34=1,SUM(VLOOKUP($A34,main!$A$2:$L$34,12,FALSE), VLOOKUP(I$1,main!$A$2:$L$34,12,FALSE)),0) -> 0 | J34: =IF(feasible_mat!J34=1,SUM(VLOOKUP($A34,main!$A$2:$L$34,12,FALSE), VLOOKUP(J$1,main!$A$2:$L$34,12,FALSE)),0) -> 0 | ... AH34: =IF(feasible_mat!AH34=1,SUM(VLOOKUP($A34,main!$A$2:$L$34,12,FALSE), VLOOKUP(AH$1,main!$A$2:$L$34,12,FALSE)),0) -> 0

Sheet recharge_mat
C1: 0 | D1: 1 | E1: 2 | F1: 3 | G1: 4 | H1: 5 | I1: 6 | J1: 7 | K1: 8 | L1: 9 | M1: 10 | N1: 11 | O1: 12 | P1: 13 | Q1: 14 | R1: 15 | S1: 16 | T1: 17 | U1: 18 | V1: 19 | W1: 20 | X1: 21 | Y1: 22 | Z1: 23 | AA1: 24 | AB1: 25 | AC1: 26 | AD1: 27 | AE1: 28 | AF1: 29 | AG1: 30
A2: 31 | B2: 0 | C2: 0 | D2: 0 | E2: 0 | F2: 0 | G2: 0 | H2: 0 | I2: 0 | J2: 0 | K2: 0 | L2: 0 | M2: 0 | N2: 0 | O2: 0 | P2: 0 | Q2: 0 | R2: 0 | S2: 0 | T2: 0 | U2: 0 | V2: 0 | W2: 0 | X2: 0 | Y2: 0 | Z2: 0 | AA2: 0 | AB2: 0 | AC2: 0 | AD2: 0 | AE2: 0 | AF2: 0 | AG2: 0
A3: 31 | B3: 1 | C3: 0 | D3: =IF(AND(VLOOKUP(D$1,main!$A$2:$L$34,8,FALSE) - VLOOKUP($B3,main!$A$2:$L$32,9,FALSE) >= (36+VLOOKUP(VLOOKUP(D$1,main!$A$2:$L$34,4,FALSE),main!$N$7:$P$9,2,FALSE))),1,0) -> 0 | E3: =IF(AND(VLOOKUP(E$1,main!$A$2:$L$34,8,FALSE) - VLOOKUP($B3,main!$A$2:$L$32,9,FALSE) >= (36+VLOOKUP(VLOOKUP(E$1,main!$A$2:$L$34,4,FALSE),main!$N$7:$P$9,2,FALSE))),1,0) -> 0 | F3: =IF(AND(VLOOKUP(F$1,main!$A$2:$L$34,8,FALSE) - VLOOKUP($B3,main!$A$2:$L$32,9,FALSE) >= (36+VLOOKUP(VLOOKUP(F$1,main!$A$2:$L$34,4,FALSE),main!$N$7:$P$9,2,FALSE))),1,0) -> 0 | G3: =IF(AND(VLOOKUP(G$1,main!$A$2:$L$34,8,FALSE) - VLOOKUP($B3,main!$A$2:$L$32,9,FALSE) >= (36+VLOOKUP(VLOOKUP(G$1,main!$A$2:$L$34,4,FALSE),main!$N$7:$P$9,2,FALSE))),1,0) -> 0 | H3: =IF(AND(VLOOKUP(H$1,main!$A$2:$L$34,8,FALSE) - VLOOKUP($B3,main!$A$2:$L$32,9,FALSE) >= (36+VLOOKUP(VLOOKUP(H$1,main!$A$2:$L$34,4,FALSE),main!$N$7:$P$9,2,FALSE))),1,0) -> 0 | I3: =IF(AND(VLOOKUP(I$1,main!$A$2:$L$34,8,FALSE) - VLOOKUP($B3,main!$A$2:$L$32,9,FALSE) >= (36+VLOOKUP(VLOOKUP(I$1,main!$A$2:$L$34,4,FALSE),main!$N$7:$P$9,2,FALSE))),1,0) -> 0 | J3: =IF(AND(VLOOKUP(J$1,main!$A$2:$L$34,8,FALSE) - VLOOKUP($B3,main!$A$2:$L$32,9,FALSE) >= (36+VLOOKUP(VLOOKUP(J$1,main!$A$2:$L$34,4,FALSE),main!$N$7:$P$9,2,FALSE))),1,0) -> 0 | K3: =IF(AND(VLOOKUP(K$1,main!$A$2:$L$34,8,FALSE) - VLOOKUP($B3,main!$A$2:$L$32,9,FALSE) >= (36+VLOOKUP(VLOOKUP(K$1,main!$A$2:$L$34,4,FALSE),main!$N$7:$P$9,2,FALSE))),1,0) -> 0 | ... AG3: =IF(AND(VLOOKUP(AG$1,main!$A$2:$L$34,8,FALSE) - VLOOKUP($B3,main!$A$2:$L$32,9,FALSE) >= (36+VLOOKUP(VLOOKUP(AG$1,main!$A$2:$L$34,4,FALSE),main!$N$7:$P$9,2,FALSE))),1,0) -> 1
A4: 31 | B4: 2 | C4: 0 | D4: =IF(AND(VLOOKUP(D$1,main!$A$2:$L$34,8,FALSE) - VLOOKUP($B4,main!$A$2:$L$32,9,FALSE) >= (36+VLOOKUP(VLOOKUP(D$1,main!$A$2:$L$34,4,FALSE),main!$N$7:$P$9,2,FALSE))),1,0) -> 0 | E4: =IF(AND(VLOOKUP(E$1,main!$A$2:$L$34,8,FALSE) - VLOOKUP($B4,main!$A$2:$L$32,9,FALSE) >= (36+VLOOKUP(VLOOKUP(E$1,main!$A$2:$L$34,4,FALSE),main!$N$7:$P$9,2,FALSE))),1,0) -> 0 | F4: =IF(AND(VLOOKUP(F$1,main!$A$2:$L$34,8,FALSE) - VLOOKUP($B4,main!$A$2:$L$32,9,FALSE) >= (36+VLOOKUP(VLOOKUP(F$1,main!$A$2:$L$34,4,FALSE),main!$N$7:$P$9,2,FALSE))),1,0) -> 0 | G4: =IF(AND(VLOOKUP(G$1,main!$A$2:$L$34,8,FALSE) - VLOOKUP($B4,main!$A$2:$L$32,9,FALSE) >= (36+VLOOKUP(VLOOKUP(G$1,main!$A$2:$L$34,4,FALSE),main!$N$7:$P$9,2,FALSE))),1,0) -> 0 | H4: =IF(AND(VLOOKUP(H$1,main!$A$2:$L$34,8,FALSE) - VLOOKUP($B4,main!$A$2:$L$32,9,FALSE) >= (36+VLOOKUP(VLOOKUP(H$1,main!$A$2:$L$34,4,FALSE),main!$N$7:$P$9,2,FALSE))),1,0) -> 0 | I4: =IF(AND(VLOOKUP(I$1,main!$A$2:$L$34,8,FALSE) - VLOOKUP($B4,main!$A$2:$L$32,9,FALSE) >= (36+VLOOKUP(VLOOKUP(I$1,main!$A$2:$L$34,4,FALSE),main!$N$7:$P$9,2,FALSE))),1,0) -> 0 | J4: =IF(AND(VLOOKUP(J$1,main!$A$2:$L$34,8,FALSE) - VLOOKUP($B4,main!$A$2:$L$32,9,FALSE) >= (36+VLOOKUP(VLOOKUP(J$1,main!$A$2:$L$34,4,FALSE),main!$N$7:$P$9,2,FALSE))),1,0) -> 0 | K4: =IF(AND(VLOOKUP(K$1,main!$A$2:$L$34,8,FALSE) - VLOOKUP($B4,main!$A$2:$L$32,9,FALSE) >= (36+VLOOKUP(VLOOKUP(K$1,main!$A$2:$L$34,4,FALSE),main!$N$7:$P$9,2,FALSE))),1,0) -> 0 | ... AG4: =IF(AND(VLOOKUP(AG$1,main!$A$2:$L$34,8,FALSE) - VLOOKUP($B4,main!$A$2:$L$32,9,FALSE) >= (36+VLOOKUP(VLOOKUP(AG$1,main!$A$2:$L$34,4,FALSE),main!$N$7:$P$9,2,FALSE))),1,0) -> 1
A5: 31 | B5: 3 | C5: 0 | D5: =IF(AND(VLOOKUP(D$1,main!$A$2:$L$34,8,FALSE) - VLOOKUP($B5,main!$A$2:$L$32,9,FALSE) >= (36+VLOOKUP(VLOOKUP(D$1,main!$A$2:$L$34,4,FALSE),main!$N$7:$P$9,2,FALSE))),1,0) -> 0 | E5: =IF(AND(VLOOKUP(E$1,main!$A$2:$L$34,8,FALSE) - VLOOKUP($B5,main!$A$2:$L$32,9,FALSE) >= (36+VLOOKUP(VLOOKUP(E$1,main!$A$2:$L$34,4,FALSE),main!$N$7:$P$9,2,FALSE))),1,0) -> 0 | F5: =IF(AND(VLOOKUP(F$1,main!$A$2:$L$34,8,FALSE) - VLOOKUP($B5,main!$A$2:$L$32,9,FALSE) >= (36+VLOOKUP(VLOOKUP(F$1,main!$A$2:$L$34,4,FALSE),main!$N$7:$P$9,2,FALSE))),1,0) -> 0 | G5: =IF(AND(VLOOKUP(G$1,main!$A$2:$L$34,8,FALSE) - VLOOKUP($B5,main!$A$2:$L$32,9,FALSE) >= (36+VLOOKUP(VLOOKUP(G$1,main!$A$2:$L$34,4,FALSE),main!$N$7:$P$9,2,FALSE))),1,0) -> 0 | H5: =IF(AND(VLOOKUP(H$1,main!$A$2:$L$34,8,FALSE) - VLOOKUP($B5,main!$A$2:$L$32,9,FALSE) >= (36+VLOOKUP(VLOOKUP(H$1,main!$A$2:$L$34,4,FALSE),main!$N$7:$P$9,2,FALSE))),1,0) -> 0 | I5: =IF(AND(VLOOKUP(I$1,main!$A$2:$L$34,8,FALSE) - VLOOKUP($B5,main!$A$2:$L$32,9,FALSE) >= (36+VLOOKUP(VLOOKUP(I$1,main!$A$2:$L$34,4,FALSE),main!$N$7:$P$9,2,FALSE))),1,0) -> 0 | J5: =IF(AND(VLOOKUP(J$1,main!$A$2:$L$34,8,FALSE) - VLOOKUP($B5,main!$A$2:$L$32,9,FALSE) >= (36+VLOOKUP(VLOOKUP(J$1,main!$A$2:$L$34,4,FALSE),main!$N$7:$P$9,2,FALSE))),1,0) -> 0 | K5: =IF(AND(VLOOKUP(K$1,main!$A$2:$L$34,8,FALSE) - VLOOKUP($B5,main!$A$2:$L$32,9,FALSE) >= (36+VLOOKUP(VLOOKUP(K$1,main!$A$2:$L$34,4,FALSE),main!$N$7:$P$9,2,FALSE))),1,0) -> 0 | ... AG5: =IF(AND(VLOOKUP(AG$1,main!$A$2:$L$34,8,FALSE) - VLOOKUP($B5,main!$A$2:$L$32,9,FALSE) >= (36+VLOOKUP(VLOOKUP(AG$1,main!$A$2:$L$34,4,FALSE),main!$N$7:$P$9,2,FALSE))),1,0) -> 1
A6: 31 | B6: 4 | C6: 0 | D6: =IF(AND(VLOOKUP(D$1,main!$A$2:$L$34,8,FALSE) - VLOOKUP($B6,main!$A$2:$L$32,9,FALSE) >= (36+VLOOKUP(VLOOKUP(D$1,main!$A$2:$L$34,4,FALSE),main!$N$7:$P$9,2,FALSE))),1,0) -> 0 | E6: =IF(AND(VLOOKUP(E$1,main!$A$2:$L$34,8,FALSE) - VLOOKUP($B6,main!$A$2:$L$32,9,FALSE) >= (36+VLOOKUP(VLOOKUP(E$1,main!$A$2:$L$34,4,FALSE),main!$N$7:$P$9,2,FALSE))),1,0) -> 0 | F6: =IF(AND(VLOOKUP(F$1,main!$A$2:$L$34,8,FALSE) - VLOOKUP($B6,main!$A$2:$L$32,9,FALSE) >= (36+VLOOKUP(VLOOKUP(F$1,main!$A$2:$L$34,4,FALSE),main!$N$7:$P$9,2,FALSE))),1,0) -> 0 | G6: =IF(AND(VLOOKUP(G$1,main!$A$2:$L$34,8,FALSE) - VLOOKUP($B6,main!$A$2:$L$32,9,FALSE) >= (36+VLOOKUP(VLOOKUP(G$1,main!$A$2:$L$34,4,FALSE),main!$N$7:$P$9,2,FALSE))),1,0) -> 0 | H6: =IF(AND(VLOOKUP(H$1,main!$A$2:$L$34,8,FALSE) - VLOOKUP($B6,main!$A$2:$L$32,9,FALSE) >= (36+VLOOKUP(VLOOKUP(H$1,main!$A$2:$L$34,4,FALSE),main!$N$7:$P$9,2,FALSE))),1,0) -> 0 | I6: =IF(AND(VLOOKUP(I$1,main!$A$2:$L$34,8,FALSE) - VLOOKUP($B6,main!$A$2:$L$32,9,FALSE) >= (36+VLOOKUP(VLOOKUP(I$1,main!$A$2:$L$34,4,FALSE),main!$N$7:$P$9,2,FALSE))),1,0) -> 0 | J6: =IF(AND(VLOOKUP(J$1,main!$A$2:$L$34,8,FALSE) - VLOOKUP($B6,main!$A$2:$L$32,9,FALSE) >= (36+VLOOKUP(VLOOKUP(J$1,main!$A$2:$L$34,4,FALSE),main!$N$7:$P$9,2,FALSE))),1,0) -> 0 | K6: =IF(AND(VLOOKUP(K$1,main!$A$2:$L$34,8,FALSE) - VLOOKUP($B6,main!$A$2:$L$32,9,FALSE) >= (36+VLOOKUP(VLOOKUP(K$1,main!$A$2:$L$34,4,FALSE),main!$N$7:$P$9,2,FALSE))),1,0) -> 0 | ... AG6: =IF(AND(VLOOKUP(AG$1,main!$A$2:$L$34,8,FALSE) - VLOOKUP($B6,main!$A$2:$L$32,9,FALSE) >= (36+VLOOKUP(VLOOKUP(AG$1,main!$A$2:$L$34,4,FALSE),main!$N$7:$P$9,2,FALSE))),1,0) -> 1
A7: 31 | B7: 5 | C7: 0 | D7: =IF(AND(VLOOKUP(D$1,main!$A$2:$L$34,8,FALSE) - VLOOKUP($B7,main!$A$2:$L$32,9,FALSE) >= (36+VLOOKUP(VLOOKUP(D$1,main!$A$2:$L$34,4,FALSE),main!$N$7:$P$9,2,FALSE))),1,0) -> 0 | E7: =IF(AND(VLOOKUP(E$1,main!$A$2:$L$34,8,FALSE) - VLOOKUP($B7,main!$A$2:$L$32,9,FALSE) >= (36+VLOOKUP(VLOOKUP(E$1,main!$A$2:$L$34,4,FALSE),main!$N$7:$P$9,2,FALSE))),1,0) -> 0 | F7: =IF(AND(VLOOKUP(F$1,main!$A$2:$L$34,8,FALSE) - VLOOKUP($B7,main!$A$2:$L$32,9,FALSE) >= (36+VLOOKUP(VLOOKUP(F$1,main!$A$2:$L$34,4,FALSE),main!$N$7:$P$9,2,FALSE))),1,0) -> 0 | G7: =IF(AND(VLOOKUP(G$1,main!$A$2:$L$34,8,FALSE) - VLOOKUP($B7,main!$A$2:$L$32,9,FALSE) >= (36+VLOOKUP(VLOOKUP(G$1,main!$A$2:$L$34,4,FALSE),main!$N$7:$P$9,2,FALSE))),1,0) -> 0 | H7: =IF(AND(VLOOKUP(H$1,main!$A$2:$L$34,8,FALSE) - VLOOKUP($B7,main!$A$2:$L$32,9,FALSE) >= (36+VLOOKUP(VLOOKUP(H$1,main!$A$2:$L$34,4,FALSE),main!$N$7:$P$9,2,FALSE))),1,0) -> 0 | I7: =IF(AND(VLOOKUP(I$1,main!$A$2:$L$34,8,FALSE) - VLOOKUP($B7,main!$A$2:$L$32,9,FALSE) >= (36+VLOOKUP(VLOOKUP(I$1,main!$A$2:$L$34,4,FALSE),main!$N$7:$P$9,2,FALSE))),1,0) -> 0 | J7: =IF(AND(VLOOKUP(J$1,main!$A$2:$L$34,8,FALSE) - VLOOKUP($B7,main!$A$2:$L$32,9,FALSE) >= (36+VLOOKUP(VLOOKUP(J$1,main!$A$2:$L$34,4,FALSE),main!$N$7:$P$9,2,FALSE))),1,0) -> 0 | K7: =IF(AND(VLOOKUP(K$1,main!$A$2:$L$34,8,FALSE) - VLOOKUP($B7,main!$A$2:$L$32,9,FALSE) >= (36+VLOOKUP(VLOOKUP(K$1,main!$A$2:$L$34,4,FALSE),main!$N$7:$P$9,2,FALSE))),1,0) -> 0 | ... AG7: =IF(AND(VLOOKUP(AG$1,main!$A$2:$L$34,8,FALSE) - VLOOKUP($B7,main!$A$2:$L$32,9,FALSE) >= (36+VLOOKUP(VLOOKUP(AG$1,main!$A$2:$L$34,4,FALSE),main!$N$7:$P$9,2,FALSE))),1,0) -> 1
A8: 31 | B8: 6 | C8: 0 | D8: =IF(AND(VLOOKUP(D$1,main!$A$2:$L$34,8,FALSE) - VLOOKUP($B8,main!$A$2:$L$32,9,FALSE) >= (36+VLOOKUP(VLOOKUP(D$1,main!$A$2:$L$34,4,FALSE),main!$N$7:$P$9,2,FALSE))),1,0) -> 0 | E8: =IF(AND(VLOOKUP(E$1,main!$A$2:$L$34,8,FALSE) - VLOOKUP($B8,main!$A$2:$L$32,9,FALSE) >= (36+VLOOKUP(VLOOKUP(E$1,main!$A$2:$L$34,4,FALSE),main!$N$7:$P$9,2,FALSE))),1,0) -> 0 | F8: =IF(AND(VLOOKUP(F$1,main!$A$2:$L$34,8,FALSE) - VLOOKUP($B8,main!$A$2:$L$32,9,FALSE) >= (36+VLOOKUP(VLOOKUP(F$1,main!$A$2:$L$34,4,FALSE),main!$N$7:$P$9,2,FALSE))),1,0) -> 0 | G8: =IF(AND(VLOOKUP(G$1,main!$A$2:$L$34,8,FALSE) - VLOOKUP($B8,main!$A$2:$L$32,9,FALSE) >= (36+VLOOKUP(VLOOKUP(G$1,main!$A$2:$L$34,4,FALSE),main!$N$7:$P$9,2,FALSE))),1,0) -> 0 | H8: =IF(AND(VLOOKUP(H$1,main!$A$2:$L$34,8,FALSE) - VLOOKUP($B8,main!$A$2:$L$32,9,FALSE) >= (36+VLOOKUP(VLOOKUP(H$1,main!$A$2:$L$34,4,FALSE),main!$N$7:$P$9,2,FALSE))),1,0) -> 0 | I8: =IF(AND(VLOOKUP(I$1,main!$A$2:$L$34,8,FALSE) - VLOOKUP($B8,main!$A$2:$L$32,9,FALSE) >= (36+VLOOKUP(VLOOKUP(I$1,main!$A$2:$L$34,4,FALSE),main!$N$7:$P$9,2,FALSE))),1,0) -> 0 | J8: =IF(AND(VLOOKUP(J$1,main!$A$2:$L$34,8,FALSE) - VLOOKUP($B8,main!$A$2:$L$32,9,FALSE) >= (36+VLOOKUP(VLOOKUP(J$1,main!$A$2:$L$34,4,FALSE),main!$N$7:$P$9,2,FALSE))),1,0) -> 0 | K8: =IF(AND(VLOOKUP(K$1,main!$A$2:$L$34,8,FALSE) - VLOOKUP($B8,main!$A$2:$L$32,9,FALSE) >= (36+VLOOKUP(VLOOKUP(K$1,main!$A$2:$L$34,4,FALSE),main!$N$7:$P$9,2,FALSE))),1,0) -> 0 | ... AG8: =IF(AND(VLOOKUP(AG$1,main!$A$2:$L$34,8,FALSE) - VLOOKUP($B8,main!$A$2:$L$32,9,FALSE) >= (36+VLOOKUP(VLOOKUP(AG$1,main!$A$2:$L$34,4,FALSE),main!$N$7:$P$9,2,FALSE))),1,0) -> 1
A9: 31 | B9: 7 | C9: 0 | D9: =IF(AND(VLOOKUP(D$1,main!$A$2:$L$34,8,FALSE) - VLOOKUP($B9,main!$A$2:$L$32,9,FALSE) >= (36+VLOOKUP(VLOOKUP(D$1,main!$A$2:$L$34,4,FALSE),main!$N$7:$P$9,2,FALSE))),1,0) -> 0 | E9: =IF(AND(VLOOKUP(E$1,main!$A$2:$L$34,8,FALSE) - VLOOKUP($B9,main!$A$2:$L$32,9,FALSE) >= (36+VLOOKUP(VLOOKUP(E$1,main!$A$2:$L$34,4,FALSE),main!$N$7:$P$9,2,FALSE))),1,0) -> 0 | F9: =IF(AND(VLOOKUP(F$1,main!$A$2:$L$34,8,FALSE) - VLOOKUP($B9,main!$A$2:$L$32,9,FALSE) >= (36+VLOOKUP(VLOOKUP(F$1,main!$A$2:$L$34,4,FALSE),main!$N$7:$P$9,2,FALSE))),1,0) -> 0 | G9: =IF(AND(VLOOKUP(G$1,main!$A$2:$L$34,8,FALSE) - VLOOKUP($B9,main!$A$2:$L$32,9,FALSE) >= (36+VLOOKUP(VLOOKUP(G$1,main!$A$2:$L$34,4,FALSE),main!$N$7:$P$9,2,FALSE))),1,0) -> 0 | H9: =IF(AND(VLOOKUP(H$1,main!$A$2:$L$34,8,FALSE) - VLOOKUP($B9,main!$A$2:$L$32,9,FALSE) >= (36+VLOOKUP(VLOOKUP(H$1,main!$A$2:$L$34,4,FALSE),main!$N$7:$P$9,2,FALSE))),1,0) -> 0 | I9: =IF(AND(VLOOKUP(I$1,main!$A$2:$L$34,8,FALSE) - VLOOKUP($B9,main!$A$2:$L$32,9,FALSE) >= (36+VLOOKUP(VLOOKUP(I$1,main!$A$2:$L$34,4,FALSE),main!$N$7:$P$9,2,FALSE))),1,0) -> 0 | J9: =IF(AND(VLOOKUP(J$1,main!$A$2:$L$34,8,FALSE) - VLOOKUP($B9,main!$A$2:$L$32,9,FALSE) >= (36+VLOOKUP(VLOOKUP(J$1,main!$A$2:$L$34,4,FALSE),main!$N$7:$P$9,2,FALSE))),1,0) -> 0 | K9: =IF(AND(VLOOKUP(K$1,main!$A$2:$L$34,8,FALSE) - VLOOKUP($B9,main!$A$2:$L$32,9,FALSE) >= (36+VLOOKUP(VLOOKUP(K$1,main!$A$2:$L$34,4,FALSE),main!$N$7:$P$9,2,FALSE))),1,0) -> 0 | ... AG9: =IF(AND(VLOOKUP(AG$1,main!$A$2:$L$34,8,FALSE) - VLOOKUP($B9,main!$A$2:$L$32,9,FALSE) >= (36+VLOOKUP(VLOOKUP(AG$1,main!$A$2:$L$34,4,FALSE),main!$N$7:$P$9,2,FALSE))),1,0) -> 1
A10: 31 | B10: 8 | C10: 0 | D10: =IF(AND(VLOOKUP(D$1,main!$A$2:$L$34,8,FALSE) - VLOOKUP($B10,main!$A$2:$L$32,9,FALSE) >= (36+VLOOKUP(VLOOKUP(D$1,main!$A$2:$L$34,4,FALSE),main!$N$7:$P$9,2,FALSE))),1,0) -> 0 | E10: =IF(AND(VLOOKUP(E$1,main!$A$2:$L$34,8,FALSE) - VLOOKUP($B10,main!$A$2:$L$32,9,FALSE) >= (36+VLOOKUP(VLOOKUP(E$1,main!$A$2:$L$34,4,FALSE),main!$N$7:$P$9,2,FALSE))),1,0) -> 0 | F10: =IF(AND(VLOOKUP(F$1,main!$A$2:$L$34,8,FALSE) - VLOOKUP($B10,main!$A$2:$L$32,9,FALSE) >= (36+VLOOKUP(VLOOKUP(F$1,main!$A$2:$L$34,4,FALSE),main!$N$7:$P$9,2,FALSE))),1,0) -> 0 | G10: =IF(AND(VLOOKUP(G$1,main!$A$2:$L$34,8,FALSE) - VLOOKUP($B10,main!$A$2:$L$32,9,FALSE) >= (36+VLOOKUP(VLOOKUP(G$1,main!$A$2:$L$34,4,FALSE),main!$N$7:$P$9,2,FALSE))),1,0) -> 0 | H10: =IF(AND(VLOOKUP(H$1,main!$A$2:$L$34,8,FALSE) - VLOOKUP($B10,main!$A$2:$L$32,9,FALSE) >= (36+VLOOKUP(VLOOKUP(H$1,main!$A$2:$L$34,4,FALSE),main!$N$7:$P$9,2,FALSE))),1,0) -> 0 | I10: =IF(AND(VLOOKUP(I$1,main!$A$2:$L$34,8,FALSE) - VLOOKUP($B10,main!$A$2:$L$32,9,FALSE) >= (36+VLOOKUP(VLOOKUP(I$1,main!$A$2:$L$34,4,FALSE),main!$N$7:$P$9,2,FALSE))),1,0) -> 0 | J10: =IF(AND(VLOOKUP(J$1,main!$A$2:$L$34,8,FALSE) - VLOOKUP($B10,main!$A$2:$L$32,9,FALSE) >= (36+VLOOKUP(VLOOKUP(J$1,main!$A$2:$L$34,4,FALSE),main!$N$7:$P$9,2,FALSE))),1,0) -> 0 | K10: =IF(AND(VLOOKUP(K$1,main!$A$2:$L$34,8,FALSE) - VLOOKUP($B10,main!$A$2:$L$32,9,FALSE) >= (36+VLOOKUP(VLOOKUP(K$1,main!$A$2:$L$34,4,FALSE),main!$N$7:$P$9,2,FALSE))),1,0) -> 0 | ... AG10: =IF(AND(VLOOKUP(AG$1,main!$A$2:$L$34,8,FALSE) - VLOOKUP($B10,main!$A$2:$L$32,9,FALSE) >= (36+VLOOKUP(VLOOKUP(AG$1,main!$A$2:$L$34,4,FALSE),main!$N$7:$P$9,2,FALSE))),1,0) -> 1
A11: 31 | B11: 9 | C11: 0 | D11: =IF(AND(VLOOKUP(D$1,main!$A$2:$L$34,8,FALSE) - VLOOKUP($B11,main!$A$2:$L$32,9,FALSE) >= (36+VLOOKUP(VLOOKUP(D$1,main!$A$2:$L$34,4,FALSE),main!$N$7:$P$9,2,FALSE))),1,0) -> 0 | E11: =IF(AND(VLOOKUP(E$1,main!$A$2:$L$34,8,FALSE) - VLOOKUP($B11,main!$A$2:$L$32,9,FALSE) >= (36+VLOOKUP(VLOOKUP(E$1,main!$A$2:$L$34,4,FALSE),main!$N$7:$P$9,2,FALSE))),1,0) -> 0 | F11: =IF(AND(VLOOKUP(F$1,main!$A$2:$L$34,8,FALSE) - VLOOKUP($B11,main!$A$2:$L$32,9,FALSE) >= (36+VLOOKUP(VLOOKUP(F$1,main!$A$2:$L$34,4,FALSE),main!$N$7:$P$9,2,FALSE))),1,0) -> 0 | G11: =IF(AND(VLOOKUP(G$1,main!$A$2:$L$34,8,FALSE) - VLOOKUP($B11,main!$A$2:$L$32,9,FALSE) >= (36+VLOOKUP(VLOOKUP(G$1,main!$A$2:$L$34,4,FALSE),main!$N$7:$P$9,2,FALSE))),1,0) -> 0 | H11: =IF(AND(VLOOKUP(H$1,main!$A$2:$L$34,8,FALSE) - VLOOKUP($B11,main!$A$2:$L$32,9,FALSE) >= (36+VLOOKUP(VLOOKUP(H$1,main!$A$2:$L$34,4,FALSE),main!$N$7:$P$9,2,FALSE))),1,0) -> 0 | I11: =IF(AND(VLOOKUP(I$1,main!$A$2:$L$34,8,FALSE) - VLOOKUP($B11,main!$A$2:$L$32,9,FALSE) >= (36+VLOOKUP(VLOOKUP(I$1,main!$A$2:$L$34,4,FALSE),main!$N$7:$P$9,2,FALSE))),1,0) -> 0 | J11: =IF(AND(VLOOKUP(J$1,main!$A$2:$L$34,8,FALSE) - VLOOKUP($B11,main!$A$2:$L$32,9,FALSE) >= (36+VLOOKUP(VLOOKUP(J$1,main!$A$2:$L$34,4,FALSE),main!$N$7:$P$9,2,FALSE))),1,0) -> 0 | K11: =IF(AND(VLOOKUP(K$1,main!$A$2:$L$34,8,FALSE) - VLOOKUP($B11,main!$A$2:$L$32,9,FALSE) >= (36+VLOOKUP(VLOOKUP(K$1,main!$A$2:$L$34,4,FALSE),main!$N$7:$P$9,2,FALSE))),1,0) -> 0 | ... AG11: =IF(AND(VLOOKUP(AG$1,main!$A$2:$L$34,8,FALSE) - VLOOKUP($B11,main!$A$2:$L$32,9,FALSE) >= (36+VLOOKUP(VLOOKUP(AG$1,main!$A$2:$L$34,4,FALSE),main!$N$7:$P$9,2,FALSE))),1,0) -> 1
A12: 31 | B12: 10 | C12: 0 | D12: =IF(AND(VLOOKUP(D$1,main!$A$2:$L$34,8,FALSE) - VLOOKUP($B12,main!$A$2:$L$32,9,FALSE) >= (36+VLOOKUP(VLOOKUP(D$1,main!$A$2:$L$34,4,FALSE),main!$N$7:$P$9,2,FALSE))),1,0) -> 0 | E12: =IF(AND(VLOOKUP(E$1,main!$A$2:$L$34,8,FALSE) - VLOOKUP($B12,main!$A$2:$L$32,9,FALSE) >= (36+VLOOKUP(VLOOKUP(E$1,main!$A$2:$L$34,4,FALSE),main!$N$7:$P$9,2,FALSE))),1,0) -> 0 | F12: =IF(AND(VLOOKUP(F$1,main!$A$2:$L$34,8,FALSE) - VLOOKUP($B12,main!$A$2:$L$32,9,FALSE) >= (36+VLOOKUP(VLOOKUP(F$1,main!$A$2:$L$34,4,FALSE),main!$N$7:$P$9,2,FALSE))),1,0) -> 0 | G12: =IF(AND(VLOOKUP(G$1,main!$A$2:$L$34,8,FALSE) - VLOOKUP($B12,main!$A$2:$L$32,9,FALSE) >= (36+VLOOKUP(VLOOKUP(G$1,main!$A$2:$L$34,4,FALSE),main!$N$7:$P$9,2,FALSE))),1,0) -> 0 | H12: =IF(AND(VLOOKUP(H$1,main!$A$2:$L$34,8,FALSE) - VLOOKUP($B12,main!$A$2:$L$32,9,FALSE) >= (36+VLOOKUP(VLOOKUP(H$1,main!$A$2:$L$34,4,FALSE),main!$N$7:$P$9,2,FALSE))),1,0) -> 0 | I12: =IF(AND(VLOOKUP(I$1,main!$A$2:$L$34,8,FALSE) - VLOOKUP($B12,main!$A$2:$L$32,9,FALSE) >= (36+VLOOKUP(VLOOKUP(I$1,main!$A$2:$L$34,4,FALSE),main!$N$7:$P$9,2,FALSE))),1,0) -> 0 | J12: =IF(AND(VLOOKUP(J$1,main!$A$2:$L$34,8,FALSE) - VLOOKUP($B12,main!$A$2:$L$32,9,FALSE) >= (36+VLOOKUP(VLOOKUP(J$1,main!$A$2:$L$34,4,FALSE),main!$N$7:$P$9,2,FALSE))),1,0) -> 0 | K12: =IF(AND(VLOOKUP(K$1,main!$A$2:$L$34,8,FALSE) - VLOOKUP($B12,main!$A$2:$L$32,9,FALSE) >= (36+VLOOKUP(VLOOKUP(K$1,main!$A$2:$L$34,4,FALSE),main!$N$7:$P$9,2,FALSE))),1,0) -> 0 | ... AG12: =IF(AND(VLOOKUP(AG$1,main!$A$2:$L$34,8,FALSE) - VLOOKUP($B12,main!$A$2:$L$32,9,FALSE) >= (36+VLOOKUP(VLOOKUP(AG$1,main!$A$2:$L$34,4,FALSE),main!$N$7:$P$9,2,FALSE))),1,0) -> 1
A13: 31 | B13: 11 | C13: 0 | D13: =IF(AND(VLOOKUP(D$1,main!$A$2:$L$34,8,FALSE) - VLOOKUP($B13,main!$A$2:$L$32,9,FALSE) >= (36+VLOOKUP(VLOOKUP(D$1,main!$A$2:$L$34,4,FALSE),main!$N$7:$P$9,2,FALSE))),1,0) -> 0 | E13: =IF(AND(VLOOKUP(E$1,main!$A$2:$L$34,8,FALSE) - VLOOKUP($B13,main!$A$2:$L$32,9,FALSE) >= (36+VLOOKUP(VLOOKUP(E$1,main!$A$2:$L$34,4,FALSE),main!$N$7:$P$9,2,FALSE))),1,0) -> 0 | F13: =IF(AND(VLOOKUP(F$1,main!$A$2:$L$34,8,FALSE) - VLOOKUP($B13,main!$A$2:$L$32,9,FALSE) >= (36+VLOOKUP(VLOOKUP(F$1,main!$A$2:$L$34,4,FALSE),main!$N$7:$P$9,2,FALSE))),1,0) -> 0 | G13: =IF(AND(VLOOKUP(G$1,main!$A$2:$L$34,8,FALSE) - VLOOKUP($B13,main!$A$2:$L$32,9,FALSE) >= (36+VLOOKUP(VLOOKUP(G$1,main!$A$2:$L$34,4,FALSE),main!$N$7:$P$9,2,FALSE))),1,0) -> 0 | H13: =IF(AND(VLOOKUP(H$1,main!$A$2:$L$34,8,FALSE) - VLOOKUP($B13,main!$A$2:$L$32,9,FALSE) >= (36+VLOOKUP(VLOOKUP(H$1,main!$A$2:$L$34,4,FALSE),main!$N$7:$P$9,2,FALSE))),1,0) -> 0 | I13: =IF(AND(VLOOKUP(I$1,main!$A$2:$L$34,8,FALSE) - VLOOKUP($B13,main!$A$2:$L$32,9,FALSE) >= (36+VLOOKUP(VLOOKUP(I$1,main!$A$2:$L$34,4,FALSE),main!$N$7:$P$9,2,FALSE))),1,0) -> 0 | J13: =IF(AND(VLOOKUP(J$1,main!$A$2:$L$34,8,FALSE) - VLOOKUP($B13,main!$A$2:$L$32,9,FALSE) >= (36+VLOOKUP(VLOOKUP(J$1,main!$A$2:$L$34,4,FALSE),main!$N$7:$P$9,2,FALSE))),1,0) -> 0 | K13: =IF(AND(VLOOKUP(K$1,main!$A$2:$L$34,8,FALSE) - VLOOKUP($B13,main!$A$2:$L$32,9,FALSE) >= (36+VLOOKUP(VLOOKUP(K$1,main!$A$2:$L$34,4,FALSE),main!$N$7:$P$9,2,FALSE))),1,0) -> 0 | ... AG13: =IF(AND(VLOOKUP(AG$1,main!$A$2:$L$34,8,FALSE) - VLOOKUP($B13,main!$A$2:$L$32,9,FALSE) >= (36+VLOOKUP(VLOOKUP(AG$1,main!$A$2:$L$34,4,FALSE),main!$N$7:$P$9,2,FALSE))),1,0) -> 1
A14: 31 | B14: 12 | C14: 0 | D14: =IF(AND(VLOOKUP(D$1,main!$A$2:$L$34,8,FALSE) - VLOOKUP($B14,main!$A$2:$L$32,9,FALSE) >= (36+VLOOKUP(VLOOKUP(D$1,main!$A$2:$L$34,4,FALSE),main!$N$7:$P$9,2,FALSE))),1,0) -> 0 | E14: =IF(AND(VLOOKUP(E$1,main!$A$2:$L$34,8,FALSE) - VLOOKUP($B14,main!$A$2:$L$32,9,FALSE) >= (36+VLOOKUP(VLOOKUP(E$1,main!$A$2:$L$34,4,FALSE),main!$N$7:$P$9,2,FALSE))),1,0) -> 0 | F14: =IF(AND(VLOOKUP(F$1,main!$A$2:$L$34,8,FALSE) - VLOOKUP($B14,main!$A$2:$L$32,9,FALSE) >= (36+VLOOKUP(VLOOKUP(F$1,main!$A$2:$L$34,4,FALSE),main!$N$7:$P$9,2,FALSE))),1,0) -> 0 | G14: =IF(AND(VLOOKUP(G$1,main!$A$2:$L$34,8,FALSE) - VLOOKUP($B14,main!$A$2:$L$32,9,FALSE) >= (36+VLOOKUP(VLOOKUP(G$1,main!$A$2:$L$34,4,FALSE),main!$N$7:$P$9,2,FALSE))),1,0) -> 0 | H14: =IF(AND(VLOOKUP(H$1,main!$A$2:$L$34,8,FALSE) - VLOOKUP($B14,main!$A$2:$L$32,9,FALSE) >= (36+VLOOKUP(VLOOKUP(H$1,main!$A$2:$L$34,4,FALSE),main!$N$7:$P$9,2,FALSE))),1,0) -> 0 | I14: =IF(AND(VLOOKUP(I$1,main!$A$2:$L$34,8,FALSE) - VLOOKUP($B14,main!$A$2:$L$32,9,FALSE) >= (36+VLOOKUP(VLOOKUP(I$1,main!$A$2:$L$34,4,FALSE),main!$N$7:$P$9,2,FALSE))),1,0) -> 0 | J14: =IF(AND(VLOOKUP(J$1,main!$A$2:$L$34,8,FALSE) - VLOOKUP($B14,main!$A$2:$L$32,9,FALSE) >= (36+VLOOKUP(VLOOKUP(J$1,main!$A$2:$L$34,4,FALSE),main!$N$7:$P$9,2,FALSE))),1,0) -> 0 | K14: =IF(AND(VLOOKUP(K$1,main!$A$2:$L$34,8,FALSE) - VLOOKUP($B14,main!$A$2:$L$32,9,FALSE) >= (36+VLOOKUP(VLOOKUP(K$1,main!$A$2:$L$34,4,FALSE),main!$N$7:$P$9,2,FALSE))),1,0) -> 0 | ... AG14: =IF(AND(VLOOKUP(AG$1,main!$A$2:$L$34,8,FALSE) - VLOOKUP($B14,main!$A$2:$L$32,9,FALSE) >= (36+VLOOKUP(VLOOKUP(AG$1,main!$A$2:$L$34,4,FALSE),main!$N$7:$P$9,2,FALSE))),1,0) -> 1
... A32: 31 | B32: 30 | C32: 0 | D32: =IF(AND(VLOOKUP(D$1,main!$A$2:$L$34,8,FALSE) - VLOOKUP($B32,main!$A$2:$L$32,9,FALSE) >= (36+VLOOKUP(VLOOKUP(D$1,main!$A$2:$L$34,4,FALSE),main!$N$7:$P$9,2,FALSE))),1,0) -> 0 | E32: =IF(AND(VLOOKUP(E$1,main!$A$2:$L$34,8,FALSE) - VLOOKUP($B32,main!$A$2:$L$32,9,FALSE) >= (36+VLOOKUP(VLOOKUP(E$1,main!$A$2:$L$34,4,FALSE),main!$N$7:$P$9,2,FALSE))),1,0) -> 0 | F32: =IF(AND(VLOOKUP(F$1,main!$A$2:$L$34,8,FALSE) - VLOOKUP($B32,main!$A$2:$L$32,9,FALSE) >= (36+VLOOKUP(VLOOKUP(F$1,main!$A$2:$L$34,4,FALSE),main!$N$7:$P$9,2,FALSE))),1,0) -> 0 | G32: =IF(AND(VLOOKUP(G$1,main!$A$2:$L$34,8,FALSE) - VLOOKUP($B32,main!$A$2:$L$32,9,FALSE) >= (36+VLOOKUP(VLOOKUP(G$1,main!$A$2:$L$34,4,FALSE),main!$N$7:$P$9,2,FALSE))),1,0) -> 0 | H32: =IF(AND(VLOOKUP(H$1,main!$A$2:$L$34,8,FALSE) - VLOOKUP($B32,main!$A$2:$L$32,9,FALSE) >= (36+VLOOKUP(VLOOKUP(H$1,main!$A$2:$L$34,4,FALSE),main!$N$7:$P$9,2,FALSE))),1,0) -> 0 | I32: =IF(AND(VLOOKUP(I$1,main!$A$2:$L$34,8,FALSE) - VLOOKUP($B32,main!$A$2:$L$32,9,FALSE) >= (36+VLOOKUP(VLOOKUP(I$1,main!$A$2:$L$34,4,FALSE),main!$N$7:$P$9,2,FALSE))),1,0) -> 0 | J32: =IF(AND(VLOOKUP(J$1,main!$A$2:$L$34,8,FALSE) - VLOOKUP($B32,main!$A$2:$L$32,9,FALSE) >= (36+VLOOKUP(VLOOKUP(J$1,main!$A$2:$L$34,4,FALSE),main!$N$7:$P$9,2,FALSE))),1,0) -> 0 | K32: =IF(AND(VLOOKUP(K$1,main!$A$2:$L$34,8,FALSE) - VLOOKUP($B32,main!$A$2:$L$32,9,FALSE) >= (36+VLOOKUP(VLOOKUP(K$1,main!$A$2:$L$34,4,FALSE),main!$N$7:$P$9,2,FALSE))),1,0) -> 0 | ... AG32: =IF(AND(VLOOKUP(AG$1,main!$A$2:$L$34,8,FALSE) - VLOOKUP($B32,main!$A$2:$L$32,9,FALSE) >= (36+VLOOKUP(VLOOKUP(AG$1,main!$A$2:$L$34,4,FALSE),main!$N$7:$P$9,2,FALSE))),1,0) -> 0
A33: 32 | B33: 0 | C33: 0 | D33: 0 | E33: 0 | F33: 0 | G33: 0 | H33: 0 | I33: 0 | J33: 0 | K33: 0 | L33: 0 | M33: 0 | N33: 0 | O33: 0 | P33: 0 | Q33: 0 | R33: 0 | S33: 0 | T33: 0 | U33: 0 | V33: 0 | W33: 0 | X33: 0 | Y33: 0 | Z33: 0 | AA33: 0 | AB33: 0 | AC33: 0 | AD33: 0 | AE33: 0 | AF33: 0 | AG33: 0
A34: 32 | B34: 1 | C34: 0 | D34: =IF(AND(VLOOKUP(D$1,main!$A$2:$L$34,8,FALSE) - VLOOKUP($B34,main!$A$2:$L$32,9,FALSE) >= (36+VLOOKUP(VLOOKUP(D$1,main!$A$2:$L$34,4,FALSE),main!$N$7:$P$9,3,FALSE))),1,0) -> 0 | E34: =IF(AND(VLOOKUP(E$1,main!$A$2:$L$34,8,FALSE) - VLOOKUP($B34,main!$A$2:$L$32,9,FALSE) >= (36+VLOOKUP(VLOOKUP(E$1,main!$A$2:$L$34,4,FALSE),main!$N$7:$P$9,3,FALSE))),1,0) -> 0 | F34: =IF(AND(VLOOKUP(F$1,main!$A$2:$L$34,8,FALSE) - VLOOKUP($B34,main!$A$2:$L$32,9,FALSE) >= (36+VLOOKUP(VLOOKUP(F$1,main!$A$2:$L$34,4,FALSE),main!$N$7:$P$9,3,FALSE))),1,0) -> 0 | G34: =IF(AND(VLOOKUP(G$1,main!$A$2:$L$34,8,FALSE) - VLOOKUP($B34,main!$A$2:$L$32,9,FALSE) >= (36+VLOOKUP(VLOOKUP(G$1,main!$A$2:$L$34,4,FALSE),main!$N$7:$P$9,3,FALSE))),1,0) -> 0 | H34: =IF(AND(VLOOKUP(H$1,main!$A$2:$L$34,8,FALSE) - VLOOKUP($B34,main!$A$2:$L$32,9,FALSE) >= (36+VLOOKUP(VLOOKUP(H$1,main!$A$2:$L$34,4,FALSE),main!$N$7:$P$9,3,FALSE))),1,0) -> 0 | I34: =IF(AND(VLOOKUP(I$1,main!$A$2:$L$34,8,FALSE) - VLOOKUP($B34,main!$A$2:$L$32,9,FALSE) >= (36+VLOOKUP(VLOOKUP(I$1,main!$A$2:$L$34,4,FALSE),main!$N$7:$P$9,3,FALSE))),1,0) -> 0 | J34: =IF(AND(VLOOKUP(J$1,main!$A$2:$L$34,8,FALSE) - VLOOKUP($B34,main!$A$2:$L$32,9,FALSE) >= (36+VLOOKUP(VLOOKUP(J$1,main!$A$2:$L$34,4,FALSE),main!$N$7:$P$9,3,FALSE))),1,0) -> 0 | K34: =IF(AND(VLOOKUP(K$1,main!$A$2:$L$34,8,FALSE) - VLOOKUP($B34,main!$A$2:$L$32,9,FALSE) >= (36+VLOOKUP(VLOOKUP(K$1,main!$A$2:$L$34,4,FALSE),main!$N$7:$P$9,3,FALSE))),1,0) -> 0 | ... AG34: =IF(AND(VLOOKUP(AG$1,main!$A$2:$L$34,8,FALSE) - VLOOKUP($B34,main!$A$2:$L$32,9,FALSE) >= (36+VLOOKUP(VLOOKUP(AG$1,main!$A$2:$L$34,4,FALSE),main!$N$7:$P$9,3,FALSE))),1,0) -> 1
A35: 32 | B35: 2 | C35: 0 | D35: =IF(AND(VLOOKUP(D$1,main!$A$2:$L$34,8,FALSE) - VLOOKUP($B35,main!$A$2:$L$32,9,FALSE) >= (36+VLOOKUP(VLOOKUP(D$1,main!$A$2:$L$34,4,FALSE),main!$N$7:$P$9,3,FALSE))),1,0) -> 0 | E35: =IF(AND(VLOOKUP(E$1,main!$A$2:$L$34,8,FALSE) - VLOOKUP($B35,main!$A$2:$L$32,9,FALSE) >= (36+VLOOKUP(VLOOKUP(E$1,main!$A$2:$L$34,4,FALSE),main!$N$7:$P$9,3,FALSE))),1,0) -> 0 | F35: =IF(AND(VLOOKUP(F$1,main!$A$2:$L$34,8,FALSE) - VLOOKUP($B35,main!$A$2:$L$32,9,FALSE) >= (36+VLOOKUP(VLOOKUP(F$1,main!$A$2:$L$34,4,FALSE),main!$N$7:$P$9,3,FALSE))),1,0) -> 0 | G35: =IF(AND(VLOOKUP(G$1,main!$A$2:$L$34,8,FALSE) - VLOOKUP($B35,main!$A$2:$L$32,9,FALSE) >= (36+VLOOKUP(VLOOKUP(G$1,main!$A$2:$L$34,4,FALSE),main!$N$7:$P$9,3,FALSE))),1,0) -> 0 | H35: =IF(AND(VLOOKUP(H$1,main!$A$2:$L$34,8,FALSE) - VLOOKUP($B35,main!$A$2:$L$32,9,FALSE) >= (36+VLOOKUP(VLOOKUP(H$1,main!$A$2:$L$34,4,FALSE),main!$N$7:$P$9,3,FALSE))),1,0) -> 0 | I35: =IF(AND(VLOOKUP(I$1,main!$A$2:$L$34,8,FALSE) - VLOOKUP($B35,main!$A$2:$L$32,9,FALSE) >= (36+VLOOKUP(VLOOKUP(I$1,main!$A$2:$L$34,4,FALSE),main!$N$7:$P$9,3,FALSE))),1,0) -> 0 | J35: =IF(AND(VLOOKUP(J$1,main!$A$2:$L$34,8,FALSE) - VLOOKUP($B35,main!$A$2:$L$32,9,FALSE) >= (36+VLOOKUP(VLOOKUP(J$1,main!$A$2:$L$34,4,FALSE),main!$N$7:$P$9,3,FALSE))),1,0) -> 0 | K35: =IF(AND(VLOOKUP(K$1,main!$A$2:$L$34,8,FALSE) - VLOOKUP($B35,main!$A$2:$L$32,9,FALSE) >= (36+VLOOKUP(VLOOKUP(K$1,main!$A$2:$L$34,4,FALSE),main!$N$7:$P$9,3,FALSE))),1,0) -> 0 | ... AG35: =IF(AND(VLOOKUP(AG$1,main!$A$2:$L$34,8,FALSE) - VLOOKUP($B35,main!$A$2:$L$32,9,FALSE) >= (36+VLOOKUP(VLOOKUP(AG$1,main!$A$2:$L$34,4,FALSE),main!$N$7:$P$9,3,FALSE))),1,0) -> 1
A36: 32 | B36: 3 | C36: 0 | D36: =IF(AND(VLOOKUP(D$1,main!$A$2:$L$34,8,FALSE) - VLOOKUP($B36,main!$A$2:$L$32,9,FALSE) >= (36+VLOOKUP(VLOOKUP(D$1,main!$A$2:$L$34,4,FALSE),main!$N$7:$P$9,3,FALSE))),1,0) -> 0 | E36: =IF(AND(VLOOKUP(E$1,main!$A$2:$L$34,8,FALSE) - VLOOKUP($B36,main!$A$2:$L$32,9,FALSE) >= (36+VLOOKUP(VLOOKUP(E$1,main!$A$2:$L$34,4,FALSE),main!$N$7:$P$9,3,FALSE))),1,0) -> 0 | F36: =IF(AND(VLOOKUP(F$1,main!$A$2:$L$34,8,FALSE) - VLOOKUP($B36,main!$A$2:$L$32,9,FALSE) >= (36+VLOOKUP(VLOOKUP(F$1,main!$A$2:$L$34,4,FALSE),main!$N$7:$P$9,3,FALSE))),1,0) -> 0 | G36: =IF(AND(VLOOKUP(G$1,main!$A$2:$L$34,8,FALSE) - VLOOKUP($B36,main!$A$2:$L$32,9,FALSE) >= (36+VLOOKUP(VLOOKUP(G$1,main!$A$2:$L$34,4,FALSE),main!$N$7:$P$9,3,FALSE))),1,0) -> 0 | H36: =IF(AND(VLOOKUP(H$1,main!$A$2:$L$34,8,FALSE) - VLOOKUP($B36,main!$A$2:$L$32,9,FALSE) >= (36+VLOOKUP(VLOOKUP(H$1,main!$A$2:$L$34,4,FALSE),main!$N$7:$P$9,3,FALSE))),1,0) -> 0 | I36: =IF(AND(VLOOKUP(I$1,main!$A$2:$L$34,8,FALSE) - VLOOKUP($B36,main!$A$2:$L$32,9,FALSE) >= (36+VLOOKUP(VLOOKUP(I$1,main!$A$2:$L$34,4,FALSE),main!$N$7:$P$9,3,FALSE))),1,0) -> 0 | J36: =IF(AND(VLOOKUP(J$1,main!$A$2:$L$34,8,FALSE) - VLOOKUP($B36,main!$A$2:$L$32,9,FALSE) >= (36+VLOOKUP(VLOOKUP(J$1,main!$A$2:$L$34,4,FALSE),main!$N$7:$P$9,3,FALSE))),1,0) -> 0 | K36: =IF(AND(VLOOKUP(K$1,main!$A$2:$L$34,8,FALSE) - VLOOKUP($B36,main!$A$2:$L$32,9,FALSE) >= (36+VLOOKUP(VLOOKUP(K$1,main!$A$2:$L$34,4,FALSE),main!$N$7:$P$9,3,FALSE))),1,0) -> 0 | ... AG36: =IF(AND(VLOOKUP(AG$1,main!$A$2:$L$34,8,FALSE) - VLOOKUP($B36,main!$A$2:$L$32,9,FALSE) >= (36+VLOOKUP(VLOOKUP(AG$1,main!$A$2:$L$34,4,FALSE),main!$N$7:$P$9,3,FALSE))),1,0) -> 1
